{
  "xsize": 16,
  "zsize": 16,
  "palette": {
    "palette": [
      {
        "char": " ",
        "block": "minecraft:air"
      },
      {
        "char": "o",
        "block": "minecraft:cyan_terracotta"
      },
      {
        "char": "i",
        "block": "minecraft:glass"
      },
      {
        "char": "ӛ",
        "block": "minecraft:air"
      },
      {
        "char": "将",
        "block": "immersive_weathering:exposed_iron_bars[east\u003dfalse,north\u003dtrue,south\u003dfalse,waterlogged\u003dfalse,west\u003dfalse]"
      },
      {
        "char": "ѓ",
        "block": "minecraft:air"
      },
      {
        "char": "7",
        "block": "minecraft:air"
      },
      {
        "char": "ύ",
        "block": "minecraft:air"
      },
      {
        "char": "ӣ",
        "block": "minecraft:air"
      },
      {
        "char": "给",
        "block": "immersive_weathering:exposed_iron_bars[east\u003dfalse,north\u003dfalse,south\u003dfalse,waterlogged\u003dfalse,west\u003dtrue]"
      },
      {
        "char": "x",
        "block": "minecraft:air"
      },
      {
        "char": "є",
        "block": "immersive_weathering:exposed_iron_bars[east\u003dfalse,north\u003dfalse,south\u003dfalse,waterlogged\u003dfalse,west\u003dfalse]"
      },
      {
        "char": "ӗ",
        "block": "minecraft:air"
      },
      {
        "char": "数",
        "block": "minecraft:air"
      },
      {
        "char": "Ә",
        "block": "immersive_weathering:exposed_iron_bars[east\u003dfalse,north\u003dtrue,south\u003dtrue,waterlogged\u003dfalse,west\u003dfalse]"
      },
      {
        "char": "系",
        "block": "minecraft:air"
      },
      {
        "char": "u",
        "block": "minecraft:light_gray_concrete"
      },
      {
        "char": "他",
        "block": "immersive_weathering:exposed_iron_bars[east\u003dtrue,north\u003dfalse,south\u003dfalse,waterlogged\u003dfalse,west\u003dtrue]"
      },
      {
        "char": "y",
        "block": "minecraft:gray_concrete"
      },
      {
        "char": "猜",
        "block": "minecraft:air"
      },
      {
        "char": "门",
        "block": "minecraft:air"
      },
      {
        "char": "吗",
        "block": "immersive_weathering:exposed_iron_bars[east\u003dfalse,north\u003dfalse,south\u003dtrue,waterlogged\u003dfalse,west\u003dfalse]"
      },
      {
        "char": "排",
        "block": "minecraft:air"
      },
      {
        "char": "主",
        "block": "immersive_weathering:exposed_iron_bars[east\u003dtrue,north\u003dfalse,south\u003dfalse,waterlogged\u003dfalse,west\u003dfalse]"
      },
      {
        "char": "3",
        "block": "minecraft:stone_brick_wall[east\u003dnone,north\u003dnone,south\u003dnone,up\u003dtrue,waterlogged\u003dfalse,weathering\u003dfalse,west\u003dnone]"
      }
    ]
  },
  "slices": [
    [
      "                ",
      "                ",
      "              o ",
      "            iiii",
      "         iiiiiii",
      "        ӛiii  将 ",
      "       ѓ 7      ",
      "         ύ      ",
      "     iiӛ7       ",
      "     ii        7",
      "     ii        ύ",
      "    ii         ӣ",
      "    ii       ӛ ӛ",
      "   oii给      xє ",
      "          7ѓ xx7",
      "    ii    ӗ   7 "
    ],
    [
      "                ",
      "                ",
      "              o ",
      "              ii",
      "          iiiiii",
      "        ӛ数ii  Ә ",
      "       ѓ 系    将 ",
      "        系ύ      ",
      "       ӛ7       ",
      "      i        7",
      "     i         ύ",
      "     i         ӣ",
      "    ii         ӛ",
      "   uii他给      є ",
      "    ii    7ѓ  x7",
      "     ii   ӗ     "
    ],
    [
      "                ",
      "                ",
      "              y ",
      "              u ",
      "           iii i",
      "        ӛiiiiiii",
      "       ѓiii   将 ",
      "        i猜      ",
      "       ӛ门       ",
      "      ii       7",
      "     ii        ύ",
      "      i        ӣ",
      "      i        ӛ",
      "   ooi є      єx",
      "     ii   7ѓ  x7",
      "     ii   ӗ     "
    ],
    [
      "                ",
      "                ",
      "                ",
      "              o ",
      "            iiii",
      "          iii   ",
      "        iii   吗 ",
      "       iii    将 ",
      "        i       ",
      "       i       7",
      "       i       ύ",
      "     ii        ӣ",
      "     i         排",
      "    yii他给     єx",
      "      i   7ѓ    ",
      "     ii   ӗ     "
    ],
    [
      "                ",
      "                ",
      "                ",
      "              u ",
      "              u ",
      "           iiiii",
      "         iiiiii ",
      "        iii   Ә ",
      "        ii    将 ",
      "       i       7",
      "      ii       ύ",
      "      ii       ӣ",
      "       i       x",
      "    uoi 主给    єx",
      "      ii  7ѓ    ",
      "      i   ӗ     "
    ],
    [
      "                ",
      "                ",
      "                ",
      "                ",
      "              u ",
      "              u ",
      "           i i i",
      "          iiiiii",
      "        iii   Ә ",
      "        ii    将7",
      "        i      ύ",
      "       i       ӣ",
      "       ii       ",
      "     ou i他给   3 ",
      "        i 7ѓ    ",
      "       ii ӗ     "
    ]
  ]
}