{
  "xsize": 16,
  "zsize": 16,
  "palette": {
    "palette": [
      {
        "char": " ",
        "block": "minecraft:air"
      },
      {
        "char": "h",
        "block": "minecraft:air"
      },
      {
        "char": "y",
        "block": "minecraft:air"
      },
      {
        "char": "c",
        "block": "minecraft:air"
      },
      {
        "char": "E",
        "block": "minecraft:air"
      },
      {
        "char": "H",
        "block": "minecraft:air"
      },
      {
        "char": "i",
        "block": "minecraft:diorite"
      },
      {
        "char": "G",
        "block": "minecraft:air"
      },
      {
        "char": "d",
        "block": "minecraft:air"
      },
      {
        "char": "Χ",
        "block": "immersive_weathering:exposed_iron_bars[east\u003dtrue,north\u003dfalse,south\u003dfalse,waterlogged\u003dfalse,west\u003dfalse]"
      },
      {
        "char": "ͽ",
        "block": "minecraft:loom[facing\u003dwest]"
      },
      {
        "char": "v",
        "block": "minecraft:gray_stained_glass"
      },
      {
        "char": "a",
        "block": "minecraft:smooth_quartz"
      },
      {
        "char": "R",
        "block": "minecraft:stone_slab[type\u003dbottom,waterlogged\u003dfalse,weathering\u003dfalse]"
      },
      {
        "char": "e",
        "block": "minecraft:polished_andesite"
      },
      {
        "char": "Q",
        "block": "minecraft:air"
      },
      {
        "char": "n",
        "block": "minecraft:stone[weathering\u003dfalse]"
      },
      {
        "char": "2",
        "block": "minecraft:polished_andesite_slab[type\u003dbottom,waterlogged\u003dfalse]"
      },
      {
        "char": "4",
        "block": "immersive_weathering:exposed_iron_bars[east\u003dfalse,north\u003dtrue,south\u003dfalse,waterlogged\u003dfalse,west\u003dfalse]"
      },
      {
        "char": "x",
        "block": "minecraft:white_concrete"
      },
      {
        "char": "ͺ",
        "block": "immersive_weathering:exposed_iron_bars[east\u003dfalse,north\u003dfalse,south\u003dfalse,waterlogged\u003dfalse,west\u003dfalse]"
      },
      {
        "char": "A",
        "block": "immersive_weathering:mossy_stone"
      },
      {
        "char": "s",
        "block": "minecraft:air"
      },
      {
        "char": "K",
        "block": "minecraft:air"
      },
      {
        "char": "ѩ",
        "block": "immersive_weathering:exposed_iron_bars[east\u003dtrue,north\u003dtrue,south\u003dtrue,waterlogged\u003dfalse,west\u003dfalse]"
      },
      {
        "char": "Ј",
        "block": "immersive_weathering:weathered_iron_bars[east\u003dtrue,north\u003dtrue,south\u003dfalse,waterlogged\u003dfalse,west\u003dfalse]"
      }
    ]
  },
  "slices": [
    [
      " hy  cEEE HiGddE",
      "   ΧͽvvvvvaRaaaa",
      "     cccccheQc  ",
      "         ccc    ",
      "                ",
      "                ",
      "                ",
      "                ",
      "                ",
      "                ",
      "                ",
      "                ",
      "                ",
      "                ",
      "                ",
      "                "
    ],
    [
      "     caaaaaaGdda",
      "     Χiiiiinaaaa",
      "      c cch2Qc  ",
      "         ccc    ",
      "                ",
      "                ",
      "                ",
      "                ",
      "                ",
      "                ",
      "                ",
      "                ",
      "                ",
      "                ",
      "                ",
      "                "
    ],
    [
      "  4   ͽdd  addda",
      "      vvvvx2iaaa",
      "          hnQc  ",
      "         ccc    ",
      "                ",
      "                ",
      "                ",
      "                ",
      "                ",
      "                ",
      "                ",
      "                ",
      "                ",
      "                ",
      "                ",
      "                "
    ],
    [
      "  ͺ   ͽdd  add a",
      "      vvvvaeivaa",
      "          hAQc  ",
      "         ccc    ",
      "                ",
      "                ",
      "                ",
      "                ",
      "                ",
      "                ",
      "                ",
      "                ",
      "                ",
      "                ",
      "                ",
      "                "
    ],
    [
      "  4  sEEE  iEE a",
      "     aaaxaanaiii",
      "           n K  ",
      "         ccc    ",
      "                ",
      "                ",
      "                ",
      "                ",
      "                ",
      "                ",
      "                ",
      "                ",
      "                ",
      "                ",
      "                ",
      "                "
    ],
    [
      "  Raaaaaiaaiiaai",
      "   ѩeeeeeAnneeee",
      "   ЈnneneAAARenn",
      "         ccc    ",
      "                ",
      "                ",
      "                ",
      "                ",
      "                ",
      "                ",
      "                ",
      "                ",
      "                ",
      "                ",
      "                ",
      "                "
    ]
  ]
}