{
  "xsize": 16,
  "zsize": 16,
  "palette": {
    "palette": [
      {
        "char": " ",
        "block": "minecraft:air"
      },
      {
        "char": "d",
        "block": "minecraft:air"
      },
      {
        "char": "Ή",
        "block": "minecraft:rail[shape\u003dnorth_east,waterlogged\u003dfalse]"
      },
      {
        "char": "Ύ",
        "block": "minecraft:rail[shape\u003dnorth_west,waterlogged\u003dfalse]"
      },
      {
        "char": "k",
        "block": "minecraft:terracotta"
      },
      {
        "char": "g",
        "block": "minecraft:air"
      },
      {
        "char": "o",
        "block": "immersive_weathering:mossy_bricks"
      },
      {
        "char": "Ϲ",
        "block": "minecraft:cobblestone_wall[east\u003dnone,north\u003dnone,south\u003dtall,up\u003dtrue,waterlogged\u003dfalse,weathering\u003dfalse,west\u003dtall]"
      },
      {
        "char": "Ё",
        "block": "minecraft:cobblestone_wall[east\u003dtall,north\u003dnone,south\u003dtall,up\u003dtrue,waterlogged\u003dfalse,weathering\u003dfalse,west\u003dnone]"
      },
      {
        "char": "b",
        "block": "minecraft:bricks[weathering\u003dfalse]"
      },
      {
        "char": "l",
        "block": "minecraft:granite"
      },
      {
        "char": "a",
        "block": "minecraft:smooth_quartz"
      },
      {
        "char": "h",
        "block": "minecraft:air"
      },
      {
        "char": "n",
        "block": "minecraft:stone[weathering\u003dfalse]"
      },
      {
        "char": "c",
        "block": "minecraft:air"
      },
      {
        "char": "e",
        "block": "minecraft:polished_andesite"
      },
      {
        "char": "υ",
        "block": "minecraft:mossy_cobblestone_wall[east\u003dnone,north\u003dnone,south\u003dtall,up\u003dtrue,waterlogged\u003dfalse,west\u003dnone]"
      },
      {
        "char": "0",
        "block": "minecraft:polished_andesite_slab[type\u003ddouble,waterlogged\u003dfalse]"
      },
      {
        "char": "E",
        "block": "minecraft:air"
      },
      {
        "char": "F",
        "block": "minecraft:cobblestone_wall[east\u003dnone,north\u003dtall,south\u003dtall,up\u003dfalse,waterlogged\u003dfalse,weathering\u003dfalse,west\u003dnone]"
      },
      {
        "char": "ζ",
        "block": "minecraft:mossy_cobblestone_wall[east\u003dnone,north\u003dtall,south\u003dtall,up\u003dfalse,waterlogged\u003dfalse,west\u003dnone]"
      },
      {
        "char": "H",
        "block": "minecraft:air"
      },
      {
        "char": "M",
        "block": "minecraft:air"
      },
      {
        "char": "K",
        "block": "minecraft:air"
      },
      {
        "char": "R",
        "block": "minecraft:stone_slab[type\u003dbottom,waterlogged\u003dfalse,weathering\u003dfalse]"
      },
      {
        "char": "f",
        "block": "minecraft:gray_concrete"
      },
      {
        "char": "N",
        "block": "minecraft:quartz_pillar[axis\u003dy]"
      },
      {
        "char": "u",
        "block": "minecraft:smooth_stone_slab[type\u003dbottom,waterlogged\u003dfalse]"
      },
      {
        "char": "Ί",
        "block": "minecraft:rail[shape\u003dsouth_east,waterlogged\u003dfalse]"
      },
      {
        "char": "Ό",
        "block": "minecraft:rail[shape\u003dsouth_west,waterlogged\u003dfalse]"
      }
    ]
  },
  "slices": [
    [
      " dd ddΉΎ  ddkg  ",
      "oooϹ     Ёobbg  ",
      "llbaaaaaaabbkg  ",
      "lbo       lbbg  ",
      "hng  c     ec   ",
      " c              ",
      "                ",
      "                ",
      "                ",
      "                ",
      "                ",
      "                ",
      "                ",
      "                ",
      "                ",
      "                "
    ],
    [
      " ddυdddd υddlg  ",
      "oklbbololbblog  ",
      "lkkklbbklllkkg  ",
      "kbkblkkkokbklg  ",
      "h0g  c     n    ",
      " c              ",
      "                ",
      "                ",
      "                ",
      "                ",
      "                ",
      "                ",
      "                ",
      "                ",
      "                ",
      "                "
    ],
    [
      " E F     ζEEog  ",
      "kobblobkkbobkg  ",
      "blklbbbllbkblg  ",
      "bllbboboobblbg  ",
      "H0M  K     n    ",
      " c              ",
      "                ",
      "                ",
      "                ",
      "                ",
      "                ",
      "                ",
      "                ",
      "                ",
      "                ",
      "                "
    ],
    [
      "bblbbbklblokb   ",
      "bokbllbkbkkbb   ",
      "bbblbbkbbblblg  ",
      "lbbbbblklblbbg  ",
      "eReeeeneeeeR    ",
      "                ",
      "                ",
      "                ",
      "                ",
      "                ",
      "                ",
      "                ",
      "                ",
      "                ",
      "                ",
      "                "
    ],
    [
      " fffff  NNN u   ",
      "        NNN u   ",
      "            u   ",
      "uuuuuuuuuuuuu   ",
      "                ",
      "                ",
      "                ",
      "                ",
      "                ",
      "                ",
      "                ",
      "                ",
      "                ",
      "                ",
      "                ",
      "                "
    ],
    [
      "        ΊΌ      ",
      "        ΉΎ      ",
      "                ",
      "                ",
      "                ",
      "                ",
      "                ",
      "                ",
      "                ",
      "                ",
      "                ",
      "                ",
      "                ",
      "                ",
      "                ",
      "                "
    ]
  ]
}