{
  "xsize": 16,
  "zsize": 16,
  "palette": {
    "palette": [
      {
        "char": " ",
        "block": "minecraft:air"
      },
      {
        "char": "d",
        "block": "minecraft:air"
      },
      {
        "char": "y",
        "block": "minecraft:air"
      },
      {
        "char": "b",
        "block": "minecraft:bricks[weathering\u003dfalse]"
      },
      {
        "char": "o",
        "block": "immersive_weathering:mossy_bricks"
      },
      {
        "char": "k",
        "block": "minecraft:terracotta"
      },
      {
        "char": "l",
        "block": "minecraft:granite"
      },
      {
        "char": "ϼ",
        "block": "immersive_weathering:mossy_brick_slab[type\u003dbottom,waterlogged\u003dfalse]"
      },
      {
        "char": "c",
        "block": "minecraft:air"
      },
      {
        "char": "g",
        "block": "minecraft:air"
      },
      {
        "char": "h",
        "block": "minecraft:air"
      },
      {
        "char": "Ί",
        "block": "minecraft:rail[shape\u003dsouth_east,waterlogged\u003dfalse]"
      },
      {
        "char": "Ό",
        "block": "minecraft:rail[shape\u003dsouth_west,waterlogged\u003dfalse]"
      },
      {
        "char": "L",
        "block": "minecraft:rail[shape\u003dnorth_south,waterlogged\u003dfalse]"
      },
      {
        "char": "E",
        "block": "minecraft:air"
      },
      {
        "char": "Φ",
        "block": "minecraft:brick_slab[type\u003dbottom,waterlogged\u003dfalse,weathering\u003dfalse]"
      },
      {
        "char": "K",
        "block": "minecraft:air"
      },
      {
        "char": "s",
        "block": "minecraft:air"
      },
      {
        "char": "·",
        "block": "minecraft:cobblestone_wall[east\u003dnone,north\u003dnone,south\u003dtall,up\u003dtrue,waterlogged\u003dfalse,weathering\u003dfalse,west\u003dnone]"
      },
      {
        "char": "F",
        "block": "minecraft:cobblestone_wall[east\u003dnone,north\u003dtall,south\u003dtall,up\u003dfalse,waterlogged\u003dfalse,weathering\u003dfalse,west\u003dnone]"
      },
      {
        "char": "H",
        "block": "minecraft:air"
      },
      {
        "char": "ζ",
        "block": "minecraft:mossy_cobblestone_wall[east\u003dnone,north\u003dtall,south\u003dtall,up\u003dfalse,waterlogged\u003dfalse,west\u003dnone]"
      },
      {
        "char": "G",
        "block": "minecraft:air"
      },
      {
        "char": "u",
        "block": "minecraft:smooth_stone_slab[type\u003dbottom,waterlogged\u003dfalse]"
      },
      {
        "char": "f",
        "block": "minecraft:gray_concrete"
      },
      {
        "char": "I",
        "block": "minecraft:yellow_concrete"
      },
      {
        "char": "щ",
        "block": "horror_element_mod:marine_body[facing\u003dnorth,waterlogged\u003dfalse]"
      }
    ]
  },
  "slices": [
    [
      "                ",
      "                ",
      "d               ",
      " ddy  ddddy     ",
      "bokkbbbkolbyϼ   ",
      " ccc  c  g  d   ",
      "           hbg  ",
      "            bg  ",
      "            k   ",
      "            k   ",
      "      ΊΌ    bg  ",
      "      LL   hl   ",
      "      LL   hk   ",
      "      LL    b   ",
      "      LL   hl   ",
      "      LL    k   "
    ],
    [
      "                ",
      "                ",
      "d               ",
      " EEy  dddd      ",
      "lkbbbbkkkby     ",
      "  c      g      ",
      "            d   ",
      "            bg  ",
      "            b   ",
      "            b   ",
      "            k   ",
      "           hl   ",
      "           ho   ",
      "            b   ",
      "           hk   ",
      "            b   "
    ],
    [
      "                ",
      "                ",
      "d               ",
      " yyd   dd       ",
      "llokbkbooΦ      ",
      "  K      g      ",
      "                ",
      "      sss       ",
      "        sss k   ",
      "   ·     ·s b   ",
      "   F     F sl   ",
      "   F     F Hk   ",
      "   F     F Hb   ",
      "   F     F sb   ",
      "   F     FsHo   ",
      "   F     ζs l   "
    ],
    [
      "                ",
      "                ",
      "d               ",
      "yGdd   dd       ",
      "boblkbookg      ",
      "bbllbllbbg      ",
      "kbkbbbkbbkΦ     ",
      "bbbbkblkobb Φ   ",
      "bkklbkbboobkb   ",
      "kbbbbkkklbobb   ",
      "bbkbbblbbbbbk   ",
      "obbbblbbbbbol   ",
      "obbbkblkbbbkk   ",
      "lllbkblkkokol   ",
      "oolbbbblboblb   ",
      "bllbbkbbkklkb   "
    ],
    [
      "                ",
      "                ",
      "                ",
      "                ",
      "yuuuuuuuu       ",
      "                ",
      "                ",
      "                ",
      " fffff      u   ",
      "fffffff     u   ",
      "fIfffIff    u   ",
      "fIfffIff    u   ",
      "fIIIIIff    u   ",
      "fIfffIff    u   ",
      "fIfffIff    u   ",
      "fffffff щ   u   "
    ],
    [
      "                ",
      "                ",
      "                ",
      "                ",
      "                ",
      "                ",
      "                ",
      "                ",
      "                ",
      "                ",
      "                ",
      "                ",
      "                ",
      "                ",
      "                ",
      "                "
    ]
  ]
}