{
  "xsize": 16,
  "zsize": 16,
  "palette": {
    "palette": [
      {
        "char": " ",
        "block": "minecraft:structure_voiducture_voiducture_void"
      },
      {
        "char": "a",
        "block": "minecraft:dirt"
      },
      {
        "char": "D",
        "block": "minecraft:stone[weathering\u003dfalse]"
      },
      {
        "char": "t",
        "block": "create:layered_tuff"
      },
      {
        "char": "C",
        "block": "minecraft:cobblestone[weathering\u003dfalse]"
      },
      {
        "char": "g",
        "block": "minecraft:smooth_stone"
      },
      {
        "char": "y",
        "block": "minecraft:cobblestone[weathering\u003dtrue]"
      },
      {
        "char": "w",
        "block": "minecraft:stone[weathering\u003dtrue]"
      },
      {
        "char": "n",
        "block": "minecraft:polished_basalt[axis\u003dy]"
      },
      {
        "char": "E",
        "block": "minecraft:deepslate_bricks[weathering\u003dfalse]"
      },
      {
        "char": "i",
        "block": "minecraft:basalt[axis\u003dy]"
      },
      {
        "char": "d",
        "block": "minecraft:stone_bricks[weathering\u003dtrue]"
      },
      {
        "char": "b",
        "block": "minecraft:water[level\u003d0]"
      },
      {
        "char": "q",
        "block": "minecraft:deepslate_bricks[weathering\u003dtrue]"
      },
      {
        "char": "k",
        "block": "minecraft:cracked_deepslate_bricks"
      },
      {
        "char": "I",
        "block": "minecraft:kelp_plant"
      },
      {
        "char": "Q",
        "block": "minecraft:air"
      },
      {
        "char": "m",
        "block": "minecraft:cracked_stone_bricks"
      },
      {
        "char": "ҿ",
        "block": "minecraft:kelp[age\u003d3]"
      },
      {
        "char": "à",
        "block": "minecraft:kelp[age\u003d13]"
      }
    ]
  },
  "slices": [
    [
      "aaaaaaaaaaaaaaaa",
      "aaaaaaaaaaaaaaaa",
      "aaaaaaaaaaaaaaaa",
      "aaaaaaaaaaaaaaaa",
      "aaaaaaaaaaaaaaaa",
      "aaaaaaaaaaaaaaaa",
      "aaaaaaaaaaaaaaaa",
      "aaaaaaaaaaaaaaaa",
      "aaaaaaaaaaaaaaaa",
      "aaaaaaaaaaaaaaaa",
      "aaaaaaaaaaaaaaaa",
      "aaaaaaaaaaaaaaaa",
      "aaaaaaaaaaaaaaaa",
      "aaaaaaaaaaaaaaaa",
      "aaaaaaaaaaaaaaaa",
      "aaaaaaaaaaaaaaaa"
    ],
    [
      "aaaaaaaaaaaaaaaa",
      "aaaaaaaaaaaaaaaa",
      "aaaaaaaaaaaaaaaa",
      "aaaaaaaaaaaaaaaa",
      "aaaaaaaaaaaaaaaa",
      "aaaaaaaaaaaaaaaa",
      "aaaaaaaaaaaaaaaa",
      "aaaaaaaaaaaaaaaa",
      "aaaaaaaaaaaaaaaa",
      "aaaaaaaaaaaaaaaa",
      "DtCCggggtgCgaaaa",
      "ygwtwtyttggtaaaa",
      "gtytgwtwyggtaaaa",
      "gygwggygwwwCaaaa",
      "DwttggwygygDaaaa",
      "tgttytgggwgDaaaa"
    ],
    [
      "aaaaaaaaaaaaaaaa",
      "aaaaaaaaaaaaaaaa",
      "aaaaaaaaaaaaaaaa",
      "aaaaaaaaaaaaaaaa",
      "aaaaaaaaaaaaaaaa",
      "aaaaaaaaaaaaaaaa",
      "aaaaaaaaaaaaaaaa",
      "aaaaaaaaaaaaaaaa",
      "aaaaaaaaaaaaaaaa",
      "aaaaaaaaaaaaaaaa",
      "nEididddidEdaaaa",
      "bbbbbbbbbbbEaaaa",
      "bbbbbbbbbbbqaaaa",
      "bbbbbbbbbbbkaaaa",
      "kbEdbbbbbbbiaaaa",
      "IQIibbbbbbbqaaaa"
    ],
    [
      "aaaaaaaaaaaaaaaa",
      "aaaaaaaaaaaaaaaa",
      "aaaaaaaaaaaaaaaa",
      "aaaaaaaaaaaaaaaa",
      "aaaaaaaaaaaaaaaa",
      "aaaaaaaaaaaaaaaa",
      "aaaaaaaaaaaaaaaa",
      "aaaaaaaaaaaaaaaa",
      "aaaaaaaaaaaaaaaa",
      "aaaaaaaaaaaaaaaa",
      "kdiEddqkniikaaaa",
      "bbbbbbbbbbbdaaaa",
      "bbbbbbbbbbbiaaaa",
      "bbbbbbbbbbbqaaaa",
      "nbiibbbbbbbqaaaa",
      "IbIdbbbbbbbmaaaa"
    ],
    [
      "aaaaaaaaaaaaaaaa",
      "aaaaaaaaaaaaaaaa",
      "aaaaaaaaaaaaaaaa",
      "aaaaaaaaaaaaaaaa",
      "aaaaaaaaaaaaaaaa",
      "aaaaaaaaaaaaaaaa",
      "aaaaaaaaaaaaaaaa",
      "aaaaaaaaaaaaaaaa",
      "aaaaaaaaaaaaaaaa",
      "aaaaaaaaaaaaaaaa",
      "nkdndEikkiqkaaaa",
      "bbbbbbbbbbbdaaaa",
      "bbbbbbbbbbbkaaaa",
      "bbbbbbbbbbbiaaaa",
      "nbEibbbbbbbqaaaa",
      "ҿbInbbbbbbbiaaaa"
    ],
    [
      "aaaaaaaaaaaaaaaa",
      "aaaaaaaaaaaaaaaa",
      "aaaaaaaaaaaaaaaa",
      "aaaaaaaaaaaaaaaa",
      "aaaaaaaaaaaaaaaa",
      "aaaaaaaaaaaaaaaa",
      "aaaaaaaaaaaaaaaa",
      "aaaaaaaaaaaaaaaa",
      "aaaaaaaaaaaaaaaa",
      "aaaaaaaaaaaaaaaa",
      "EinddnkddqEiaaaa",
      "bbbbbbbbbbbkaaaa",
      "bbbbbbbbbbbnaaaa",
      "bbbbbbbbbbbdaaaa",
      "Edqibbbbbbbkaaaa",
      "bbàkbbbbbbbkaaaa"
    ]
  ]
}