{
  "xsize": 16,
  "zsize": 16,
  "palette": {
    "palette": [
      {
        "char": " ",
        "block": "minecraft:structure_voiducture_void"
      },
      {
        "char": "a",
        "block": "minecraft:dirt"
      },
      {
        "char": "g",
        "block": "minecraft:smooth_stone"
      },
      {
        "char": "t",
        "block": "create:layered_tuff"
      },
      {
        "char": "D",
        "block": "minecraft:stone[weathering\u003dfalse]"
      },
      {
        "char": "C",
        "block": "minecraft:cobblestone[weathering\u003dfalse]"
      },
      {
        "char": "w",
        "block": "minecraft:stone[weathering\u003dtrue]"
      },
      {
        "char": "y",
        "block": "minecraft:cobblestone[weathering\u003dtrue]"
      },
      {
        "char": "i",
        "block": "minecraft:basalt[axis\u003dy]"
      },
      {
        "char": "n",
        "block": "minecraft:polished_basalt[axis\u003dy]"
      },
      {
        "char": "d",
        "block": "minecraft:stone_bricks[weathering\u003dtrue]"
      },
      {
        "char": "k",
        "block": "minecraft:cracked_deepslate_bricks"
      },
      {
        "char": "b",
        "block": "minecraft:water[level\u003d0]"
      },
      {
        "char": "E",
        "block": "minecraft:deepslate_bricks[weathering\u003dfalse]"
      },
      {
        "char": "q",
        "block": "minecraft:deepslate_bricks[weathering\u003dtrue]"
      },
      {
        "char": "Q",
        "block": "minecraft:air"
      },
      {
        "char": "Ӯ",
        "block": "doomsday_decoration:insulationcabinet[facing\u003dsouth,waterlogged\u003dtrue]"
      },
      {
        "char": "х",
        "block": "doomsday_decoration:goodsshelves_5[facing\u003dsouth,waterlogged\u003dtrue]"
      },
      {
        "char": "I",
        "block": "minecraft:kelp_plant"
      },
      {
        "char": "M",
        "block": "minecraft:seagrass"
      },
      {
        "char": "ϗ",
        "block": "doomsday_decoration:goodsshelves[facing\u003dsouth,waterlogged\u003dtrue]"
      },
      {
        "char": "а",
        "block": "doomsday_decoration:goodsshelves_4[facing\u003dsouth,waterlogged\u003dtrue]"
      },
      {
        "char": "ж",
        "block": "doomsday_decoration:goodsshelves_3[facing\u003dsouth,waterlogged\u003dtrue]"
      },
      {
        "char": "m",
        "block": "minecraft:cracked_stone_bricks"
      },
      {
        "char": "ҿ",
        "block": "minecraft:kelp[age\u003d3]"
      },
      {
        "char": "子",
        "block": "minecraft:kelp[age\u003d8]"
      }
    ]
  },
  "slices": [
    [
      "aaaaaaaaaaaaaaaa",
      "aaaaaaaaaaaaaaaa",
      "aaaaaaaaaaaaaaaa",
      "aaaaaaaaaaaaaaaa",
      "aaaaaaaaaaaaaaaa",
      "aaaaaaaaaaaaaaaa",
      "aaaaaaaaaaaaaaaa",
      "aaaaaaaaaaaaaaaa",
      "aaaaaaaaaaaaaaaa",
      "aaaaaaaaaaaaaaaa",
      "aaaaaaaaaaaaaaaa",
      "aaaaaaaaaaaaaaaa",
      "aaaaaaaaaaaaaaaa",
      "aaaaaaaaaaaaaaaa",
      "aaaaaaaaaaaaaaaa",
      "aaaaaaaaaaaaaaaa"
    ],
    [
      "aaaaaaaaaaaaaaaa",
      "aaaaaaaaaaaaaaaa",
      "aaaaaaaaaaaaaaaa",
      "aaaaaaaaaaaaaaaa",
      "aaaaaaaaaaaaaaaa",
      "aaaaaaaaaaaaaaaa",
      "aaaaaaaaaaaaaaaa",
      "aaaaaaaaaaaaaaaa",
      "aaaaaaaaaaaaaaaa",
      "aaaaaaaaaaaaaaaa",
      "gtgDgtCCgCDttgDg",
      "ggwggwygtwggyggy",
      "wgwytwttggggggwy",
      "gyygygtgwttyggwg",
      "DgCggtwgtgggggCg",
      "ggywggygtgtgggyy"
    ],
    [
      "aaaaaaaaaaaaaaaa",
      "aaaaaaaaaaaaaaaa",
      "aaaaaaaaaaaaaaaa",
      "aaaaaaaaaaaaaaaa",
      "aaaaaaaaaaaaaaaa",
      "aaaaaaaaaaaaaaaa",
      "aaaaaaaaaaaaaaaa",
      "aaaaaaaaaaaaaaaa",
      "aaaaaaaaaaaaaaaa",
      "aaaaaaaaaaaaaaaa",
      "indiikdiiddinnki",
      "bbbbbbbbbbbbbbbb",
      "bbbbbbbbbbbbbbbb",
      "bbbbbbbbbbbbbbbb",
      "EnniiibqkinqkdEn",
      "QӮхIQQbMkQbӮхIbb"
    ],
    [
      "aaaaaaaaaaaaaaaa",
      "aaaaaaaaaaaaaaaa",
      "aaaaaaaaaaaaaaaa",
      "aaaaaaaaaaaaaaaa",
      "aaaaaaaaaaaaaaaa",
      "aaaaaaaaaaaaaaaa",
      "aaaaaaaaaaaaaaaa",
      "aaaaaaaaaaaaaaaa",
      "aaaaaaaaaaaaaaaa",
      "aaaaaaaaaaaaaaaa",
      "knndkdikndddkqin",
      "bbbbbbbbbbbbbbbb",
      "bbbbbbbbbbbbbbbb",
      "bbbbbbbbbbbbbbbb",
      "ikikikbEikniqidi",
      "bbϗIQbbbiQbbϗIbb"
    ],
    [
      "aaaaaaaaaaaaaaaa",
      "aaaaaaaaaaaaaaaa",
      "aaaaaaaaaaaaaaaa",
      "aaaaaaaaaaaaaaaa",
      "aaaaaaaaaaaaaaaa",
      "aaaaaaaaaaaaaaaa",
      "aaaaaaaaaaaaaaaa",
      "aaaaaaaaaaaaaaaa",
      "aaaaaaaaaaaaaaaa",
      "aaaaaaaaaaaaaaaa",
      "diEnkndnEEidkqnk",
      "bbbbbbbbbbbbbbbb",
      "bbbbbbbbbbbbbbbb",
      "bbbbbbbbbbbbbbbb",
      "Enqqiqbqqkikkkqi",
      "ϗажIbbbbkbϗажIbb"
    ],
    [
      "aaaaaaaaaaaaaaaa",
      "aaaaaaaaaaaaaaaa",
      "aaaaaaaaaaaaaaaa",
      "aaaaaaaaaaaaaaaa",
      "aaaaaaaaaaaaaaaa",
      "aaaaaaaaaaaaaaaa",
      "aaaaaaaaaaaaaaaa",
      "aaaaaaaaaaaaaaaa",
      "aaaaaaaaaaaaaaaa",
      "aaaaaaaaaaaaaaaa",
      "dniidqinniqEiimi",
      "bbbbbbbbbbbbbbbb",
      "bbbbbbbbbbbbbbbb",
      "bbbbbbbbbbbbbbbb",
      "qkinkqnkkqkqiikq",
      "bbbҿbbbbdbbbb子bb"
    ]
  ]
}