{
  "xsize": 16,
  "zsize": 16,
  "palette": {
    "palette": [
      {
        "char": " ",
        "block": "minecraft:structure_void"
      },
      {
        "char": "a",
        "block": "minecraft:dirt"
      },
      {
        "char": "g",
        "block": "minecraft:smooth_stone"
      },
      {
        "char": "w",
        "block": "minecraft:stone[weathering\u003dtrue]"
      },
      {
        "char": "D",
        "block": "minecraft:stone[weathering\u003dfalse]"
      },
      {
        "char": "t",
        "block": "create:layered_tuff"
      },
      {
        "char": "y",
        "block": "minecraft:cobblestone[weathering\u003dtrue]"
      },
      {
        "char": "i",
        "block": "minecraft:basalt[axis\u003dy]"
      },
      {
        "char": "k",
        "block": "minecraft:cracked_deepslate_bricks"
      },
      {
        "char": "b",
        "block": "minecraft:water[level\u003d0]"
      },
      {
        "char": "E",
        "block": "minecraft:deepslate_bricks[weathering\u003dfalse]"
      },
      {
        "char": "q",
        "block": "minecraft:deepslate_bricks[weathering\u003dtrue]"
      },
      {
        "char": "n",
        "block": "minecraft:polished_basalt[axis\u003dy]"
      },
      {
        "char": "d",
        "block": "minecraft:stone_bricks[weathering\u003dtrue]"
      },
      {
        "char": "Q",
        "block": "minecraft:air"
      },
      {
        "char": "m",
        "block": "minecraft:cracked_stone_bricks"
      }
    ]
  },
  "slices": [
    [
      "aaaaaaaaaaaaaaaa",
      "aaaaaaaaaaaaaaaa",
      "aaaaaaaaaaaaaaaa",
      "aaaaaaaaaaaaaaaa",
      "aaaaaaaaaaaaaaaa",
      "aaaaaaaaaaaaaaaa",
      "aaaaaaaaaaaaaaaa",
      "aaaaaaaaaaaaaaaa",
      "aaaaaaaaaaaaaaaa",
      "aaaaaaaaaaaaaaaa",
      "aaaaaaaaaaaaaaaa",
      "aaaaaaaaaaaaaaaa",
      "aaaaaaaaaaaaaaaa",
      "aaaaaaaaaaaaaaaa",
      "aaaaaaaaaaaaaaaa",
      "aaaaaaaaaaaaaaaa"
    ],
    [
      "aaaaaaaaaaaaaaaa",
      "aaaaaaaaaaaaaaaa",
      "aaaaaaaaaaaaaaaa",
      "aaaaaaaaaaaaaaaa",
      "aaaaaaaaaaaaaaaa",
      "aaaaaaaaaaaaaaaa",
      "aaaaaaaaaaaaaaaa",
      "aaaaaaaaaaaaaaaa",
      "aaaaaaaaaaaaaaaa",
      "aaaaaaaaaaaaaaaa",
      "aaaaaaaaaaaaaagg",
      "aaaaaaaaaaaaaagw",
      "aaaaaaaaaaaaaaDg",
      "aaaaaaaaaaaaaatg",
      "aaaaaaaaaaaaaaDg",
      "aaaaaaaaaaaaaaty"
    ],
    [
      "aaaaaaaaaaaaaaaa",
      "aaaaaaaaaaaaaaaa",
      "aaaaaaaaaaaaaaaa",
      "aaaaaaaaaaaaaaaa",
      "aaaaaaaaaaaaaaaa",
      "aaaaaaaaaaaaaaaa",
      "aaaaaaaaaaaaaaaa",
      "aaaaaaaaaaaaaaaa",
      "aaaaaaaaaaaaaaaa",
      "aaaaaaaaaaaaaaaa",
      "aaaaaaaaaaaaaaik",
      "aaaaaaaaaaaaaaib",
      "aaaaaaaaaaaaaaEb",
      "aaaaaaaaaaaaaaqb",
      "aaaaaaaaaaaaaaEn",
      "aaaaaaaaaaaaaadQ"
    ],
    [
      "aaaaaaaaaaaaaaaa",
      "aaaaaaaaaaaaaaaa",
      "aaaaaaaaaaaaaaaa",
      "aaaaaaaaaaaaaaaa",
      "aaaaaaaaaaaaaaaa",
      "aaaaaaaaaaaaaaaa",
      "aaaaaaaaaaaaaaaa",
      "aaaaaaaaaaaaaaaa",
      "aaaaaaaaaaaaaaaa",
      "aaaaaaaaaaaaaaaa",
      "aaaaaaaaaaaaaakm",
      "aaaaaaaaaaaaaaqb",
      "aaaaaaaaaaaaaanb",
      "aaaaaaaaaaaaaakb",
      "aaaaaaaaaaaaaain",
      "aaaaaaaaaaaaaakQ"
    ],
    [
      "aaaaaaaaaaaaaaaa",
      "aaaaaaaaaaaaaaaa",
      "aaaaaaaaaaaaaaaa",
      "aaaaaaaaaaaaaaaa",
      "aaaaaaaaaaaaaaaa",
      "aaaaaaaaaaaaaaaa",
      "aaaaaaaaaaaaaaaa",
      "aaaaaaaaaaaaaaaa",
      "aaaaaaaaaaaaaaaa",
      "aaaaaaaaaaaaaaaa",
      "aaaaaaaaaaaaaamn",
      "aaaaaaaaaaaaaakb",
      "aaaaaaaaaaaaaamb",
      "aaaaaaaaaaaaaakb",
      "aaaaaaaaaaaaaaqE",
      "aaaaaaaaaaaaaanb"
    ],
    [
      "aaaaaaaaaaaaaaaa",
      "aaaaaaaaaaaaaaaa",
      "aaaaaaaaaaaaaaaa",
      "aaaaaaaaaaaaaaaa",
      "aaaaaaaaaaaaaaaa",
      "aaaaaaaaaaaaaaaa",
      "aaaaaaaaaaaaaaaa",
      "aaaaaaaaaaaaaaaa",
      "aaaaaaaaaaaaaaaa",
      "aaaaaaaaaaaaaaaa",
      "aaaaaaaaaaaaaaki",
      "aaaaaaaaaaaaaaqb",
      "aaaaaaaaaaaaaaqb",
      "aaaaaaaaaaaaaanb",
      "aaaaaaaaaaaaaaid",
      "aaaaaaaaaaaaaaqb"
    ]
  ]
}