{
  "xsize": 16,
  "zsize": 16,
  "palette": {
    "palette": [
      {
        "char": " ",
        "block": "minecraft:structure_voiducture_voiducture_voiducture_voiducture_void"
      },
      {
        "char": "a",
        "block": "minecraft:dirt"
      },
      {
        "char": "w",
        "block": "minecraft:stone[weathering\u003dtrue]"
      },
      {
        "char": "y",
        "block": "minecraft:cobblestone[weathering\u003dtrue]"
      },
      {
        "char": "g",
        "block": "minecraft:smooth_stone"
      },
      {
        "char": "t",
        "block": "create:layered_tuff"
      },
      {
        "char": "C",
        "block": "minecraft:cobblestone[weathering\u003dfalse]"
      },
      {
        "char": "D",
        "block": "minecraft:stone[weathering\u003dfalse]"
      },
      {
        "char": "b",
        "block": "minecraft:water[level\u003d0]"
      },
      {
        "char": "q",
        "block": "minecraft:deepslate_bricks[weathering\u003dtrue]"
      },
      {
        "char": "n",
        "block": "minecraft:polished_basalt[axis\u003dy]"
      },
      {
        "char": "k",
        "block": "minecraft:cracked_deepslate_bricks"
      },
      {
        "char": "i",
        "block": "minecraft:basalt[axis\u003dy]"
      },
      {
        "char": "d",
        "block": "minecraft:stone_bricks[weathering\u003dtrue]"
      },
      {
        "char": "E",
        "block": "minecraft:deepslate_bricks[weathering\u003dfalse]"
      },
      {
        "char": "l",
        "block": "minecraft:mossy_stone_bricks"
      },
      {
        "char": "F",
        "block": "minecraft:air"
      },
      {
        "char": "e",
        "block": "minecraft:grass_block[snowy\u003dfalse]"
      },
      {
        "char": "G",
        "block": "minecraft:dark_oak_leaves[distance\u003d7,persistent\u003dfalse,waterlogged\u003dfalse]"
      },
      {
        "char": "u",
        "block": "minecraft:deepslate[axis\u003dy]"
      },
      {
        "char": "z",
        "block": "minecraft:cyan_terracotta"
      },
      {
        "char": "H",
        "block": "minecraft:cobbled_deepslate"
      }
    ]
  },
  "slices": [
    [
      "aaaaaaaaaaaaaaaa",
      "aaaaaaaaaaaaaaaa",
      "aaaaaaaaaaaaaaaa",
      "aaaaaaaaaaaaaaaa",
      "aaaaaaaaaaaaaaaa",
      "aaaaaaaaaaaaaaaa",
      "aaaaaaaaaaaaaaaa",
      "aaaaaaaaaaaaaaaa",
      "aaaaaaaaaaaaaaaa",
      "aaaaaaaaaaaaaaaa",
      "aaaaaaaaaaaaaaaa",
      "aaaaaaaaaaaaaaaa",
      "aaaaaaaaaaaaaaaa",
      "aaaaaaaaaaaaaaaa",
      "aaaaaaaaaaaaaaaa",
      "aaaaaaaaaaaaaaaa"
    ],
    [
      "wyygtgggyggtgwtw",
      "gyytggwgyggygttg",
      "CgCgCgCCtDgDtDCD",
      "aaaaaaaaaaaaaaaa",
      "aaaaaaaaaaaaaaaa",
      "aaaaaaaaaaaaaaaa",
      "aaaaaaaaaaaaaaaa",
      "aaaaaaaaaaaaaaaa",
      "aaaaaaaaaaaaaaaa",
      "aaaaaaaaaaaaaaaa",
      "aaaaaaaaaaaaaaaa",
      "aaaaaaaaaaaaaaaa",
      "aaaaaaaaaaaaaaaa",
      "aaaaaaaaaaaaaaaa",
      "aaaaaaaaaaaaaaaa",
      "aaaaaaaaaaaaaaaa"
    ],
    [
      "bbbbbbbbbbbbbbbb",
      "bbbbbbbbbbbbbbbb",
      "qnnknidkqqqEdqdn",
      "aaaaaaaaaaaaaaaa",
      "aaaaaaaaaaaaaaaa",
      "aaaaaaaaaaaaaaaa",
      "aaaaaaaaaaaaaaaa",
      "aaaaaaaaaaaaaaaa",
      "aaaaaaaaaaaaaaaa",
      "aaaaaaaaaaaaaaaa",
      "aaaaaaaaaaaaaaaa",
      "aaaaaaaaaaaaaaaa",
      "aaaaaaaaaaaaaaaa",
      "aaaaaaaaaaaaaaaa",
      "aaaaaaaaaaaaaaaa",
      "aaaaaaaaaaaaaaaa"
    ],
    [
      "bbbbbbbbbbbbbbbb",
      "bbbbbbbbbbbbbbbb",
      "kqknliqqkkddqkii",
      "aaaaaaaaaaaaaaaa",
      "aaaaaaaaaaaaaaaa",
      "aaaaaaaaaaaaaaaa",
      "aaaaaaaaaaaaaaaa",
      "aaaaaaaaaaaaaaaa",
      "aaaaaaaaaaaaaaaa",
      "aaaaaaaaaaaaaaaa",
      "aaaaaaaaaaaaaaaa",
      "aaaaaaaaaaaaaaaa",
      "aaaaaaaaaaaaaaaa",
      "aaaaaaaaaaaaaaaa",
      "aaaaaaaaaaaaaaaa",
      "aaaaaaaaaaaaaaaa"
    ],
    [
      "bbbbbbbbbbbbbbbb",
      "bbbbbbbbbbbbbbbb",
      "inkdknnqnnEinnqd",
      "aaaaaaaaaaaaaaaa",
      "aaaaaaaaaaaaaaaa",
      "aaaaaaaaaaaaaaaa",
      "aaaaaaaaaaaaaaaa",
      "aaaFaaaaaaaaaaaa",
      "aaaaaaaaaaaaaaaa",
      "aaaaaaaaaaaaaaaa",
      "aaaaaaaaaaaaaaaa",
      "aaaaaaaaaaaaaaaa",
      "aaaaaaaaaaaaaaaa",
      "aaaaaaaaaaaaaaaa",
      "aaaaaaaaaaaaaaaa",
      "aaaaaaaaaaaaaaaa"
    ],
    [
      "bbbbbbbbbbbbbbbb",
      "bbbbbbbbbbbbbbbb",
      "nknkinndknddnqkn",
      "aaaaaaaeeeeeeeee",
      "Faaaaaaagggggggg",
      "aGFaaaaauuzuuHHH",
      "aaaaaaaazHHuzuHz",
      "FaFaGaaazuHHzuzH",
      "GaaFFaaaHuHHHHHH",
      "GaaaaaaaHuuzHHuu",
      "aaaaaaaazuHzHHzH",
      "aaaaaaaagggggggg",
      "aaaaaaaaaaaaaaaa",
      "aaaaaaaaaaaaaaaa",
      "aaaaaaaaaaaaaaaa",
      "aaaaaaaaaaaaaaaa"
    ]
  ]
}