{
  "xsize": 16,
  "zsize": 16,
  "palette": {
    "palette": [
      {
        "char": " ",
        "block": "minecraft:air"
      },
      {
        "char": "p",
        "block": "minecraft:yellow_concrete"
      },
      {
        "char": "f",
        "block": "minecraft:air"
      },
      {
        "char": "Α",
        "block": "minecraft:air"
      },
      {
        "char": "O",
        "block": "minecraft:air"
      },
      {
        "char": "ϫ",
        "block": "minecraft:air"
      },
      {
        "char": "x",
        "block": "immersive_weathering:weathered_plate_iron"
      },
      {
        "char": "C",
        "block": "immersive_weathering:exposed_plate_iron"
      },
      {
        "char": "A",
        "block": "immersive_weathering:weathered_cut_iron"
      },
      {
        "char": "y",
        "block": "immersive_weathering:exposed_cut_iron"
      },
      {
        "char": "o",
        "block": "minecraft:mossy_stone_bricks"
      },
      {
        "char": "λ",
        "block": "minecraft:air"
      },
      {
        "char": "i",
        "block": "minecraft:air"
      },
      {
        "char": "u",
        "block": "minecraft:red_wool"
      },
      {
        "char": "b",
        "block": "minecraft:stone_bricks[weathering\u003dfalse]"
      },
      {
        "char": "7",
        "block": "minecraft:redstone_lamp[lit\u003dfalse]"
      },
      {
        "char": "s",
        "block": "minecraft:cracked_stone_bricks"
      },
      {
        "char": "v",
        "block": "minecraft:red_carpet"
      },
      {
        "char": "r",
        "block": "minecraft:smooth_stone_slab[type\u003dbottom,waterlogged\u003dfalse]"
      }
    ]
  },
  "slices": [
    [
      "ppf            Α",
      "ppf      O  ϫxCx",
      "pp  O     O CAyy",
      "ppfOOO      xCxx",
      "pp  O        yxA",
      "ppf             ",
      "ppf             ",
      "p      o        ",
      "ppf    λ        ",
      " i            O ",
      "                ",
      "                ",
      "   iii   ii   ii",
      "                ",
      "                ",
      "                "
    ],
    [
      "   ubbob7bbboob7",
      "   ubbsbboobooss",
      "   ubbbbbbobsssb",
      "   ubbbbbbsssbbb",
      "   usbob7bbbbbb7",
      "   ubbbbbbbbbbsb",
      "   ubbbbbbbsbbbb",
      "   ubbssoobbbbbo",
      "   ubbsobbbbobss",
      "   ubbbobbsbbboo",
      "   ubbbbbbbbbbbb",
      "   uuuuuuuuuuuuu",
      "   iii   ii   ii",
      "                ",
      "                ",
      "                "
    ],
    [
      "   v    rrrrrrrr",
      "   v    r      r",
      "   v    r      r",
      "   v    r      r",
      "   v    rrrrrrrr",
      "   v            ",
      "   v            ",
      "   v            ",
      "   v            ",
      "   v            ",
      "   v            ",
      "   vvvvvvvvvvvvv",
      "                ",
      "                ",
      "                ",
      "                "
    ],
    [
      "                ",
      "                ",
      "                ",
      "                ",
      "                ",
      "                ",
      "                ",
      "                ",
      "                ",
      "                ",
      "                ",
      "                ",
      "                ",
      "                ",
      "                ",
      "                "
    ],
    [
      "                ",
      "                ",
      "                ",
      "                ",
      "                ",
      "                ",
      "                ",
      "                ",
      "                ",
      "                ",
      "                ",
      "                ",
      "                ",
      "                ",
      "                ",
      "                "
    ],
    [
      "                ",
      "                ",
      "                ",
      "                ",
      "                ",
      "                ",
      "                ",
      "                ",
      "                ",
      "                ",
      "                ",
      "                ",
      "                ",
      "                ",
      "                ",
      "                "
    ]
  ]
}