{
  "xsize": 16,
  "zsize": 16,
  "palette": {
    "palette": [
      {
        "char": " ",
        "block": "minecraft:air"
      },
      {
        "char": "儸",
        "block": "minecraft:diorite_stairs[facing\u003deast,half\u003dtop,shape\u003dstraight,waterlogged\u003dfalse]"
      },
      {
        "char": "b",
        "block": "minecraft:polished_diorite"
      },
      {
        "char": "d",
        "block": "minecraft:diorite"
      },
      {
        "char": "c",
        "block": "minecraft:smooth_quartz"
      },
      {
        "char": "绮",
        "block": "minecraft:oak_fence[east\u003dfalse,north\u003dfalse,south\u003dfalse,waterlogged\u003dfalse,west\u003dfalse]"
      },
      {
        "char": "j",
        "block": "minecraft:air"
      },
      {
        "char": "m",
        "block": "minecraft:air"
      },
      {
        "char": "袱",
        "block": "minecraft:quartz_stairs[facing\u003deast,half\u003dtop,shape\u003dstraight,waterlogged\u003dfalse]"
      },
      {
        "char": "e",
        "block": "minecraft:quartz_block"
      },
      {
        "char": "n",
        "block": "minecraft:air"
      },
      {
        "char": "w",
        "block": "minecraft:quartz_slab[type\u003dbottom,waterlogged\u003dfalse]"
      },
      {
        "char": "q",
        "block": "minecraft:blackstone"
      },
      {
        "char": "J",
        "block": "minecraft:polished_blackstone"
      },
      {
        "char": "I",
        "block": "minecraft:black_concrete"
      },
      {
        "char": "K",
        "block": "minecraft:diorite_slab[type\u003dbottom,waterlogged\u003dfalse]"
      },
      {
        "char": "H",
        "block": "minecraft:glass_pane[east\u003dfalse,north\u003dtrue,south\u003dtrue,waterlogged\u003dfalse,west\u003dfalse]"
      },
      {
        "char": "p",
        "block": "minecraft:quartz_pillar[axis\u003dy]"
      },
      {
        "char": "C",
        "block": "immersive_weathering:mossy_stone"
      },
      {
        "char": "z",
        "block": "minecraft:clay"
      },
      {
        "char": "役",
        "block": "minecraft:dead_fire_coral_block"
      },
      {
        "char": "h",
        "block": "minecraft:deepslate[axis\u003dy]"
      }
    ]
  },
  "slices": [
    [
      "            儸bdd",
      "             bbc",
      "          绮 儸cdc",
      "           j bdd",
      "         j   ccc",
      "          mj袱bcc",
      "             bec",
      "             ceb",
      "          绮 袱bed",
      "          j  bdc",
      "             edc",
      "            袱dec",
      "           n bdd",
      "          j  bdc",
      "          绮 袱cbc",
      "           n bdc"
    ],
    [
      "              wq",
      "              wJ",
      "          www ed",
      "           j  wJ",
      "         j    wI",
      "          mj jbe",
      "              wq",
      "              wJ",
      "          wwK dd",
      "          j   KI",
      "              wI",
      "              cb",
      "           n  wJ",
      "          j   wJ",
      "          KwK eb",
      "           n  wq"
    ],
    [
      "              mJ",
      "                ",
      "              be",
      "           j    ",
      "         j    nI",
      "          mj jec",
      "              mq",
      "                ",
      "           m  eb",
      "          j    I",
      "                ",
      "              cd",
      "           n   q",
      "          j    J",
      "              cd",
      "           n   J"
    ],
    [
      "              mH",
      "               H",
      "              dc",
      "           j   H",
      "         j    nH",
      "          mj jeb",
      "              mH",
      "               H",
      "           m  dd",
      "          j     ",
      "                ",
      "              pc",
      "           n   H",
      "          j    H",
      "              pd",
      "           n   H"
    ],
    [
      "              mH",
      "               H",
      "              pc",
      "           j   H",
      "         j    nH",
      "          mj jcb",
      "              mH",
      "               H",
      "           m  bd",
      "          j    H",
      "               H",
      "              pb",
      "           n   H",
      "          j    H",
      "              cd",
      "           n   H"
    ],
    [
      "               C",
      "               z",
      "              dd",
      "           j   z",
      "         j    nz",
      "          mj jdb",
      "              mz",
      "               z",
      "           m  ec",
      "          j    z",
      "               役",
      "              ec",
      "           n   h",
      "          j    h",
      "              bc",
      "           n   z"
    ]
  ]
}