{
  "xsize": 16,
  "zsize": 16,
  "palette": {
    "palette": [
      {
        "char": " ",
        "block": "minecraft:air"
      },
      {
        "char": "暸",
        "block": "minecraft:air"
      },
      {
        "char": "麒",
        "block": "minecraft:air"
      },
      {
        "char": "y",
        "block": "minecraft:quartz_slab[type\u003dtop,waterlogged\u003dfalse]"
      },
      {
        "char": "b",
        "block": "minecraft:polished_diorite"
      },
      {
        "char": "e",
        "block": "minecraft:quartz_block"
      },
      {
        "char": "N",
        "block": "minecraft:diorite_slab[type\u003dtop,waterlogged\u003dfalse]"
      },
      {
        "char": "d",
        "block": "minecraft:diorite"
      },
      {
        "char": "皈",
        "block": "minecraft:quartz_slab[type\u003ddouble,waterlogged\u003dfalse]"
      },
      {
        "char": "l",
        "block": "minecraft:air"
      },
      {
        "char": "z",
        "block": "minecraft:clay"
      },
      {
        "char": "C",
        "block": "immersive_weathering:mossy_stone"
      },
      {
        "char": "c",
        "block": "minecraft:smooth_quartz"
      },
      {
        "char": "q",
        "block": "minecraft:blackstone"
      },
      {
        "char": "h",
        "block": "minecraft:deepslate[axis\u003dy]"
      },
      {
        "char": "T",
        "block": "minecraft:air"
      },
      {
        "char": "歉",
        "block": "minecraft:air"
      },
      {
        "char": "g",
        "block": "minecraft:cyan_terracotta"
      },
      {
        "char": "x",
        "block": "minecraft:redstone_lamp[lit\u003dfalse]"
      },
      {
        "char": "n",
        "block": "minecraft:air"
      },
      {
        "char": "j",
        "block": "minecraft:air"
      },
      {
        "char": "f",
        "block": "minecraft:basalt[axis\u003dx]"
      },
      {
        "char": "i",
        "block": "minecraft:cobbled_deepslate"
      },
      {
        "char": "m",
        "block": "minecraft:air"
      },
      {
        "char": "调",
        "block": "minecraft:air"
      },
      {
        "char": "跆",
        "block": "minecraft:stone_button[face\u003dwall,facing\u003dsouth,powered\u003dfalse]"
      },
      {
        "char": "蹬",
        "block": "minecraft:stone_slab[type\u003dbottom,waterlogged\u003dfalse,weathering\u003dtrue]"
      },
      {
        "char": "a",
        "block": "minecraft:smooth_stone_slab[type\u003dtop,waterlogged\u003dfalse]"
      },
      {
        "char": "喃",
        "block": "minecraft:cobblestone_slab[type\u003dbottom,waterlogged\u003dfalse,weathering\u003dfalse]"
      },
      {
        "char": "刍",
        "block": "minecraft:stone_button[face\u003dfloor,facing\u003dnorth,powered\u003dfalse]"
      },
      {
        "char": "剷",
        "block": "minecraft:stone_button[face\u003dfloor,facing\u003deast,powered\u003dfalse]"
      },
      {
        "char": "荀",
        "block": "minecraft:stone_button[face\u003dfloor,facing\u003dsouth,powered\u003dfalse]"
      },
      {
        "char": "Q",
        "block": "minecraft:smooth_stone_slab[type\u003dbottom,waterlogged\u003dfalse]"
      },
      {
        "char": "埵",
        "block": "minecraft:stone_button[face\u003dfloor,facing\u003dwest,powered\u003dfalse]"
      },
      {
        "char": "锁",
        "block": "minecraft:stone_slab[type\u003dbottom,waterlogged\u003dfalse,weathering\u003dfalse]"
      }
    ]
  },
  "slices": [
    [
      "  暸  暸 麒     y  ",
      "yybyyeNNeyNd皈yl ",
      "zCczzeqzczhdNT  ",
      "            C歉  ",
      "            hgl ",
      "     x       Cn ",
      "              Cl",
      "qqg          CCl",
      " jC           h ",
      "  fC          q ",
      "    g x  x     g",
      "     h   x      ",
      "        i       ",
      "         gi     ",
      "n         CC    ",
      "i歉    mm   调qg  "
    ],
    [
      "ebcdeeebddeeb   ",
      "fffhCqgiCiqhhCl ",
      "fgffhqiCfghqCT  ",
      "iigCgqhChgfCql  ",
      "fhfgCfgihqff跆   ",
      "fqiqgqiqhqqif   ",
      "qgihgCqgqgCgCCl ",
      "蹬  iqiifiiihfh  ",
      " jCfCggCqhgqqC  ",
      "  miCgiCihqqgCq ",
      "    jiCqffgfhg i",
      "     fifhihhhgqC",
      "      hfChgCqiff",
      "      hqigqgiiCq",
      "a     ff  m igCg",
      "f     mm     hCi"
    ],
    [
      "cdbcbeccbeddceby",
      "           喃    ",
      "         刍  刍   ",
      "  剷剷     荀Q     ",
      "                ",
      "   Q   剷   Q    ",
      "     荀      刍   ",
      "             Q  ",
      "      Q         ",
      "             埵  ",
      "           剷    ",
      "      锁  锁      ",
      "             荀Q ",
      "                ",
      "              Q ",
      "                "
    ],
    [
      "                ",
      "                ",
      "                ",
      "                ",
      "                ",
      "                ",
      "                ",
      "                ",
      "                ",
      "                ",
      "                ",
      "                ",
      "                ",
      "                ",
      "                ",
      "                "
    ],
    [
      "                ",
      "                ",
      "                ",
      "                ",
      "                ",
      "                ",
      "                ",
      "                ",
      "                ",
      "                ",
      "                ",
      "                ",
      "                ",
      "                ",
      "                ",
      "                "
    ],
    [
      "                ",
      "                ",
      "                ",
      "                ",
      "                ",
      "                ",
      "                ",
      "                ",
      "                ",
      "                ",
      "                ",
      "                ",
      "                ",
      "                ",
      "                ",
      "                "
    ]
  ]
}