{
  "xsize": 16,
  "zsize": 16,
  "palette": {
    "palette": [
      {
        "char": " ",
        "block": "minecraft:air"
      },
      {
        "char": "n",
        "block": "minecraft:air"
      },
      {
        "char": "b",
        "block": "minecraft:polished_diorite"
      },
      {
        "char": "p",
        "block": "minecraft:quartz_pillar[axis\u003dy]"
      },
      {
        "char": "伟",
        "block": "minecraft:air"
      },
      {
        "char": "c",
        "block": "minecraft:smooth_quartz"
      },
      {
        "char": "l",
        "block": "minecraft:air"
      },
      {
        "char": "e",
        "block": "minecraft:quartz_block"
      },
      {
        "char": "d",
        "block": "minecraft:diorite"
      },
      {
        "char": "w",
        "block": "minecraft:quartz_slab[type\u003dbottom,waterlogged\u003dfalse]"
      }
    ]
  },
  "slices": [
    [
      "                ",
      "                ",
      "                ",
      "                ",
      "                ",
      "                ",
      "                ",
      "                ",
      "                ",
      "                ",
      "                ",
      "                ",
      "     nnn     nnn",
      "nn    nnn       ",
      "bp  n伟pcpl      ",
      "epdeddpeeedcdbbe"
    ],
    [
      "                ",
      "                ",
      "                ",
      "                ",
      "                ",
      "                ",
      "                ",
      "                ",
      "                ",
      "                ",
      "                ",
      "                ",
      "     nnn     nnn",
      "nn    nnn       ",
      "ep  n伟pepl     w",
      "deebdcpcdecbdebb"
    ],
    [
      "                ",
      "                ",
      "                ",
      "                ",
      "                ",
      "                ",
      "                ",
      "                ",
      "                ",
      "                ",
      "                ",
      "                ",
      "     nnn     nnn",
      "nn    nnn       ",
      "be  n伟cdpl      ",
      "epdceedbbbededdc"
    ],
    [
      "                ",
      "                ",
      "                ",
      "                ",
      "                ",
      "                ",
      "                ",
      "                ",
      "                ",
      "                ",
      "                ",
      "                ",
      "     nnn     nnn",
      "nn    nnn       ",
      "de  n伟pdpl      ",
      "cpbdeepdeeccbdbe"
    ],
    [
      "                ",
      "                ",
      "                ",
      "                ",
      "                ",
      "                ",
      "                ",
      "                ",
      "                ",
      "                ",
      "                ",
      "                ",
      "     nnn     nnn",
      "nn    nnn       ",
      "ee  n伟ebpl      ",
      "bpbccepbdcccdbbe"
    ],
    [
      "                ",
      "                ",
      "                ",
      "                ",
      "                ",
      "                ",
      "                ",
      "                ",
      "                ",
      "                ",
      "                ",
      "                ",
      "     nnn     nnn",
      "nn    nnn       ",
      "cp  n伟pdel      ",
      "bpcddbcddebbbcbc"
    ]
  ]
}