{
  "xsize": 16,
  "zsize": 16,
  "palette": {
    "palette": [
      {
        "char": " ",
        "block": "minecraft:air"
      },
      {
        "char": "床",
        "block": "minecraft:air"
      },
      {
        "char": "巡",
        "block": "minecraft:air"
      },
      {
        "char": "d",
        "block": "minecraft:diorite"
      },
      {
        "char": "e",
        "block": "minecraft:quartz_block"
      },
      {
        "char": "瓣",
        "block": "minecraft:oak_log[axis\u003dy]"
      },
      {
        "char": "p",
        "block": "minecraft:quartz_pillar[axis\u003dy]"
      },
      {
        "char": "b",
        "block": "minecraft:polished_diorite"
      },
      {
        "char": "j",
        "block": "minecraft:air"
      },
      {
        "char": "m",
        "block": "minecraft:air"
      },
      {
        "char": "c",
        "block": "minecraft:smooth_quartz"
      },
      {
        "char": "伟",
        "block": "minecraft:air"
      },
      {
        "char": "N",
        "block": "minecraft:diorite_slab[type\u003dtop,waterlogged\u003dfalse]"
      },
      {
        "char": "焢",
        "block": "minecraft:air"
      },
      {
        "char": "u",
        "block": "minecraft:red_concrete"
      },
      {
        "char": "v",
        "block": "minecraft:red_terracotta"
      },
      {
        "char": "蒙",
        "block": "minecraft:quartz_stairs[facing\u003dnorth,half\u003dbottom,shape\u003dstraight,waterlogged\u003dfalse]"
      },
      {
        "char": "儸",
        "block": "minecraft:diorite_stairs[facing\u003deast,half\u003dtop,shape\u003dstraight,waterlogged\u003dfalse]"
      },
      {
        "char": "狡",
        "block": "minecraft:air"
      },
      {
        "char": "袱",
        "block": "minecraft:quartz_stairs[facing\u003deast,half\u003dtop,shape\u003dstraight,waterlogged\u003dfalse]"
      },
      {
        "char": "佯",
        "block": "minecraft:diorite_stairs[facing\u003dsouth,half\u003dtop,shape\u003dstraight,waterlogged\u003dfalse]"
      },
      {
        "char": "竺",
        "block": "minecraft:quartz_pillar[axis\u003dz]"
      },
      {
        "char": "椎",
        "block": "minecraft:quartz_stairs[facing\u003dnorth,half\u003dtop,shape\u003dstraight,waterlogged\u003dfalse]"
      },
      {
        "char": "亥",
        "block": "minecraft:quartz_stairs[facing\u003dsouth,half\u003dtop,shape\u003dstraight,waterlogged\u003dfalse]"
      },
      {
        "char": "桨",
        "block": "minecraft:diorite_stairs[facing\u003dnorth,half\u003dtop,shape\u003dstraight,waterlogged\u003dfalse]"
      }
    ]
  },
  "slices": [
    [
      "  床巡床         de",
      "  巡瓣巡        pbe",
      "  床巡床       j de",
      "            jdeb",
      "            jmee",
      "              bd",
      "            j de",
      "             pcc",
      "              dd",
      "            伟pdd",
      "      床    j  dc",
      "     床巡床   j  db",
      "      床    jjbdd",
      "             ebb",
      "          j jebb",
      "            jNcb"
    ],
    [
      "   床          ec",
      "  床巡床        pee",
      "   床        j bb",
      "            jpbe",
      "            jmbb",
      "              cb",
      "            j bc",
      "             pde",
      "              ee",
      "            伟pce",
      "           j  ee",
      "           j  ce",
      "           jjpdc",
      "             dcc",
      "          j jdeb",
      "            j焢ee"
    ],
    [
      "              du",
      "             pbu",
      "            j bv",
      "            jpcv",
      "            jmcv",
      "              du",
      "            j cv",
      "             bbv",
      "              bu",
      "            伟pcu",
      "           j  cv",
      "           j  bu",
      "           jjebu",
      "          u  bdv",
      "          j jpev",
      "            j蒙ev"
    ],
    [
      "              cb",
      "             dbc",
      "            j ce",
      "            jeed",
      "            jmdb",
      "              cc",
      "            j cc",
      "             pee",
      "              db",
      "            伟eeb",
      "           j  dd",
      "           j  dc",
      "           jjpdb",
      "          v  dbc",
      "          j jdbc",
      "            jmbb"
    ],
    [
      "              be",
      "             cbd",
      "            j儸eb",
      "            jped",
      "            j狡bc",
      "             儸bc",
      "            j db",
      "             dbb",
      "             袱be",
      "            伟pcd",
      "           j  ec",
      "           j  dc",
      "           jjpbd",
      "          u  cec",
      "          j jdee",
      "            j狡db"
    ],
    [
      "              bb",
      "             佯cd",
      "            j竺cc",
      "            j椎cb",
      "            j亥be",
      "             ebb",
      "            j桨bd",
      "             亥bb",
      "             cbe",
      "            伟桨cd",
      "           j  ed",
      "           j  db",
      "           jjbee",
      "          u  bde",
      "          j jdeb",
      "            j椎dc"
    ]
  ]
}