{
  "xsize": 16,
  "zsize": 16,
  "palette": {
    "palette": [
      {
        "char": " ",
        "block": "minecraft:air"
      },
      {
        "char": "y",
        "block": "minecraft:quartz_slab[type\u003dtop,waterlogged\u003dfalse]"
      },
      {
        "char": "h",
        "block": "minecraft:deepslate[axis\u003dy]"
      },
      {
        "char": "c",
        "block": "minecraft:smooth_quartz"
      },
      {
        "char": "d",
        "block": "minecraft:diorite"
      },
      {
        "char": "g",
        "block": "minecraft:cyan_terracotta"
      },
      {
        "char": "z",
        "block": "minecraft:clay"
      },
      {
        "char": "j",
        "block": "minecraft:air"
      },
      {
        "char": "b",
        "block": "minecraft:polished_diorite"
      },
      {
        "char": "役",
        "block": "minecraft:dead_fire_coral_block"
      },
      {
        "char": "N",
        "block": "minecraft:diorite_slab[type\u003dtop,waterlogged\u003dfalse]"
      },
      {
        "char": "e",
        "block": "minecraft:quartz_block"
      },
      {
        "char": "p",
        "block": "minecraft:quartz_pillar[axis\u003dy]"
      },
      {
        "char": "m",
        "block": "minecraft:air"
      },
      {
        "char": "w",
        "block": "minecraft:quartz_slab[type\u003dbottom,waterlogged\u003dfalse]"
      },
      {
        "char": "q",
        "block": "minecraft:blackstone"
      },
      {
        "char": "J",
        "block": "minecraft:polished_blackstone"
      },
      {
        "char": "I",
        "block": "minecraft:black_concrete"
      },
      {
        "char": "K",
        "block": "minecraft:diorite_slab[type\u003dbottom,waterlogged\u003dfalse]"
      },
      {
        "char": "f",
        "block": "minecraft:basalt[axis\u003dx]"
      },
      {
        "char": "麒",
        "block": "minecraft:air"
      },
      {
        "char": "埠",
        "block": "minecraft:air"
      },
      {
        "char": "i",
        "block": "minecraft:cobbled_deepslate"
      },
      {
        "char": "C",
        "block": "immersive_weathering:mossy_stone"
      }
    ]
  },
  "slices": [
    [
      "              yh",
      "              cd",
      "              yg",
      "              yz",
      "             jbd",
      "              y役",
      "              Nz",
      "              be",
      "             dec",
      "           j ecb",
      "           j pdd",
      "           j  ce",
      "           j    ",
      "            mmm ",
      "                ",
      "                "
    ],
    [
      "              wq",
      "              dc",
      "              wJ",
      "              wI",
      "             jcb",
      "              wI",
      "              wq",
      "              bb",
      "             bdb",
      "           j ecc",
      "           j cdb",
      "           j  be",
      "           j    ",
      "            mmm ",
      "                ",
      "                "
    ],
    [
      "              w役",
      "              ce",
      "              Kf",
      "              wz",
      "             jed",
      "              wz",
      "              Kz",
      "              bd",
      "             pdc",
      "           j ecb",
      "           j pbd",
      "           j  bd",
      "           j    ",
      "            mmm ",
      "                ",
      "                "
    ],
    [
      "              yz",
      "              be",
      "              y役",
      "            麒麒yz",
      "            麒埠be",
      "              yz",
      "              yz",
      "              dd",
      "             bce",
      "           j cdd",
      "           j ped",
      "           j  pe",
      "           j    ",
      "            mmm ",
      "                ",
      "                "
    ],
    [
      "            cdii",
      "            eeqf",
      "            cbgq",
      "            dbii",
      "            cbgh",
      "            ecqq",
      "            edgh",
      "            edhC",
      "            edfq",
      "           jcbfC",
      "           jedff",
      "           jcccb",
      "           jbcde",
      "            mmm ",
      "                ",
      "                "
    ],
    [
      "            dc  ",
      "            dc  ",
      "            ee  ",
      "            cd  ",
      "            de  ",
      "          麒 be  ",
      "            cd  ",
      "            ec  ",
      "            ed  ",
      "           jcc  ",
      "           jeb  ",
      "           jdbcd",
      "           jedec",
      "            mmm ",
      "                ",
      "                "
    ]
  ]
}