{
  "xsize": 16,
  "zsize": 16,
  "palette": {
    "palette": [
      {
        "char": " ",
        "block": "minecraft:air"
      },
      {
        "char": "伟",
        "block": "minecraft:air"
      },
      {
        "char": "e",
        "block": "minecraft:quartz_block"
      },
      {
        "char": "c",
        "block": "minecraft:smooth_quartz"
      },
      {
        "char": "j",
        "block": "minecraft:air"
      },
      {
        "char": "p",
        "block": "minecraft:quartz_pillar[axis\u003dy]"
      },
      {
        "char": "m",
        "block": "minecraft:air"
      },
      {
        "char": "d",
        "block": "minecraft:diorite"
      },
      {
        "char": "b",
        "block": "minecraft:polished_diorite"
      },
      {
        "char": "巡",
        "block": "minecraft:air"
      },
      {
        "char": "调",
        "block": "minecraft:air"
      },
      {
        "char": "瓣",
        "block": "minecraft:oak_log[axis\u003dy]"
      },
      {
        "char": "床",
        "block": "minecraft:air"
      }
    ]
  },
  "slices": [
    [
      "             伟ec",
      "            jpce",
      "             mec",
      "              dd",
      "            jpeb",
      "            jcec",
      "            jedb",
      "         巡   调cp",
      "        巡瓣巡   调b",
      "         巡床    m",
      "                ",
      "                ",
      "                ",
      "                ",
      "                ",
      "                "
    ],
    [
      "             伟ee",
      "            jbdc",
      "             mce",
      "              bc",
      "            jcpc",
      "            jbdb",
      "            jepd",
      "         床   调cp",
      "        床巡床   调d",
      "         床     m",
      "                ",
      "                ",
      "                ",
      "                ",
      "                ",
      "                "
    ],
    [
      "             伟eb",
      "            jeec",
      "             mdc",
      "              eb",
      "             ppd",
      "            jdbc",
      "            jepd",
      "             调pp",
      "              调p",
      "               m",
      "                ",
      "                ",
      "                ",
      "                ",
      "                ",
      "                "
    ],
    [
      "             伟db",
      "            jcee",
      "             mcd",
      "              cb",
      "             dpe",
      "            jdcc",
      "            jcbc",
      "             调pc",
      "              调d",
      "               m",
      "                ",
      "                ",
      "                ",
      "                ",
      "                ",
      "                "
    ],
    [
      "             伟de",
      "            jpbc",
      "             med",
      "              db",
      "             pce",
      "             edd",
      "            jped",
      "             调pp",
      "              调p",
      "               m",
      "                ",
      "                ",
      "                ",
      "                ",
      "                ",
      "                "
    ],
    [
      "             伟cc",
      "            jpee",
      "             meb",
      "              cd",
      "             pcc",
      "             bdc",
      "            jdcd",
      "             调pe",
      "              调p",
      "               m",
      "                ",
      "                ",
      "                ",
      "                ",
      "                ",
      "                "
    ]
  ]
}