{
  "xsize": 16,
  "zsize": 16,
  "palette": {
    "palette": [
      {
        "char": " ",
        "block": "minecraft:air"
      },
      {
        "char": "x",
        "block": "minecraft:redstone_lamp[lit\u003dfalse]"
      },
      {
        "char": "f",
        "block": "minecraft:basalt[axis\u003dx]"
      },
      {
        "char": "y",
        "block": "minecraft:quartz_slab[type\u003dtop,waterlogged\u003dfalse]"
      },
      {
        "char": "醉",
        "block": "minecraft:repeater[delay\u003d1,facing\u003dnorth,locked\u003dfalse,powered\u003dfalse]"
      },
      {
        "char": "b",
        "block": "minecraft:polished_diorite"
      },
      {
        "char": "e",
        "block": "minecraft:quartz_block"
      },
      {
        "char": "l",
        "block": "minecraft:air"
      },
      {
        "char": "z",
        "block": "minecraft:clay"
      },
      {
        "char": "N",
        "block": "minecraft:diorite_slab[type\u003dtop,waterlogged\u003dfalse]"
      },
      {
        "char": "d",
        "block": "minecraft:diorite"
      },
      {
        "char": "h",
        "block": "minecraft:deepslate[axis\u003dy]"
      },
      {
        "char": "麒",
        "block": "minecraft:air"
      },
      {
        "char": "c",
        "block": "minecraft:smooth_quartz"
      },
      {
        "char": "i",
        "block": "minecraft:cobbled_deepslate"
      },
      {
        "char": "役",
        "block": "minecraft:dead_fire_coral_block"
      },
      {
        "char": "g",
        "block": "minecraft:cyan_terracotta"
      },
      {
        "char": "q",
        "block": "minecraft:blackstone"
      },
      {
        "char": "C",
        "block": "immersive_weathering:mossy_stone"
      },
      {
        "char": "n",
        "block": "minecraft:air"
      }
    ]
  },
  "slices": [
    [
      "x        fy     ",
      "     醉   be l   ",
      "     x   zN l   ",
      "x        zy l   ",
      "         bb     ",
      "         zy     ",
      "         zy     ",
      "x        dd     ",
      "         hy     ",
      "         zy麒    ",
      "     醉   cc麒    ",
      "     x   iy麒    ",
      "x        役y     ",
      "         ce     ",
      "         iy     ",
      "         zN     "
    ],
    [
      "iihihiffgige    ",
      "hgghfqhhhqhel   ",
      "qqggqffgqCfel   ",
      "fgqhhfhghhfbl   ",
      "CiqfghgChhqc    ",
      "ghqCggghqiqb    ",
      "CqhqiCgfhqfd    ",
      "qfiggfCfiqhe    ",
      "qfigCgqhqiic    ",
      "iCghqgffqqfd    ",
      "igifCfiffgie    ",
      "hihqiiqqigge    ",
      "hqhhfffhqffe    ",
      "qqfghqqihhid    ",
      "qigqCfCqffgd    ",
      "fqfqffgggiie    "
    ],
    [
      "           e    ",
      "           dl   ",
      "           bl   ",
      "           el   ",
      "           e    ",
      "           b    ",
      "           b    ",
      "           d    ",
      "           b    ",
      "           c    ",
      "           b    ",
      "           c    ",
      "           d    ",
      "n          c    ",
      "           d    ",
      " l         e    "
    ],
    [
      "                ",
      "                ",
      "                ",
      "                ",
      "                ",
      "                ",
      "                ",
      "                ",
      "                ",
      "                ",
      "                ",
      "                ",
      "                ",
      "n               ",
      "                ",
      " l              "
    ],
    [
      "                ",
      "                ",
      "                ",
      "                ",
      "                ",
      "                ",
      "                ",
      "                ",
      "                ",
      "                ",
      "                ",
      "                ",
      "                ",
      "n               ",
      "                ",
      " l              "
    ],
    [
      "                ",
      "                ",
      "                ",
      "                ",
      "                ",
      "                ",
      "                ",
      "                ",
      "                ",
      "                ",
      "                ",
      "                ",
      "                ",
      "n               ",
      "                ",
      " l              "
    ]
  ]
}