{
  "xsize": 16,
  "zsize": 16,
  "palette": {
    "palette": [
      {
        "char": " ",
        "block": "minecraft:air"
      },
      {
        "char": "j",
        "block": "minecraft:air"
      },
      {
        "char": "y",
        "block": "minecraft:quartz_slab[type\u003dtop,waterlogged\u003dfalse]"
      },
      {
        "char": "f",
        "block": "minecraft:basalt[axis\u003dx]"
      },
      {
        "char": "袱",
        "block": "minecraft:quartz_stairs[facing\u003deast,half\u003dtop,shape\u003dstraight,waterlogged\u003dfalse]"
      },
      {
        "char": "c",
        "block": "minecraft:smooth_quartz"
      },
      {
        "char": "d",
        "block": "minecraft:diorite"
      },
      {
        "char": "z",
        "block": "minecraft:clay"
      },
      {
        "char": "h",
        "block": "minecraft:deepslate[axis\u003dy]"
      },
      {
        "char": "b",
        "block": "minecraft:polished_diorite"
      },
      {
        "char": "p",
        "block": "minecraft:quartz_pillar[axis\u003dy]"
      },
      {
        "char": "e",
        "block": "minecraft:quartz_block"
      },
      {
        "char": "m",
        "block": "minecraft:air"
      },
      {
        "char": "N",
        "block": "minecraft:diorite_slab[type\u003dtop,waterlogged\u003dfalse]"
      },
      {
        "char": "w",
        "block": "minecraft:quartz_slab[type\u003dbottom,waterlogged\u003dfalse]"
      },
      {
        "char": "I",
        "block": "minecraft:black_concrete"
      },
      {
        "char": "袅",
        "block": "minecraft:quartz_stairs[facing\u003deast,half\u003dbottom,shape\u003dstraight,waterlogged\u003dfalse]"
      },
      {
        "char": "q",
        "block": "minecraft:blackstone"
      },
      {
        "char": "K",
        "block": "minecraft:diorite_slab[type\u003dbottom,waterlogged\u003dfalse]"
      },
      {
        "char": "J",
        "block": "minecraft:polished_blackstone"
      },
      {
        "char": "庇",
        "block": "minecraft:diorite_stairs[facing\u003deast,half\u003dbottom,shape\u003dstraight,waterlogged\u003dfalse]"
      },
      {
        "char": "u",
        "block": "minecraft:red_concrete"
      },
      {
        "char": "训",
        "block": "immersive_weathering:exposed_iron_bars[east\u003dfalse,north\u003dtrue,south\u003dtrue,waterlogged\u003dfalse,west\u003dfalse]"
      },
      {
        "char": "H",
        "block": "minecraft:glass_pane[east\u003dfalse,north\u003dtrue,south\u003dtrue,waterlogged\u003dfalse,west\u003dfalse]"
      },
      {
        "char": "穿",
        "block": "immersive_weathering:exposed_iron_bars[east\u003dfalse,north\u003dtrue,south\u003dfalse,waterlogged\u003dfalse,west\u003dfalse]"
      },
      {
        "char": "拭",
        "block": "minecraft:cobblestone_wall[east\u003dlow,north\u003dnone,south\u003dnone,up\u003dfalse,waterlogged\u003dfalse,weathering\u003dfalse,west\u003dlow]"
      },
      {
        "char": "飒",
        "block": "minecraft:cobblestone_wall[east\u003dlow,north\u003dnone,south\u003dlow,up\u003dtrue,waterlogged\u003dfalse,weathering\u003dfalse,west\u003dlow]"
      },
      {
        "char": "v",
        "block": "minecraft:red_terracotta"
      },
      {
        "char": "翌",
        "block": "minecraft:cobblestone_wall[east\u003dlow,north\u003dlow,south\u003dnone,up\u003dtrue,waterlogged\u003dfalse,weathering\u003dfalse,west\u003dlow]"
      }
    ]
  },
  "slices": [
    [
      "          j   yf",
      "             袱cd",
      "              yz",
      "              yh",
      "             袱bd",
      "              yz",
      "              yz",
      "             袱bb",
      "             pde",
      "           j bcc",
      "           j pbb",
      "           j 袱cc",
      "           j  yh",
      "            m yz",
      "             袱ec",
      "              Nz"
    ],
    [
      "          j   wI",
      "            袅wed",
      "              wI",
      "              wq",
      "            袅wed",
      "              KJ",
      "              wJ",
      "            庇wbe",
      "             eed",
      "           j bde",
      "           j pdd",
      "           j袅wbd",
      "           j  wJ",
      "            m wq",
      "            庇wcd",
      "              KJ"
    ],
    [
      "          j     ",
      "              ed",
      "                ",
      "               q",
      "              db",
      "                ",
      "               J",
      "              bu",
      "             pdu",
      "           j bce",
      "           j peu",
      "           j  cu",
      "           j   q",
      "            m   ",
      "              ec",
      "                "
    ],
    [
      "          j    训",
      "              pc",
      "               训",
      "               训",
      "              de",
      "               H",
      "               训",
      "              pd",
      "             pcb",
      "           j ddc",
      "           j pbd",
      "           j  pe",
      "           j   H",
      "            m  训",
      "              bd",
      "               穿"
    ],
    [
      "          j    训",
      "              pb",
      "               训",
      "               训",
      "              pe",
      "               穿",
      "                ",
      "              be",
      "             pcd",
      "           j dde",
      "           j pce",
      "           j  cc",
      "           j   训",
      "            m  训",
      "              pb",
      "               H"
    ],
    [
      "          ju拭拭飒z",
      "              ee",
      "               h",
      "           u拭拭飒z",
      "              bd",
      "           v拭拭翌z",
      "               z",
      "           v拭飒cd",
      "           v pdb",
      "           j dee",
      "           j pee",
      "           j  db",
      "           j   z",
      "            m  z",
      "              eb",
      "               z"
    ]
  ]
}