{
  "xsize": 16,
  "zsize": 16,
  "palette": {
    "palette": [
      {
        "char": " ",
        "block": "minecraft:air"
      },
      {
        "char": "n",
        "block": "minecraft:air"
      },
      {
        "char": "p",
        "block": "minecraft:quartz_pillar[axis\u003dy]"
      },
      {
        "char": "c",
        "block": "minecraft:smooth_quartz"
      },
      {
        "char": "b",
        "block": "minecraft:polished_diorite"
      },
      {
        "char": "歉",
        "block": "minecraft:air"
      },
      {
        "char": "l",
        "block": "minecraft:air"
      },
      {
        "char": "d",
        "block": "minecraft:diorite"
      },
      {
        "char": "e",
        "block": "minecraft:quartz_block"
      },
      {
        "char": "a",
        "block": "minecraft:smooth_stone_slab[type\u003dtop,waterlogged\u003dfalse]"
      },
      {
        "char": "k",
        "block": "minecraft:stone_slab[type\u003dtop,waterlogged\u003dfalse,weathering\u003dfalse]"
      },
      {
        "char": "r",
        "block": "minecraft:cobblestone_slab[type\u003dtop,waterlogged\u003dfalse,weathering\u003dfalse]"
      },
      {
        "char": "A",
        "block": "minecraft:smooth_stone_slab[type\u003ddouble,waterlogged\u003dfalse]"
      },
      {
        "char": "x",
        "block": "minecraft:redstone_lamp[lit\u003dfalse]"
      },
      {
        "char": "D",
        "block": "minecraft:redstone_wire[east\u003dnone,north\u003dside,power\u003d0,south\u003dside,west\u003dnone]"
      },
      {
        "char": "E",
        "block": "minecraft:redstone_wire[east\u003dside,north\u003dnone,power\u003d0,south\u003dnone,west\u003dside]"
      },
      {
        "char": "怨",
        "block": "minecraft:repeater[delay\u003d1,facing\u003dwest,locked\u003dfalse,powered\u003dfalse]"
      },
      {
        "char": "y",
        "block": "minecraft:quartz_slab[type\u003dtop,waterlogged\u003dfalse]"
      },
      {
        "char": "i",
        "block": "minecraft:cobbled_deepslate"
      },
      {
        "char": "g",
        "block": "minecraft:cyan_terracotta"
      },
      {
        "char": "B",
        "block": "minecraft:moss_block"
      },
      {
        "char": "h",
        "block": "minecraft:deepslate[axis\u003dy]"
      },
      {
        "char": "烤",
        "block": "minecraft:air"
      },
      {
        "char": "u",
        "block": "minecraft:red_concrete"
      },
      {
        "char": "裔",
        "block": "minecraft:air"
      },
      {
        "char": "w",
        "block": "minecraft:quartz_slab[type\u003dbottom,waterlogged\u003dfalse]"
      }
    ]
  },
  "slices": [
    [
      "    npcb歉l      ",
      " deeceddpl      ",
      "ceebceedbl      ",
      "dcbbcddcpl      ",
      "aaaaaacd        ",
      "kaararbel       ",
      "akaakadc        ",
      "aaaarrccl       ",
      "AaraAabdl       ",
      "araaaace        ",
      "aaararbel       ",
      "aakaaabcl       ",
      "AaaaAade        ",
      "AaaaAkecl       ",
      "araaaabel       ",
      "akkakabd        "
    ],
    [
      "    ndcp歉l      ",
      " ddeccddpl      ",
      "eecccdebdl      ",
      "dccdbceepl      ",
      "      cc        ",
      "      cel       ",
      "      ed        ",
      "      cdl       ",
      "x   x dcl       ",
      "D   D ed        ",
      "D   D cel       ",
      "D   D cd        ",
      "xEE怨x dd        ",
      "x   x bcl       ",
      "      bbl       ",
      "      ed        "
    ],
    [
      "yy  npee歉l      ",
      "yeebdbbbel      ",
      "edbeeddecl      ",
      "igBBhbbcpl      ",
      "      cc        ",
      "      cdl       ",
      "      bd        ",
      "      ccl       ",
      "      ebl       ",
      "      bc        ",
      "      bbl       ",
      "      dd        ",
      "      ec        ",
      "      ecl       ",
      "      cdl       ",
      "      de烤       "
    ],
    [
      "u   npbc歉l      ",
      "bbcecedcdl      ",
      "edbbedddel      ",
      "     debpl      ",
      "      db        ",
      "      eel       ",
      "      ce        ",
      "      bdl       ",
      "      cbl       ",
      "      be        ",
      "      del       ",
      "      be        ",
      "      ee        ",
      "      bcl       ",
      "      be裔       ",
      "      be烤       "
    ],
    [
      "dw  npdp歉l      ",
      "cdecdcbdbl      ",
      "cebbbeebdl      ",
      "     bbdpl      ",
      "      ed        ",
      "      edl       ",
      "      cc        ",
      "      ebl       ",
      "      cel       ",
      "      cc        ",
      "      ccl       ",
      "      ec        ",
      "      ec        ",
      "      cel       ",
      "      cb烤       ",
      "      bb烤       "
    ],
    [
      "    npcp歉l      ",
      "ccdbbcdepl      ",
      "cdbecebddl      ",
      "     dbdbl      ",
      "      de        ",
      "      dbl       ",
      "      ed        ",
      "      cel       ",
      "      ddl       ",
      "      cb        ",
      "      bdl       ",
      "      bc        ",
      "      db        ",
      "      del       ",
      "      bbl       ",
      "      bc烤       "
    ]
  ]
}