{
  "xsize": 16,
  "zsize": 16,
  "palette": {
    "palette": [
      {
        "char": " ",
        "block": "minecraft:air"
      },
      {
        "char": "床",
        "block": "minecraft:air"
      },
      {
        "char": "j",
        "block": "minecraft:air"
      },
      {
        "char": "竺",
        "block": "minecraft:quartz_pillar[axis\u003dz]"
      },
      {
        "char": "b",
        "block": "minecraft:polished_diorite"
      },
      {
        "char": "e",
        "block": "minecraft:quartz_block"
      },
      {
        "char": "巡",
        "block": "minecraft:air"
      },
      {
        "char": "y",
        "block": "minecraft:quartz_slab[type\u003dtop,waterlogged\u003dfalse]"
      },
      {
        "char": "d",
        "block": "minecraft:diorite"
      },
      {
        "char": "睫",
        "block": "minecraft:quartz_stairs[facing\u003deast,half\u003dtop,shape\u003douter_right,waterlogged\u003dfalse]"
      },
      {
        "char": "亥",
        "block": "minecraft:quartz_stairs[facing\u003dsouth,half\u003dtop,shape\u003dstraight,waterlogged\u003dfalse]"
      },
      {
        "char": "袱",
        "block": "minecraft:quartz_stairs[facing\u003deast,half\u003dtop,shape\u003dstraight,waterlogged\u003dfalse]"
      },
      {
        "char": "c",
        "block": "minecraft:smooth_quartz"
      },
      {
        "char": "儸",
        "block": "minecraft:diorite_stairs[facing\u003deast,half\u003dtop,shape\u003dstraight,waterlogged\u003dfalse]"
      },
      {
        "char": "p",
        "block": "minecraft:quartz_pillar[axis\u003dy]"
      },
      {
        "char": "m",
        "block": "minecraft:air"
      },
      {
        "char": "n",
        "block": "minecraft:air"
      },
      {
        "char": "K",
        "block": "minecraft:diorite_slab[type\u003dbottom,waterlogged\u003dfalse]"
      },
      {
        "char": "v",
        "block": "minecraft:red_terracotta"
      },
      {
        "char": "箍",
        "block": "minecraft:diorite_stairs[facing\u003dsouth,half\u003dbottom,shape\u003dstraight,waterlogged\u003dfalse]"
      },
      {
        "char": "u",
        "block": "minecraft:red_concrete"
      },
      {
        "char": "擂",
        "block": "minecraft:diorite_stairs[facing\u003dnorth,half\u003dbottom,shape\u003dstraight,waterlogged\u003dfalse]"
      },
      {
        "char": "w",
        "block": "minecraft:quartz_slab[type\u003dbottom,waterlogged\u003dfalse]"
      },
      {
        "char": "唆",
        "block": "minecraft:quartz_stairs[facing\u003dsouth,half\u003dbottom,shape\u003dstraight,waterlogged\u003dfalse]"
      },
      {
        "char": "蒙",
        "block": "minecraft:quartz_stairs[facing\u003dnorth,half\u003dbottom,shape\u003dstraight,waterlogged\u003dfalse]"
      },
      {
        "char": "庇",
        "block": "minecraft:diorite_stairs[facing\u003deast,half\u003dbottom,shape\u003dstraight,waterlogged\u003dfalse]"
      },
      {
        "char": "袅",
        "block": "minecraft:quartz_stairs[facing\u003deast,half\u003dbottom,shape\u003dstraight,waterlogged\u003dfalse]"
      },
      {
        "char": "佯",
        "block": "minecraft:diorite_stairs[facing\u003dsouth,half\u003dtop,shape\u003dstraight,waterlogged\u003dfalse]"
      },
      {
        "char": "椎",
        "block": "minecraft:quartz_stairs[facing\u003dnorth,half\u003dtop,shape\u003dstraight,waterlogged\u003dfalse]"
      },
      {
        "char": "N",
        "block": "minecraft:diorite_slab[type\u003dtop,waterlogged\u003dfalse]"
      }
    ]
  },
  "slices": [
    [
      "床           j竺be",
      "巡            yed",
      "床         睫亥亥亥eb",
      "          袱ddccc",
      "         j袱cdbbc",
      "          儸eeedc",
      "          袱cdccb",
      "          儸cbbcd",
      "          袱edddd",
      "          袱eebed",
      "          袱decbd",
      "          袱ecccd",
      "          袱bebcc",
      "          袱dbcbe",
      "          儸cebed",
      "          袱cbddc"
    ],
    [
      "            jpbb",
      "床             bc",
      "             pcd",
      "           j  ee",
      "         j   eec",
      "          mj  be",
      "             cdc",
      "              db",
      "             pec",
      "          j   dc",
      "             pbc",
      "              cc",
      "           n pec",
      "          j   bb",
      "             pdc",
      "           n  ed"
    ],
    [
      "             Kcv",
      "             箍bu",
      "          u  竺bv",
      "           j 擂cu",
      "         j   wcv",
      "          mj wev",
      "             Keu",
      "             唆eu",
      "          u  竺cu",
      "          j  擂cv",
      "             weu",
      "             Kbv",
      "           n weu",
      "          j  箍cv",
      "          v  竺cu",
      "           n 蒙bu"
    ],
    [
      "             袱bb",
      "              ed",
      "          v  dce",
      "           j  be",
      "         j   袱bb",
      "          mj  dc",
      "             儸ec",
      "              dc",
      "          v  pee",
      "          j   ee",
      "             袱dc",
      "              eb",
      "           n 儸cd",
      "          j   bd",
      "          v  ddc",
      "           n  de"
    ],
    [
      "             庇cc",
      "              dd",
      "          u  eed",
      "           j  db",
      "         j   袅ed",
      "          mj  ec",
      "             袅ed",
      "              ee",
      "          u  pec",
      "          j   ed",
      "             袅bd",
      "              bd",
      "           n 袅bc",
      "          j   be",
      "          u  pbc",
      "           n  be"
    ],
    [
      "             yee",
      "             佯dc",
      "          u  竺bd",
      "           j 椎cc",
      "         j   Ndb",
      "          mj ydc",
      "             ybe",
      "             佯cb",
      "          u  edc",
      "          j  椎bd",
      "             yec",
      "             Nec",
      "           n yed",
      "          j  亥bb",
      "          v  竺db",
      "           n 椎de"
    ]
  ]
}