{
  "xsize": 16,
  "zsize": 16,
  "palette": {
    "palette": [
      {
        "char": " ",
        "block": "minecraft:air"
      },
      {
        "char": "d",
        "block": "minecraft:diorite"
      },
      {
        "char": "c",
        "block": "minecraft:smooth_quartz"
      },
      {
        "char": "e",
        "block": "minecraft:quartz_block"
      },
      {
        "char": "b",
        "block": "minecraft:polished_diorite"
      },
      {
        "char": "m",
        "block": "minecraft:air"
      },
      {
        "char": "调",
        "block": "minecraft:air"
      },
      {
        "char": "j",
        "block": "minecraft:air"
      },
      {
        "char": "g",
        "block": "minecraft:cyan_terracotta"
      },
      {
        "char": "C",
        "block": "immersive_weathering:mossy_stone"
      },
      {
        "char": "i",
        "block": "minecraft:cobbled_deepslate"
      },
      {
        "char": "f",
        "block": "minecraft:basalt[axis\u003dx]"
      },
      {
        "char": "h",
        "block": "minecraft:deepslate[axis\u003dy]"
      },
      {
        "char": "q",
        "block": "minecraft:blackstone"
      },
      {
        "char": "膝",
        "block": "minecraft:cobblestone_wall[east\u003dnone,north\u003dnone,south\u003dnone,up\u003dtrue,waterlogged\u003dfalse,weathering\u003dfalse,west\u003dnone]"
      },
      {
        "char": "M",
        "block": "immersive_weathering:exposed_plate_iron"
      },
      {
        "char": "a",
        "block": "minecraft:smooth_stone_slab[type\u003dtop,waterlogged\u003dfalse]"
      },
      {
        "char": "r",
        "block": "minecraft:cobblestone_slab[type\u003dtop,waterlogged\u003dfalse,weathering\u003dfalse]"
      },
      {
        "char": "Q",
        "block": "minecraft:smooth_stone_slab[type\u003dbottom,waterlogged\u003dfalse]"
      },
      {
        "char": "堐",
        "block": "minecraft:cobblestone_slab[type\u003dbottom,waterlogged\u003dfalse,weathering\u003dtrue]"
      }
    ]
  },
  "slices": [
    [
      "                ",
      "                ",
      "                ",
      "                ",
      "                ",
      "                ",
      "                ",
      "                ",
      "                ",
      "                ",
      "                ",
      "dcebde          ",
      "cddcbd          ",
      " mm调be          ",
      "   jbd          ",
      "    ed          "
    ],
    [
      "                ",
      "                ",
      "                ",
      "                ",
      "                ",
      "                ",
      "                ",
      "                ",
      "                ",
      "                ",
      "                ",
      "dcbebc          ",
      "dcdebb          ",
      " mm调ee          ",
      "   jbb          ",
      "    cb          "
    ],
    [
      "                ",
      "                ",
      "                ",
      "                ",
      "                ",
      "                ",
      "                ",
      "                ",
      "                ",
      "                ",
      "                ",
      "cbcbeb          ",
      "decdcc          ",
      " mm调bc          ",
      "   jdd          ",
      "    de          "
    ],
    [
      "                ",
      "                ",
      "                ",
      "                ",
      "                ",
      "                ",
      "                ",
      "                ",
      "                ",
      "                ",
      "                ",
      "ededbc          ",
      "dcdece          ",
      "  m调ec          ",
      "   jcc          ",
      "    ce          "
    ],
    [
      "gCCifhihhihffqfh",
      "fghqhhqqCqifCqiq",
      "fiChiqfqiqqhfqgf",
      "gqifhfhfCigfqiqg",
      "ggqiCihqqhggCChh",
      "ihqiigCCqfghhiCq",
      "CffffCfgigiCqhqg",
      "hiCgqhfqCggfhiqg",
      "fCChqfihihfiqqff",
      "hqhqhiifgiqgiifg",
      "fChiqifigiihqghg",
      "dddbceihhqfiqqqf",
      "bdbdbegqggiqCCii",
      "  m调befhhfhiiqhg",
      "   jcbfhhfqgffig",
      "    cdhgqihCiifh"
    ],
    [
      "cdddc       eeeb",
      "bddcb 膝      M M",
      "dbcdd           ",
      "ecdbb 膝         ",
      "deeecar         ",
      "dbebbQQ    Qa膝 膝",
      "cbccc      堐a   ",
      "bcdbc      膝 膝 膝",
      "mmmm            ",
      "          dbddde",
      "          dccdbd",
      "cddcdc    dedcdc",
      "dccbdd   jbccedb",
      "  m调cb   jddccbd",
      "   jdb   jdbcecb",
      "    cd   jebbecc"
    ]
  ]
}