{
  "xsize": 16,
  "zsize": 16,
  "palette": {
    "palette": [
      {
        "char": " ",
        "block": "minecraft:air"
      },
      {
        "char": "m",
        "block": "minecraft:air"
      },
      {
        "char": "忐",
        "block": "horror_element_mod:chained_entity[facing\u003dnorth]"
      },
      {
        "char": "划",
        "block": "refurbished_furniture:light_ceiling_light[face\u003dceiling,facing\u003dnorth,powered\u003dfalse]",
        "tag": {
          "z": 453,
          "x": -27,
          "ForgeCaps": {},
          "id": "refurbished_furniture:ceiling_light",
          "y": 148,
          "NodePos": "-7421701631852L",
          "Connections": [
            "L"
          ]
        }
      },
      {
        "char": "谱",
        "block": "refurbished_furniture:light_ceiling_light[face\u003dceiling,facing\u003deast,powered\u003dfalse]",
        "tag": {
          "z": 465,
          "x": -59,
          "ForgeCaps": {},
          "id": "refurbished_furniture:ceiling_light",
          "y": 136,
          "NodePos": "-16217794604920L",
          "Connections": [
            "L"
          ]
        }
      },
      {
        "char": "法",
        "block": "refurbished_furniture:light_ceiling_light[face\u003dceiling,facing\u003dsouth,powered\u003dfalse]",
        "tag": {
          "z": 483,
          "x": -73,
          "ForgeCaps": {},
          "id": "refurbished_furniture:ceiling_light",
          "y": 160,
          "NodePos": "-20066085228384L",
          "Connections": [
            "L"
          ]
        }
      },
      {
        "char": "a",
        "block": "minecraft:smooth_stone_slab[type\u003dtop,waterlogged\u003dfalse]"
      },
      {
        "char": "k",
        "block": "minecraft:stone_slab[type\u003dtop,waterlogged\u003dfalse,weathering\u003dfalse]"
      },
      {
        "char": "A",
        "block": "minecraft:smooth_stone_slab[type\u003ddouble,waterlogged\u003dfalse]"
      },
      {
        "char": "r",
        "block": "minecraft:cobblestone_slab[type\u003dtop,waterlogged\u003dfalse,weathering\u003dfalse]"
      },
      {
        "char": "h",
        "block": "minecraft:deepslate[axis\u003dy]"
      }
    ]
  },
  "slices": [
    [
      "mmmmmmmmm     mm",
      "                ",
      "                ",
      "                ",
      "                ",
      "                ",
      "                ",
      "                ",
      "                ",
      "                ",
      "                ",
      "                ",
      "                ",
      "                ",
      "                ",
      "                "
    ],
    [
      "  mmmmmm      mm",
      "                ",
      "                ",
      "                ",
      "                ",
      "                ",
      "                ",
      "                ",
      "                ",
      "                ",
      "                ",
      "                ",
      "                ",
      "                ",
      "                ",
      "                "
    ],
    [
      "  m  mm         ",
      "                ",
      "                ",
      "                ",
      "                ",
      "                ",
      "                ",
      "                ",
      "                ",
      "                ",
      "                ",
      "                ",
      "                ",
      "                ",
      "                ",
      "                "
    ],
    [
      "  m  mm         ",
      "                ",
      "                ",
      "                ",
      "                ",
      "                ",
      "                ",
      "                ",
      "         忐      ",
      "                ",
      "                ",
      "                ",
      "                ",
      "                ",
      "                ",
      "                "
    ],
    [
      "     mm         ",
      "划  谱谱  划划  划谱  划",
      "                ",
      "                ",
      "划  划划  谱谱  法法  谱",
      "                ",
      "                ",
      "划  划划  法法  法法  法",
      "                ",
      "                ",
      "划  划划  法法  法法  法",
      "                ",
      "                ",
      "划  划划  法法  法法  法",
      "                ",
      "                "
    ],
    [
      "akkkkakaaka kaka",
      "AaaAAaaAAaaAAakA",
      "aakaaaaaakaraakk",
      "kakkkaaaaaaaaakk",
      "AarAAaaAAarAAaaA",
      "arrkarkkaakrkraa",
      "aaakaakaaaakaaak",
      "AakAAarAAkkAAaaA",
      "aakakaaarhaaaara",
      "akarkaaakkkakaar",
      "AarAAaaAAaaAAakA",
      "raraakkakrakakra",
      "akaaaaaakrkakkaa",
      "AaaAAkaAAarAAakA",
      "aarkaaaaarrkrraa",
      "aaaaaarkakaakkaa"
    ]
  ]
}