{
  "xsize": 16,
  "zsize": 16,
  "palette": {
    "palette": [
      {
        "char": " ",
        "block": "minecraft:air"
      },
      {
        "char": "j",
        "block": "minecraft:air"
      },
      {
        "char": "e",
        "block": "minecraft:quartz_block"
      },
      {
        "char": "c",
        "block": "minecraft:smooth_quartz"
      },
      {
        "char": "袱",
        "block": "minecraft:quartz_stairs[facing\u003deast,half\u003dtop,shape\u003dstraight,waterlogged\u003dfalse]"
      },
      {
        "char": "d",
        "block": "minecraft:diorite"
      },
      {
        "char": "b",
        "block": "minecraft:polished_diorite"
      },
      {
        "char": "绮",
        "block": "minecraft:oak_fence[east\u003dfalse,north\u003dfalse,south\u003dfalse,waterlogged\u003dfalse,west\u003dfalse]"
      },
      {
        "char": "儸",
        "block": "minecraft:diorite_stairs[facing\u003deast,half\u003dtop,shape\u003dstraight,waterlogged\u003dfalse]"
      },
      {
        "char": "m",
        "block": "minecraft:air"
      },
      {
        "char": "w",
        "block": "minecraft:quartz_slab[type\u003dbottom,waterlogged\u003dfalse]"
      },
      {
        "char": "J",
        "block": "minecraft:polished_blackstone"
      },
      {
        "char": "K",
        "block": "minecraft:diorite_slab[type\u003dbottom,waterlogged\u003dfalse]"
      },
      {
        "char": "I",
        "block": "minecraft:black_concrete"
      },
      {
        "char": "q",
        "block": "minecraft:blackstone"
      },
      {
        "char": "p",
        "block": "minecraft:quartz_pillar[axis\u003dy]"
      },
      {
        "char": "调",
        "block": "minecraft:air"
      },
      {
        "char": "n",
        "block": "minecraft:air"
      },
      {
        "char": "v",
        "block": "minecraft:red_terracotta"
      },
      {
        "char": "u",
        "block": "minecraft:red_concrete"
      },
      {
        "char": "H",
        "block": "minecraft:glass_pane[east\u003dfalse,north\u003dtrue,south\u003dtrue,waterlogged\u003dfalse,west\u003dfalse]"
      },
      {
        "char": "涨",
        "block": "minecraft:glass_pane[east\u003dfalse,north\u003dfalse,south\u003dtrue,waterlogged\u003dfalse,west\u003dfalse]"
      },
      {
        "char": "捕",
        "block": "minecraft:glass_pane[east\u003dfalse,north\u003dtrue,south\u003dfalse,waterlogged\u003dfalse,west\u003dfalse]"
      },
      {
        "char": "z",
        "block": "minecraft:clay"
      },
      {
        "char": "役",
        "block": "minecraft:dead_fire_coral_block"
      },
      {
        "char": "h",
        "block": "minecraft:deepslate[axis\u003dy]"
      }
    ]
  },
  "slices": [
    [
      "          j  eec",
      "            袱cdb",
      "             bce",
      "             cdc",
      "          绮 儸ddb",
      "             edc",
      "            儸cdd",
      "             bdd",
      "             beb",
      "          绮 袱dde",
      "           jjdce",
      "           jjbde",
      "           j bcc",
      "            mcee",
      "             dde",
      "             beb"
    ],
    [
      "          j   wJ",
      "             jce",
      "              KI",
      "              wq",
      "          www de",
      "              wI",
      "              wJ",
      "              bc",
      "             pbb",
      "          wwwdce",
      "           jjpdc",
      "           j 调cd",
      "           j  wq",
      "            m wI",
      "             jec",
      "              wJ"
    ],
    [
      "          j   n ",
      "             jbc",
      "              m ",
      "               J",
      "              bc",
      "                ",
      "               J",
      "              bv",
      "             cdu",
      "           jjcdb",
      "           jjbdv",
      "           j 调eu",
      "           j   I",
      "            m   ",
      "             jdd",
      "              调 "
    ],
    [
      "          j   nH",
      "             jbb",
      "              mH",
      "               H",
      "              pd",
      "               H",
      "               H",
      "              bb",
      "             ece",
      "           j ceb",
      "           jjpcb",
      "           j jdb",
      "           j   H",
      "            m  H",
      "             jpd",
      "              调H"
    ],
    [
      "          j   nH",
      "             jpb",
      "              m ",
      "               涨",
      "              pd",
      "               捕",
      "                ",
      "              bb",
      "             pbb",
      "           j dbe",
      "           j pdc",
      "           j  bb",
      "           j   H",
      "            m  H",
      "             jpe",
      "              调 "
    ],
    [
      "          j    z",
      "             jdb",
      "              m役",
      "               z",
      "              cc",
      "               z",
      "               z",
      "              be",
      "             pdb",
      "           j dbe",
      "           j pbc",
      "           j  cb",
      "           j   z",
      "            m  h",
      "             jcc",
      "              调z"
    ]
  ]
}