{
  "xsize": 16,
  "zsize": 16,
  "palette": {
    "palette": [
      {
        "char": " ",
        "block": "minecraft:air"
      },
      {
        "char": "j",
        "block": "minecraft:air"
      },
      {
        "char": "y",
        "block": "minecraft:quartz_slab[type\u003dtop,waterlogged\u003dfalse]"
      },
      {
        "char": "z",
        "block": "minecraft:clay"
      },
      {
        "char": "e",
        "block": "minecraft:quartz_block"
      },
      {
        "char": "c",
        "block": "minecraft:smooth_quartz"
      },
      {
        "char": "N",
        "block": "minecraft:diorite_slab[type\u003dtop,waterlogged\u003dfalse]"
      },
      {
        "char": "m",
        "block": "minecraft:air"
      },
      {
        "char": "b",
        "block": "minecraft:polished_diorite"
      },
      {
        "char": "役",
        "block": "minecraft:dead_fire_coral_block"
      },
      {
        "char": "d",
        "block": "minecraft:diorite"
      },
      {
        "char": "C",
        "block": "immersive_weathering:mossy_stone"
      },
      {
        "char": "w",
        "block": "minecraft:quartz_slab[type\u003dbottom,waterlogged\u003dfalse]"
      },
      {
        "char": "J",
        "block": "minecraft:polished_blackstone"
      },
      {
        "char": "q",
        "block": "minecraft:blackstone"
      },
      {
        "char": "K",
        "block": "minecraft:diorite_slab[type\u003dbottom,waterlogged\u003dfalse]"
      },
      {
        "char": "I",
        "block": "minecraft:black_concrete"
      },
      {
        "char": "H",
        "block": "minecraft:glass_pane[east\u003dfalse,north\u003dtrue,south\u003dtrue,waterlogged\u003dfalse,west\u003dfalse]"
      },
      {
        "char": "繁",
        "block": "minecraft:cobblestone_wall[east\u003dtall,north\u003dnone,south\u003dnone,up\u003dtrue,waterlogged\u003dfalse,weathering\u003dfalse,west\u003dnone]"
      },
      {
        "char": "瀑",
        "block": "minecraft:mossy_cobblestone_wall[east\u003dtall,north\u003dnone,south\u003dnone,up\u003dtrue,waterlogged\u003dfalse,west\u003dnone]"
      },
      {
        "char": "捕",
        "block": "minecraft:glass_pane[east\u003dfalse,north\u003dtrue,south\u003dfalse,waterlogged\u003dfalse,west\u003dfalse]"
      },
      {
        "char": "涨",
        "block": "minecraft:glass_pane[east\u003dfalse,north\u003dfalse,south\u003dtrue,waterlogged\u003dfalse,west\u003dfalse]"
      },
      {
        "char": "h",
        "block": "minecraft:deepslate[axis\u003dy]"
      }
    ]
  },
  "slices": [
    [
      "           j  yz",
      "              yz",
      "              ec",
      "           j  Nz",
      "         j    yz",
      "          mj jbe",
      "              N役",
      "              yz",
      "             jbe",
      "              yz",
      "              yz",
      "             jdb",
      "              yz",
      "              yC",
      "             jcc",
      "              Nz"
    ],
    [
      "           j  wJ",
      "              wq",
      "              dc",
      "           j  KI",
      "         j    wI",
      "          mj jcd",
      "              wq",
      "              KJ",
      "             jdd",
      "              wq",
      "              wJ",
      "             jcd",
      "              wq",
      "              wI",
      "             jdc",
      "              wJ"
    ],
    [
      "           j  NI",
      "              yJ",
      "              de",
      "           j  Nq",
      "         j    yJ",
      "          mj jcd",
      "              yJ",
      "              yJ",
      "             jec",
      "              yq",
      "              yI",
      "             jeb",
      "              NJ",
      "              yq",
      "             jcc",
      "              yI"
    ],
    [
      "           j   H",
      "               H",
      "              繁e",
      "           j    ",
      "         j      ",
      "          mj j繁d",
      "               H",
      "               H",
      "             j瀑d",
      "               捕",
      "                ",
      "             j繁c",
      "               H",
      "               H",
      "             j瀑b",
      "               捕"
    ],
    [
      "           j   H",
      "               H",
      "              繁b",
      "           j    ",
      "         j     涨",
      "          mj j繁e",
      "               捕",
      "                ",
      "             j瀑e",
      "               捕",
      "                ",
      "             j瀑d",
      "               H",
      "               H",
      "             j瀑b",
      "               捕"
    ],
    [
      "           j  w役",
      "              wh",
      "              bb",
      "           j  Kz",
      "         j    wz",
      "          mj jcb",
      "              Kz",
      "              Kz",
      "             jcb",
      "              wq",
      "              wz",
      "             jbb",
      "              wz",
      "              wz",
      "             jbd",
      "              wz"
    ]
  ]
}