{
  "xsize": 16,
  "zsize": 16,
  "palette": {
    "palette": [
      {
        "char": " ",
        "block": "minecraft:air"
      },
      {
        "char": "y",
        "block": "minecraft:quartz_slab[type\u003dtop,waterlogged\u003dfalse]"
      },
      {
        "char": "h",
        "block": "minecraft:deepslate[axis\u003dy]"
      },
      {
        "char": "c",
        "block": "minecraft:smooth_quartz"
      },
      {
        "char": "e",
        "block": "minecraft:quartz_block"
      },
      {
        "char": "N",
        "block": "minecraft:diorite_slab[type\u003dtop,waterlogged\u003dfalse]"
      },
      {
        "char": "q",
        "block": "minecraft:blackstone"
      },
      {
        "char": "g",
        "block": "minecraft:cyan_terracotta"
      },
      {
        "char": "j",
        "block": "minecraft:air"
      },
      {
        "char": "z",
        "block": "minecraft:clay"
      },
      {
        "char": "p",
        "block": "minecraft:quartz_pillar[axis\u003dy]"
      },
      {
        "char": "d",
        "block": "minecraft:diorite"
      },
      {
        "char": "b",
        "block": "minecraft:polished_diorite"
      },
      {
        "char": "m",
        "block": "minecraft:air"
      },
      {
        "char": "w",
        "block": "minecraft:quartz_slab[type\u003dbottom,waterlogged\u003dfalse]"
      },
      {
        "char": "I",
        "block": "minecraft:black_concrete"
      },
      {
        "char": "J",
        "block": "minecraft:polished_blackstone"
      },
      {
        "char": "H",
        "block": "minecraft:glass_pane[east\u003dfalse,north\u003dtrue,south\u003dtrue,waterlogged\u003dfalse,west\u003dfalse]"
      },
      {
        "char": "繁",
        "block": "minecraft:cobblestone_wall[east\u003dtall,north\u003dnone,south\u003dnone,up\u003dtrue,waterlogged\u003dfalse,weathering\u003dfalse,west\u003dnone]"
      },
      {
        "char": "瀑",
        "block": "minecraft:mossy_cobblestone_wall[east\u003dtall,north\u003dnone,south\u003dnone,up\u003dtrue,waterlogged\u003dfalse,west\u003dnone]"
      },
      {
        "char": "沿",
        "block": "minecraft:cobblestone_wall[east\u003dtall,north\u003dnone,south\u003dtall,up\u003dtrue,waterlogged\u003dfalse,weathering\u003dfalse,west\u003dnone]"
      },
      {
        "char": "羚",
        "block": "minecraft:cobblestone_wall[east\u003dlow,north\u003dnone,south\u003dnone,up\u003dtrue,waterlogged\u003dfalse,weathering\u003dfalse,west\u003dnone]"
      },
      {
        "char": "捕",
        "block": "minecraft:glass_pane[east\u003dfalse,north\u003dtrue,south\u003dfalse,waterlogged\u003dfalse,west\u003dfalse]"
      },
      {
        "char": "甬",
        "block": "minecraft:cobblestone_wall[east\u003dlow,north\u003dnone,south\u003dlow,up\u003dtrue,waterlogged\u003dfalse,weathering\u003dfalse,west\u003dnone]"
      },
      {
        "char": "K",
        "block": "minecraft:diorite_slab[type\u003dbottom,waterlogged\u003dfalse]"
      },
      {
        "char": "埠",
        "block": "minecraft:air"
      }
    ]
  },
  "slices": [
    [
      "              yh",
      "              ce",
      "              Nq",
      "              yg",
      "             jee",
      "              yz",
      "              yh",
      "              cc",
      "             pec",
      "           j dbc",
      "           j dbd",
      "           j  pb",
      "           j    ",
      "            mmm ",
      "                ",
      "                "
    ],
    [
      "              wI",
      "              ee",
      "              wJ",
      "              wI",
      "             jde",
      "              wq",
      "              wJ",
      "              cd",
      "             eec",
      "           j ddc",
      "           j ebb",
      "           j  cd",
      "           j    ",
      "            mmm ",
      "                ",
      "                "
    ],
    [
      "              yJ",
      "              ce",
      "              yq",
      "              y ",
      "             jcb",
      "              y ",
      "              yJ",
      "              ce",
      "             ebe",
      "           j cdc",
      "           j ped",
      "           j  ce",
      "           j    ",
      "            mmm ",
      "                ",
      "                "
    ],
    [
      "               H",
      "              繁c",
      "               H",
      "               H",
      "             j瀑e",
      "               H",
      "               H",
      "              沿e",
      "             edb",
      "           j dcc",
      "           j pee",
      "           j  pd",
      "           j    ",
      "            mmm ",
      "                ",
      "                "
    ],
    [
      "                ",
      "              繁e",
      "               H",
      "               H",
      "             j羚b",
      "               捕",
      "                ",
      "              甬b",
      "              bb",
      "           j bec",
      "           j ped",
      "           j  pc",
      "           j    ",
      "            mmm ",
      "                ",
      "                "
    ],
    [
      "              Kg",
      "              db",
      "              wz",
      "              Kz",
      "             j埠c",
      "              wz",
      "              wz",
      "               c",
      "               b",
      "           j dcd",
      "           j cce",
      "           j  ce",
      "           j    ",
      "            mmm ",
      "                ",
      "                "
    ]
  ]
}