{
  "xsize": 16,
  "zsize": 16,
  "palette": {
    "palette": [
      {
        "char": " ",
        "block": "minecraft:air"
      },
      {
        "char": "z",
        "block": "minecraft:clay"
      },
      {
        "char": "y",
        "block": "minecraft:quartz_slab[type\u003dtop,waterlogged\u003dfalse]"
      },
      {
        "char": "贷",
        "block": "minecraft:redstone_wire[east\u003dnone,north\u003dnone,power\u003d0,south\u003dside,west\u003dside]"
      },
      {
        "char": "e",
        "block": "minecraft:quartz_block"
      },
      {
        "char": "l",
        "block": "minecraft:air"
      },
      {
        "char": "醉",
        "block": "minecraft:repeater[delay\u003d1,facing\u003dnorth,locked\u003dfalse,powered\u003dfalse]"
      },
      {
        "char": "x",
        "block": "minecraft:redstone_lamp[lit\u003dfalse]"
      },
      {
        "char": "c",
        "block": "minecraft:smooth_quartz"
      },
      {
        "char": "歉",
        "block": "minecraft:air"
      },
      {
        "char": "p",
        "block": "minecraft:quartz_pillar[axis\u003dy]"
      },
      {
        "char": "役",
        "block": "minecraft:dead_fire_coral_block"
      },
      {
        "char": "d",
        "block": "minecraft:diorite"
      },
      {
        "char": "b",
        "block": "minecraft:polished_diorite"
      },
      {
        "char": "T",
        "block": "minecraft:air"
      },
      {
        "char": "m",
        "block": "minecraft:air"
      },
      {
        "char": "i",
        "block": "minecraft:cobbled_deepslate"
      },
      {
        "char": "f",
        "block": "minecraft:basalt[axis\u003dx]"
      },
      {
        "char": "h",
        "block": "minecraft:deepslate[axis\u003dy]"
      },
      {
        "char": "J",
        "block": "minecraft:polished_blackstone"
      },
      {
        "char": "K",
        "block": "minecraft:diorite_slab[type\u003dbottom,waterlogged\u003dfalse]"
      },
      {
        "char": "G",
        "block": "minecraft:cobblestone_slab[type\u003ddouble,waterlogged\u003dfalse,weathering\u003dfalse]"
      },
      {
        "char": "I",
        "block": "minecraft:black_concrete"
      },
      {
        "char": "w",
        "block": "minecraft:quartz_slab[type\u003dbottom,waterlogged\u003dfalse]"
      },
      {
        "char": "B",
        "block": "minecraft:moss_block"
      },
      {
        "char": "q",
        "block": "minecraft:blackstone"
      },
      {
        "char": "a",
        "block": "minecraft:smooth_stone_slab[type\u003dtop,waterlogged\u003dfalse]"
      },
      {
        "char": "r",
        "block": "minecraft:cobblestone_slab[type\u003dtop,waterlogged\u003dfalse,weathering\u003dfalse]"
      },
      {
        "char": "k",
        "block": "minecraft:stone_slab[type\u003dtop,waterlogged\u003dfalse,weathering\u003dfalse]"
      },
      {
        "char": "g",
        "block": "minecraft:cyan_terracotta"
      },
      {
        "char": "N",
        "block": "minecraft:diorite_slab[type\u003dtop,waterlogged\u003dfalse]"
      },
      {
        "char": "C",
        "block": "immersive_weathering:mossy_stone"
      }
    ]
  },
  "slices": [
    [
      "   zy           ",
      "贷  eel          ",
      "醉  zy           ",
      "x  zy  l        ",
      "   ec歉 l        ",
      "   eepll        ",
      "役ddcbdll        ",
      "yeeebpl         ",
      "  bepT          ",
      "   mm           ",
      "mmmm            ",
      "                ",
      "                ",
      "                ",
      "                ",
      "                "
    ],
    [
      "ifhJK           ",
      "hficel          ",
      "fGhIw           ",
      "fiBqK  l        ",
      "hhhdc  l        ",
      "ffhccbll        ",
      "qceeebll        ",
      "Kbedcpl         ",
      "  pceT          ",
      "   mm           ",
      "mmmm            ",
      "                ",
      "                ",
      "                ",
      "                ",
      "                "
    ],
    [
      "aaazw           ",
      "aaade           ",
      "rakzK           ",
      "aaafw  l        ",
      "aaadc  l        ",
      "aaaebp l        ",
      "zebcbd l        ",
      "wecbcc          ",
      "  eep           ",
      "                ",
      "mmmm            ",
      "                ",
      "                ",
      "                ",
      "                ",
      "                "
    ],
    [
      "   gy           ",
      "   dd           ",
      "   zy           ",
      "   hy  l        ",
      "   be  l        ",
      "   cec l        ",
      "iccebe l        ",
      "Nbdbed          ",
      "  pep           ",
      "                ",
      "mmmm            ",
      "                ",
      "                ",
      "                ",
      "                ",
      "                "
    ],
    [
      "Chgihcc         ",
      "qgifgbe         ",
      "gqhihed         ",
      "hhgficdl        ",
      "Cgigqbbl        ",
      "qgfqfbdl        ",
      "ggfCfbcl        ",
      "ihCfqcc         ",
      "deecebe         ",
      "bbcceec         ",
      "mmmm            ",
      "                ",
      "                ",
      "                ",
      "                ",
      "                "
    ],
    [
      "     bd         ",
      "     eb         ",
      "     bd         ",
      "     ddl        ",
      "     cdl        ",
      "     cel        ",
      "     bbl        ",
      "     dd         ",
      "bddcbeb         ",
      "edccbbe         ",
      "mmmm            ",
      "                ",
      "                ",
      "                ",
      "                ",
      "                "
    ]
  ]
}