{
  "xsize": 16,
  "zsize": 16,
  "palette": {
    "palette": [
      {
        "char": " ",
        "block": "minecraft:air"
      },
      {
        "char": "p",
        "block": "minecraft:quartz_pillar[axis\u003dy]"
      },
      {
        "char": "d",
        "block": "minecraft:diorite"
      },
      {
        "char": "c",
        "block": "minecraft:smooth_quartz"
      },
      {
        "char": "踵",
        "block": "minecraft:quartz_stairs[facing\u003deast,half\u003dbottom,shape\u003douter_right,waterlogged\u003dfalse]"
      },
      {
        "char": "峋",
        "block": "minecraft:quartz_stairs[facing\u003dsouth,half\u003dbottom,shape\u003douter_right,waterlogged\u003dfalse]"
      },
      {
        "char": "谟",
        "block": "minecraft:quartz_stairs[facing\u003dnorth,half\u003dbottom,shape\u003douter_right,waterlogged\u003dfalse]"
      },
      {
        "char": "佚",
        "block": "minecraft:diorite_stairs[facing\u003dwest,half\u003dbottom,shape\u003douter_right,waterlogged\u003dfalse]"
      },
      {
        "char": "衹",
        "block": "minecraft:quartz_stairs[facing\u003dwest,half\u003dbottom,shape\u003douter_right,waterlogged\u003dfalse]"
      },
      {
        "char": "N",
        "block": "minecraft:diorite_slab[type\u003dtop,waterlogged\u003dfalse]"
      },
      {
        "char": "y",
        "block": "minecraft:quartz_slab[type\u003dtop,waterlogged\u003dfalse]"
      },
      {
        "char": "b",
        "block": "minecraft:polished_diorite"
      },
      {
        "char": "v",
        "block": "minecraft:red_terracotta"
      },
      {
        "char": "u",
        "block": "minecraft:red_concrete"
      },
      {
        "char": "w",
        "block": "minecraft:quartz_slab[type\u003dbottom,waterlogged\u003dfalse]"
      },
      {
        "char": "K",
        "block": "minecraft:diorite_slab[type\u003dbottom,waterlogged\u003dfalse]"
      },
      {
        "char": "e",
        "block": "minecraft:quartz_block"
      },
      {
        "char": "n",
        "block": "minecraft:air"
      }
    ]
  },
  "slices": [
    [
      "                ",
      "                ",
      "                ",
      "                ",
      "                ",
      "                ",
      "                ",
      "                ",
      "                ",
      "                ",
      " pd           pd",
      " cp           pc",
      "                ",
      "                ",
      "                ",
      "                "
    ],
    [
      "                ",
      "                ",
      "                ",
      "                ",
      "                ",
      "                ",
      "                ",
      "                ",
      "                ",
      "                ",
      " 踵峋           踵峋",
      " 谟佚           谟衹",
      "                ",
      "                ",
      "                ",
      "                "
    ],
    [
      "                ",
      "                ",
      "                ",
      "                ",
      "                ",
      "                ",
      "                ",
      "                ",
      "NyyNNNNNyNyyyyNy",
      "yyyyyyyyyyyyNNyy",
      "Ncd           bc",
      "ycc           cc",
      "N               ",
      "y               ",
      "y               ",
      "N               "
    ],
    [
      "                ",
      "                ",
      "                ",
      "                ",
      "                ",
      "                ",
      "                ",
      "                ",
      "                ",
      "vuvuvuvvuuvuvuuv",
      "uuuvuvuuvvuuuvuv",
      "vuuvvuvvuvuuuuuv",
      "vuuvuuvuuvvuvvuv",
      "vuvuuvvvvvuuuvvu",
      "uuuvvvuuuvuuuuuu",
      "vvvuuuvvuuuvvvuu"
    ],
    [
      "                ",
      "                ",
      "                ",
      "                ",
      "                ",
      "                ",
      "                ",
      "                ",
      "wwKwwKwKKwwwwwwK",
      "cbcccceecccbecec",
      "cededeceeeeddcce",
      "beebcdbccbeceede",
      "ccbbbeedbdcdeede",
      "bddbbbcbebddcddc",
      "bebcccdeebddbdbd",
      "dbbebbdccbdddccb"
    ],
    [
      "                ",
      "                ",
      "                ",
      "                ",
      "                ",
      "                ",
      "                ",
      "                ",
      "                ",
      "          w     ",
      "           e w w",
      "                ",
      "              b ",
      "        d K w K ",
      "                ",
      "nnnn nnn  nb w  "
    ]
  ]
}