{
  "xsize": 16,
  "zsize": 16,
  "palette": {
    "palette": [
      {
        "char": " ",
        "block": "minecraft:air"
      },
      {
        "char": "麒",
        "block": "minecraft:air"
      },
      {
        "char": "b",
        "block": "minecraft:polished_diorite"
      },
      {
        "char": "e",
        "block": "minecraft:quartz_block"
      },
      {
        "char": "d",
        "block": "minecraft:diorite"
      },
      {
        "char": "l",
        "block": "minecraft:air"
      },
      {
        "char": "c",
        "block": "minecraft:smooth_quartz"
      },
      {
        "char": "C",
        "block": "immersive_weathering:mossy_stone"
      },
      {
        "char": "i",
        "block": "minecraft:cobbled_deepslate"
      },
      {
        "char": "h",
        "block": "minecraft:deepslate[axis\u003dy]"
      },
      {
        "char": "q",
        "block": "minecraft:blackstone"
      },
      {
        "char": "f",
        "block": "minecraft:basalt[axis\u003dx]"
      },
      {
        "char": "g",
        "block": "minecraft:cyan_terracotta"
      },
      {
        "char": "v",
        "block": "minecraft:red_terracotta"
      },
      {
        "char": "蕤",
        "block": "minecraft:powered_rail[powered\u003dtrue,shape\u003dascending_west,waterlogged\u003dfalse]"
      },
      {
        "char": "珈",
        "block": "minecraft:rail[shape\u003dsouth_west,waterlogged\u003dfalse]"
      },
      {
        "char": "獠",
        "block": "minecraft:rail[shape\u003dascending_south,waterlogged\u003dfalse]"
      },
      {
        "char": "挹",
        "block": "minecraft:powered_rail[powered\u003dtrue,shape\u003dascending_east,waterlogged\u003dfalse]"
      },
      {
        "char": "捂",
        "block": "minecraft:lever[face\u003dwall,facing\u003deast,powered\u003dtrue]"
      },
      {
        "char": "耻",
        "block": "immersive_weathering:plate_iron"
      },
      {
        "char": "膝",
        "block": "minecraft:cobblestone_wall[east\u003dnone,north\u003dnone,south\u003dnone,up\u003dtrue,waterlogged\u003dfalse,weathering\u003dfalse,west\u003dnone]"
      },
      {
        "char": "u",
        "block": "minecraft:red_concrete"
      },
      {
        "char": "M",
        "block": "immersive_weathering:exposed_plate_iron"
      }
    ]
  },
  "slices": [
    [
      " 麒be dbl        ",
      "dee  bcl        ",
      "     cdl        ",
      "     bcl        ",
      "     ee         ",
      "     dc         ",
      "     cc         ",
      "     bc         ",
      "     dd         ",
      "     dc         ",
      "     db         ",
      "     ee         ",
      "     bb         ",
      "     cd         ",
      "     cb         ",
      "     cc         "
    ],
    [
      "bedc db         ",
      "     ddl        ",
      "     bel        ",
      "     eel        ",
      "     eb         ",
      "     bb         ",
      "     bd         ",
      "     ee         ",
      "     ec         ",
      "     bb         ",
      "     db         ",
      "     cc         ",
      "     dd         ",
      "     bd         ",
      "     ce         ",
      "     eb         "
    ],
    [
      "     ed         ",
      "      bl        ",
      "     cbl        ",
      "     ccl        ",
      "     cb         ",
      "     dc         ",
      "     cd         ",
      "     dd         ",
      "     db         ",
      "     ce         ",
      "     ee         ",
      "     bb         ",
      "     bb         ",
      "     bd         ",
      "     bd         ",
      "     dd         "
    ],
    [
      "     be         ",
      "     cd         ",
      "     dbl        ",
      "     edl        ",
      "     dc         ",
      "     bc         ",
      "     bb         ",
      "     cc         ",
      "     bd         ",
      "     ce         ",
      "     cc         ",
      "     db         ",
      "     ec         ",
      "     cd         ",
      "     bd         ",
      "     dc         "
    ],
    [
      "Ciihqce         ",
      "fhhgibb         ",
      "ggCqhec         ",
      "hhigibd         ",
      "fhhCfdc         ",
      "giqffeb         ",
      "igqghbc         ",
      "hgifhdc         ",
      "qhgqCec         ",
      "qqiifee         ",
      "iigfgec         ",
      "qqhghddv        ",
      "ghhqqee         ",
      "ghhghed         ",
      "fCfggbb         ",
      "Cqgqhdd         "
    ],
    [
      "bccc de         ",
      "蕤珈 d ec         ",
      " 獠 e bb         ",
      "挹q捂c ce         ",
      "cbde ce         ",
      "     bc         ",
      " 耻   eb         ",
      "     be         ",
      "  膝  db         ",
      "     ed         ",
      "     ccu        ",
      "     bbv        ",
      "     edv        ",
      "  膝  de         ",
      "     bd         ",
      " M   eb         "
    ]
  ]
}