{
  "xsize": 16,
  "zsize": 16,
  "palette": {
    "palette": [
      {
        "char": " ",
        "block": "minecraft:air"
      },
      {
        "char": "e",
        "block": "minecraft:quartz_block"
      },
      {
        "char": "d",
        "block": "minecraft:diorite"
      },
      {
        "char": "b",
        "block": "minecraft:polished_diorite"
      },
      {
        "char": "床",
        "block": "minecraft:air"
      },
      {
        "char": "巡",
        "block": "minecraft:air"
      },
      {
        "char": "p",
        "block": "minecraft:quartz_pillar[axis\u003dy]"
      },
      {
        "char": "c",
        "block": "minecraft:smooth_quartz"
      },
      {
        "char": "j",
        "block": "minecraft:air"
      },
      {
        "char": "伟",
        "block": "minecraft:air"
      },
      {
        "char": "调",
        "block": "minecraft:air"
      },
      {
        "char": "v",
        "block": "minecraft:red_terracotta"
      },
      {
        "char": "u",
        "block": "minecraft:red_concrete"
      },
      {
        "char": "袱",
        "block": "minecraft:quartz_stairs[facing\u003deast,half\u003dtop,shape\u003dstraight,waterlogged\u003dfalse]"
      },
      {
        "char": "儸",
        "block": "minecraft:diorite_stairs[facing\u003deast,half\u003dtop,shape\u003dstraight,waterlogged\u003dfalse]"
      },
      {
        "char": "亥",
        "block": "minecraft:quartz_stairs[facing\u003dsouth,half\u003dtop,shape\u003dstraight,waterlogged\u003dfalse]"
      },
      {
        "char": "椎",
        "block": "minecraft:quartz_stairs[facing\u003dnorth,half\u003dtop,shape\u003dstraight,waterlogged\u003dfalse]"
      },
      {
        "char": "竺",
        "block": "minecraft:quartz_pillar[axis\u003dz]"
      },
      {
        "char": "桨",
        "block": "minecraft:diorite_stairs[facing\u003dnorth,half\u003dtop,shape\u003dstraight,waterlogged\u003dfalse]"
      }
    ]
  },
  "slices": [
    [
      "              ed",
      "              db",
      "        床     ee",
      "       床巡床   peb",
      "        床     de",
      "             pdd",
      "              ec",
      "              be",
      "             pcb",
      "              dc",
      "              dd",
      "             pbe",
      "             jde",
      "             伟be",
      "            jccd",
      "             调ee"
    ],
    [
      "              cd",
      "              db",
      "              bc",
      "             cdd",
      "              cc",
      "             pcb",
      "              bc",
      "              ee",
      "             pee",
      "              dd",
      "              bb",
      "             cbd",
      "             jcb",
      "             伟de",
      "            jpee",
      "             调dd"
    ],
    [
      "              ev",
      "              du",
      "              dv",
      "             pcu",
      "              bu",
      "             dbu",
      "              dv",
      "              eu",
      "             pbv",
      "              bv",
      "              eu",
      "             peu",
      "             jce",
      "             伟be",
      "            jddd",
      "             调bd"
    ],
    [
      "              bc",
      "              eb",
      "              ce",
      "             cde",
      "              de",
      "             peb",
      "              ce",
      "              bb",
      "             bdc",
      "              ce",
      "              de",
      "             cbd",
      "             jce",
      "             伟bd",
      "            jeeb",
      "             调db"
    ],
    [
      "              ce",
      "             袱bd",
      "              cb",
      "             pcd",
      "             儸ee",
      "             cde",
      "              bd",
      "              bc",
      "             bbc",
      "              bd",
      "              dc",
      "             pcd",
      "             jdc",
      "             伟ee",
      "            jbbb",
      "             调bb"
    ],
    [
      "             亥ed",
      "             dbd",
      "             椎db",
      "             亥bc",
      "             竺ce",
      "             桨ec",
      "              be",
      "              ee",
      "             pbc",
      "              cb",
      "              ee",
      "             cbd",
      "             jec",
      "             伟de",
      "            jdbe",
      "             调ee"
    ]
  ]
}