{
  "xsize": 16,
  "zsize": 16,
  "palette": {
    "palette": [
      {
        "char": " ",
        "block": "minecraft:air"
      },
      {
        "char": "y",
        "block": "minecraft:quartz_slab[type\u003dtop,waterlogged\u003dfalse]"
      },
      {
        "char": "z",
        "block": "minecraft:clay"
      },
      {
        "char": "皈",
        "block": "minecraft:quartz_slab[type\u003ddouble,waterlogged\u003dfalse]"
      },
      {
        "char": "i",
        "block": "minecraft:cobbled_deepslate"
      },
      {
        "char": "j",
        "block": "minecraft:air"
      },
      {
        "char": "e",
        "block": "minecraft:quartz_block"
      },
      {
        "char": "d",
        "block": "minecraft:diorite"
      },
      {
        "char": "N",
        "block": "minecraft:diorite_slab[type\u003dtop,waterlogged\u003dfalse]"
      },
      {
        "char": "c",
        "block": "minecraft:smooth_quartz"
      },
      {
        "char": "伟",
        "block": "minecraft:air"
      },
      {
        "char": "袱",
        "block": "minecraft:quartz_stairs[facing\u003deast,half\u003dtop,shape\u003dstraight,waterlogged\u003dfalse]"
      },
      {
        "char": "p",
        "block": "minecraft:quartz_pillar[axis\u003dy]"
      },
      {
        "char": "b",
        "block": "minecraft:polished_diorite"
      },
      {
        "char": "v",
        "block": "minecraft:red_terracotta"
      },
      {
        "char": "q",
        "block": "minecraft:blackstone"
      },
      {
        "char": "f",
        "block": "minecraft:basalt[axis\u003dx]"
      },
      {
        "char": "h",
        "block": "minecraft:deepslate[axis\u003dy]"
      },
      {
        "char": "C",
        "block": "immersive_weathering:mossy_stone"
      },
      {
        "char": "儸",
        "block": "minecraft:diorite_stairs[facing\u003deast,half\u003dtop,shape\u003dstraight,waterlogged\u003dfalse]"
      },
      {
        "char": "袅",
        "block": "minecraft:quartz_stairs[facing\u003deast,half\u003dbottom,shape\u003dstraight,waterlogged\u003dfalse]"
      },
      {
        "char": "u",
        "block": "minecraft:red_concrete"
      },
      {
        "char": "K",
        "block": "minecraft:diorite_slab[type\u003dbottom,waterlogged\u003dfalse]"
      },
      {
        "char": "n",
        "block": "minecraft:air"
      },
      {
        "char": "拭",
        "block": "minecraft:cobblestone_wall[east\u003dlow,north\u003dnone,south\u003dnone,up\u003dfalse,waterlogged\u003dfalse,weathering\u003dfalse,west\u003dlow]"
      },
      {
        "char": "调",
        "block": "minecraft:air"
      },
      {
        "char": "鲸",
        "block": "minecraft:mossy_cobblestone_wall[east\u003dtall,north\u003dtall,south\u003dnone,up\u003dtrue,waterlogged\u003dfalse,west\u003dnone]"
      }
    ]
  },
  "slices": [
    [
      "              yz",
      "              皈i",
      "            j  e",
      "            j y ",
      "            j y ",
      "              dd",
      "            j Nz",
      "              Ny",
      "               c",
      "            伟 yz",
      "           j  皈z",
      "           j 袱dd",
      "           jjpdc",
      "           jjbcc",
      "          jv ped",
      "             袱be"
    ],
    [
      "             eqf",
      "             dhf",
      "            jdqq",
      "            jdqi",
      "            j Cq",
      "            儸dqh",
      "            jchf",
      "             Niq",
      "            袅 fh",
      "            伟cqf",
      "           j cCC",
      "           j袅eeb",
      "           jjceb",
      "           jjdce",
      "           v pcb",
      "           u Kec"
    ],
    [
      "             e  ",
      "             b  ",
      "            jd  ",
      "            jd  ",
      "            jd  ",
      "             d  ",
      "             b  ",
      "             b  ",
      "             c  ",
      "            nbn ",
      "           j cnn",
      "           j bbd",
      "           jjdbc",
      "           jjcdd",
      "           u拭bce",
      "           j 调bc"
    ],
    [
      "                ",
      "                ",
      "                ",
      "                ",
      "                ",
      "                ",
      "                ",
      "                ",
      "                ",
      "            nnn ",
      "           j  nn",
      "           j 伟pb",
      "           jjcbb",
      "           jjeed",
      "           jjbce",
      "           j 调鲸b"
    ],
    [
      "                ",
      "                ",
      "                ",
      "                ",
      "                ",
      "                ",
      "                ",
      "                ",
      "                ",
      "            nnn ",
      "           j  nn",
      "           j 伟eb",
      "           jjpbc",
      "           jjedd",
      "           jjcee",
      "           j 调鲸d"
    ],
    [
      "                ",
      "                ",
      "                ",
      "                ",
      "                ",
      "                ",
      "                ",
      "                ",
      "                ",
      "            nnn ",
      "           j  nn",
      "           j 伟ed",
      "           jjpec",
      "           jjcbd",
      "           jjpdc",
      "           j 调de"
    ]
  ]
}