{
  "xsize": 16,
  "zsize": 16,
  "palette": {
    "palette": [
      {
        "char": " ",
        "block": "minecraft:air"
      },
      {
        "char": "t",
        "block": "minecraft:grass_block[snowy=false]"
      },
      {
        "char": "o",
        "block": "minecraft:dirt"
      },
      {
        "char": "i",
        "block": "minecraft:cobbled_deepslate"
      },
      {
        "char": "f",
        "block": "minecraft:basalt[axis=x]"
      },
      {
        "char": "h",
        "block": "minecraft:deepslate[axis=y]"
      },
      {
        "char": "g",
        "block": "minecraft:cyan_terracotta"
      },
      {
        "char": "q",
        "block": "minecraft:blackstone"
      },
      {
        "char": "s",
        "block": "minecraft:air"
      },
      {
        "char": "胡",
        "block": "immersive_weathering:oak_leaf_pile[age=0,layers=1]"
      },
      {
        "char": "c",
        "block": "minecraft:smooth_quartz"
      },
      {
        "char": "b",
        "block": "minecraft:polished_diorite"
      },
      {
        "char": "d",
        "block": "minecraft:diorite"
      },
      {
        "char": "e",
        "block": "minecraft:quartz_block"
      },
      {
        "char": "j",
        "block": "minecraft:air"
      },
      {
        "char": "p",
        "block": "minecraft:quartz_pillar[axis=y]"
      },
      {
        "char": "俎",
        "block": "immersive_weathering:oak_leaf_pile[age=0,layers=2]"
      },
      {
        "char": "淅",
        "block": "immersive_weathering:oak_leaf_pile[age=0,layers=3]"
      },
      {
        "char": "瓣",
        "block": "minecraft:oak_log[axis=y]"
      },
      {
        "char": "恁",
        "block": "minecraft:air"
      },
      {
        "char": "劲",
        "block": "minecraft:air"
      },
      {
        "char": "床",
        "block": "minecraft:air"
      },
      {
        "char": "m",
        "block": "minecraft:air"
      },
      {
        "char": "嘹",
        "block": "minecraft:diorite_stairs[facing=east,half=bottom,shape=outer_right,waterlogged=false]"
      },
      {
        "char": "箍",
        "block": "minecraft:diorite_stairs[facing=south,half=bottom,shape=straight,waterlogged=false]"
      },
      {
        "char": "袅",
        "block": "minecraft:quartz_stairs[facing=east,half=bottom,shape=straight,waterlogged=false]"
      },
      {
        "char": "竺",
        "block": "minecraft:quartz_pillar[axis=z]"
      },
      {
        "char": "狩",
        "block": "minecraft:quartz_stairs[facing=east,half=bottom,shape=outer_left,waterlogged=false]"
      },
      {
        "char": "擂",
        "block": "minecraft:diorite_stairs[facing=north,half=bottom,shape=straight,waterlogged=false]"
      },
      {
        "char": "K",
        "block": "minecraft:diorite_slab[type=bottom,waterlogged=false]"
      },
      {
        "char": "谟",
        "block": "minecraft:quartz_stairs[facing=north,half=bottom,shape=outer_right,waterlogged=false]"
      },
      {
        "char": "蒙",
        "block": "minecraft:quartz_stairs[facing=north,half=bottom,shape=straight,waterlogged=false]"
      },
      {
        "char": "伟",
        "block": "minecraft:air"
      },
      {
        "char": "巡",
        "block": "minecraft:air"
      },
      {
        "char": "调",
        "block": "minecraft:air"
      }
    ]
  },
  "slices": [
    [
      "ttttttttttttoooo",
      "ttttttttttttoooo",
      "ttttttttttttoooo",
      "tttttttttttttooo",
      "tttttttttttttooo",
      "tttttttttttttooo",
      "tttttttttttttooo",
      "tttttttttttttooo",
      "tttttttttotttooo",
      "tttttttttttttttt",
      "tttttttttttttttt",
      "ifhihgggtgiqhqfg",
      "ififqffigiithiif",
      "ghiitqggqitfqfht",
      "qfqqgtgihhqhghhf",
      "ghhgqqgfqfhgggqf"
    ],
    [
      "ssss胡胡sssssscbdb",
      "ssssssssssssdecc",
      "ssssssssssssdcdd",
      "ssssssssssssjebb",
      "ssssssssssssjcpc",
      "ssssssssssssjcbd",
      "ssssssss胡胡s胡jbee",
      "ssssssss胡ssssbed",
      "sssssss俎淅瓣s胡sbbe",
      "sssssss胡sss胡ssss",
      "ssssssssss胡胡ssss",
      "        s       ",
      "           s    ",
      "    ss s  s    s",
      "     s          ",
      "s           s   "
    ],
    [
      "   恁劲床劲恁    cdee",
      "            decc",
      "            cbce",
      "             eeb",
      "            jpdd",
      "            jcde",
      "            jdpb",
      "             cbd",
      "         瓣   cdp",
      "               m",
      "                ",
      "                ",
      "                ",
      "                ",
      "                ",
      "                "
    ],
    [
      "   恁劲床劲恁    嘹箍cc",
      "            袅竺be",
      "            狩擂bb",
      "             Kbc",
      "            jped",
      "            jbeb",
      "            jppc",
      "             袅dp",
      "         瓣   谟蒙p",
      "               m",
      "                ",
      "                ",
      "                ",
      "                ",
      "                ",
      "                "
    ],
    [
      "             伟db",
      "            jpec",
      "             mde",
      "              cd",
      "            jppd",
      "            jdee",
      "        劲床劲 jppb",
      "       劲床巡床劲 调ed",
      "       床巡瓣巡床  调p",
      "       劲床巡床劲   m",
      "       恁劲床劲     ",
      "                ",
      "                ",
      "                ",
      "                ",
      "                "
    ],
    [
      "             伟cb",
      "            jbcd",
      "             mec",
      "              cd",
      "            jbec",
      "            jcee",
      "       恁劲床劲恁jdpd",
      "       劲床巡床劲 调pe",
      "       床巡瓣巡床  调p",
      "       劲床巡床劲   m",
      "        劲床劲恁    ",
      "                ",
      "                ",
      "                ",
      "                ",
      "                "
    ]
  ]
}