{
  "xsize": 16,
  "zsize": 16,
  "palette": {
    "palette": [
      {
        "char": " ",
        "block": "minecraft:air"
      },
      {
        "char": "i",
        "block": "minecraft:air"
      },
      {
        "char": "z",
        "block": "minecraft:cracked_stone_bricks"
      },
      {
        "char": "h",
        "block": "minecraft:air"
      },
      {
        "char": "b",
        "block": "minecraft:glass"
      },
      {
        "char": "d",
        "block": "minecraft:mossy_cobblestone"
      },
      {
        "char": "c",
        "block": "minecraft:stone[weathering\u003dfalse]"
      },
      {
        "char": "a",
        "block": "minecraft:cobblestone[weathering\u003dfalse]"
      },
      {
        "char": "g",
        "block": "minecraft:air"
      },
      {
        "char": "f",
        "block": "minecraft:air"
      },
      {
        "char": "ΐ",
        "block": "minecraft:air"
      },
      {
        "char": "e",
        "block": "minecraft:smooth_stone_slab[type\u003ddouble,waterlogged\u003dfalse]"
      },
      {
        "char": "Ϛ",
        "block": "minecraft:air"
      },
      {
        "char": "M",
        "block": "minecraft:cobblestone_slab[type\u003dbottom,waterlogged\u003dfalse,weathering\u003dfalse]"
      },
      {
        "char": "j",
        "block": "minecraft:bookshelf"
      },
      {
        "char": "k",
        "block": "minecraft:stone_bricks[weathering\u003dfalse]"
      },
      {
        "char": "C",
        "block": "minecraft:stone_brick_stairs[facing\u003dnorth,half\u003dbottom,shape\u003dstraight,waterlogged\u003dfalse,weathering\u003dfalse]"
      },
      {
        "char": "y",
        "block": "minecraft:mossy_stone_bricks"
      },
      {
        "char": "Ы",
        "block": "minecraft:air"
      }
    ]
  },
  "slices": [
    [
      "                ",
      "                ",
      "                ",
      "                ",
      "                ",
      "                ",
      "                ",
      "   iii  i       ",
      "        zh      ",
      "bdbcbcba h      ",
      "       b        ",
      "       c        ",
      "       b h      ",
      "       d h      ",
      "g      b h      ",
      " fΐ    d h      "
    ],
    [
      "                ",
      "                ",
      "                ",
      "                ",
      "                ",
      "                ",
      "                ",
      "   iii  i       ",
      "eeeeeeeeeh      ",
      "aaaaaaaaeh      ",
      "acddddcae       ",
      "addcadcae       ",
      "cdadccaaeh      ",
      "acdaccaaeh      ",
      "gdcddadaeh      ",
      " fΐddadaeh      "
    ],
    [
      "                ",
      "                ",
      "                ",
      "                ",
      "                ",
      "                ",
      "                ",
      "   iii  i       ",
      "        zh      ",
      "babdbabaϚ       ",
      "Maa  jjb        ",
      "  g  kkc        ",
      "d a  kkb h      ",
      "a    kkc h      ",
      "     CCb h      ",
      "       c h      "
    ],
    [
      "                ",
      "                ",
      "                ",
      "                ",
      "                ",
      "                ",
      "                ",
      "   iii  i       ",
      "        kh      ",
      "bdbcbcbdϚ       ",
      "  a  jjb        ",
      "  g  kkd        ",
      "  M  kkb h      ",
      "     CCa h      ",
      "       b h      ",
      "       c h      "
    ],
    [
      "                ",
      "                ",
      "                ",
      "                ",
      "                ",
      "                ",
      "                ",
      "   iii  i       ",
      "        yh      ",
      "bdbabdbcЫ       ",
      "     jjb        ",
      "  g  kkc        ",
      "     CCb h      ",
      "       c h      ",
      "       b h      ",
      "       d h      "
    ],
    [
      "                ",
      "                ",
      "                ",
      "                ",
      "                ",
      "                ",
      "                ",
      "   iii  i       ",
      " eeeeeeeeh      ",
      "MM aaaaae       ",
      "   adaaae       ",
      "  gccCCae       ",
      "    a  aeh      ",
      "   aa  aeh      ",
      " aadc  aeh      ",
      "daddcccaeh      "
    ]
  ]
}