{
  "xsize": 16,
  "zsize": 16,
  "palette": {
    "palette": [
      {
        "char": " ",
        "block": "minecraft:air"
      },
      {
        "char": "i",
        "block": "minecraft:air"
      },
      {
        "char": "g",
        "block": "minecraft:air"
      },
      {
        "char": "y",
        "block": "minecraft:mossy_stone_bricks"
      },
      {
        "char": "Ί",
        "block": "minecraft:air"
      },
      {
        "char": "d",
        "block": "minecraft:mossy_cobblestone"
      },
      {
        "char": "b",
        "block": "minecraft:glass"
      },
      {
        "char": "B",
        "block": "minecraft:water[level\u003d8]"
      },
      {
        "char": "h",
        "block": "minecraft:air"
      },
      {
        "char": "c",
        "block": "minecraft:stone[weathering\u003dfalse]"
      },
      {
        "char": ";",
        "block": "immersive_weathering:exposed_iron_bars[east\u003dtrue,north\u003dfalse,south\u003dtrue,waterlogged\u003dfalse,west\u003dfalse]"
      },
      {
        "char": "w",
        "block": "immersive_weathering:exposed_iron_bars[east\u003dtrue,north\u003dfalse,south\u003dfalse,waterlogged\u003dfalse,west\u003dtrue]"
      },
      {
        "char": "A",
        "block": "immersive_weathering:exposed_iron_bars[east\u003dfalse,north\u003dtrue,south\u003dtrue,waterlogged\u003dfalse,west\u003dfalse]"
      },
      {
        "char": "a",
        "block": "minecraft:cobblestone[weathering\u003dfalse]"
      },
      {
        "char": "I",
        "block": "minecraft:iron_bars[east\u003dfalse,north\u003dtrue,south\u003dtrue,waterlogged\u003dfalse,west\u003dfalse]"
      },
      {
        "char": "v",
        "block": "minecraft:stone_brick_stairs[facing\u003dsouth,half\u003dbottom,shape\u003dstraight,waterlogged\u003dfalse,weathering\u003dfalse]"
      },
      {
        "char": "k",
        "block": "minecraft:stone_bricks[weathering\u003dfalse]"
      },
      {
        "char": "F",
        "block": "minecraft:redstone_lamp[lit\u003dfalse]"
      },
      {
        "char": "z",
        "block": "minecraft:cracked_stone_bricks"
      },
      {
        "char": "e",
        "block": "minecraft:smooth_stone_slab[type\u003ddouble,waterlogged\u003dfalse]"
      },
      {
        "char": "u",
        "block": "minecraft:stone_brick_slab[type\u003dtop,waterlogged\u003dfalse,weathering\u003dfalse]"
      },
      {
        "char": "M",
        "block": "minecraft:cobblestone_slab[type\u003dbottom,waterlogged\u003dfalse,weathering\u003dfalse]"
      },
      {
        "char": "ΐ",
        "block": "minecraft:air"
      },
      {
        "char": "j",
        "block": "minecraft:bookshelf"
      },
      {
        "char": "H",
        "block": "minecraft:oak_stairs[facing\u003dnorth,half\u003dbottom,shape\u003dstraight,waterlogged\u003dfalse]"
      },
      {
        "char": "Q",
        "block": "minecraft:oak_stairs[facing\u003dwest,half\u003dbottom,shape\u003dstraight,waterlogged\u003dfalse]"
      },
      {
        "char": "G",
        "block": "minecraft:oak_stairs[facing\u003deast,half\u003dbottom,shape\u003dstraight,waterlogged\u003dfalse]"
      },
      {
        "char": "f",
        "block": "minecraft:air"
      },
      {
        "char": "U",
        "block": "minecraft:flower_pot"
      }
    ]
  },
  "slices": [
    [
      "                ",
      "                ",
      "                ",
      "                ",
      "                ",
      "                ",
      "                ",
      "        i  iiiii",
      "       gyΊ      ",
      "       g dbdb   ",
      "       g bBb h  ",
      "         cb     ",
      "     ;wwwb      ",
      "     A   a      ",
      "     I v b      ",
      "     A   c      "
    ],
    [
      "                ",
      "                ",
      "                ",
      "                ",
      "                ",
      "                ",
      "                ",
      "        i  iiiii",
      "       gkΊ      ",
      "       g abab   ",
      "       g bBF h  ",
      "         cF     ",
      "         b      ",
      "         d      ",
      "         b      ",
      "       v d      "
    ],
    [
      "                ",
      "                ",
      "                ",
      "                ",
      "                ",
      "                ",
      "                ",
      "        i  iiiii",
      "       gzΊ      ",
      "       g abab   ",
      "       g bBb h  ",
      "         db     ",
      "         b      ",
      "         d      ",
      "         b      ",
      "         c      "
    ],
    [
      "                ",
      "                ",
      "                ",
      "                ",
      "                ",
      "                ",
      "                ",
      "        i  iiiii",
      "       geΊ eee  ",
      "       geaaaaaa ",
      "       geaBbdh  ",
      "        eabaa   ",
      "        eacdcd  ",
      "      uueacdcddM",
      "      u eadcdcac",
      "      u eaaacccd"
    ],
    [
      "                ",
      "                ",
      "                ",
      "                ",
      "                ",
      "                ",
      "                ",
      "        i  iiiii",
      "       gyΊ      ",
      "       gΐababd  ",
      "       g bBbj   ",
      "         abj    ",
      "     ;wwwbj     ",
      "     I   a      ",
      "     I v b HH   ",
      "     A   dQkkG  "
    ],
    [
      "                ",
      "                ",
      "                ",
      "                ",
      "                ",
      "                ",
      "                ",
      "        i  iiiii",
      "       gzΊ      ",
      "       gfdbaba  ",
      "       g bBbj   ",
      "         abj    ",
      "         bj     ",
      "         d      ",
      "         b      ",
      "       v a U    "
    ]
  ]
}