{
  "xsize": 16,
  "zsize": 16,
  "palette": {
    "palette": [
      {
        "char": " ",
        "block": "minecraft:air"
      },
      {
        "char": "b",
        "block": "minecraft:glass"
      },
      {
        "char": "h",
        "block": "minecraft:air"
      },
      {
        "char": "a",
        "block": "minecraft:cobblestone[weathering\u003dfalse]"
      },
      {
        "char": "d",
        "block": "minecraft:mossy_cobblestone"
      },
      {
        "char": "F",
        "block": "minecraft:redstone_lamp[lit\u003dfalse]"
      },
      {
        "char": "c",
        "block": "minecraft:stone[weathering\u003dfalse]"
      },
      {
        "char": "z",
        "block": "minecraft:cracked_stone_bricks"
      },
      {
        "char": "f",
        "block": "minecraft:air"
      },
      {
        "char": "e",
        "block": "minecraft:smooth_stone_slab[type\u003ddouble,waterlogged\u003dfalse]"
      },
      {
        "char": "L",
        "block": "minecraft:polished_andesite_slab[type\u003dbottom,waterlogged\u003dfalse]"
      },
      {
        "char": "T",
        "block": "minecraft:jungle_leaves[distance\u003d7,persistent\u003dtrue,waterlogged\u003dfalse]"
      },
      {
        "char": "ͺ",
        "block": "minecraft:gray_carpet"
      },
      {
        "char": "k",
        "block": "minecraft:stone_bricks[weathering\u003dfalse]"
      },
      {
        "char": "y",
        "block": "minecraft:mossy_stone_bricks"
      }
    ]
  },
  "slices": [
    [
      "       b h      ",
      "       a        ",
      "       b        ",
      "       a        ",
      "       b        ",
      "       d        ",
      "      Fb        ",
      "bcbcbabd h      ",
      "        zh      ",
      " fff ffff       ",
      "                ",
      "                ",
      "                ",
      "                ",
      "                ",
      "                "
    ],
    [
      "cccccadaeh      ",
      "aaadacaae       ",
      "dcdaacdae       ",
      "dcccaddae       ",
      "daaaddaae       ",
      "accaaddae       ",
      "acdccccae       ",
      "aaaaaaaaeh      ",
      "eeeeeeeeeh      ",
      " fff ffff       ",
      "                ",
      "                ",
      "                ",
      "                ",
      "                ",
      "                "
    ],
    [
      "     L b h      ",
      "    L  a        ",
      "  LL  Tb        ",
      "    ͺͺ d        ",
      "    ͺͺTb        ",
      "       d        ",
      "      Tb        ",
      "babababd h      ",
      "        kh      ",
      " fff ffff       ",
      "                ",
      "                ",
      "                ",
      "                ",
      "                ",
      "                "
    ],
    [
      "       b h      ",
      "       d        ",
      "      Tb        ",
      "       a        ",
      "      Tb        ",
      "       c        ",
      "      Tb        ",
      "babdbcbd h      ",
      "        yh      ",
      " fff ffff       ",
      "                ",
      "                ",
      "                ",
      "                ",
      "                ",
      "                "
    ],
    [
      "       b h      ",
      "       a        ",
      "      Tb        ",
      "       d        ",
      "      Tb        ",
      "       d        ",
      "      Tb        ",
      "bcbababa h      ",
      "        yh      ",
      " fff ffff       ",
      "                ",
      "                ",
      "                ",
      "                ",
      "                ",
      "                "
    ],
    [
      "cacdddcaeh      ",
      "dcacaacae       ",
      "cacadaaae       ",
      "dccdcaaae       ",
      "adccccdae       ",
      "cdacaaaae       ",
      "cacccddae       ",
      "aaaaaaaaeh      ",
      "eeeeeeeeeh      ",
      " fff ffff       ",
      "                ",
      "                ",
      "                ",
      "                ",
      "                ",
      "                "
    ]
  ]
}