{
  "xsize": 16,
  "zsize": 16,
  "palette": {
    "palette": [
      {
        "char": " ",
        "block": "minecraft:air"
      },
      {
        "char": "H",
        "block": "minecraft:oak_stairs[facing\u003dnorth,half\u003dbottom,shape\u003dstraight,waterlogged\u003dfalse]"
      },
      {
        "char": "b",
        "block": "minecraft:glass"
      },
      {
        "char": "h",
        "block": "minecraft:air"
      },
      {
        "char": "Q",
        "block": "minecraft:oak_stairs[facing\u003dwest,half\u003dbottom,shape\u003dstraight,waterlogged\u003dfalse]"
      },
      {
        "char": "k",
        "block": "minecraft:stone_bricks[weathering\u003dfalse]"
      },
      {
        "char": "G",
        "block": "minecraft:oak_stairs[facing\u003deast,half\u003dbottom,shape\u003dstraight,waterlogged\u003dfalse]"
      },
      {
        "char": "T",
        "block": "minecraft:jungle_leaves[distance\u003d7,persistent\u003dtrue,waterlogged\u003dfalse]"
      },
      {
        "char": "a",
        "block": "minecraft:cobblestone[weathering\u003dfalse]"
      },
      {
        "char": "E",
        "block": "minecraft:oak_stairs[facing\u003dsouth,half\u003dbottom,shape\u003dstraight,waterlogged\u003dfalse]"
      },
      {
        "char": "c",
        "block": "minecraft:stone[weathering\u003dfalse]"
      },
      {
        "char": "F",
        "block": "minecraft:redstone_lamp[lit\u003dfalse]"
      },
      {
        "char": "d",
        "block": "minecraft:mossy_cobblestone"
      },
      {
        "char": "f",
        "block": "minecraft:air"
      },
      {
        "char": "U",
        "block": "minecraft:flower_pot"
      },
      {
        "char": "z",
        "block": "minecraft:cracked_stone_bricks"
      },
      {
        "char": "y",
        "block": "minecraft:mossy_stone_bricks"
      },
      {
        "char": "e",
        "block": "minecraft:smooth_stone_slab[type\u003ddouble,waterlogged\u003dfalse]"
      },
      {
        "char": "j",
        "block": "minecraft:bookshelf"
      }
    ]
  },
  "slices": [
    [
      " HH    b h      ",
      "QkkG  Ta h      ",
      "QkkG   b        ",
      " EE   Ta        ",
      "       b        ",
      "       c h      ",
      "      Fb h      ",
      "bdbdbcba h      ",
      "        kh      ",
      "ffff ffff       ",
      "                ",
      "                ",
      "                ",
      "                ",
      "                ",
      "                "
    ],
    [
      "       b h      ",
      "      Td h      ",
      "  U    b        ",
      "      Tc        ",
      "       b        ",
      "       c h      ",
      "      Fb h      ",
      "babcbdbd h      ",
      "        zh      ",
      "ffff ffff       ",
      "                ",
      "                ",
      "                ",
      "                ",
      "                ",
      "                "
    ],
    [
      "       b h      ",
      "       c h      ",
      "       b        ",
      "       a        ",
      "       b        ",
      "       a h      ",
      "       b h      ",
      "bdbdbdbd h      ",
      "        yh      ",
      "ffff ffff       ",
      "                ",
      "                ",
      "                ",
      "                ",
      "                ",
      "                "
    ],
    [
      "dcdaaaaaeh      ",
      "acadaaaaeh      ",
      "dcdaaacae       ",
      "cdccdccae       ",
      "dddddcaae       ",
      "dacadcaaeh      ",
      "dcadadaaeh      ",
      "aaaaaaaaeh      ",
      "eeeeeeeeeh      ",
      "ffff ffff       ",
      "                ",
      "                ",
      "                ",
      "                ",
      "                ",
      "                "
    ],
    [
      "       b h      ",
      "  jjj  c h      ",
      "       b        ",
      "  jjj  d        ",
      "G      b        ",
      "G jjj  d        ",
      "      Fb        ",
      "bdbcbdbd h      ",
      "        kh      ",
      "ffff ffff       ",
      "                ",
      "                ",
      "                ",
      "                ",
      "                ",
      "                "
    ],
    [
      "       b h      ",
      "  jjj  c h      ",
      "       b        ",
      "  jjj  d        ",
      "       b        ",
      "  jjj  c        ",
      "      Fb        ",
      "bcbabcba h      ",
      "        kh      ",
      "ffff ffff       ",
      "                ",
      "                ",
      "                ",
      "                ",
      "                ",
      "                "
    ]
  ]
}