{
  "xsize": 16,
  "zsize": 16,
  "palette": {
    "palette": [
      {
        "char": " ",
        "block": "minecraft:air"
      },
      {
        "char": "v",
        "block": "minecraft:stone_brick_stairs[facing\u003dsouth,half\u003dbottom,shape\u003dstraight,waterlogged\u003dfalse,weathering\u003dfalse]"
      },
      {
        "char": "ͻ",
        "block": "minecraft:air"
      },
      {
        "char": "b",
        "block": "minecraft:glass"
      },
      {
        "char": "d",
        "block": "minecraft:mossy_cobblestone"
      },
      {
        "char": "g",
        "block": "minecraft:air"
      },
      {
        "char": "a",
        "block": "minecraft:cobblestone[weathering\u003dfalse]"
      },
      {
        "char": "c",
        "block": "minecraft:stone[weathering\u003dfalse]"
      },
      {
        "char": "y",
        "block": "minecraft:mossy_stone_bricks"
      },
      {
        "char": "f",
        "block": "minecraft:air"
      },
      {
        "char": "u",
        "block": "minecraft:stone_brick_slab[type\u003dtop,waterlogged\u003dfalse,weathering\u003dfalse]"
      },
      {
        "char": "e",
        "block": "minecraft:smooth_stone_slab[type\u003ddouble,waterlogged\u003dfalse]"
      },
      {
        "char": "A",
        "block": "immersive_weathering:exposed_iron_bars[east\u003dfalse,north\u003dtrue,south\u003dtrue,waterlogged\u003dfalse,west\u003dfalse]"
      },
      {
        "char": "ͺ",
        "block": "minecraft:gray_carpet"
      },
      {
        "char": "j",
        "block": "minecraft:bookshelf"
      },
      {
        "char": "·",
        "block": "immersive_weathering:exposed_iron_bars[east\u003dtrue,north\u003dtrue,south\u003dfalse,waterlogged\u003dfalse,west\u003dfalse]"
      },
      {
        "char": "w",
        "block": "immersive_weathering:exposed_iron_bars[east\u003dtrue,north\u003dfalse,south\u003dfalse,waterlogged\u003dfalse,west\u003dtrue]"
      },
      {
        "char": "k",
        "block": "minecraft:stone_bricks[weathering\u003dfalse]"
      },
      {
        "char": "z",
        "block": "minecraft:cracked_stone_bricks"
      }
    ]
  },
  "slices": [
    [
      "       vͻb      ",
      "        ͻd      ",
      "         b      ",
      "       g a      ",
      "       g b      ",
      "       g d      ",
      "       g b      ",
      "       g ababdbc",
      "        y       ",
      "         ff f   ",
      "                ",
      "                ",
      "                ",
      "                ",
      "                ",
      "                "
    ],
    [
      "      u eaaadaaa",
      "      uveaadcacd",
      "      uueaaacaac",
      "       geacaccca",
      "       geaccddad",
      "       geacaadac",
      "       geaaaccda",
      "       geaaaaaaa",
      "        eeeeeeee",
      "         ff f   ",
      "                ",
      "                ",
      "                ",
      "                ",
      "                ",
      "                "
    ],
    [
      "     A   bͺͺ    ",
      "     A   dͺͺ    ",
      "     A   bvv jjj",
      "     ·wwwakk    ",
      "       g bkk    ",
      "       g dkk jjj",
      "       g bjj    ",
      "       g abcbcbd",
      "        y       ",
      "          f     ",
      "                ",
      "                ",
      "                ",
      "                ",
      "                ",
      "                "
    ],
    [
      "         b      ",
      "         c      ",
      "         b   jjj",
      "         avv    ",
      "       g bkk    ",
      "       g akk jjj",
      "       g bjj    ",
      "       g abcbdbd",
      "        z       ",
      "          f     ",
      "                ",
      "                ",
      "                ",
      "                ",
      "                ",
      "                "
    ],
    [
      "       v b      ",
      "         c      ",
      "         b      ",
      "         c      ",
      "       g bvv    ",
      "       g dkk    ",
      "       g bjj    ",
      "       g cbcbaba",
      "        z       ",
      "          f     ",
      "                ",
      "                ",
      "                ",
      "                ",
      "                ",
      "                "
    ],
    [
      "      u eaaaccdd",
      "      uveacadaca",
      "      uuea  dada",
      "        ea  cccd",
      "       gea  ddcc",
      "       geavvddcd",
      "       geadadccc",
      "       geaaaaaaa",
      "        eeeeeeee",
      "          f     ",
      "                ",
      "                ",
      "                ",
      "                ",
      "                ",
      "                "
    ]
  ]
}