{
  "xsize": 16,
  "zsize": 16,
  "palette": {
    "palette": [
      {
        "char": " ",
        "block": "minecraft:air"
      },
      {
        "char": "B",
        "block": "minecraft:glass_pane[east\u003dtrue,north\u003dtrue,south\u003dtrue,waterlogged\u003dfalse,west\u003dfalse]"
      },
      {
        "char": "c",
        "block": "minecraft:cobblestone[weathering\u003dfalse]"
      },
      {
        "char": "b",
        "block": "minecraft:stone[weathering\u003dfalse]"
      },
      {
        "char": "τ",
        "block": "minecraft:cobblestone_slab[type\u003ddouble,waterlogged\u003dfalse,weathering\u003dfalse]"
      },
      {
        "char": "i",
        "block": "minecraft:air"
      },
      {
        "char": "a",
        "block": "minecraft:stone_bricks[weathering\u003dfalse]"
      },
      {
        "char": "e",
        "block": "minecraft:mossy_stone_bricks"
      },
      {
        "char": "k",
        "block": "minecraft:chiseled_stone_bricks[weathering\u003dfalse]"
      },
      {
        "char": "x",
        "block": "minecraft:dark_oak_fence[east\u003dtrue,north\u003dfalse,south\u003dtrue,waterlogged\u003dfalse,west\u003dfalse]"
      },
      {
        "char": "d",
        "block": "minecraft:cracked_stone_bricks"
      },
      {
        "char": "M",
        "block": "minecraft:glass_pane[east\u003dtrue,north\u003dtrue,south\u003dfalse,waterlogged\u003dfalse,west\u003dtrue]"
      },
      {
        "char": "y",
        "block": "minecraft:dark_oak_fence[east\u003dfalse,north\u003dtrue,south\u003dfalse,waterlogged\u003dfalse,west\u003dtrue]"
      },
      {
        "char": "l",
        "block": "minecraft:air"
      },
      {
        "char": "g",
        "block": "minecraft:glass_pane[east\u003dfalse,north\u003dtrue,south\u003dtrue,waterlogged\u003dfalse,west\u003dfalse]"
      },
      {
        "char": "o",
        "block": "minecraft:gray_carpet"
      },
      {
        "char": "V",
        "block": "minecraft:black_carpet"
      },
      {
        "char": "Ҕ",
        "block": "minecraft:furnace[facing\u003deast,lit\u003dfalse]",
        "tag": {
          "z": 593,
          "x": 138,
          "CookTimeTotal": 0,
          "ForgeData": {
            "LockFlag": "1b"
          },
          "CookTime": 0,
          "ForgeCaps": {
            "polymorph:block_entity_recipe_data": {}
          },
          "id": "minecraft:furnace",
          "y": 169,
          "Items": [],
          "BurnTime": 0,
          "RecipesUsed": {}
        }
      },
      {
        "char": "E",
        "block": "minecraft:cobblestone_slab[type\u003dbottom,waterlogged\u003dfalse,weathering\u003dfalse]"
      },
      {
        "char": "h",
        "block": "minecraft:glass_pane[east\u003dtrue,north\u003dfalse,south\u003dfalse,waterlogged\u003dfalse,west\u003dtrue]"
      },
      {
        "char": "p",
        "block": "minecraft:mossy_cobblestone"
      },
      {
        "char": "Έ",
        "block": "minecraft:cobblestone_slab[type\u003dtop,waterlogged\u003dfalse,weathering\u003dfalse]"
      }
    ]
  },
  "slices": [
    [
      "         Bcbb τ ",
      "        iabb    ",
      "         Bcc    ",
      "        iebcb   ",
      "         Bccbcb ",
      "        ikbcbbcb",
      "        xdaMkMeM",
      "       icy  l   ",
      "        l       ",
      "                ",
      "                ",
      "                ",
      "                ",
      "                ",
      "                ",
      "                "
    ],
    [
      "         g oV o ",
      "        iaҔE    ",
      "         goV    ",
      "        iaVcV   ",
      "         gV EoV ",
      "        idτττoEV",
      "        xadMehdh",
      "       icy  l   ",
      "        l       ",
      "                ",
      "                ",
      "                ",
      "                ",
      "                ",
      "                ",
      "                "
    ],
    [
      "         g      ",
      "        id      ",
      "         g      ",
      "        ie      ",
      "         g      ",
      "        idEEτ   ",
      "        xddhahdh",
      "       ipy  l   ",
      "        l       ",
      "                ",
      "                ",
      "                ",
      "                ",
      "                ",
      "                ",
      "                "
    ],
    [
      "         g      ",
      "        id      ",
      "         g      ",
      "        id      ",
      "         g      ",
      "        ie      ",
      "        xakhkhah",
      "       ipy  l   ",
      "        l       ",
      "                ",
      "                ",
      "                ",
      "                ",
      "                ",
      "                ",
      "                "
    ],
    [
      "         g      ",
      "        id      ",
      "         g      ",
      "        id      ",
      "         g      ",
      "        ie      ",
      "        xaahehdh",
      "       icy  l   ",
      "        l       ",
      "                ",
      "                ",
      "                ",
      "                ",
      "                ",
      "                ",
      "                "
    ],
    [
      "         Bbbc   ",
      "        ikccEE  ",
      "         Bcbc   ",
      "        iebbcΈ  ",
      "         Bcbc   ",
      "        idbc    ",
      "        xdeMehdh",
      "       ipy  l   ",
      "        l       ",
      "                ",
      "                ",
      "                ",
      "                ",
      "                ",
      "                ",
      "                "
    ]
  ]
}