{
  "xsize": 16,
  "zsize": 16,
  "palette": {
    "palette": [
      {
        "char": " ",
        "block": "minecraft:air"
      },
      {
        "char": "H",
        "block": "minecraft:oak_stairs[facing\u003dnorth,half\u003dbottom,shape\u003dstraight,waterlogged\u003dfalse]"
      },
      {
        "char": "З",
        "block": "minecraft:oak_stairs[facing\u003deast,half\u003dbottom,shape\u003dinner_left,waterlogged\u003dfalse]"
      },
      {
        "char": "b",
        "block": "minecraft:glass"
      },
      {
        "char": "h",
        "block": "minecraft:air"
      },
      {
        "char": "G",
        "block": "minecraft:oak_stairs[facing\u003deast,half\u003dbottom,shape\u003dstraight,waterlogged\u003dfalse]"
      },
      {
        "char": "c",
        "block": "minecraft:stone[weathering\u003dfalse]"
      },
      {
        "char": "k",
        "block": "minecraft:stone_bricks[weathering\u003dfalse]"
      },
      {
        "char": "Q",
        "block": "minecraft:oak_stairs[facing\u003dwest,half\u003dbottom,shape\u003dstraight,waterlogged\u003dfalse]"
      },
      {
        "char": "d",
        "block": "minecraft:mossy_cobblestone"
      },
      {
        "char": "Ъ",
        "block": "minecraft:oak_stairs[facing\u003dsouth,half\u003dbottom,shape\u003dinner_right,waterlogged\u003dfalse]"
      },
      {
        "char": "E",
        "block": "minecraft:oak_stairs[facing\u003dsouth,half\u003dbottom,shape\u003dstraight,waterlogged\u003dfalse]"
      },
      {
        "char": "F",
        "block": "minecraft:redstone_lamp[lit\u003dfalse]"
      },
      {
        "char": "a",
        "block": "minecraft:cobblestone[weathering\u003dfalse]"
      },
      {
        "char": "y",
        "block": "minecraft:mossy_stone_bricks"
      },
      {
        "char": "f",
        "block": "minecraft:air"
      },
      {
        "char": "U",
        "block": "minecraft:flower_pot"
      },
      {
        "char": "z",
        "block": "minecraft:cracked_stone_bricks"
      },
      {
        "char": "e",
        "block": "minecraft:smooth_stone_slab[type\u003ddouble,waterlogged\u003dfalse]"
      },
      {
        "char": "ϻ",
        "block": "minecraft:oak_stairs[facing\u003dnorth,half\u003dbottom,shape\u003dinner_right,waterlogged\u003dfalse]"
      },
      {
        "char": "ύ",
        "block": "minecraft:oak_stairs[facing\u003dwest,half\u003dbottom,shape\u003dinner_left,waterlogged\u003dfalse]"
      }
    ]
  },
  "slices": [
    [
      "   HHHЗb h      ",
      "      Gc        ",
      "  kkk Gb        ",
      "Q kkk Gd        ",
      "Q kkk Gb        ",
      "Q     Gc        ",
      "ЪEEEEEFb        ",
      "bababdba h      ",
      "        yh      ",
      " fff ffff       ",
      "                ",
      "                ",
      "                ",
      "                ",
      "                ",
      "                "
    ],
    [
      "       b h      ",
      "       d        ",
      "  U U  b        ",
      "       d        ",
      "  U    b        ",
      "       d        ",
      "      Fb        ",
      "babababd h      ",
      "        kh      ",
      " fff ffff       ",
      "                ",
      "                ",
      "                ",
      "                ",
      "                ",
      "                "
    ],
    [
      "       b h      ",
      "       a        ",
      "       b        ",
      "       c        ",
      "       b        ",
      "       a        ",
      "      Fb        ",
      "bdbabdbc h      ",
      "        zh      ",
      " fff ffff       ",
      "                ",
      "                ",
      "                ",
      "                ",
      "                ",
      "                "
    ],
    [
      "accdcacaeh      ",
      "aaacadaae       ",
      "caadcdcae       ",
      "accaaadae       ",
      "dacdadaae       ",
      "cacaddcae       ",
      "ddcadacae       ",
      "aaaaaaaaeh      ",
      "eeeeeeeeeh      ",
      " fff ffff       ",
      "                ",
      "                ",
      "                ",
      "                ",
      "                ",
      "                "
    ],
    [
      "  HH   b h      ",
      " QkkG  ch       ",
      " QkkG  b        ",
      "  EE  ϻd        ",
      "      Gb        ",
      "      Ga        ",
      "   ύEEFb        ",
      "babdbcbc h      ",
      "        zh      ",
      " fff    f       ",
      "                ",
      "                ",
      "                ",
      "                ",
      "                ",
      "                "
    ],
    [
      "       b h      ",
      "   U   ch       ",
      "       b        ",
      "       c        ",
      "       b        ",
      "       d        ",
      "      Fb        ",
      "bcbdbabd h      ",
      "        zh      ",
      " fff    f       ",
      "                ",
      "                ",
      "                ",
      "                ",
      "                ",
      "                "
    ]
  ]
}