{
  "xsize": 16,
  "zsize": 16,
  "palette": {
    "palette": [
      {
        "char": " ",
        "block": "minecraft:air"
      },
      {
        "char": "b",
        "block": "minecraft:glass"
      },
      {
        "char": "h",
        "block": "minecraft:air"
      },
      {
        "char": "j",
        "block": "minecraft:bookshelf"
      },
      {
        "char": "a",
        "block": "minecraft:cobblestone[weathering\u003dfalse]"
      },
      {
        "char": "΄",
        "block": "minecraft:green_carpet"
      },
      {
        "char": "V",
        "block": "minecraft:stone_brick_stairs[facing\u003deast,half\u003dbottom,shape\u003dstraight,waterlogged\u003dfalse,weathering\u003dfalse]"
      },
      {
        "char": "k",
        "block": "minecraft:stone_bricks[weathering\u003dfalse]"
      },
      {
        "char": "d",
        "block": "minecraft:mossy_cobblestone"
      },
      {
        "char": "Ϫ",
        "block": "minecraft:chest[facing\u003dnorth,type\u003dsingle,waterlogged\u003dfalse]",
        "loot": "bigbuildingsloot",
        "tag": {
          "z": 598,
          "x": 47,
          "ForgeData": {
            "LockFlag": "1b"
          },
          "ForgeCaps": {},
          "id": "minecraft:chest",
          "y": 154,
          "Items": []
        }
      },
      {
        "char": "c",
        "block": "minecraft:stone[weathering\u003dfalse]"
      },
      {
        "char": "z",
        "block": "minecraft:cracked_stone_bricks"
      },
      {
        "char": "f",
        "block": "minecraft:air"
      },
      {
        "char": "ͻ",
        "block": "minecraft:air"
      },
      {
        "char": "Π",
        "block": "minecraft:air"
      },
      {
        "char": "e",
        "block": "minecraft:smooth_stone_slab[type\u003ddouble,waterlogged\u003dfalse]"
      },
      {
        "char": "Ή",
        "block": "immersive_weathering:weathered_iron_bars[east\u003dfalse,north\u003dtrue,south\u003dtrue,waterlogged\u003dfalse,west\u003dfalse]"
      },
      {
        "char": "i",
        "block": "minecraft:air"
      },
      {
        "char": "ί",
        "block": "immersive_weathering:exposed_iron_bars[east\u003dfalse,north\u003dtrue,south\u003dtrue,waterlogged\u003dfalse,west\u003dtrue]"
      },
      {
        "char": "ά",
        "block": "minecraft:stone_brick_stairs[facing\u003dwest,half\u003dtop,shape\u003dstraight,waterlogged\u003dfalse,weathering\u003dfalse]"
      },
      {
        "char": "N",
        "block": "minecraft:iron_bars[east\u003dtrue,north\u003dfalse,south\u003dfalse,waterlogged\u003dfalse,west\u003dtrue]"
      },
      {
        "char": "Ν",
        "block": "immersive_weathering:exposed_iron_bars[east\u003dtrue,north\u003dtrue,south\u003dfalse,waterlogged\u003dfalse,west\u003dtrue]"
      },
      {
        "char": "Ф",
        "block": "minecraft:iron_bars[east\u003dtrue,north\u003dtrue,south\u003dfalse,waterlogged\u003dfalse,west\u003dtrue]"
      },
      {
        "char": "ϫ",
        "block": "immersive_weathering:exposed_iron_bars[east\u003dfalse,north\u003dtrue,south\u003dfalse,waterlogged\u003dfalse,west\u003dtrue]"
      },
      {
        "char": "y",
        "block": "minecraft:mossy_stone_bricks"
      },
      {
        "char": "Ϩ",
        "block": "minecraft:air"
      }
    ]
  },
  "slices": [
    [
      "       bh       ",
      "j  jjj ah       ",
      "       b        ",
      "       a        ",
      "       b        ",
      "΄Vk kj d        ",
      "΄VkϪkj b        ",
      "bcbababc h      ",
      "        zh      ",
      " fff    f       ",
      "                ",
      "                ",
      "                ",
      "                ",
      "                ",
      "                "
    ],
    [
      "       b        ",
      "j  jjj ah       ",
      "       b        ",
      "       c        ",
      "       b        ",
      "  Vkkj a        ",
      "  V kj b        ",
      "babdbdba h      ",
      "        kh      ",
      " fff    f       ",
      "                ",
      "                ",
      "                ",
      "                ",
      "                ",
      "                "
    ],
    [
      "       bͻ       ",
      "       aΠ       ",
      "       bͻ       ",
      "       cͻ       ",
      "       b        ",
      "   Vkj a        ",
      "   Vkj b        ",
      "babcbcbd h      ",
      "        zh      ",
      " fff    f       ",
      "                ",
      "                ",
      "                ",
      "                ",
      "                ",
      "                "
    ],
    [
      "dcccaadae       ",
      "ccccdcdae       ",
      "caadcdaae       ",
      "ddcdcccae       ",
      "dadcdddae       ",
      "a   Vddae       ",
      "a   Vdaae       ",
      "aaaaaaaaeh      ",
      "eeeeeeeeeh      ",
      " fff    f       ",
      "                ",
      "                ",
      "                ",
      "                ",
      "                ",
      "                "
    ],
    [
      "        Ή       ",
      "        Ή       ",
      "        Ή       ",
      "  iiii  Ή       ",
      "Vkkkkk kί       ",
      "Vά     kί       ",
      "Vά   i kί       ",
      "Vkkkkkkkί       ",
      "NΝΝΝФΝΝΝϫ       ",
      "                ",
      "                ",
      "                ",
      "                ",
      "                ",
      "                ",
      "                "
    ],
    [
      "                ",
      "                ",
      "                ",
      "  iii           ",
      " Vyk   y        ",
      " Vά    k        ",
      " Vά  Ϩ k        ",
      " Vkkkyyk        ",
      "                ",
      "                ",
      "                ",
      "                ",
      "                ",
      "                ",
      "                ",
      "                "
    ]
  ]
}