{
  "xsize": 16,
  "zsize": 16,
  "palette": {
    "palette": [
      {
        "char": " ",
        "block": "minecraft:air"
      },
      {
        "char": "v",
        "block": "minecraft:stone_brick_stairs[facing\u003dsouth,half\u003dbottom,shape\u003dstraight,waterlogged\u003dfalse,weathering\u003dfalse]"
      },
      {
        "char": "a",
        "block": "minecraft:cobblestone[weathering\u003dfalse]"
      },
      {
        "char": "b",
        "block": "minecraft:glass"
      },
      {
        "char": "d",
        "block": "minecraft:mossy_cobblestone"
      },
      {
        "char": "g",
        "block": "minecraft:air"
      },
      {
        "char": "c",
        "block": "minecraft:stone[weathering\u003dfalse]"
      },
      {
        "char": "k",
        "block": "minecraft:stone_bricks[weathering\u003dfalse]"
      },
      {
        "char": "j",
        "block": "minecraft:bookshelf"
      },
      {
        "char": "f",
        "block": "minecraft:air"
      },
      {
        "char": "u",
        "block": "minecraft:stone_brick_slab[type\u003dtop,waterlogged\u003dfalse,weathering\u003dfalse]"
      },
      {
        "char": "e",
        "block": "minecraft:smooth_stone_slab[type\u003ddouble,waterlogged\u003dfalse]"
      },
      {
        "char": "A",
        "block": "immersive_weathering:exposed_iron_bars[east\u003dfalse,north\u003dtrue,south\u003dtrue,waterlogged\u003dfalse,west\u003dfalse]"
      },
      {
        "char": "L",
        "block": "minecraft:polished_andesite_slab[type\u003dbottom,waterlogged\u003dfalse]"
      },
      {
        "char": "͵",
        "block": "minecraft:glass_pane[east\u003dtrue,north\u003dfalse,south\u003dfalse,waterlogged\u003dfalse,west\u003dtrue]"
      },
      {
        "char": "Ϙ",
        "block": "minecraft:glass_pane[east\u003dfalse,north\u003dfalse,south\u003dfalse,waterlogged\u003dfalse,west\u003dtrue]"
      },
      {
        "char": "Μ",
        "block": "minecraft:glass_pane[east\u003dfalse,north\u003dfalse,south\u003dtrue,waterlogged\u003dfalse,west\u003dfalse]"
      },
      {
        "char": "·",
        "block": "immersive_weathering:exposed_iron_bars[east\u003dtrue,north\u003dtrue,south\u003dfalse,waterlogged\u003dfalse,west\u003dfalse]"
      },
      {
        "char": "w",
        "block": "immersive_weathering:exposed_iron_bars[east\u003dtrue,north\u003dfalse,south\u003dfalse,waterlogged\u003dfalse,west\u003dtrue]"
      },
      {
        "char": "K",
        "block": "minecraft:glass_pane[east\u003dfalse,north\u003dtrue,south\u003dtrue,waterlogged\u003dfalse,west\u003dfalse]"
      },
      {
        "char": "ͺ",
        "block": "minecraft:gray_carpet"
      },
      {
        "char": "Δ",
        "block": "minecraft:glass_pane[east\u003dfalse,north\u003dtrue,south\u003dfalse,waterlogged\u003dfalse,west\u003dfalse]"
      },
      {
        "char": "Ξ",
        "block": "minecraft:air"
      },
      {
        "char": "z",
        "block": "minecraft:cracked_stone_bricks"
      },
      {
        "char": "h",
        "block": "minecraft:air"
      },
      {
        "char": "Љ",
        "block": "minecraft:air"
      },
      {
        "char": "y",
        "block": "minecraft:mossy_stone_bricks"
      },
      {
        "char": "Π",
        "block": "minecraft:air"
      }
    ]
  },
  "slices": [
    [
      "       v        ",
      "         a      ",
      "         b      ",
      "         d      ",
      "       g bvv    ",
      "       g ckk    ",
      "       g bjj    ",
      "       g cbcbcbd",
      "        k       ",
      "        fffff   ",
      "                ",
      "                ",
      "                ",
      "                ",
      "                ",
      "                "
    ],
    [
      "      u eadcaacc",
      "      uveaadccdd",
      "      uuea  cdac",
      "        ea  acdc",
      "       gea  ccca",
      "       geavvdadc",
      "       geaacccca",
      "       geaaaaaaa",
      "        eeeeeeee",
      "        fffff   ",
      "                ",
      "                ",
      "                ",
      "                ",
      "                ",
      "                "
    ],
    [
      "     A   b L    ",
      "     A   c͵ϘL  b",
      "     A   b  ΜL  ",
      "     ·wwwa  K ͺͺ",
      "       g b  K ͺͺ",
      "       g c  Δ   ",
      "       g b      ",
      "       gΞabdbcbd",
      "        zh      ",
      "        fffff   ",
      "                ",
      "                ",
      "                ",
      "                ",
      "                ",
      "                "
    ],
    [
      "         b      ",
      "         a      ",
      "         b      ",
      "         a      ",
      "       g b      ",
      "       g a      ",
      "       g b      ",
      "       gΞabdbdbc",
      "        zh      ",
      "        fffff   ",
      "                ",
      "                ",
      "                ",
      "                ",
      "                ",
      "                "
    ],
    [
      "       v b      ",
      "         a      ",
      "         b      ",
      "         c      ",
      "       g b      ",
      "       g d      ",
      "       g b      ",
      "       gЉcbcbdbc",
      "        yΠ      ",
      "        fffff   ",
      "                ",
      "                ",
      "                ",
      "                ",
      "                ",
      "                "
    ],
    [
      "      ugeaaaaacd",
      "      uveacccdca",
      "      uueadcddad",
      "        eaccdcaa",
      "       geaaaacad",
      "       geaccacda",
      "       geacadada",
      "       geaaaaaaa",
      "        eeeeeeee",
      "         ffff   ",
      "                ",
      "                ",
      "                ",
      "                ",
      "                ",
      "                "
    ]
  ]
}