{
  "xsize": 16,
  "zsize": 16,
  "palette": {
    "palette": [
      {
        "char": " ",
        "block": "minecraft:air"
      },
      {
        "char": "p",
        "block": "minecraft:air"
      },
      {
        "char": "d",
        "block": "minecraft:glass"
      },
      {
        "char": "h",
        "block": "minecraft:mossy_stone_bricks"
      },
      {
        "char": "B",
        "block": "minecraft:air"
      },
      {
        "char": "i",
        "block": "minecraft:cracked_stone_bricks"
      },
      {
        "char": "n",
        "block": "minecraft:air"
      },
      {
        "char": "r",
        "block": "minecraft:smooth_stone_slab[type\u003dbottom,waterlogged\u003dfalse]"
      },
      {
        "char": "j",
        "block": "minecraft:stone_bricks[weathering\u003dfalse]"
      },
      {
        "char": "b",
        "block": "minecraft:quartz_pillar[axis\u003dy]"
      },
      {
        "char": "ͳ",
        "block": "immersive_weathering:exposed_iron_bars[east\u003dtrue,north\u003dfalse,south\u003dfalse,waterlogged\u003dfalse,west\u003dfalse]"
      },
      {
        "char": "c",
        "block": "minecraft:cobblestone[weathering\u003dfalse]"
      },
      {
        "char": "ͱ",
        "block": "immersive_weathering:exposed_iron_bars[east\u003dtrue,north\u003dtrue,south\u003dfalse,waterlogged\u003dfalse,west\u003dtrue]"
      },
      {
        "char": "t",
        "block": "minecraft:stone[weathering\u003dfalse]"
      },
      {
        "char": "S",
        "block": "minecraft:black_concrete"
      },
      {
        "char": "g",
        "block": "minecraft:smooth_stone_slab[type\u003ddouble,waterlogged\u003dfalse]"
      },
      {
        "char": "D",
        "block": "minecraft:stone_brick_slab[type\u003dbottom,waterlogged\u003dfalse,weathering\u003dfalse]"
      },
      {
        "char": "Ύ",
        "block": "minecraft:stone_brick_slab[type\u003dtop,waterlogged\u003dfalse,weathering\u003dfalse]"
      },
      {
        "char": "k",
        "block": "minecraft:gray_stained_glass"
      },
      {
        "char": "G",
        "block": "immersive_weathering:weathered_iron_bars[east\u003dtrue,north\u003dfalse,south\u003dfalse,waterlogged\u003dfalse,west\u003dtrue]"
      },
      {
        "char": "ώ",
        "block": "immersive_weathering:weathered_iron_bars[east\u003dfalse,north\u003dfalse,south\u003dfalse,waterlogged\u003dfalse,west\u003dtrue]"
      },
      {
        "char": "η",
        "block": "immersive_weathering:weathered_iron_bars[east\u003dtrue,north\u003dfalse,south\u003dfalse,waterlogged\u003dfalse,west\u003dfalse]"
      },
      {
        "char": "ͺ",
        "block": "immersive_weathering:weathered_iron_bars[east\u003dfalse,north\u003dfalse,south\u003dtrue,waterlogged\u003dfalse,west\u003dtrue]"
      },
      {
        "char": "Ͷ",
        "block": "immersive_weathering:weathered_iron_bars[east\u003dtrue,north\u003dtrue,south\u003dfalse,waterlogged\u003dfalse,west\u003dfalse]"
      },
      {
        "char": "I",
        "block": "immersive_weathering:weathered_iron_bars[east\u003dfalse,north\u003dtrue,south\u003dtrue,waterlogged\u003dfalse,west\u003dfalse]"
      },
      {
        "char": "έ",
        "block": "immersive_weathering:weathered_iron_bars[east\u003dfalse,north\u003dtrue,south\u003dfalse,waterlogged\u003dfalse,west\u003dfalse]"
      }
    ]
  },
  "slices": [
    [
      "                ",
      "                ",
      "  p             ",
      "ddhBp           ",
      "   hddd         ",
      "       d        ",
      "        i       ",
      "         d      ",
      "          d     ",
      "          dn    ",
      "          dn    ",
      "rr        j     ",
      "bbr        i    ",
      "b br      ͳdn   ",
      "dbbr       d    ",
      "bbbr       d    "
    ],
    [
      "                ",
      "                ",
      "  p             ",
      "iicBp           ",
      "ͱͱͱchih         ",
      "       h        ",
      "        t       ",
      "         i      ",
      "          h     ",
      "          in    ",
      "          jn    ",
      "          c     ",
      "b          t    ",
      "Sb        ͳhn   ",
      "dSb        h    ",
      "Sb         i    "
    ],
    [
      "                ",
      "                ",
      "                ",
      "                ",
      "hjj             ",
      "                ",
      "        i       ",
      "         h      ",
      "          h     ",
      "          hn    ",
      "          hn    ",
      "          g     ",
      "          i     ",
      "b         i     ",
      "db        h     ",
      "b         i     "
    ],
    [
      "                ",
      "                ",
      "                ",
      "                ",
      "                ",
      "jhD             ",
      "      Dh        ",
      "        j       ",
      "         h      ",
      "         h      ",
      "         j      ",
      "         g      ",
      "         h      ",
      "S        i      ",
      "dS       j      ",
      "S        h      "
    ],
    [
      "                ",
      "                ",
      "                ",
      "                ",
      "                ",
      "                ",
      "ggg Ύ           ",
      "ijhhgjii        ",
      "kkkkjgijj       ",
      "    kjgih       ",
      "     kjgh       ",
      "      kig       ",
      "      kjg       ",
      "      kjg       ",
      "      khg       ",
      "      khg       "
    ],
    [
      "                ",
      "                ",
      "                ",
      "                ",
      "                ",
      "                ",
      "GGώ             ",
      "      ηͺ        ",
      "       Ͷͺ       ",
      "kkkk    I       ",
      "  kkk   I       ",
      "    kk  I       ",
      "     k  I       ",
      "     k  I       ",
      "     k  I       ",
      "     k  έ       "
    ]
  ]
}