{
  "xsize": 16,
  "zsize": 16,
  "palette": {
    "palette": [
      {
        "char": " ",
        "block": "minecraft:air"
      },
      {
        "char": "c",
        "block": "minecraft:mossy_stone_bricks"
      },
      {
        "char": "b",
        "block": "minecraft:stone_bricks[weathering\u003dfalse]"
      },
      {
        "char": "p",
        "block": "minecraft:mossy_stone_brick_stairs[facing\u003dnorth,half\u003dbottom,shape\u003dstraight,waterlogged\u003dfalse]"
      },
      {
        "char": "G",
        "block": "immersive_weathering:mossy_stone"
      },
      {
        "char": "k",
        "block": "minecraft:stone_brick_slab[type\u003dbottom,waterlogged\u003dfalse,weathering\u003dfalse]"
      },
      {
        "char": "m",
        "block": "minecraft:smooth_stone_slab[type\u003dbottom,waterlogged\u003dfalse]"
      },
      {
        "char": "B",
        "block": "minecraft:polished_andesite_stairs[facing\u003dsouth,half\u003dbottom,shape\u003dstraight,waterlogged\u003dfalse]"
      },
      {
        "char": "n",
        "block": "minecraft:stone_brick_stairs[facing\u003dsouth,half\u003dbottom,shape\u003dstraight,waterlogged\u003dfalse,weathering\u003dfalse]"
      },
      {
        "char": "q",
        "block": "minecraft:quartz_pillar[axis\u003dx]"
      },
      {
        "char": "w",
        "block": "minecraft:polished_andesite_stairs[facing\u003dnorth,half\u003dbottom,shape\u003dstraight,waterlogged\u003dfalse]"
      },
      {
        "char": "o",
        "block": "minecraft:stone_brick_stairs[facing\u003dnorth,half\u003dbottom,shape\u003dstraight,waterlogged\u003dfalse,weathering\u003dfalse]"
      },
      {
        "char": "v",
        "block": "minecraft:mossy_stone_brick_stairs[facing\u003dsouth,half\u003dbottom,shape\u003dstraight,waterlogged\u003dfalse]"
      },
      {
        "char": "u",
        "block": "minecraft:stone[weathering\u003dfalse]"
      },
      {
        "char": "h",
        "block": "minecraft:air"
      },
      {
        "char": "a",
        "block": "minecraft:structure_void"
      },
      {
        "char": "D",
        "block": "minecraft:mossy_stone_brick_slab[type\u003dbottom,waterlogged\u003dfalse]"
      },
      {
        "char": "s",
        "block": "minecraft:rail[shape\u003deast_west,waterlogged\u003dfalse]"
      },
      {
        "char": "H",
        "block": "minecraft:rail[shape\u003dascending_east,waterlogged\u003dfalse]"
      },
      {
        "char": "K",
        "block": "minecraft:air"
      },
      {
        "char": "d",
        "block": "minecraft:white_stained_glass"
      },
      {
        "char": "z",
        "block": "minecraft:quartz_pillar[axis\u003dz]"
      },
      {
        "char": "r",
        "block": "minecraft:air"
      },
      {
        "char": "J",
        "block": "minecraft:redstone_block"
      },
      {
        "char": "e",
        "block": "minecraft:air"
      },
      {
        "char": "x",
        "block": "minecraft:air"
      },
      {
        "char": "g",
        "block": "minecraft:air"
      },
      {
        "char": "f",
        "block": "minecraft:quartz_pillar[axis\u003dy]"
      },
      {
        "char": "j",
        "block": "minecraft:stone_brick_stairs[facing\u003dnorth,half\u003dtop,shape\u003dstraight,waterlogged\u003dfalse,weathering\u003dfalse]"
      },
      {
        "char": "i",
        "block": "minecraft:stone_brick_stairs[facing\u003dsouth,half\u003dtop,shape\u003dstraight,waterlogged\u003dfalse,weathering\u003dfalse]"
      },
      {
        "char": "C",
        "block": "minecraft:mossy_stone_brick_stairs[facing\u003dnorth,half\u003dtop,shape\u003dstraight,waterlogged\u003dfalse]"
      },
      {
        "char": "l",
        "block": "minecraft:air"
      },
      {
        "char": "E",
        "block": "minecraft:mossy_stone_brick_stairs[facing\u003dsouth,half\u003dtop,shape\u003dstraight,waterlogged\u003dfalse]"
      },
      {
        "char": "t",
        "block": "minecraft:air"
      },
      {
        "char": "y",
        "block": "minecraft:smooth_quartz_stairs[facing\u003dnorth,half\u003dtop,shape\u003dstraight,waterlogged\u003dfalse]"
      },
      {
        "char": "A",
        "block": "minecraft:smooth_quartz_stairs[facing\u003dsouth,half\u003dtop,shape\u003dstraight,waterlogged\u003dfalse]"
      },
      {
        "char": "F",
        "block": "minecraft:smooth_quartz_slab[type\u003ddouble,waterlogged\u003dfalse]"
      },
      {
        "char": "I",
        "block": "minecraft:smooth_quartz_slab[type\u003dbottom,waterlogged\u003dfalse]"
      }
    ]
  },
  "slices": [
    [
      "                ",
      "                ",
      "                ",
      "                ",
      "cb              ",
      "cc              ",
      "cc              ",
      "cb              ",
      "bb              ",
      "bb              ",
      "bb              ",
      "bb              ",
      "bb              ",
      "                ",
      "                ",
      "                "
    ],
    [
      "                ",
      "                ",
      "                ",
      "                ",
      "ccc             ",
      "pGc             ",
      "kmc             ",
      "Bnc             ",
      "qqb             ",
      "wob             ",
      "kmb             ",
      "vuc             ",
      "bbc             ",
      "                ",
      "                ",
      "                "
    ],
    [
      "                ",
      "                ",
      "                ",
      "                ",
      "obcc            ",
      "hhpc            ",
      "aaDc            ",
      "aaBb            ",
      "sHqb            ",
      "aawb            ",
      "aakb            ",
      "aKvc            ",
      "nbbb            ",
      "                ",
      "                ",
      "                "
    ],
    [
      "                ",
      "                ",
      "                ",
      "                ",
      "dbpzb           ",
      "hrhGc           ",
      "aaamc           ",
      "aaanc           ",
      "aaHJb           ",
      "aaaob           ",
      "aaemb           ",
      "axgub           ",
      "dcnzb           ",
      "                ",
      "                ",
      "                "
    ],
    [
      "                ",
      "                ",
      "                ",
      "                ",
      "dbdfcb          ",
      "rarhpc          ",
      "aaaaDc          ",
      "aaaaBb          ",
      "aaaHqc          ",
      "aaaawc          ",
      "aaeeDc          ",
      "aaggvc          ",
      "dbdfbb          ",
      "                ",
      "                ",
      "                "
    ],
    [
      "                ",
      "                ",
      "                ",
      "                ",
      "jbdfpbcbccbbbbcb",
      "aaahhucbbcbbbbcb",
      "aaaaemccbbbbcccb",
      "aaaaanbcbbbbcbbb",
      "aaaaHqccbbbbcccb",
      "aaaaapbbbbbbbbbb",
      "aaeeembbbbbbcbbb",
      "aaxggGcbbbbbcbbb",
      "ibdfvccbbbbbcccb",
      "                ",
      "                ",
      "                "
    ],
    [
      "                ",
      "                ",
      "                ",
      "                ",
      "bbjfdcczbcbzbccz",
      "CCahhhpGpGoGouou",
      "alaaeeDmkmkmkmkm",
      "aaaaaaBnBnBnBnBn",
      "llaaeHqJqqqJqqqJ",
      "aaaaaawowowowowo",
      "laeeeeDmDmkmDmkm",
      "Eiaxggvuvunuvunu",
      "bbifdcbzbbbzbbcz",
      "                ",
      "                ",
      "                "
    ],
    [
      "                ",
      "                ",
      "                ",
      "                ",
      "  bfdcpfpcpfpbof",
      "ccChrhhhhhhhhhhh",
      "ddaaeeeaaaaaaaaa",
      "jjaaaaaaaaaaaaaa",
      "ddaaeessssssssss",
      "iiaaaaaaaaaaaaaa",
      "ddteeeeaaaaaaaaa",
      "bbiaxgggggggaggg",
      "  bfdcvfvbvfncnf",
      "                ",
      "                ",
      "                "
    ],
    [
      "                ",
      "                ",
      "                ",
      "                ",
      "   fjbdfdcdfdbdf",
      "  cyarrhhrhhhhhh",
      "  daeeeaaaaaaaaa",
      "bbjaaaaaaaaaaaaa",
      "bbdaeeeaaaaaaaaa",
      "bbiaaaaaaaaaaaaa",
      "  dteeeaaaaaaaaa",
      "  bAagggggggaggg",
      "   ficdfdbdfdcdf",
      "                ",
      "                ",
      "                "
    ],
    [
      "                ",
      "                ",
      "                ",
      "                ",
      "    bbdfdbdfdcdf",
      "   bCaahrarhrhrh",
      "   dteeaaaaaaaaa",
      "  byaaaaaaaaaaaa",
      "  bdteeaaaaaaaaa",
      "  bAaaaaaaaaaaaa",
      "   dteeaaaaaaaaa",
      "   bEgxgxgxgagxg",
      "    bcdfdbdfdcdf",
      "                ",
      "                ",
      "                "
    ],
    [
      "                ",
      "                ",
      "                ",
      "                ",
      "     bjfjbjfjcjf",
      "    cCahaaahahah",
      "    dteaaaaaaaaa",
      "   bjaaaaaaaaaaa",
      "   bdteaaaaaaaaa",
      "   biaaaaaaaaaaa",
      "    dteaaaaaaaaa",
      "    cEagagagagag",
      "     bifibificif",
      "                ",
      "                ",
      "                "
    ],
    [
      "                ",
      "                ",
      "                ",
      "                ",
      "      cfbbcfbbbf",
      "     bCyjjCyjjjy",
      "     dtalallllll",
      "    bjaaaaaaaaaa",
      "    bdtlaallllll",
      "    biaaaaaaaaaa",
      "     dtallaaalll",
      "     bEAiEiAiEiA",
      "      cfbcbfbbbf",
      "                ",
      "                ",
      "                "
    ],
    [
      "                ",
      "                ",
      "                ",
      "                ",
      "                ",
      "      cFbbbFbbcF",
      "      dddddddddd",
      "     bjyjjjyjjjy",
      "     bdddddddddd",
      "     biAiiiAiiiA",
      "      dddddddddd",
      "      bFbbbFbbbF",
      "                ",
      "                ",
      "                ",
      "                "
    ],
    [
      "                ",
      "                ",
      "                ",
      "                ",
      "                ",
      "                ",
      "                ",
      "      kIkkkIkkkI",
      "                ",
      "      kkkkkIkkkI",
      "                ",
      "                ",
      "                ",
      "                ",
      "                ",
      "                "
    ]
  ]
}