{
  "xsize": 16,
  "zsize": 16,
  "palette": {
    "palette": [
      {
        "char": " ",
        "block": "minecraft:air"
      },
      {
        "char": "a",
        "block": "minecraft:polished_andesite_slab[type\u003dtop,waterlogged\u003dfalse]"
      },
      {
        "char": "w",
        "block": "minecraft:terracotta"
      },
      {
        "char": "h",
        "block": "minecraft:bricks[weathering\u003dfalse]"
      },
      {
        "char": "Ύ",
        "block": "minecraft:note_block[instrument\u003dharp,note\u003d0,powered\u003dfalse]"
      },
      {
        "char": "q",
        "block": "minecraft:granite"
      },
      {
        "char": "Ά",
        "block": "minecraft:polished_andesite_slab[type\u003ddouble,waterlogged\u003dfalse]"
      },
      {
        "char": "Ν",
        "block": "minecraft:air"
      },
      {
        "char": "t",
        "block": "minecraft:air"
      },
      {
        "char": "e",
        "block": "minecraft:andesite"
      },
      {
        "char": "b",
        "block": "minecraft:polished_andesite"
      },
      {
        "char": "x",
        "block": "minecraft:quartz_stairs[facing\u003dwest,half\u003dbottom,shape\u003dstraight,waterlogged\u003dfalse]"
      },
      {
        "char": "r",
        "block": "minecraft:quartz_stairs[facing\u003dnorth,half\u003dbottom,shape\u003dstraight,waterlogged\u003dfalse]"
      },
      {
        "char": "ͽ",
        "block": "minecraft:quartz_stairs[facing\u003dwest,half\u003dbottom,shape\u003douter_right,waterlogged\u003dfalse]"
      },
      {
        "char": "Α",
        "block": "minecraft:quartz_stairs[facing\u003dnorth,half\u003dbottom,shape\u003douter_left,waterlogged\u003dfalse]"
      }
    ]
  },
  "slices": [
    [
      "aaaaa aaaaaaaw  ",
      "aaaaaaaaaaaaah  ",
      "aaaaaaΎaaaaaΎq  ",
      "aaaaaaahhqwwhq  ",
      "aaaaaaawaaaaaq  ",
      "aaaaaaahaaaaaq  ",
      "aaaaaaahaahhhh  ",
      "aΆaaaaaqaahaaq  ",
      "aaaaaaawaahaaq  ",
      "aaaaaaaqaahaaw  ",
      "aaaaaaahaaqaaw  ",
      "aaaaaaaqaahaaq  ",
      "aaaaaaaqaawaah  ",
      "aaaaaaΎqaahaah  ",
      "wqhhhwwhqqwhhh  ",
      "     Ν    Νtt   "
    ],
    [
      "ebbe ebbbbeebhx ",
      "ebe  b ebeeeehx ",
      "beebeeeeebbbbqx ",
      "bbbeeeeeeeebbqx ",
      " eeebbbeeeeeehx ",
      "e beeeebbeebehx ",
      "   bebbbeeebbhx ",
      "bebeebeebebbbqx ",
      "ebeebeebebeeehx ",
      "bbbbbeeebeebehx ",
      "eebbeeeebbebewx ",
      "ebbebeeeeeebbwx ",
      "ebbbbbeebbeebwx ",
      "beeebeebebbbbhx ",
      "qqqwhhqhhhhhwqx ",
      "rrrrrrrrrrrrrrͽ "
    ],
    [
      "  b          x  ",
      "             x  ",
      "             x  ",
      "             x  ",
      "             x  ",
      "    b        x  ",
      "             x  ",
      "             x  ",
      "             x  ",
      "b            x  ",
      "             x  ",
      "             x  ",
      "             x  ",
      "             x  ",
      "rrrrrrrrrrrrrΑ  ",
      "                "
    ],
    [
      "                ",
      "                ",
      "                ",
      "                ",
      "                ",
      "                ",
      "                ",
      "                ",
      "                ",
      "                ",
      "                ",
      "                ",
      "                ",
      "                ",
      "                ",
      "                "
    ],
    [
      "                ",
      "                ",
      "                ",
      "                ",
      "                ",
      "                ",
      "                ",
      "                ",
      "                ",
      "                ",
      "                ",
      "                ",
      "                ",
      "                ",
      "                ",
      "                "
    ],
    [
      "                ",
      "                ",
      "                ",
      "                ",
      "                ",
      "                ",
      "                ",
      "                ",
      "                ",
      "                ",
      "                ",
      "                ",
      "                ",
      "                ",
      "                ",
      "                "
    ]
  ]
}