{
  "xsize": 16,
  "zsize": 16,
  "palette": {
    "palette": [
      {
        "char": " ",
        "block": "minecraft:air"
      },
      {
        "char": "c",
        "block": "minecraft:air"
      },
      {
        "char": "g",
        "block": "minecraft:glass_pane[east\u003dtrue,north\u003dfalse,south\u003dfalse,waterlogged\u003dfalse,west\u003dtrue]"
      },
      {
        "char": "h",
        "block": "minecraft:cracked_stone_bricks"
      },
      {
        "char": "e",
        "block": "minecraft:stone_bricks[weathering\u003dfalse]"
      },
      {
        "char": "f",
        "block": "minecraft:glass_pane[east\u003dfalse,north\u003dtrue,south\u003dtrue,waterlogged\u003dfalse,west\u003dfalse]"
      },
      {
        "char": "i",
        "block": "minecraft:mossy_stone_bricks"
      },
      {
        "char": "a",
        "block": "minecraft:cobblestone[weathering\u003dfalse]"
      },
      {
        "char": "d",
        "block": "minecraft:mossy_cobblestone"
      },
      {
        "char": "b",
        "block": "minecraft:stone[weathering\u003dfalse]"
      },
      {
        "char": "Q",
        "block": "minecraft:crafting_table"
      },
      {
        "char": "C",
        "block": "minecraft:redstone_lamp[lit\u003dfalse]"
      },
      {
        "char": "Ғ",
        "block": "minecraft:stone_button[face\u003dfloor,facing\u003dwest,powered\u003dfalse]"
      },
      {
        "char": "j",
        "block": "minecraft:light_gray_carpet"
      },
      {
        "char": "σ",
        "block": "minecraft:cobblestone_slab[type\u003dbottom,waterlogged\u003dfalse,weathering\u003dfalse]"
      },
      {
        "char": "л",
        "block": "minecraft:stone_button[face\u003dfloor,facing\u003dsouth,powered\u003dfalse]"
      },
      {
        "char": "x",
        "block": "minecraft:cobblestone_stairs[facing\u003dnorth,half\u003dbottom,shape\u003dstraight,waterlogged\u003dfalse,weathering\u003dfalse]"
      },
      {
        "char": "д",
        "block": "minecraft:sea_pickle[pickles\u003d3,waterlogged\u003dfalse]"
      },
      {
        "char": "Ѩ",
        "block": "minecraft:sea_pickle[pickles\u003d1,waterlogged\u003dfalse]"
      },
      {
        "char": "l",
        "block": "minecraft:bookshelf"
      },
      {
        "char": "T",
        "block": "minecraft:flower_pot"
      },
      {
        "char": "Я",
        "block": "minecraft:stone_button[face\u003dfloor,facing\u003deast,powered\u003dfalse]"
      }
    ]
  },
  "slices": [
    [
      "                ",
      "                ",
      "                ",
      "                ",
      "                ",
      "                ",
      "                ",
      "ccc cccc        ",
      "ghghgege        ",
      "       f        ",
      "       i        ",
      "       f        ",
      "       e        ",
      "       f        ",
      "       i        ",
      "       f        "
    ],
    [
      "                ",
      "                ",
      "                ",
      "                ",
      "                ",
      "                ",
      "                ",
      "ccc cccc        ",
      "adaadada        ",
      "bbbbbbba        ",
      "aaaabaaa        ",
      "bbababba        ",
      "aabbabad        ",
      "abbbbbbd        ",
      "bbababaa        ",
      "abbbaaba        "
    ],
    [
      "                ",
      "                ",
      "                ",
      "                ",
      "                ",
      "                ",
      "                ",
      "ccc cccc        ",
      "gigegigi        ",
      " Q     f        ",
      "Q QCaaai        ",
      "ҒQ ja  f        ",
      "jQjQa  h        ",
      " jσ a  f        ",
      "jjjja  e        ",
      " Q лxxxf        "
    ],
    [
      "                ",
      "                ",
      "                ",
      "                ",
      "                ",
      "                ",
      "                ",
      "ccc cccc        ",
      "gigighgi        ",
      " Q     f        ",
      "д QѨaaae        ",
      "     l f        ",
      " T  дl h        ",
      "    a  f        ",
      "    xxxh        ",
      " Q     f        "
    ],
    [
      "                ",
      "                ",
      "                ",
      "                ",
      "                ",
      "                ",
      "                ",
      "ccc cccc        ",
      "adaadadd        ",
      "       a        ",
      "    aaaa        ",
      "     l a        ",
      "     l a        ",
      "    xxxa        ",
      "       d        ",
      " Я     d        "
    ],
    [
      "                ",
      "                ",
      "                ",
      "                ",
      "                ",
      "                ",
      "                ",
      "ccc cc          ",
      "ghgighge        ",
      "       f        ",
      " C  aaai        ",
      "    a  f        ",
      "    xxxi        ",
      "       f        ",
      "       e        ",
      "       f        "
    ]
  ]
}