{
  "xsize": 16,
  "zsize": 16,
  "palette": {
    "palette": [
      {
        "char": " ",
        "block": "minecraft:air"
      },
      {
        "char": "h",
        "block": "minecraft:air"
      },
      {
        "char": "f",
        "block": "minecraft:air"
      },
      {
        "char": "a",
        "block": "minecraft:smooth_stone_slab[type\u003ddouble,waterlogged\u003dfalse]"
      },
      {
        "char": "p",
        "block": "minecraft:air"
      },
      {
        "char": "d",
        "block": "minecraft:air"
      },
      {
        "char": "e",
        "block": "minecraft:stone[weathering\u003dfalse]"
      },
      {
        "char": "c",
        "block": "minecraft:mossy_cobblestone"
      },
      {
        "char": "i",
        "block": "minecraft:glass_pane[east\u003dtrue,north\u003dfalse,south\u003dfalse,waterlogged\u003dfalse,west\u003dtrue]"
      },
      {
        "char": "n",
        "block": "minecraft:cracked_stone_bricks"
      },
      {
        "char": "D",
        "block": "minecraft:air"
      },
      {
        "char": "b",
        "block": "minecraft:cobblestone[weathering\u003dfalse]"
      },
      {
        "char": "j",
        "block": "minecraft:glass_pane[east\u003dfalse,north\u003dtrue,south\u003dtrue,waterlogged\u003dfalse,west\u003dfalse]"
      },
      {
        "char": "z",
        "block": "minecraft:air"
      },
      {
        "char": "G",
        "block": "minecraft:redstone_lamp[lit\u003dfalse]"
      },
      {
        "char": "m",
        "block": "minecraft:mossy_stone_bricks"
      },
      {
        "char": "Ζ",
        "block": "minecraft:oak_stairs[facing\u003dnorth,half\u003dbottom,shape\u003dstraight,waterlogged\u003dfalse]"
      },
      {
        "char": "N",
        "block": "minecraft:smooth_stone_slab[type\u003dbottom,waterlogged\u003dfalse]"
      },
      {
        "char": "8",
        "block": "minecraft:oak_wall_sign[facing\u003dsouth,waterlogged\u003dfalse]",
        "tag": {
          "z": 619,
          "x": 51,
          "is_waxed": "0b",
          "ForgeCaps": {
            "supplementaries:antique_ink": {
              "ink": "0b"
            }
          },
          "id": "minecraft:sign",
          "y": 185,
          "front_text": {
            "color": "black",
            "has_glowing_text": "0b",
            "messages": [
              "{\"extra\":[{\"text\":\"Floor 11:\"}],\"text\":\"\"}",
              "{\"extra\":[{\"text\":\"CEO Offices\"}],\"text\":\"\"}",
              "{\"text\":\"\"}",
              "{\"text\":\"\"}"
            ]
          },
          "back_text": {
            "color": "black",
            "has_glowing_text": "0b",
            "messages": [
              "{\"text\":\"\"}",
              "{\"text\":\"\"}",
              "{\"text\":\"\"}",
              "{\"text\":\"\"}"
            ]
          }
        }
      }
    ]
  },
  "slices": [
    [
      "                ",
      "                ",
      "                ",
      "                ",
      "                ",
      "                ",
      "                ",
      "                ",
      " h hh  h        ",
      "fapaafda        ",
      "eciccinD        ",
      "b     jz        ",
      "      ea        ",
      "   a  ca        ",
      "   a  j         ",
      "      eaf       "
    ],
    [
      "                ",
      "                ",
      "                ",
      "                ",
      "                ",
      "                ",
      "                ",
      "                ",
      " h hh  h        ",
      "fapaafda        ",
      "cbbecccD        ",
      "Gbbbbbez        ",
      " bbbbbba        ",
      "   b  ba        ",
      "      c         ",
      "   b  caf       "
    ],
    [
      "                ",
      "                ",
      "                ",
      "                ",
      "                ",
      "                ",
      "                ",
      "                ",
      " h hh  h        ",
      "fadaafda        ",
      "bciceimD        ",
      "ΖΖ    jz        ",
      " N    ea        ",
      "   a  ea        ",
      "      j         ",
      "   a  caf       "
    ],
    [
      "                ",
      "                ",
      "                ",
      "                ",
      "                ",
      "                ",
      "                ",
      "                ",
      " h hh  h        ",
      "fadaafda        ",
      "ccibbinD        ",
      "   8  jz        ",
      "      ca        ",
      "   a  ca        ",
      "   a  j         ",
      "   a  baf       "
    ],
    [
      "                ",
      "                ",
      "                ",
      "                ",
      "                ",
      "                ",
      "                ",
      "                ",
      " h hh  h        ",
      "fadaafda        ",
      "cciecinD        ",
      "      jz        ",
      "      ba        ",
      "   a  ca        ",
      "      j         ",
      "      caf       "
    ],
    [
      "                ",
      "                ",
      "                ",
      "                ",
      "                ",
      "                ",
      "                ",
      "                ",
      " h hh  h        ",
      "fadaaf a        ",
      "ecicbinf        ",
      "      jz        ",
      "      ea        ",
      "   a  ea        ",
      "      j         ",
      "      baf       "
    ]
  ]
}