{
  "xsize": 16,
  "zsize": 16,
  "palette": {
    "palette": [
      {
        "char": " ",
        "block": "minecraft:air"
      },
      {
        "char": "b",
        "block": "minecraft:cobblestone[weathering\u003dfalse]"
      },
      {
        "char": "c",
        "block": "minecraft:mossy_cobblestone"
      },
      {
        "char": "A",
        "block": "minecraft:air"
      },
      {
        "char": "a",
        "block": "minecraft:smooth_stone_slab[type\u003ddouble,waterlogged\u003dfalse]"
      },
      {
        "char": "f",
        "block": "minecraft:air"
      },
      {
        "char": "e",
        "block": "minecraft:stone[weathering\u003dfalse]"
      },
      {
        "char": "g",
        "block": "minecraft:air"
      },
      {
        "char": "d",
        "block": "minecraft:air"
      },
      {
        "char": "p",
        "block": "minecraft:air"
      },
      {
        "char": "k",
        "block": "minecraft:stone_bricks[weathering\u003dfalse]"
      },
      {
        "char": "j",
        "block": "minecraft:glass_pane[east\u003dfalse,north\u003dtrue,south\u003dtrue,waterlogged\u003dfalse,west\u003dfalse]"
      },
      {
        "char": "i",
        "block": "minecraft:glass_pane[east\u003dtrue,north\u003dfalse,south\u003dfalse,waterlogged\u003dfalse,west\u003dtrue]"
      },
      {
        "char": "ζ",
        "block": "minecraft:oak_wall_sign[facing\u003dwest,waterlogged\u003dfalse]",
        "tag": {
          "z": 618,
          "x": 47,
          "is_waxed": "0b",
          "ForgeCaps": {
            "supplementaries:antique_ink": {
              "ink": "0b"
            }
          },
          "id": "minecraft:sign",
          "y": 136,
          "front_text": {
            "color": "black",
            "has_glowing_text": "0b",
            "messages": [
              "{\"extra\":[{\"text\":\"O.C.T\"}],\"text\":\"\"}",
              "{\"extra\":[{\"text\":\"---------------\"}],\"text\":\"\"}",
              "{\"extra\":[{\"text\":\"Thanks for\"}],\"text\":\"\"}",
              "{\"extra\":[{\"text\":\"Visiting!\"}],\"text\":\"\"}"
            ]
          },
          "back_text": {
            "color": "black",
            "has_glowing_text": "0b",
            "messages": [
              "{\"text\":\"\"}",
              "{\"text\":\"\"}",
              "{\"text\":\"\"}",
              "{\"text\":\"\"}"
            ]
          }
        }
      },
      {
        "char": "n",
        "block": "minecraft:cracked_stone_bricks"
      }
    ]
  },
  "slices": [
    [
      "   b  cA        ",
      "   bb caf       ",
      "      eA        ",
      "      caf       ",
      "     bcaf       ",
      "b   bbeg        ",
      "cbccbec  d      ",
      " apaaf af       ",
      " g gg  g        ",
      "                ",
      "                ",
      "                ",
      "                ",
      "                ",
      "                ",
      "                "
    ],
    [
      "   akkbA        ",
      "   a  caf       ",
      "      jA        ",
      "      caf       ",
      "      baf       ",
      "      jg        ",
      "ccicbik  d      ",
      " apaaf af       ",
      " g gg  g        ",
      "                ",
      "                ",
      "                ",
      "                ",
      "                ",
      "                ",
      "                "
    ],
    [
      "   a  bA        ",
      "     ζcaf       ",
      "      jA        ",
      "      eaf       ",
      "      eaf       ",
      "      jg        ",
      "bbibcin  d      ",
      " apaaf af       ",
      " g gg  g        ",
      "                ",
      "                ",
      "                ",
      "                ",
      "                ",
      "                ",
      "                "
    ],
    [
      "      cA        ",
      "      eaf       ",
      "      jA        ",
      "      caf       ",
      "      baf       ",
      "      jg        ",
      "cbieeik  d      ",
      " apaaf af       ",
      " g gg  g        ",
      "                ",
      "                ",
      "                ",
      "                ",
      "                ",
      "                ",
      "                "
    ],
    [
      "      cA        ",
      "      eaf       ",
      "      jA        ",
      "      eaf       ",
      "      eaf       ",
      "      jg        ",
      "bcicein  d      ",
      " apaaf af       ",
      " g gg  g        ",
      "                ",
      "                ",
      "                ",
      "                ",
      "                ",
      "                ",
      "                "
    ],
    [
      "bbbb  eA        ",
      " bbbbbbaf       ",
      "bb  bbbA        ",
      "bbb bbeaf       ",
      "bbbbbbeaf       ",
      "bbbbbbbg        ",
      "bceecbb  d      ",
      " apaaf af       ",
      " g gg  g        ",
      "                ",
      "                ",
      "                ",
      "                ",
      "                ",
      "                ",
      "                "
    ]
  ]
}