{
  "xsize": 16,
  "zsize": 16,
  "palette": {
    "palette": [
      {
        "char": " ",
        "block": "minecraft:air"
      },
      {
        "char": "c",
        "block": "minecraft:air"
      },
      {
        "char": "e",
        "block": "minecraft:stone_bricks[weathering\u003dfalse]"
      },
      {
        "char": "g",
        "block": "minecraft:glass_pane[east\u003dtrue,north\u003dfalse,south\u003dfalse,waterlogged\u003dfalse,west\u003dtrue]"
      },
      {
        "char": "h",
        "block": "minecraft:cracked_stone_bricks"
      },
      {
        "char": "f",
        "block": "minecraft:glass_pane[east\u003dfalse,north\u003dtrue,south\u003dtrue,waterlogged\u003dfalse,west\u003dfalse]"
      },
      {
        "char": "я",
        "block": "minecraft:glass_pane[east\u003dfalse,north\u003dtrue,south\u003dfalse,waterlogged\u003dfalse,west\u003dfalse]"
      },
      {
        "char": "Б",
        "block": "minecraft:glass_pane[east\u003dfalse,north\u003dfalse,south\u003dtrue,waterlogged\u003dfalse,west\u003dfalse]"
      },
      {
        "char": "a",
        "block": "minecraft:cobblestone[weathering\u003dfalse]"
      },
      {
        "char": "d",
        "block": "minecraft:mossy_cobblestone"
      },
      {
        "char": "b",
        "block": "minecraft:stone[weathering\u003dfalse]"
      },
      {
        "char": "J",
        "block": "minecraft:glass_pane[east\u003dtrue,north\u003dfalse,south\u003dtrue,waterlogged\u003dfalse,west\u003dtrue]"
      },
      {
        "char": "I",
        "block": "minecraft:glass_pane[east\u003dtrue,north\u003dtrue,south\u003dtrue,waterlogged\u003dfalse,west\u003dfalse]"
      },
      {
        "char": "ϴ",
        "block": "minecraft:spruce_log[axis\u003dy]"
      },
      {
        "char": "φ",
        "block": "minecraft:dark_oak_trapdoor[facing\u003deast,half\u003dbottom,open\u003dtrue,powered\u003dfalse,waterlogged\u003dfalse]"
      },
      {
        "char": "k",
        "block": "minecraft:red_carpet"
      },
      {
        "char": "Ϛ",
        "block": "minecraft:dark_oak_trapdoor[facing\u003dsouth,half\u003dbottom,open\u003dtrue,powered\u003dfalse,waterlogged\u003dfalse]"
      },
      {
        "char": "i",
        "block": "minecraft:mossy_stone_bricks"
      },
      {
        "char": "϶",
        "block": "minecraft:dark_oak_leaves[distance\u003d1,persistent\u003dtrue,waterlogged\u003dfalse]"
      },
      {
        "char": "ϸ",
        "block": "minecraft:dark_oak_leaves[distance\u003d2,persistent\u003dtrue,waterlogged\u003dfalse]"
      }
    ]
  },
  "slices": [
    [
      "                ",
      "                ",
      "                ",
      "                ",
      "                ",
      "                ",
      "                ",
      "       cccccc cc",
      "       eghghghge",
      "       f        ",
      "       e        ",
      "       f        ",
      "       h        ",
      "       я        ",
      "                ",
      "       Б        "
    ],
    [
      "                ",
      "                ",
      "                ",
      "                ",
      "                ",
      "                ",
      "                ",
      "       cccccc cc",
      "       adddaadad",
      "       aaaabaaba",
      "       dabaaaabb",
      "       aabaaabbb",
      "       dbbbabaaa",
      "       aaaababaa",
      "       aababaaaa",
      "       aabbaabba"
    ],
    [
      "                ",
      "                ",
      "                ",
      "                ",
      "                ",
      "                ",
      "                ",
      "       cccccc cc",
      "       hJeghghge",
      "       Iϴφkk kk ",
      "       hϚ  kk  k",
      "       f k k k k",
      "       ik k     ",
      "       f kk   kk",
      "       hkk      ",
      "       fk k   k "
    ],
    [
      "                ",
      "                ",
      "                ",
      "                ",
      "                ",
      "                ",
      "                ",
      "       cccccc cc",
      "       egeghgegi",
      "       f϶       ",
      "       e        ",
      "       f        ",
      "       i        ",
      "       f        ",
      "       h        ",
      "       f        "
    ],
    [
      "                ",
      "                ",
      "                ",
      "                ",
      "                ",
      "                ",
      "                ",
      "       cccccc cc",
      "       daaadaada",
      "       aϸ       ",
      "       a        ",
      "       a        ",
      "       d        ",
      "       a        ",
      "       a        ",
      "       a        "
    ],
    [
      "                ",
      "                ",
      "                ",
      "                ",
      "                ",
      "                ",
      "                ",
      "       cccccc cc",
      "       eghgegigh",
      "       f        ",
      "       e        ",
      "       f        ",
      "       i        ",
      "       f        ",
      "       e        ",
      "       f        "
    ]
  ]
}