{
  "xsize": 16,
  "zsize": 16,
  "palette": {
    "palette": [
      {
        "char": " ",
        "block": "minecraft:air"
      },
      {
        "char": "h",
        "block": "minecraft:air"
      },
      {
        "char": "f",
        "block": "minecraft:air"
      },
      {
        "char": "a",
        "block": "minecraft:smooth_stone_slab[type\u003ddouble,waterlogged\u003dfalse]"
      },
      {
        "char": "p",
        "block": "minecraft:air"
      },
      {
        "char": "d",
        "block": "minecraft:air"
      },
      {
        "char": "b",
        "block": "minecraft:cobblestone[weathering\u003dfalse]"
      },
      {
        "char": "c",
        "block": "minecraft:mossy_cobblestone"
      },
      {
        "char": "i",
        "block": "minecraft:glass_pane[east\u003dtrue,north\u003dfalse,south\u003dfalse,waterlogged\u003dfalse,west\u003dtrue]"
      },
      {
        "char": "n",
        "block": "minecraft:cracked_stone_bricks"
      },
      {
        "char": "D",
        "block": "minecraft:air"
      },
      {
        "char": "j",
        "block": "minecraft:glass_pane[east\u003dfalse,north\u003dtrue,south\u003dtrue,waterlogged\u003dfalse,west\u003dfalse]"
      },
      {
        "char": "z",
        "block": "minecraft:air"
      },
      {
        "char": "w",
        "block": "minecraft:polished_diorite"
      },
      {
        "char": "e",
        "block": "minecraft:stone[weathering\u003dfalse]"
      },
      {
        "char": "Ι",
        "block": "minecraft:oak_slab[type\u003dtop,waterlogged\u003dfalse]"
      },
      {
        "char": "Ε",
        "block": "minecraft:chest[facing\u003dsouth,type\u003dsingle,waterlogged\u003dfalse]",
        "loot": "bigbuildingsloot",
        "tag": {
          "z": 628,
          "x": 43,
          "ForgeData": {
            "LockFlag": "1b"
          },
          "ForgeCaps": {},
          "id": "minecraft:chest",
          "y": 149,
          "Items": []
        }
      },
      {
        "char": "m",
        "block": "minecraft:mossy_stone_bricks"
      },
      {
        "char": "8",
        "block": "minecraft:oak_wall_sign[facing\u003dsouth,waterlogged\u003dfalse]",
        "tag": {
          "z": 619,
          "x": 51,
          "is_waxed": "0b",
          "ForgeCaps": {
            "supplementaries:antique_ink": {
              "ink": "0b"
            }
          },
          "id": "minecraft:sign",
          "y": 185,
          "front_text": {
            "color": "black",
            "has_glowing_text": "0b",
            "messages": [
              "{\"extra\":[{\"text\":\"Floor 11:\"}],\"text\":\"\"}",
              "{\"extra\":[{\"text\":\"CEO Offices\"}],\"text\":\"\"}",
              "{\"text\":\"\"}",
              "{\"text\":\"\"}"
            ]
          },
          "back_text": {
            "color": "black",
            "has_glowing_text": "0b",
            "messages": [
              "{\"text\":\"\"}",
              "{\"text\":\"\"}",
              "{\"text\":\"\"}",
              "{\"text\":\"\"}"
            ]
          }
        }
      },
      {
        "char": "k",
        "block": "minecraft:stone_bricks[weathering\u003dfalse]"
      },
      {
        "char": "F",
        "block": "minecraft:glass_pane[east\u003dfalse,north\u003dtrue,south\u003dtrue,waterlogged\u003dfalse,west\u003dtrue]"
      },
      {
        "char": "H",
        "block": "minecraft:glass_pane[east\u003dtrue,north\u003dfalse,south\u003dtrue,waterlogged\u003dfalse,west\u003dtrue]"
      }
    ]
  },
  "slices": [
    [
      "                ",
      "                ",
      "                ",
      "                ",
      "                ",
      "                ",
      "                ",
      "                ",
      " h hh  h        ",
      "fapaafda        ",
      "bciccinD        ",
      "      jz        ",
      "      ba        ",
      "wwwa  ea        ",
      "wΙΕa  j         ",
      "   a  caf       "
    ],
    [
      "                ",
      "                ",
      "                ",
      "                ",
      "                ",
      "                ",
      "                ",
      "                ",
      " h hh  h        ",
      "fapaafda        ",
      "ccieeimD        ",
      "   8  jz        ",
      "      ba        ",
      "wwwa  ea        ",
      "w  a  j         ",
      "   akkcaf       "
    ],
    [
      "                ",
      "                ",
      "                ",
      "                ",
      "                ",
      "                ",
      "                ",
      "                ",
      " h hh  h        ",
      "fapaafda        ",
      "ccibeikD        ",
      "      jz        ",
      "      ea        ",
      "   a  ea        ",
      "   akkF         ",
      "   akkeaf       "
    ],
    [
      "                ",
      "                ",
      "                ",
      "                ",
      "                ",
      "                ",
      "                ",
      "                ",
      " h hh  h        ",
      "fapaafda        ",
      "ceiecimD        ",
      "      jz        ",
      "      ba        ",
      "   akkea        ",
      "   akkF         ",
      "    kbeaf       "
    ],
    [
      "                ",
      "                ",
      "                ",
      "                ",
      "                ",
      "                ",
      "                ",
      "                ",
      " h hh  h        ",
      "fapaafda        ",
      "eebebecD        ",
      "bbbbbbbz        ",
      "bbbbb ba        ",
      "bbbbkbba        ",
      "bbbbbbb         ",
      "bbbbbbeaf       "
    ],
    [
      "                ",
      "                ",
      "                ",
      "                ",
      "                ",
      "                ",
      "                ",
      "                ",
      " h hh  h        ",
      "fapaafda        ",
      "bciebHnD        ",
      "     kFz        ",
      "    k ba        ",
      "wwwakkea        ",
      "wΙΕambF         ",
      "   akkbaf       "
    ]
  ]
}