{
  "xsize": 16,
  "zsize": 16,
  "palette": {
    "palette": [
      {
        "char": " ",
        "block": "minecraft:air"
      },
      {
        "char": "h",
        "block": "minecraft:air"
      },
      {
        "char": "f",
        "block": "minecraft:air"
      },
      {
        "char": "a",
        "block": "minecraft:smooth_stone_slab[type\u003ddouble,waterlogged\u003dfalse]"
      },
      {
        "char": "p",
        "block": "minecraft:air"
      },
      {
        "char": "d",
        "block": "minecraft:air"
      },
      {
        "char": "e",
        "block": "minecraft:stone[weathering\u003dfalse]"
      },
      {
        "char": "c",
        "block": "minecraft:mossy_cobblestone"
      },
      {
        "char": "i",
        "block": "minecraft:glass_pane[east\u003dtrue,north\u003dfalse,south\u003dfalse,waterlogged\u003dfalse,west\u003dtrue]"
      },
      {
        "char": "m",
        "block": "minecraft:mossy_stone_bricks"
      },
      {
        "char": "D",
        "block": "minecraft:air"
      },
      {
        "char": "j",
        "block": "minecraft:glass_pane[east\u003dfalse,north\u003dtrue,south\u003dtrue,waterlogged\u003dfalse,west\u003dfalse]"
      },
      {
        "char": "z",
        "block": "minecraft:air"
      },
      {
        "char": "b",
        "block": "minecraft:cobblestone[weathering\u003dfalse]"
      },
      {
        "char": "k",
        "block": "minecraft:stone_bricks[weathering\u003dfalse]"
      },
      {
        "char": "n",
        "block": "minecraft:cracked_stone_bricks"
      },
      {
        "char": "϶",
        "block": "minecraft:acacia_trapdoor[facing\u003dwest,half\u003dtop,open\u003dtrue,powered\u003dfalse,waterlogged\u003dfalse]"
      },
      {
        "char": "v",
        "block": "minecraft:bookshelf"
      },
      {
        "char": "N",
        "block": "minecraft:smooth_stone_slab[type\u003dbottom,waterlogged\u003dfalse]"
      },
      {
        "char": "8",
        "block": "minecraft:oak_wall_sign[facing\u003dsouth,waterlogged\u003dfalse]",
        "tag": {
          "z": 619,
          "x": 51,
          "is_waxed": "0b",
          "ForgeCaps": {
            "supplementaries:antique_ink": {
              "ink": "0b"
            }
          },
          "id": "minecraft:sign",
          "y": 185,
          "front_text": {
            "color": "black",
            "has_glowing_text": "0b",
            "messages": [
              "{\"extra\":[{\"text\":\"Floor 11:\"}],\"text\":\"\"}",
              "{\"extra\":[{\"text\":\"CEO Offices\"}],\"text\":\"\"}",
              "{\"text\":\"\"}",
              "{\"text\":\"\"}"
            ]
          },
          "back_text": {
            "color": "black",
            "has_glowing_text": "0b",
            "messages": [
              "{\"text\":\"\"}",
              "{\"text\":\"\"}",
              "{\"text\":\"\"}",
              "{\"text\":\"\"}"
            ]
          }
        }
      },
      {
        "char": "E",
        "block": "minecraft:cobblestone_slab[type\u003dbottom,waterlogged\u003dfalse,weathering\u003dfalse]"
      }
    ]
  },
  "slices": [
    [
      "                ",
      "                ",
      "                ",
      "                ",
      "                ",
      "                ",
      "                ",
      "                ",
      " h hh  h        ",
      "fapaafda        ",
      "eciccimD        ",
      "      jz        ",
      "      ba        ",
      "bbba kea        ",
      "bbbak j         ",
      "bbba ncaf       "
    ],
    [
      "                ",
      "                ",
      "                ",
      "                ",
      "                ",
      "                ",
      "                ",
      "                ",
      " h hh  h        ",
      "fapaafda ϶      ",
      "ccicbimD        ",
      "      jz        ",
      "      ba        ",
      "  ba  ca        ",
      "bbba  j         ",
      "bbb   caf       "
    ],
    [
      "                ",
      "                ",
      "                ",
      "                ",
      "                ",
      "                ",
      "                ",
      "                ",
      " h hh  h        ",
      "fapaafda        ",
      "ecbbcccD        ",
      "bbbbbbbz        ",
      "bb bbbea        ",
      "b  b  ea        ",
      "vvNb  c         ",
      "bbbb  caf       "
    ],
    [
      "                ",
      "                ",
      "                ",
      "                ",
      "                ",
      "                ",
      "                ",
      "                ",
      " h hh  h        ",
      "fapaafda        ",
      "ebiebinD        ",
      "v     jz        ",
      "v     ca        ",
      "v  a  ea        ",
      "NN a  j         ",
      "vN a  caf       "
    ],
    [
      "                ",
      "                ",
      "                ",
      "                ",
      "                ",
      "                ",
      "                ",
      "                ",
      " h hh  h        ",
      "fapaafda        ",
      "beieeikD        ",
      "v  8  jz        ",
      "v     ca        ",
      "v  a  ea        ",
      "   a  j         ",
      "vN a  caf       "
    ],
    [
      "                ",
      "                ",
      "                ",
      "                ",
      "                ",
      "                ",
      "                ",
      "                ",
      " h hh  h        ",
      "fapaafda        ",
      "bbibcimD        ",
      "b     jz        ",
      "E     ea        ",
      "N  a  ba        ",
      "   a  j         ",
      "N  a  caf       "
    ]
  ]
}