{
  "xsize": 16,
  "zsize": 16,
  "palette": {
    "palette": [
      {
        "char": " ",
        "block": "minecraft:air"
      },
      {
        "char": "b",
        "block": "minecraft:cobblestone[weathering\u003dfalse]"
      },
      {
        "char": "A",
        "block": "minecraft:air"
      },
      {
        "char": "e",
        "block": "minecraft:stone[weathering\u003dfalse]"
      },
      {
        "char": "a",
        "block": "minecraft:smooth_stone_slab[type\u003ddouble,waterlogged\u003dfalse]"
      },
      {
        "char": "f",
        "block": "minecraft:air"
      },
      {
        "char": "j",
        "block": "minecraft:glass_pane[east\u003dfalse,north\u003dtrue,south\u003dtrue,waterlogged\u003dfalse,west\u003dfalse]"
      },
      {
        "char": "I",
        "block": "minecraft:air"
      },
      {
        "char": "c",
        "block": "minecraft:mossy_cobblestone"
      },
      {
        "char": "g",
        "block": "minecraft:air"
      },
      {
        "char": "i",
        "block": "minecraft:glass_pane[east\u003dtrue,north\u003dfalse,south\u003dfalse,waterlogged\u003dfalse,west\u003dtrue]"
      },
      {
        "char": "m",
        "block": "minecraft:mossy_stone_bricks"
      },
      {
        "char": "p",
        "block": "minecraft:air"
      },
      {
        "char": "k",
        "block": "minecraft:stone_bricks[weathering\u003dfalse]"
      },
      {
        "char": "϶",
        "block": "minecraft:acacia_trapdoor[facing\u003dwest,half\u003dtop,open\u003dtrue,powered\u003dfalse,waterlogged\u003dfalse]"
      },
      {
        "char": "v",
        "block": "minecraft:bookshelf"
      },
      {
        "char": "F",
        "block": "minecraft:glass_pane[east\u003dfalse,north\u003dtrue,south\u003dtrue,waterlogged\u003dfalse,west\u003dtrue]"
      },
      {
        "char": "L",
        "block": "minecraft:glass_pane[east\u003dtrue,north\u003dtrue,south\u003dfalse,waterlogged\u003dfalse,west\u003dtrue]"
      },
      {
        "char": "E",
        "block": "minecraft:cobblestone_slab[type\u003dbottom,waterlogged\u003dfalse,weathering\u003dfalse]"
      },
      {
        "char": "n",
        "block": "minecraft:cracked_stone_bricks"
      }
    ]
  },
  "slices": [
    [
      "bbb   bA        ",
      "bbb   eaf       ",
      "bbbb  jI        ",
      "bbbb  caf       ",
      "bbb   baf       ",
      "      jg        ",
      "bbiebim         ",
      " apaaf af       ",
      " g gg  g        ",
      "                ",
      "                ",
      "                ",
      "                ",
      "                ",
      "                ",
      "                "
    ],
    [
      "bbb   eA        ",
      "bbb   baf       ",
      "bbbb  jI        ",
      "bbb   eaf       ",
      "      baf       ",
      "      jg        ",
      "eeibeik         ",
      " apaaf af϶      ",
      " g gg  g        ",
      "                ",
      "                ",
      "                ",
      "                ",
      "                ",
      "                ",
      "                "
    ],
    [
      "bbbb  cA        ",
      "bbbbbbcaf       ",
      "bbbb beI        ",
      "bbb   baf       ",
      "   bbbbaf       ",
      "bbbbbbcg        ",
      "cbcecbe         ",
      " apaaf af       ",
      " g gg  g        ",
      "                ",
      "                ",
      "                ",
      "                ",
      "                ",
      "                ",
      "                "
    ],
    [
      "vb a  cA        ",
      "v ba  baf       ",
      "vbb   jI        ",
      "v     eaf       ",
      "   b  eaf       ",
      "   bbbFg        ",
      "beiebLk         ",
      " apaaf af       ",
      " g gg  g        ",
      "                ",
      "                ",
      "                ",
      "                ",
      "                ",
      "                ",
      "                "
    ],
    [
      "v     cA        ",
      "E     eaf       ",
      "v     jI        ",
      "v     baf       ",
      "      eaf       ",
      "   b  jg        ",
      "beiebin         ",
      " apaaf af       ",
      " g gg  g        ",
      "                ",
      "                ",
      "                ",
      "                ",
      "                ",
      "                ",
      "                "
    ],
    [
      "E     bA        ",
      "      caf       ",
      "      jI        ",
      "E     eaf       ",
      "      baf       ",
      "      jg        ",
      "cbibbim         ",
      " apaaf af       ",
      " g gg  g        ",
      "                ",
      "                ",
      "                ",
      "                ",
      "                ",
      "                ",
      "                "
    ]
  ]
}