{
  "xsize": 16,
  "zsize": 16,
  "palette": {
    "palette": [
      {
        "char": " ",
        "block": "minecraft:air"
      },
      {
        "char": "e",
        "block": "minecraft:stone[weathering\u003dfalse]"
      },
      {
        "char": "b",
        "block": "minecraft:cobblestone[weathering\u003dfalse]"
      },
      {
        "char": "a",
        "block": "minecraft:smooth_stone_slab[type\u003ddouble,waterlogged\u003dfalse]"
      },
      {
        "char": "j",
        "block": "minecraft:glass_pane[east\u003dfalse,north\u003dtrue,south\u003dtrue,waterlogged\u003dfalse,west\u003dfalse]"
      },
      {
        "char": "f",
        "block": "minecraft:air"
      },
      {
        "char": "g",
        "block": "minecraft:air"
      },
      {
        "char": "c",
        "block": "minecraft:mossy_cobblestone"
      },
      {
        "char": "i",
        "block": "minecraft:glass_pane[east\u003dtrue,north\u003dfalse,south\u003dfalse,waterlogged\u003dfalse,west\u003dtrue]"
      },
      {
        "char": "m",
        "block": "minecraft:mossy_stone_bricks"
      },
      {
        "char": "p",
        "block": "minecraft:air"
      },
      {
        "char": "n",
        "block": "minecraft:cracked_stone_bricks"
      },
      {
        "char": "G",
        "block": "minecraft:redstone_lamp[lit\u003dfalse]"
      },
      {
        "char": "ϓ",
        "block": "minecraft:oak_stairs[facing\u003deast,half\u003dtop,shape\u003dstraight,waterlogged\u003dfalse]"
      },
      {
        "char": "k",
        "block": "minecraft:stone_bricks[weathering\u003dfalse]"
      },
      {
        "char": "κ",
        "block": "minecraft:oak_stairs[facing\u003deast,half\u003dbottom,shape\u003dstraight,waterlogged\u003dfalse]"
      },
      {
        "char": "R",
        "block": "minecraft:oak_stairs[facing\u003dsouth,half\u003dbottom,shape\u003dstraight,waterlogged\u003dfalse]"
      },
      {
        "char": "v",
        "block": "minecraft:bookshelf"
      },
      {
        "char": "F",
        "block": "minecraft:glass_pane[east\u003dfalse,north\u003dtrue,south\u003dtrue,waterlogged\u003dfalse,west\u003dtrue]"
      },
      {
        "char": "L",
        "block": "minecraft:glass_pane[east\u003dtrue,north\u003dtrue,south\u003dfalse,waterlogged\u003dfalse,west\u003dtrue]"
      },
      {
        "char": "Ϻ",
        "block": "minecraft:player_head[rotation\u003d15]",
        "tag": {
          "z": 624,
          "x": 50,
          "ForgeCaps": {},
          "id": "minecraft:skull",
          "y": 190
        }
      }
    ]
  },
  "slices": [
    [
      "      e         ",
      "      ba        ",
      "      j         ",
      "      eaf       ",
      "      baf       ",
      "      jg        ",
      "ceieeim         ",
      " apaa  af       ",
      " g gg  g        ",
      "                ",
      "                ",
      "                ",
      "                ",
      "                ",
      "                ",
      "                "
    ],
    [
      "      e         ",
      "      ea        ",
      "      j         ",
      "      caf       ",
      "      baf       ",
      "      jg        ",
      "beicbin         ",
      " apaa  af       ",
      " g gg  g        ",
      "                ",
      "                ",
      "                ",
      "                ",
      "                ",
      "                ",
      "                "
    ],
    [
      "   b  e         ",
      "   bbbba        ",
      "  bbbbb         ",
      "  bbbbbaf       ",
      "  bbbbcaf       ",
      " bGbbbbg        ",
      "eeecbcb         ",
      " apaa  af       ",
      " g gg  g        ",
      "                ",
      "                ",
      "                ",
      "                ",
      "                ",
      "                ",
      "                "
    ],
    [
      "  ϓakkc         ",
      "   a  ba        ",
      "      j         ",
      "     κbaf       ",
      "     κcaf       ",
      "   RRvFg        ",
      "cciecLn         ",
      " apaa  af       ",
      " g gg  g        ",
      "                ",
      "                ",
      "                ",
      "                ",
      "                ",
      "                ",
      "                "
    ],
    [
      "  Ϻa  b         ",
      "      ba        ",
      "      j         ",
      "      eaf       ",
      "      eaf       ",
      "     vFg        ",
      "eeiebLn         ",
      " apaa  af       ",
      "   gg  g        ",
      "                ",
      "                ",
      "                ",
      "                ",
      "                ",
      "                ",
      "                "
    ],
    [
      "      e         ",
      "      ea        ",
      "      j         ",
      "      eaf       ",
      "      caf       ",
      "      jg        ",
      "bbiecim         ",
      " a aa  af       ",
      "   gg  g        ",
      "                ",
      "                ",
      "                ",
      "                ",
      "                ",
      "                ",
      "                "
    ]
  ]
}