{
  "xsize": 16,
  "zsize": 16,
  "palette": {
    "palette": [
      {
        "char": " ",
        "block": "minecraft:air"
      },
      {
        "char": "c",
        "block": "minecraft:air"
      },
      {
        "char": "i",
        "block": "minecraft:mossy_stone_bricks"
      },
      {
        "char": "g",
        "block": "minecraft:glass_pane[east\u003dtrue,north\u003dfalse,south\u003dfalse,waterlogged\u003dfalse,west\u003dtrue]"
      },
      {
        "char": "h",
        "block": "minecraft:cracked_stone_bricks"
      },
      {
        "char": "e",
        "block": "minecraft:stone_bricks[weathering\u003dfalse]"
      },
      {
        "char": "f",
        "block": "minecraft:glass_pane[east\u003dfalse,north\u003dtrue,south\u003dtrue,waterlogged\u003dfalse,west\u003dfalse]"
      },
      {
        "char": "d",
        "block": "minecraft:mossy_cobblestone"
      },
      {
        "char": "a",
        "block": "minecraft:cobblestone[weathering\u003dfalse]"
      },
      {
        "char": "b",
        "block": "minecraft:stone[weathering\u003dfalse]"
      },
      {
        "char": "J",
        "block": "minecraft:glass_pane[east\u003dtrue,north\u003dfalse,south\u003dtrue,waterlogged\u003dfalse,west\u003dtrue]"
      },
      {
        "char": "I",
        "block": "minecraft:glass_pane[east\u003dtrue,north\u003dtrue,south\u003dtrue,waterlogged\u003dfalse,west\u003dfalse]"
      },
      {
        "char": "ϴ",
        "block": "minecraft:spruce_log[axis\u003dy]"
      },
      {
        "char": "К",
        "block": "minecraft:dark_oak_trapdoor[facing\u003deast,half\u003dtop,open\u003dtrue,powered\u003dfalse,waterlogged\u003dfalse]"
      },
      {
        "char": "k",
        "block": "minecraft:red_carpet"
      },
      {
        "char": "Ѕ",
        "block": "minecraft:dark_oak_trapdoor[facing\u003dsouth,half\u003dtop,open\u003dtrue,powered\u003dfalse,waterlogged\u003dfalse]"
      },
      {
        "char": "y",
        "block": "minecraft:redstone_wire[east\u003dside,north\u003dside,power\u003d0,south\u003dside,west\u003dside]"
      },
      {
        "char": "ө",
        "block": "minecraft:skeleton_skull[rotation\u003d15]",
        "tag": {
          "z": 622,
          "x": 78,
          "ForgeCaps": {},
          "id": "minecraft:skull",
          "y": 188
        }
      },
      {
        "char": "L",
        "block": "minecraft:black_carpet"
      },
      {
        "char": "϶",
        "block": "minecraft:dark_oak_leaves[distance\u003d1,persistent\u003dtrue,waterlogged\u003dfalse]"
      },
      {
        "char": "ϸ",
        "block": "minecraft:dark_oak_leaves[distance\u003d2,persistent\u003dtrue,waterlogged\u003dfalse]"
      },
      {
        "char": "Г",
        "block": "minecraft:dark_oak_leaves[distance\u003d3,persistent\u003dtrue,waterlogged\u003dfalse]"
      }
    ]
  },
  "slices": [
    [
      "                ",
      "                ",
      "                ",
      "                ",
      "                ",
      "                ",
      "                ",
      "        ccc c cc",
      "       ighghgi e",
      "       f        ",
      "       i        ",
      "       f        ",
      "       e        ",
      "                ",
      "                ",
      "                "
    ],
    [
      "                ",
      "                ",
      "                ",
      "                ",
      "                ",
      "                ",
      "                ",
      "        ccc c cc",
      "       ddaaaaadd",
      "       daababbbb",
      "       daababbba",
      "       abaabbbba",
      "       aababbaaa",
      "       daaaabbaa",
      "        aabbbabb",
      "        bbbbaaab"
    ],
    [
      "                ",
      "                ",
      "                ",
      "                ",
      "                ",
      "                ",
      "                ",
      "        ccc c cc",
      "       iJigigegh",
      "       IϴК k k  ",
      "       hЅ k k  k",
      "       f kk  kk ",
      "       ek  k    ",
      "         k    y ",
      "         k k yөy",
      "          kk  L "
    ],
    [
      "                ",
      "                ",
      "                ",
      "                ",
      "                ",
      "                ",
      "                ",
      "        ccc c cc",
      "       igegegige",
      "       f϶       ",
      "       h        ",
      "       f        ",
      "       h        ",
      "                ",
      "                ",
      "                "
    ],
    [
      "                ",
      "                ",
      "                ",
      "                ",
      "                ",
      "                ",
      "                ",
      "        ccc c cc",
      "       aaaddaaad",
      "       dϸ       ",
      "       a        ",
      "       a        ",
      "       a        ",
      "       d        ",
      "       a        ",
      "       d        "
    ],
    [
      "                ",
      "                ",
      "                ",
      "                ",
      "                ",
      "                ",
      "                ",
      "        ccc c cc",
      "       hghghgigi",
      "       fГ       ",
      "       h        ",
      "       f        ",
      "       e        ",
      "       f        ",
      "       i        ",
      "       f        "
    ]
  ]
}