{
  "xsize": 16,
  "zsize": 16,
  "palette": {
    "palette": [
      {
        "char": " ",
        "block": "minecraft:air"
      },
      {
        "char": "h",
        "block": "minecraft:cracked_stone_bricks"
      },
      {
        "char": "f",
        "block": "minecraft:glass_pane[east\u003dfalse,north\u003dtrue,south\u003dtrue,waterlogged\u003dfalse,west\u003dfalse]"
      },
      {
        "char": "i",
        "block": "minecraft:mossy_stone_bricks"
      },
      {
        "char": "g",
        "block": "minecraft:glass_pane[east\u003dtrue,north\u003dfalse,south\u003dfalse,waterlogged\u003dfalse,west\u003dtrue]"
      },
      {
        "char": "e",
        "block": "minecraft:stone_bricks[weathering\u003dfalse]"
      },
      {
        "char": "m",
        "block": "minecraft:air"
      },
      {
        "char": "b",
        "block": "minecraft:stone[weathering\u003dfalse]"
      },
      {
        "char": "a",
        "block": "minecraft:cobblestone[weathering\u003dfalse]"
      },
      {
        "char": "d",
        "block": "minecraft:mossy_cobblestone"
      },
      {
        "char": "l",
        "block": "minecraft:bookshelf"
      },
      {
        "char": "y",
        "block": "minecraft:redstone_wire[east\u003dside,north\u003dside,power\u003d0,south\u003dside,west\u003dside]"
      },
      {
        "char": "Ί",
        "block": "minecraft:glass_pane[east\u003dfalse,north\u003dtrue,south\u003dtrue,waterlogged\u003dfalse,west\u003dtrue]"
      },
      {
        "char": "Ӄ",
        "block": "minecraft:skeleton_skull[rotation\u003d0]",
        "tag": {
          "z": 626,
          "x": 83,
          "ForgeCaps": {},
          "id": "minecraft:skull",
          "y": 164
        }
      },
      {
        "char": "P",
        "block": "minecraft:glass_pane[east\u003dtrue,north\u003dtrue,south\u003dfalse,waterlogged\u003dfalse,west\u003dtrue]"
      }
    ]
  },
  "slices": [
    [
      "       h        ",
      "       f        ",
      "       i        ",
      "       f        ",
      "       i        ",
      "       f        ",
      "       i        ",
      "       f        ",
      "gigegigh        ",
      "   mmm          ",
      "                ",
      "                ",
      "                ",
      "                ",
      "                ",
      "                "
    ],
    [
      "bbbabbad        ",
      "bbabbbbd        ",
      "abababbd        ",
      "bbabaaba        ",
      "bbbababd        ",
      "abbaaaad        ",
      "aabbaaad        ",
      "bbbabbbd        ",
      "aaadddad        ",
      "   mmm          ",
      "                ",
      "                ",
      "                ",
      "                ",
      "                ",
      "                "
    ],
    [
      "       e        ",
      "ll ylllΊ        ",
      "  yӃ   h        ",
      "     y f        ",
      " ly l  h        ",
      " l  l  f        ",
      " l  l  h        ",
      " l  l  f        ",
      "geghPege        ",
      "   mmm          ",
      "                ",
      "                ",
      "                ",
      "                ",
      "                ",
      "                "
    ],
    [
      "       i        ",
      "ll  lllΊ        ",
      "       e        ",
      "       f        ",
      " l  l  i        ",
      " l  l  f        ",
      " l  l  i        ",
      " l  l  f        ",
      "ghghPhgh        ",
      "   mmm          ",
      "                ",
      "                ",
      "                ",
      "                ",
      "                ",
      "                "
    ],
    [
      "       a        ",
      "ll  llld        ",
      "       a        ",
      "       d        ",
      " l  l  d        ",
      " l  l  a        ",
      " l  l  a        ",
      " l  l  d        ",
      "aaaaaadd        ",
      "   mmm          ",
      "                ",
      "                ",
      "                ",
      "                ",
      "                ",
      "                "
    ],
    [
      "       e        ",
      "       f        ",
      "       i        ",
      "       f        ",
      "       i        ",
      "       f        ",
      "       h        ",
      "       f        ",
      "geghgigi        ",
      "   mmm          ",
      "                ",
      "                ",
      "                ",
      "                ",
      "                ",
      "                "
    ]
  ]
}