{
  "xsize": 16,
  "zsize": 16,
  "palette": {
    "palette": [
      {
        "char": " ",
        "block": "minecraft:air"
      },
      {
        "char": "h",
        "block": "minecraft:air"
      },
      {
        "char": "a",
        "block": "minecraft:smooth_stone_slab[type\u003ddouble,waterlogged\u003dfalse]"
      },
      {
        "char": "c",
        "block": "minecraft:mossy_cobblestone"
      },
      {
        "char": "e",
        "block": "minecraft:stone[weathering\u003dfalse]"
      },
      {
        "char": "b",
        "block": "minecraft:cobblestone[weathering\u003dfalse]"
      },
      {
        "char": "B",
        "block": "minecraft:air"
      },
      {
        "char": "d",
        "block": "minecraft:air"
      },
      {
        "char": "y",
        "block": "minecraft:air"
      },
      {
        "char": "n",
        "block": "minecraft:cracked_stone_bricks"
      },
      {
        "char": "H",
        "block": "minecraft:glass_pane[east\u003dtrue,north\u003dfalse,south\u003dtrue,waterlogged\u003dfalse,west\u003dtrue]"
      },
      {
        "char": "·",
        "block": "minecraft:glass_pane[east\u003dtrue,north\u003dtrue,south\u003dtrue,waterlogged\u003dfalse,west\u003dfalse]"
      },
      {
        "char": "v",
        "block": "minecraft:bookshelf"
      },
      {
        "char": "΄",
        "block": "minecraft:oak_wall_sign[facing\u003deast,waterlogged\u003dfalse]",
        "tag": {
          "z": 621,
          "x": 46,
          "is_waxed": "0b",
          "ForgeCaps": {
            "supplementaries:antique_ink": {
              "ink": "0b"
            }
          },
          "id": "minecraft:sign",
          "y": 150,
          "front_text": {
            "color": "black",
            "has_glowing_text": "0b",
            "messages": [
              "{\"extra\":[{\"text\":\"Rad S.\"}],\"text\":\"\"}",
              "{\"extra\":[{\"text\":\"Radio Speaker\"}],\"text\":\"\"}",
              "{\"text\":\"\"}",
              "{\"text\":\"\"}"
            ]
          },
          "back_text": {
            "color": "black",
            "has_glowing_text": "0b",
            "messages": [
              "{\"text\":\"\"}",
              "{\"text\":\"\"}",
              "{\"text\":\"\"}",
              "{\"text\":\"\"}"
            ]
          }
        }
      },
      {
        "char": "m",
        "block": "minecraft:mossy_stone_bricks"
      },
      {
        "char": "i",
        "block": "minecraft:glass_pane[east\u003dtrue,north\u003dfalse,south\u003dfalse,waterlogged\u003dfalse,west\u003dtrue]"
      },
      {
        "char": "j",
        "block": "minecraft:glass_pane[east\u003dfalse,north\u003dtrue,south\u003dtrue,waterlogged\u003dfalse,west\u003dfalse]"
      }
    ]
  },
  "slices": [
    [
      "                ",
      "                ",
      "                ",
      "                ",
      "                ",
      "                ",
      "                ",
      "                ",
      "            hh  ",
      "         a  aa a",
      "          ceebbe",
      "         Bbbbbbb",
      "        dacbbbb ",
      "        dabbbb  ",
      "        dyebb   ",
      "        dab     "
    ],
    [
      "                ",
      "                ",
      "                ",
      "                ",
      "                ",
      "                ",
      "                ",
      "                ",
      "            hh  ",
      "         a  aa a",
      "          nHceHc",
      "         B·vvvv ",
      "        dac     ",
      "        dab     ",
      "        dy v    ",
      "        dac     "
    ],
    [
      "                ",
      "                ",
      "                ",
      "                ",
      "                ",
      "                ",
      "                ",
      "                ",
      "            hh  ",
      "         a  aa a",
      "          nHbeHb",
      "         B·vvvv΄",
      "        dac     ",
      "        dab     ",
      "        dy      ",
      "        dac     "
    ],
    [
      "                ",
      "                ",
      "                ",
      "                ",
      "                ",
      "                ",
      "                ",
      "                ",
      "            hh  ",
      "         a  aa a",
      "          mibbie",
      "         Bj     ",
      "        dae     ",
      "        dab     ",
      "        dy      ",
      "        dae     "
    ],
    [
      "                ",
      "                ",
      "                ",
      "                ",
      "                ",
      "                ",
      "                ",
      "                ",
      "            hh  ",
      "         a  aa a",
      "          miebie",
      "         Bj     ",
      "        dab     ",
      "        dab     ",
      "        dyj     ",
      "        dae     "
    ],
    [
      "                ",
      "                ",
      "                ",
      "                ",
      "                ",
      "                ",
      "                ",
      "                ",
      "            hh  ",
      "         a  aa a",
      "          cbcbce",
      "         Bebbbbb",
      "        daebbbbb",
      "        dacbbbbb",
      "        dyebbbbb",
      "        dabbbbb "
    ]
  ]
}