{
  "xsize": 16,
  "zsize": 16,
  "palette": {
    "palette": [
      {
        "char": " ",
        "block": "minecraft:air"
      },
      {
        "char": "c",
        "block": "minecraft:air"
      },
      {
        "char": "g",
        "block": "minecraft:glass_pane[east\u003dtrue,north\u003dfalse,south\u003dfalse,waterlogged\u003dfalse,west\u003dtrue]"
      },
      {
        "char": "i",
        "block": "minecraft:mossy_stone_bricks"
      },
      {
        "char": "h",
        "block": "minecraft:cracked_stone_bricks"
      },
      {
        "char": "Ҍ",
        "block": "minecraft:air"
      },
      {
        "char": "Д",
        "block": "minecraft:stone_slab[type\u003dbottom,waterlogged\u003dfalse,weathering\u003dfalse]"
      },
      {
        "char": "Б",
        "block": "minecraft:glass_pane[east\u003dfalse,north\u003dfalse,south\u003dtrue,waterlogged\u003dfalse,west\u003dfalse]"
      },
      {
        "char": "f",
        "block": "minecraft:glass_pane[east\u003dfalse,north\u003dtrue,south\u003dtrue,waterlogged\u003dfalse,west\u003dfalse]"
      },
      {
        "char": "e",
        "block": "minecraft:stone_bricks[weathering\u003dfalse]"
      },
      {
        "char": "a",
        "block": "minecraft:cobblestone[weathering\u003dfalse]"
      },
      {
        "char": "d",
        "block": "minecraft:mossy_cobblestone"
      },
      {
        "char": "b",
        "block": "minecraft:stone[weathering\u003dfalse]"
      },
      {
        "char": "o",
        "block": "minecraft:air"
      },
      {
        "char": "j",
        "block": "minecraft:light_gray_carpet"
      },
      {
        "char": "n",
        "block": "minecraft:quartz_slab[type\u003ddouble,waterlogged\u003dfalse]"
      },
      {
        "char": "x",
        "block": "minecraft:cobblestone_stairs[facing\u003dnorth,half\u003dbottom,shape\u003dstraight,waterlogged\u003dfalse,weathering\u003dfalse]"
      },
      {
        "char": "Έ",
        "block": "minecraft:oak_wall_sign[facing\u003deast,waterlogged\u003dfalse]",
        "tag": {
          "z": 618,
          "x": 74,
          "is_waxed": "0b",
          "ForgeCaps": {
            "supplementaries:antique_ink": {
              "ink": "0b"
            }
          },
          "id": "minecraft:sign",
          "y": 219,
          "front_text": {
            "color": "black",
            "has_glowing_text": "0b",
            "messages": [
              "{\"extra\":[{\"text\":\"T. Cabel\"}],\"text\":\"\"}",
              "{\"text\":\"\"}",
              "{\"text\":\"\"}",
              "{\"text\":\"\"}"
            ]
          },
          "back_text": {
            "color": "black",
            "has_glowing_text": "0b",
            "messages": [
              "{\"text\":\"\"}",
              "{\"text\":\"\"}",
              "{\"text\":\"\"}",
              "{\"text\":\"\"}"
            ]
          }
        }
      },
      {
        "char": "б",
        "block": "minecraft:sea_pickle[pickles\u003d2,waterlogged\u003dfalse]"
      },
      {
        "char": "l",
        "block": "minecraft:bookshelf"
      },
      {
        "char": "е",
        "block": "minecraft:stone_slab[type\u003dtop,waterlogged\u003dfalse,weathering\u003dfalse]"
      }
    ]
  },
  "slices": [
    [
      "                ",
      "                ",
      "                ",
      "                ",
      "                ",
      "                ",
      "                ",
      "cccccccc        ",
      "gi hҌД          ",
      "       Б        ",
      "       i        ",
      "       f        ",
      "       e        ",
      "       f        ",
      "       h        ",
      "       f        "
    ],
    [
      "                ",
      "                ",
      "                ",
      "                ",
      "                ",
      "                ",
      "                ",
      "cccccccc        ",
      "ad  Ҍ           ",
      "bbabaaba        ",
      "aaabaabd        ",
      "baababaa        ",
      "baabbbad        ",
      "aaaaabaa        ",
      "bbaaaaba        ",
      "baababbd        "
    ],
    [
      "                ",
      "                ",
      "                ",
      "                ",
      "                ",
      "                ",
      "                ",
      "cccccccc        ",
      "gi  o           ",
      "jj              ",
      "nj jaaah        ",
      "n jjaa f        ",
      " j  a  h        ",
      "nj ja  f        ",
      "njj a  i        ",
      "   jxxxf        "
    ],
    [
      "                ",
      "                ",
      "                ",
      "                ",
      "                ",
      "                ",
      "                ",
      "cccccccc        ",
      "ge  o           ",
      "                ",
      "nΈ  aaa         ",
      "n   бl          ",
      "     l e        ",
      "nΈ  a  f        ",
      "n   xxxe        ",
      "       f        "
    ],
    [
      "                ",
      "                ",
      "                ",
      "                ",
      "                ",
      "                ",
      "                ",
      "cccccccc        ",
      "aa еo           ",
      "                ",
      "    aaa         ",
      "     l a        ",
      "     l a        ",
      "    xxxa        ",
      "       d        ",
      "       a        "
    ],
    [
      "                ",
      "                ",
      "                ",
      "                ",
      "                ",
      "                ",
      "                ",
      "cccccccc        ",
      " e hoh          ",
      "                ",
      "    aaa         ",
      "    a           ",
      "    xxxi        ",
      "       f        ",
      "       e        ",
      "       f        "
    ]
  ]
}