{
  "xsize": 16,
  "zsize": 16,
  "palette": {
    "palette": [
      {
        "char": " ",
        "block": "minecraft:air"
      },
      {
        "char": "c",
        "block": "minecraft:air"
      },
      {
        "char": "g",
        "block": "minecraft:glass_pane[east\u003dtrue,north\u003dfalse,south\u003dfalse,waterlogged\u003dfalse,west\u003dtrue]"
      },
      {
        "char": "h",
        "block": "minecraft:cracked_stone_bricks"
      },
      {
        "char": "i",
        "block": "minecraft:mossy_stone_bricks"
      },
      {
        "char": "o",
        "block": "minecraft:air"
      },
      {
        "char": "f",
        "block": "minecraft:glass_pane[east\u003dfalse,north\u003dtrue,south\u003dtrue,waterlogged\u003dfalse,west\u003dfalse]"
      },
      {
        "char": "a",
        "block": "minecraft:cobblestone[weathering\u003dfalse]"
      },
      {
        "char": "x",
        "block": "minecraft:cobblestone_stairs[facing\u003dnorth,half\u003dbottom,shape\u003dstraight,waterlogged\u003dfalse,weathering\u003dfalse]"
      },
      {
        "char": "F",
        "block": "minecraft:air"
      },
      {
        "char": "d",
        "block": "minecraft:mossy_cobblestone"
      },
      {
        "char": "b",
        "block": "minecraft:stone[weathering\u003dfalse]"
      },
      {
        "char": "e",
        "block": "minecraft:stone_bricks[weathering\u003dfalse]"
      },
      {
        "char": "k",
        "block": "minecraft:red_carpet"
      },
      {
        "char": "П",
        "block": "immersive_weathering:weathered_iron_bars[east\u003dfalse,north\u003dfalse,south\u003dtrue,waterlogged\u003dfalse,west\u003dfalse]"
      },
      {
        "char": "Ͽ",
        "block": "immersive_weathering:exposed_iron_bars[east\u003dfalse,north\u003dtrue,south\u003dtrue,waterlogged\u003dfalse,west\u003dfalse]"
      },
      {
        "char": "Є",
        "block": "immersive_weathering:exposed_iron_bars[east\u003dfalse,north\u003dtrue,south\u003dfalse,waterlogged\u003dfalse,west\u003dfalse]"
      },
      {
        "char": "l",
        "block": "minecraft:bookshelf"
      },
      {
        "char": "Ѳ",
        "block": "minecraft:air"
      },
      {
        "char": "ϟ",
        "block": "minecraft:oak_wall_sign[facing\u003dsouth,waterlogged\u003dfalse]",
        "tag": {
          "z": 617,
          "x": 85,
          "is_waxed": "0b",
          "ForgeCaps": {
            "supplementaries:antique_ink": {
              "ink": "0b"
            }
          },
          "id": "minecraft:sign",
          "y": 153,
          "front_text": {
            "color": "black",
            "has_glowing_text": "0b",
            "messages": [
              "{\"extra\":[{\"text\":\"Floor 3\"}],\"text\":\"\"}",
              "{\"extra\":[{\"text\":\"Complaints\"}],\"text\":\"\"}",
              "{\"text\":\"\"}",
              "{\"text\":\"\"}"
            ]
          },
          "back_text": {
            "color": "black",
            "has_glowing_text": "0b",
            "messages": [
              "{\"text\":\"\"}",
              "{\"text\":\"\"}",
              "{\"text\":\"\"}",
              "{\"text\":\"\"}"
            ]
          }
        }
      },
      {
        "char": "υ",
        "block": "minecraft:air"
      }
    ]
  },
  "slices": [
    [
      "                ",
      "                ",
      "                ",
      "                ",
      "                ",
      "                ",
      "                ",
      "cccccccc        ",
      "ghghghgio       ",
      "       f        ",
      "    aaai        ",
      "    xxxf        ",
      "       i        ",
      "       f        ",
      "       hF       ",
      "       f        "
    ],
    [
      "                ",
      "                ",
      "                ",
      "                ",
      "                ",
      "                ",
      "                ",
      "cccccccc        ",
      "ddadddaao       ",
      "baabbbad        ",
      "abaaxxxa        ",
      "bbbb   a        ",
      "babb   dF       ",
      "bbaa   aF       ",
      "babbaaad        ",
      "bbbaabba        "
    ],
    [
      "                ",
      "                ",
      "                ",
      "                ",
      "                ",
      "                ",
      "                ",
      "cccccccc        ",
      "gigigegio       ",
      "k  k k f        ",
      "k kП   h        ",
      " kkϿ   fF       ",
      "k  Ͽ   e        ",
      " k Ͽ   f        ",
      "k kЄllli        ",
      "k k    f        "
    ],
    [
      "                ",
      "                ",
      "                ",
      "                ",
      "                ",
      "                ",
      "                ",
      "cccccccc        ",
      "gigigighѲ       ",
      "     ϟ f        ",
      "       eF       ",
      "       f        ",
      "       e        ",
      "       f        ",
      "    lllh        ",
      "       f        "
    ],
    [
      "                ",
      "                ",
      "                ",
      "                ",
      "                ",
      "                ",
      "                ",
      "cccccccυ        ",
      "ddadadaaF       ",
      "       aF       ",
      "       d        ",
      "       d        ",
      "       d        ",
      "       d        ",
      "    llla        ",
      "       a        "
    ],
    [
      "                ",
      "                ",
      "                ",
      "                ",
      "                ",
      "                ",
      "                ",
      "cccc c F        ",
      "gegegegeo       ",
      "       f        ",
      "       e        ",
      "       f        ",
      "       e        ",
      "       f        ",
      "       h        ",
      "       f        "
    ]
  ]
}