{
  "xsize": 16,
  "zsize": 16,
  "palette": {
    "palette": [
      {
        "char": " ",
        "block": "minecraft:air"
      },
      {
        "char": "i",
        "block": "minecraft:mossy_stone_bricks"
      },
      {
        "char": "f",
        "block": "minecraft:glass_pane[east\u003dfalse,north\u003dtrue,south\u003dtrue,waterlogged\u003dfalse,west\u003dfalse]"
      },
      {
        "char": "h",
        "block": "minecraft:cracked_stone_bricks"
      },
      {
        "char": "e",
        "block": "minecraft:stone_bricks[weathering\u003dfalse]"
      },
      {
        "char": "g",
        "block": "minecraft:glass_pane[east\u003dtrue,north\u003dfalse,south\u003dfalse,waterlogged\u003dfalse,west\u003dtrue]"
      },
      {
        "char": "m",
        "block": "minecraft:air"
      },
      {
        "char": "b",
        "block": "minecraft:stone[weathering\u003dfalse]"
      },
      {
        "char": "a",
        "block": "minecraft:cobblestone[weathering\u003dfalse]"
      },
      {
        "char": "d",
        "block": "minecraft:mossy_cobblestone"
      },
      {
        "char": "l",
        "block": "minecraft:bookshelf"
      },
      {
        "char": "k",
        "block": "minecraft:red_carpet"
      },
      {
        "char": "y",
        "block": "minecraft:redstone_wire[east\u003dside,north\u003dside,power\u003d0,south\u003dside,west\u003dside]"
      },
      {
        "char": "ц",
        "block": "minecraft:skeleton_skull[rotation\u003d3]",
        "tag": {
          "z": 631,
          "x": 81,
          "ForgeCaps": {},
          "id": "minecraft:skull",
          "y": 133
        }
      },
      {
        "char": "ϯ",
        "block": "minecraft:cobblestone_slab[type\u003ddouble,waterlogged\u003dfalse,weathering\u003dfalse]"
      },
      {
        "char": "Ϲ",
        "block": "minecraft:dark_oak_fence[east\u003dfalse,north\u003dtrue,south\u003dtrue,waterlogged\u003dfalse,west\u003dfalse]"
      },
      {
        "char": "Ф",
        "block": "minecraft:dark_oak_fence[east\u003dtrue,north\u003dtrue,south\u003dfalse,waterlogged\u003dfalse,west\u003dfalse]"
      },
      {
        "char": "Ѥ",
        "block": "minecraft:dark_oak_fence[east\u003dtrue,north\u003dfalse,south\u003dfalse,waterlogged\u003dfalse,west\u003dtrue]"
      },
      {
        "char": "的",
        "block": "minecraft:dark_oak_fence[east\u003dfalse,north\u003dfalse,south\u003dfalse,waterlogged\u003dfalse,west\u003dtrue]"
      }
    ]
  },
  "slices": [
    [
      "       i        ",
      "       f        ",
      "       h        ",
      "       f        ",
      "       e        ",
      "       f        ",
      "       e        ",
      "       f        ",
      "geghgegh        ",
      "   mmm          ",
      "                ",
      "                ",
      "                ",
      "                ",
      "                ",
      "                "
    ],
    [
      "bbbbaaaa        ",
      "babbbaad        ",
      "aaaaaaba        ",
      "bbbbabaa        ",
      "abbbabaa        ",
      "babbbbbd        ",
      "abbaaaad        ",
      "aaaabbaa        ",
      "aaadadad        ",
      "   mmm          ",
      "                ",
      "                ",
      "                ",
      "                ",
      "                ",
      "                "
    ],
    [
      "l   k  i        ",
      "l   k kf        ",
      "l    k i        ",
      "lllk  kf        ",
      "  k  k h        ",
      "yk kk  f        ",
      "k yk kki        ",
      "цyk  k f        ",
      "ghghghgh        ",
      "   mmm          ",
      "                ",
      "                ",
      "                ",
      "                ",
      "                ",
      "                "
    ],
    [
      "l      ϯ        ",
      "l      f        ",
      "l      e        ",
      "lll    f        ",
      "       e        ",
      "       f        ",
      "       i        ",
      "       f        ",
      "gigegigh        ",
      "   mmm          ",
      "                ",
      "                ",
      "                ",
      "                ",
      "                ",
      "                "
    ],
    [
      "l      a        ",
      "l      d        ",
      "l      a        ",
      "lll    a        ",
      "       d        ",
      "       d        ",
      "       a        ",
      "       d        ",
      "dddddaad        ",
      "   mmm          ",
      "                ",
      "                ",
      "                ",
      "                ",
      "                ",
      "                "
    ],
    [
      "Ϲ      h        ",
      "Ϲ      f        ",
      "Ϲ      h        ",
      "ФѤ的    f        ",
      "       e        ",
      "       f        ",
      "       e        ",
      "       f        ",
      "ghghgige        ",
      "   mmm          ",
      "                ",
      "                ",
      "                ",
      "                ",
      "                ",
      "                "
    ]
  ]
}