{
  "xsize": 16,
  "zsize": 16,
  "palette": {
    "palette": [
      {
        "char": " ",
        "block": "minecraft:air"
      },
      {
        "char": "Ѝ",
        "block": "minecraft:redstone_torch[lit\u003dtrue]"
      },
      {
        "char": "h",
        "block": "minecraft:cracked_stone_bricks"
      },
      {
        "char": "ї",
        "block": "minecraft:spruce_fence[east\u003dfalse,north\u003dfalse,south\u003dfalse,waterlogged\u003dfalse,west\u003dfalse]"
      },
      {
        "char": "f",
        "block": "minecraft:glass_pane[east\u003dfalse,north\u003dtrue,south\u003dtrue,waterlogged\u003dfalse,west\u003dfalse]"
      },
      {
        "char": "i",
        "block": "minecraft:mossy_stone_bricks"
      },
      {
        "char": "g",
        "block": "minecraft:glass_pane[east\u003dtrue,north\u003dfalse,south\u003dfalse,waterlogged\u003dfalse,west\u003dtrue]"
      },
      {
        "char": "m",
        "block": "minecraft:air"
      },
      {
        "char": "a",
        "block": "minecraft:cobblestone[weathering\u003dfalse]"
      },
      {
        "char": "b",
        "block": "minecraft:stone[weathering\u003dfalse]"
      },
      {
        "char": "d",
        "block": "minecraft:mossy_cobblestone"
      },
      {
        "char": "L",
        "block": "minecraft:black_carpet"
      },
      {
        "char": "j",
        "block": "minecraft:light_gray_carpet"
      },
      {
        "char": "k",
        "block": "minecraft:red_carpet"
      },
      {
        "char": "e",
        "block": "minecraft:stone_bricks[weathering\u003dfalse]"
      },
      {
        "char": "Н",
        "block": "minecraft:cauldron"
      },
      {
        "char": "y",
        "block": "minecraft:redstone_wire[east\u003dside,north\u003dside,power\u003d0,south\u003dside,west\u003dside]"
      },
      {
        "char": "Ѓ",
        "block": "minecraft:dark_oak_trapdoor[facing\u003dnorth,half\u003dtop,open\u003dtrue,powered\u003dfalse,waterlogged\u003dfalse]"
      },
      {
        "char": "Ϸ",
        "block": "minecraft:dark_oak_trapdoor[facing\u003dwest,half\u003dtop,open\u003dtrue,powered\u003dfalse,waterlogged\u003dfalse]"
      },
      {
        "char": "ϴ",
        "block": "minecraft:spruce_log[axis\u003dy]"
      },
      {
        "char": "К",
        "block": "minecraft:dark_oak_trapdoor[facing\u003deast,half\u003dtop,open\u003dtrue,powered\u003dfalse,waterlogged\u003dfalse]"
      },
      {
        "char": "ѳ",
        "block": "minecraft:skeleton_skull[rotation\u003d13]",
        "tag": {
          "z": 629,
          "x": 84,
          "ForgeCaps": {},
          "id": "minecraft:skull",
          "y": 219
        }
      },
      {
        "char": "Ί",
        "block": "minecraft:glass_pane[east\u003dfalse,north\u003dtrue,south\u003dtrue,waterlogged\u003dfalse,west\u003dtrue]"
      },
      {
        "char": "P",
        "block": "minecraft:glass_pane[east\u003dtrue,north\u003dtrue,south\u003dfalse,waterlogged\u003dfalse,west\u003dtrue]"
      },
      {
        "char": "϶",
        "block": "minecraft:dark_oak_leaves[distance\u003d1,persistent\u003dtrue,waterlogged\u003dfalse]"
      },
      {
        "char": "ϸ",
        "block": "minecraft:dark_oak_leaves[distance\u003d2,persistent\u003dtrue,waterlogged\u003dfalse]"
      },
      {
        "char": "Г",
        "block": "minecraft:dark_oak_leaves[distance\u003d3,persistent\u003dtrue,waterlogged\u003dfalse]"
      }
    ]
  },
  "slices": [
    [
      "Ѝ      h        ",
      "їЍ     f        ",
      "Ѝ      i        ",
      "       f        ",
      "       h        ",
      "       f        ",
      "       h        ",
      "       f        ",
      "ghghghgi        ",
      "   mmm          ",
      "                ",
      "                ",
      "                ",
      "                ",
      "                ",
      "                "
    ],
    [
      "abbbbabd        ",
      "aaabbaba        ",
      "babaabaa        ",
      "abaababa        ",
      "bbababaa        ",
      "abbabaaa        ",
      "aaaaaaba        ",
      "aabbbbbd        ",
      "ddddddda        ",
      "   mmm          ",
      "                ",
      "                ",
      "                ",
      "                ",
      "                ",
      "                "
    ],
    [
      " L j k e        ",
      "j   k kf        ",
      " jjj  ki        ",
      "   kkjНf        ",
      "k k   Нh        ",
      " kkykkНf        ",
      "kЃy  yЃi        ",
      "ϷϴКyѳϷϴΊ        ",
      "geghghPi        ",
      "   mmm          ",
      "                ",
      "                ",
      "                ",
      "                ",
      "                ",
      "                "
    ],
    [
      "       h        ",
      "       f        ",
      "       h        ",
      "       f        ",
      "       i        ",
      "       f        ",
      "       h        ",
      " ϶    ϶f        ",
      "gighghgi        ",
      "   mmm          ",
      "                ",
      "                ",
      "                ",
      "                ",
      "                ",
      "                "
    ],
    [
      "       d        ",
      "       d        ",
      "       a        ",
      "       a        ",
      "       a        ",
      "       d        ",
      "       d        ",
      " ϸ    ϸd        ",
      "adadadad        ",
      "   mmm          ",
      "                ",
      "                ",
      "                ",
      "                ",
      "                ",
      "                "
    ],
    [
      "       i        ",
      "       f        ",
      "       h        ",
      "       f        ",
      "       i        ",
      "       f        ",
      "       i        ",
      " Г    Гf        ",
      "gegighgi        ",
      "   mmm          ",
      "                ",
      "                ",
      "                ",
      "                ",
      "                ",
      "                "
    ]
  ]
}