{
  "xsize": 16,
  "zsize": 16,
  "palette": {
    "palette": [
      {
        "char": " ",
        "block": "minecraft:air"
      },
      {
        "char": "c",
        "block": "minecraft:air"
      },
      {
        "char": "F",
        "block": "minecraft:air"
      },
      {
        "char": "υ",
        "block": "minecraft:air"
      },
      {
        "char": "g",
        "block": "minecraft:glass_pane[east\u003dtrue,north\u003dfalse,south\u003dfalse,waterlogged\u003dfalse,west\u003dtrue]"
      },
      {
        "char": "e",
        "block": "minecraft:stone_bricks[weathering\u003dfalse]"
      },
      {
        "char": "h",
        "block": "minecraft:cracked_stone_bricks"
      },
      {
        "char": "i",
        "block": "minecraft:mossy_stone_bricks"
      },
      {
        "char": "o",
        "block": "minecraft:air"
      },
      {
        "char": "f",
        "block": "minecraft:glass_pane[east\u003dfalse,north\u003dtrue,south\u003dtrue,waterlogged\u003dfalse,west\u003dfalse]"
      },
      {
        "char": "d",
        "block": "minecraft:mossy_cobblestone"
      },
      {
        "char": "a",
        "block": "minecraft:cobblestone[weathering\u003dfalse]"
      },
      {
        "char": "b",
        "block": "minecraft:stone[weathering\u003dfalse]"
      },
      {
        "char": "ϯ",
        "block": "minecraft:cobblestone_slab[type\u003ddouble,waterlogged\u003dfalse,weathering\u003dfalse]"
      },
      {
        "char": "J",
        "block": "minecraft:glass_pane[east\u003dtrue,north\u003dfalse,south\u003dtrue,waterlogged\u003dfalse,west\u003dtrue]"
      },
      {
        "char": "l",
        "block": "minecraft:bookshelf"
      },
      {
        "char": "ѱ",
        "block": "minecraft:skeleton_skull[rotation\u003d7]",
        "tag": {
          "z": 618,
          "x": 72,
          "ForgeCaps": {},
          "id": "minecraft:skull",
          "y": 164
        }
      },
      {
        "char": "Ί",
        "block": "minecraft:glass_pane[east\u003dfalse,north\u003dtrue,south\u003dtrue,waterlogged\u003dfalse,west\u003dtrue]"
      },
      {
        "char": "Ё",
        "block": "minecraft:redstone_wire[east\u003dnone,north\u003dside,power\u003d0,south\u003dside,west\u003dnone]"
      },
      {
        "char": "y",
        "block": "minecraft:redstone_wire[east\u003dside,north\u003dside,power\u003d0,south\u003dside,west\u003dside]"
      },
      {
        "char": "x",
        "block": "minecraft:cobblestone_stairs[facing\u003dnorth,half\u003dbottom,shape\u003dstraight,waterlogged\u003dfalse,weathering\u003dfalse]"
      },
      {
        "char": "ѹ",
        "block": "minecraft:dark_oak_fence[east\u003dfalse,north\u003dfalse,south\u003dtrue,waterlogged\u003dfalse,west\u003dfalse]"
      },
      {
        "char": "ғ",
        "block": "minecraft:dark_oak_fence[east\u003dfalse,north\u003dtrue,south\u003dfalse,waterlogged\u003dfalse,west\u003dfalse]"
      },
      {
        "char": "и",
        "block": "minecraft:dark_oak_fence[east\u003dfalse,north\u003dfalse,south\u003dtrue,waterlogged\u003dfalse,west\u003dtrue]"
      },
      {
        "char": "Ϲ",
        "block": "minecraft:dark_oak_fence[east\u003dfalse,north\u003dtrue,south\u003dtrue,waterlogged\u003dfalse,west\u003dfalse]"
      }
    ]
  },
  "slices": [
    [
      "                ",
      "                ",
      "                ",
      "                ",
      "                ",
      "                ",
      "                ",
      "ccFυcccc        ",
      "geghgigho       ",
      "       f        ",
      "       e        ",
      "       f        ",
      "       i        ",
      "       f        ",
      "       h        ",
      "       f        "
    ],
    [
      "                ",
      "                ",
      "                ",
      "                ",
      "                ",
      "                ",
      "                ",
      "cccFυccc        ",
      "daaaadado       ",
      "bbabbaba        ",
      "abϯababa        ",
      "aaababbd        ",
      "bbbbaaad        ",
      "baaaabba        ",
      "abbbbaaa        ",
      "baabaabd        "
    ],
    [
      "                ",
      "                ",
      "                ",
      "                ",
      "                ",
      "                ",
      "                ",
      "ccccFυcc        ",
      "JhgeJhJio       ",
      "lѱ laaaΊ        ",
      "lЁ laaah        ",
      " Ё la  f        ",
      "l yla  e        ",
      "ly la  f        ",
      "l  la  h        ",
      "l   xxxf        "
    ],
    [
      "                ",
      "                ",
      "                ",
      "                ",
      "                ",
      "                ",
      "                ",
      "cccccFcc        ",
      "JigeJeJho       ",
      "l  laaaΊ        ",
      "l  laaae        ",
      "   la  f        ",
      "l  la  h        ",
      "l  la  f        ",
      "l   xxxi        ",
      "l      f        "
    ],
    [
      "                ",
      "                ",
      "                ",
      "                ",
      "                ",
      "                ",
      "                ",
      "cccccccc        ",
      "aaadadddo       ",
      "l  laaaa        ",
      "l  laaaa        ",
      "   la  a        ",
      "l  la  d        ",
      "l   xxxa        ",
      "l      d        ",
      "l      a        "
    ],
    [
      "                ",
      "                ",
      "                ",
      "                ",
      "                ",
      "                ",
      "                ",
      "cccccccc        ",
      "gh hJe io       ",
      "ѹ  laaaΊ        ",
      "ғ  laaai        ",
      "   la  f        ",
      "и   xxxi        ",
      "Ϲ      f        ",
      "Ϲ      i        ",
      "Ϲ      f        "
    ]
  ]
}