{
  "xsize": 16,
  "zsize": 16,
  "palette": {
    "palette": [
      {
        "char": " ",
        "block": "minecraft:air"
      },
      {
        "char": "c",
        "block": "minecraft:air"
      },
      {
        "char": "i",
        "block": "minecraft:mossy_stone_bricks"
      },
      {
        "char": "g",
        "block": "minecraft:glass_pane[east\u003dtrue,north\u003dfalse,south\u003dfalse,waterlogged\u003dfalse,west\u003dtrue]"
      },
      {
        "char": "a",
        "block": "minecraft:cobblestone[weathering\u003dfalse]"
      },
      {
        "char": "Л",
        "block": "minecraft:dark_oak_fence[east\u003dfalse,north\u003dfalse,south\u003dfalse,waterlogged\u003dfalse,west\u003dfalse]"
      },
      {
        "char": "d",
        "block": "minecraft:mossy_cobblestone"
      },
      {
        "char": "b",
        "block": "minecraft:stone[weathering\u003dfalse]"
      },
      {
        "char": "h",
        "block": "minecraft:cracked_stone_bricks"
      },
      {
        "char": "Б",
        "block": "minecraft:glass_pane[east\u003dfalse,north\u003dfalse,south\u003dtrue,waterlogged\u003dfalse,west\u003dfalse]"
      },
      {
        "char": "Q",
        "block": "minecraft:crafting_table"
      },
      {
        "char": "T",
        "block": "minecraft:flower_pot"
      },
      {
        "char": "e",
        "block": "minecraft:stone_bricks[weathering\u003dfalse]"
      },
      {
        "char": "C",
        "block": "minecraft:redstone_lamp[lit\u003dfalse]"
      },
      {
        "char": "j",
        "block": "minecraft:light_gray_carpet"
      },
      {
        "char": "I",
        "block": "minecraft:glass_pane[east\u003dtrue,north\u003dtrue,south\u003dtrue,waterlogged\u003dfalse,west\u003dfalse]"
      },
      {
        "char": "f",
        "block": "minecraft:glass_pane[east\u003dfalse,north\u003dtrue,south\u003dtrue,waterlogged\u003dfalse,west\u003dfalse]"
      },
      {
        "char": "你",
        "block": "minecraft:sea_pickle[pickles\u003d4,waterlogged\u003dfalse]"
      },
      {
        "char": "У",
        "block": "minecraft:stone_button[face\u003dfloor,facing\u003dnorth,powered\u003dfalse]"
      },
      {
        "char": "σ",
        "block": "minecraft:cobblestone_slab[type\u003dbottom,waterlogged\u003dfalse,weathering\u003dfalse]"
      },
      {
        "char": "б",
        "block": "minecraft:sea_pickle[pickles\u003d2,waterlogged\u003dfalse]"
      },
      {
        "char": "л",
        "block": "minecraft:stone_button[face\u003dfloor,facing\u003dsouth,powered\u003dfalse]"
      },
      {
        "char": "Ғ",
        "block": "minecraft:stone_button[face\u003dfloor,facing\u003dwest,powered\u003dfalse]"
      },
      {
        "char": "Я",
        "block": "minecraft:stone_button[face\u003dfloor,facing\u003deast,powered\u003dfalse]"
      }
    ]
  },
  "slices": [
    [
      "                ",
      "                ",
      "                ",
      "                ",
      "                ",
      "                ",
      "                ",
      "        ccc c cc",
      "             igi",
      "                ",
      "       a        ",
      "         Л      ",
      "                ",
      "                ",
      "                ",
      "         Л      "
    ],
    [
      "                ",
      "                ",
      "                ",
      "                ",
      "                ",
      "                ",
      "                ",
      "        ccc c cc",
      "            ddaa",
      "          ababaa",
      "       ab  abbbb",
      "        abaababb",
      "        abaaabab",
      "       ababbbbab",
      "        bbaaabbb",
      "       aabaaabba"
    ],
    [
      "                ",
      "                ",
      "                ",
      "                ",
      "                ",
      "                ",
      "                ",
      "        ccc c cc",
      "           ighgh",
      "       Б   Q QT ",
      "       e    QC j",
      "       IQT QQ bQ",
      "       e aa jTbb",
      "       fjaj aa你a",
      "       iQjbQ Уba",
      "       fjaTУQQσj"
    ],
    [
      "                ",
      "                ",
      "                ",
      "                ",
      "                ",
      "                ",
      "                ",
      "        ccc c cc",
      "       egighghge",
      "       f     T  ",
      "       e        ",
      "       IQ  Q    ",
      "       i aб   bT",
      "       f σ  a  л",
      "       h  Ғ    a",
      "       f a      "
    ],
    [
      "                ",
      "                ",
      "                ",
      "                ",
      "                ",
      "                ",
      "                ",
      "        ccc c cc",
      "       daadaadad",
      "       a        ",
      "       a        ",
      "       dT       ",
      "       d      Я ",
      "       d        ",
      "       d        ",
      "       a        "
    ],
    [
      "                ",
      "                ",
      "                ",
      "                ",
      "                ",
      "                ",
      "                ",
      "        ccc c cc",
      "       egigeghge",
      "       f        ",
      "       i  C     ",
      "       f        ",
      "       i        ",
      "       f        ",
      "       h        ",
      "       f        "
    ]
  ]
}