{
  "xsize": 16,
  "zsize": 16,
  "palette": {
    "palette": [
      {
        "char": " ",
        "block": "minecraft:structure_void"
      },
      {
        "char": "e",
        "block": "minecraft:cyan_terracotta"
      },
      {
        "char": "c",
        "block": "minecraft:basalt[axis\u003dz]"
      },
      {
        "char": "a",
        "block": "minecraft:blackstone"
      },
      {
        "char": "b",
        "block": "minecraft:deepslate[axis\u003dy]"
      },
      {
        "char": "d",
        "block": "minecraft:cobbled_deepslate"
      },
      {
        "char": "i",
        "block": "immersive_weathering:mossy_stone_slab[type\u003dbottom,waterlogged\u003dfalse]"
      },
      {
        "char": "k",
        "block": "minecraft:air"
      },
      {
        "char": "z",
        "block": "minecraft:air"
      },
      {
        "char": "v",
        "block": "minecraft:quartz_block"
      },
      {
        "char": "x",
        "block": "minecraft:calcite"
      },
      {
        "char": "w",
        "block": "minecraft:air"
      },
      {
        "char": "l",
        "block": "minecraft:air"
      },
      {
        "char": "n",
        "block": "minecraft:polished_diorite"
      },
      {
        "char": "s",
        "block": "minecraft:diorite"
      },
      {
        "char": "h",
        "block": "minecraft:grass_block[snowy\u003dfalse]"
      },
      {
        "char": "A",
        "block": "minecraft:dirt"
      },
      {
        "char": "p",
        "block": "immersive_weathering:mossy_stone"
      },
      {
        "char": "f",
        "block": "immersive_weathering:exposed_iron_bars[east\u003dtrue,north\u003dfalse,south\u003dfalse,waterlogged\u003dfalse,west\u003dtrue]"
      },
      {
        "char": "q",
        "block": "minecraft:air"
      },
      {
        "char": "j",
        "block": "immersive_weathering:exposed_iron_bars[east\u003dfalse,north\u003dtrue,south\u003dtrue,waterlogged\u003dfalse,west\u003dfalse]"
      },
      {
        "char": "y",
        "block": "minecraft:stone[weathering\u003dfalse]"
      },
      {
        "char": "u",
        "block": "minecraft:cracked_stone_bricks"
      },
      {
        "char": "o",
        "block": "minecraft:air"
      },
      {
        "char": "r",
        "block": "minecraft:smooth_stone_slab[type\u003dbottom,waterlogged\u003dfalse]"
      },
      {
        "char": "g",
        "block": "minecraft:mossy_cobblestone_slab[type\u003dbottom,waterlogged\u003dfalse]"
      },
      {
        "char": "m",
        "block": "minecraft:moss_block"
      },
      {
        "char": "t",
        "block": "minecraft:cobblestone_slab[type\u003dbottom,waterlogged\u003dfalse,weathering\u003dfalse]"
      }
    ]
  },
  "slices": [
    [
      "ecabbaddabdedbaa",
      "dbacikk  zvxcaea",
      "baeai  wwlnsabha",
      "ddcdnsnxnvsvbcce",
      "bhbennvssnxnddaa",
      "dccAbhdadbdbehea",
      "cddadadhabcbbhhe",
      "dbehdedbcdaaahee",
      "ddccbdabbcbaacee",
      "cbbbdbceeceaaeae",
      "echhccedbcacabhe",
      "aeeeebcedcddbeca",
      "bebcbdadcdchcchh",
      "daaaabdbheaecabc",
      "baahccdhacababec",
      "aabdededcachhcba"
    ],
    [
      "  lpffffffffpq  ",
      "   k        j   ",
      "            j   ",
      "            j   ",
      "   w        j   ",
      "  lpq      lpq  ",
      "   k        k   ",
      "                ",
      "                ",
      "                ",
      "                ",
      "                ",
      "                ",
      "                ",
      "                ",
      "                "
    ],
    [
      "  lyffffffffpq  ",
      "   k        j   ",
      "            j   ",
      "            j   ",
      "   w        j   ",
      "  luq      luq  ",
      "            k   ",
      "                ",
      "                ",
      "                ",
      "                ",
      "                ",
      "                ",
      "                ",
      "                ",
      "                "
    ],
    [
      "  luffffffffu   ",
      "   k  oo    j   ",
      "      oo    j   ",
      "           oj   ",
      "    o   o   j   ",
      "   pq      lp   ",
      "            k   ",
      "                ",
      "                ",
      "                ",
      "                ",
      "                ",
      "                ",
      "                ",
      "                ",
      "                "
    ],
    [
      "   irgimgiigi   ",
      "   giimmigggg   ",
      "   gggmmrggti   ",
      "   iiggiggimr   ",
      "   rmrttmtggt   ",
      "   ggiggiiigr   ",
      "                ",
      "                ",
      "                ",
      "                ",
      "                ",
      "                ",
      "                ",
      "                ",
      "                ",
      "                "
    ]
  ]
}