{
  "xsize": 16,
  "zsize": 16,
  "palette": {
    "palette": [
      {
        "char": " ",
        "block": "minecraft:structure_void"
      },
      {
        "char": "t",
        "block": "minecraft:polished_deepslate_slab[type\u003dbottom,waterlogged\u003dfalse]"
      },
      {
        "char": "A",
        "block": "minecraft:polished_deepslate_slab[type\u003ddouble,waterlogged\u003dfalse]"
      },
      {
        "char": "n",
        "block": "minecraft:polished_deepslate_slab[type\u003dtop,waterlogged\u003dfalse]"
      },
      {
        "char": "Δ",
        "block": "minecraft:air"
      },
      {
        "char": "G",
        "block": "minecraft:air"
      },
      {
        "char": "e",
        "block": "minecraft:cobbled_deepslate_slab[type\u003dbottom,waterlogged\u003dfalse]"
      },
      {
        "char": "f",
        "block": "minecraft:cobbled_deepslate_slab[type\u003ddouble,waterlogged\u003dfalse]"
      },
      {
        "char": "b",
        "block": "minecraft:blue_terracotta"
      },
      {
        "char": "h",
        "block": "minecraft:cobbled_deepslate_slab[type\u003dtop,waterlogged\u003dfalse]"
      },
      {
        "char": "Α",
        "block": "minecraft:dark_oak_stairs[facing\u003dwest,half\u003dbottom,shape\u003dstraight,waterlogged\u003dfalse]"
      },
      {
        "char": "Ѓ",
        "block": "minecraft:air"
      },
      {
        "char": "v",
        "block": "minecraft:air"
      },
      {
        "char": "B",
        "block": "minecraft:dark_oak_leaves[distance\u003d7,persistent\u003dfalse,waterlogged\u003dfalse]"
      }
    ]
  },
  "slices": [
    [
      "                ",
      "       tAnΔG  nA",
      "       efbbbbbbf",
      "       efh    hf",
      "       efh    hf",
      "       efh    hf",
      "       efh    hf",
      "       efh    hf",
      "       efh    hf",
      "   ttttefh    hf",
      "   Affffbbbbbbbb",
      "   nb    bΑ     ",
      "   Ѓb    b      ",
      "   vb    b      ",
      "   vb    b      ",
      "    bbbbbbbbbbbb"
    ],
    [
      "                ",
      "         tAnnAt ",
      "         efbbfe ",
      "         efhhfe ",
      "         efhhfe ",
      "         efhhfe ",
      "         efhhfe ",
      "         efhhfe ",
      "         efhhfe ",
      "         efhhfe ",
      "        eeffffee",
      "   teeeeeffffffe",
      "   Affffffffffff",
      "   nbhhhhbhhhhhh",
      "   vb    b      ",
      "   vbbbbbbbbbbbb"
    ],
    [
      "                ",
      "           tt   ",
      "           ee   ",
      "           ee   ",
      "           ee   ",
      "           ee   ",
      "           ee   ",
      "           ee   ",
      "           ee   ",
      "           ee   ",
      "           ee   ",
      "           ee   ",
      "          eeee  ",
      "   teeeeeeeeeeee",
      "   Affffffffffff",
      "   nbbbbbbbbbbbb"
    ],
    [
      "                ",
      "                ",
      "                ",
      "                ",
      "                ",
      "                ",
      "                ",
      "                ",
      "                ",
      "                ",
      "                ",
      "                ",
      "                ",
      "                ",
      "                ",
      "   teeeeeeeeeeee"
    ],
    [
      "                ",
      "                ",
      "                ",
      "                ",
      "                ",
      "                ",
      "                ",
      "                ",
      "                ",
      "                ",
      "                ",
      "                ",
      "                ",
      "                ",
      "                ",
      "              B "
    ],
    [
      "                ",
      "                ",
      "                ",
      "                ",
      "                ",
      "                ",
      "                ",
      "                ",
      "                ",
      "                ",
      "                ",
      "                ",
      "                ",
      "                ",
      "                ",
      "                "
    ]
  ]
}