{
  "xsize": 16,
  "zsize": 16,
  "palette": {
    "palette": [
      {
        "char": " ",
        "block": "minecraft:structure_void"
      },
      {
        "char": "n",
        "block": "minecraft:polished_deepslate_slab[type\u003dtop,waterlogged\u003dfalse]"
      },
      {
        "char": "c",
        "block": "minecraft:green_terracotta"
      },
      {
        "char": "l",
        "block": "minecraft:spruce_slab[type\u003dtop,waterlogged\u003dfalse]"
      },
      {
        "char": "Q",
        "block": "minecraft:spruce_slab[type\u003dbottom,waterlogged\u003dfalse]"
      },
      {
        "char": "i",
        "block": "minecraft:air"
      },
      {
        "char": "H",
        "block": "minecraft:stripped_birch_wood[axis\u003dy]"
      },
      {
        "char": "P",
        "block": "minecraft:birch_planks"
      },
      {
        "char": "h",
        "block": "minecraft:cobbled_deepslate_slab[type\u003dtop,waterlogged\u003dfalse]"
      },
      {
        "char": "G",
        "block": "minecraft:air"
      },
      {
        "char": "Χ",
        "block": "minecraft:air"
      },
      {
        "char": "Ϊ",
        "block": "minecraft:air"
      },
      {
        "char": "·",
        "block": "minecraft:air"
      },
      {
        "char": "Ψ",
        "block": "minecraft:polished_deepslate_stairs[facing\u003dwest,half\u003dbottom,shape\u003dstraight,waterlogged\u003dfalse]"
      },
      {
        "char": "e",
        "block": "minecraft:cobbled_deepslate_slab[type\u003dbottom,waterlogged\u003dfalse]"
      },
      {
        "char": "f",
        "block": "minecraft:cobbled_deepslate_slab[type\u003ddouble,waterlogged\u003dfalse]"
      },
      {
        "char": "1",
        "block": "create:tiled_glass"
      },
      {
        "char": "R",
        "block": "minecraft:cobbled_deepslate_stairs[facing\u003dnorth,half\u003dbottom,shape\u003dstraight,waterlogged\u003dfalse]"
      },
      {
        "char": "p",
        "block": "immersive_weathering:oak_leaf_pile[age\u003d0,layers\u003d1]"
      },
      {
        "char": "t",
        "block": "minecraft:polished_deepslate_slab[type\u003dbottom,waterlogged\u003dfalse]"
      },
      {
        "char": "v",
        "block": "minecraft:air"
      },
      {
        "char": "η",
        "block": "minecraft:air"
      },
      {
        "char": "A",
        "block": "minecraft:polished_deepslate_slab[type\u003ddouble,waterlogged\u003dfalse]"
      },
      {
        "char": "΄",
        "block": "minecraft:air"
      },
      {
        "char": "ά",
        "block": "minecraft:cobbled_deepslate_stairs[facing\u003dsouth,half\u003dtop,shape\u003dstraight,waterlogged\u003dfalse]"
      }
    ]
  },
  "slices": [
    [
      " ncllllcllQ illl",
      " ncllllclll  Qll",
      " ncllllcllllllll",
      " nccccccccccccHP",
      " ncllllcllllllcn",
      " ncllllQ  llllch",
      " ncllllQQ Glllch",
      " ncccccccQccccch",
      " ncllllcllllllch",
      " ncllllcllllllch",
      " ncllllcllllllch",
      " ncllllcllllllch",
      " ncllllcllllllch",
      " nHcccccccccccHn",
      " nnΧ  Ϊ·     ΧnΨ",
      "                "
    ],
    [
      "  efhi  i i   i1",
      "  efh       i  c",
      "  efh      ihhhc",
      "  efh  ii iihfRR",
      "  efh  pppiihft ",
      "  efh i  vi hfe ",
      "  efh e   ηihfe ",
      "  efh iQp i hfe ",
      "  efh    pi hfe ",
      "  efhi et i hfe ",
      "  efh  e   ihfe ",
      "  efhii i iihfe ",
      "  efh   iii hfe ",
      "  efcccccccccfe ",
      "  tAn  ΄·Ϊ  nAt ",
      "   ΄         ΄  "
    ],
    [
      "    efh        1",
      "    efh   hάάάάc",
      "    efh   hfRRRR",
      "    efh   hfe   ",
      "    efh   hfe   ",
      "    efh   hfe   ",
      "    ef    hfe   ",
      "    efp  hhfe   ",
      "    efe   hfe   ",
      "    efhi  hfe   ",
      "    efh n hfe   ",
      "    efh   hfe   ",
      "    efh  ihfe   ",
      "    efcc1ccfe   ",
      "    tAnΧ ΧnAt   ",
      "                "
    ],
    [
      "      efhfffffff",
      "      efhfRRRRRR",
      "      efhfe     ",
      "      efAfe     ",
      "      eeAfe     ",
      "        tfe     ",
      "         ee     ",
      "          e     ",
      "          e     ",
      "          e     ",
      "      ee ee     ",
      "      eenfe     ",
      "      efhfe     ",
      "      efcfe     ",
      "      tAnAt     ",
      "                "
    ],
    [
      "        tttttttt",
      "        t       ",
      "        t       ",
      "                ",
      "                ",
      "                ",
      "                ",
      "                ",
      "                ",
      "                ",
      "                ",
      "                ",
      "        t       ",
      "        t       ",
      "        t       ",
      "                "
    ],
    [
      "                ",
      "                ",
      "                ",
      "                ",
      "                ",
      "                ",
      "                ",
      "                ",
      "                ",
      "                ",
      "                ",
      "                ",
      "                ",
      "                ",
      "                ",
      "                "
    ]
  ]
}