{
  "xsize": 16,
  "zsize": 16,
  "palette": {
    "palette": [
      {
        "char": " ",
        "block": "minecraft:air"
      },
      {
        "char": "b",
        "block": "minecraft:mossy_stone_bricks"
      },
      {
        "char": "f",
        "block": "minecraft:air"
      },
      {
        "char": "h",
        "block": "minecraft:glass_pane[east\u003dfalse,north\u003dtrue,south\u003dtrue,waterlogged\u003dfalse,west\u003dfalse]"
      },
      {
        "char": "i",
        "block": "minecraft:cobblestone[weathering\u003dfalse]"
      },
      {
        "char": "j",
        "block": "minecraft:stone[weathering\u003dfalse]"
      },
      {
        "char": "g",
        "block": "minecraft:glass_pane[east\u003dtrue,north\u003dfalse,south\u003dfalse,waterlogged\u003dfalse,west\u003dtrue]"
      },
      {
        "char": "a",
        "block": "minecraft:mossy_cobblestone"
      },
      {
        "char": "e",
        "block": "minecraft:air"
      },
      {
        "char": "m",
        "block": "minecraft:stone_bricks[weathering\u003dfalse]"
      },
      {
        "char": "c",
        "block": "minecraft:cracked_stone_bricks"
      },
      {
        "char": "n",
        "block": "immersive_weathering:mossy_stone"
      },
      {
        "char": "y",
        "block": "minecraft:stone_slab[type\u003dtop,waterlogged\u003dfalse,weathering\u003dfalse]"
      },
      {
        "char": "τ",
        "block": "minecraft:stripped_spruce_log[axis\u003dy]"
      },
      {
        "char": "x",
        "block": "minecraft:light_gray_carpet"
      },
      {
        "char": "C",
        "block": "minecraft:spruce_slab[type\u003dtop,waterlogged\u003dfalse]"
      },
      {
        "char": "z",
        "block": "minecraft:stone_slab[type\u003dbottom,waterlogged\u003dfalse,weathering\u003dfalse]"
      },
      {
        "char": "I",
        "block": "minecraft:bookshelf"
      },
      {
        "char": "N",
        "block": "minecraft:glass_pane[east\u003dtrue,north\u003dtrue,south\u003dtrue,waterlogged\u003dfalse,west\u003dfalse]"
      },
      {
        "char": "O",
        "block": "minecraft:spruce_trapdoor[facing\u003deast,half\u003dbottom,open\u003dfalse,powered\u003dfalse,waterlogged\u003dfalse]"
      },
      {
        "char": "ϖ",
        "block": "minecraft:spruce_trapdoor[facing\u003dnorth,half\u003dbottom,open\u003dfalse,powered\u003dfalse,waterlogged\u003dfalse]"
      }
    ]
  },
  "slices": [
    [
      "        b       ",
      "       fh       ",
      "       fb       ",
      "       fh       ",
      "       fi       ",
      "       fh       ",
      "       fj       ",
      "        h       ",
      "        bgjga   ",
      "        eee     ",
      "                ",
      "                ",
      "                ",
      "                ",
      "                ",
      "                "
    ],
    [
      "        mmacb   ",
      "       fimana   ",
      "       fbmmiccy ",
      "       fiimic i ",
      "       faijimjib",
      "       famaacica",
      "       fajijmiii",
      "        bbcjcjma",
      "        accbc   ",
      "        eee     ",
      "                ",
      "                ",
      "                ",
      "                ",
      "                ",
      "                "
    ],
    [
      "        nτ  x   ",
      "       fh       ",
      "       fbτ x x  ",
      "       fhCx x   ",
      "       faC x    ",
      "       fhCx   zx",
      "       faτ  x   ",
      "        h   τCCC",
      "        agaga   ",
      "                ",
      "                ",
      "                ",
      "                ",
      "                ",
      "                ",
      "                "
    ],
    [
      "        bI      ",
      "       fh       ",
      "       fcI      ",
      "       fNI      ",
      "       faI      ",
      "       fNI      ",
      "       fcI      ",
      "        h   IIII",
      "        igmgi   ",
      "                ",
      "                ",
      "                ",
      "                ",
      "                ",
      "                ",
      "                "
    ],
    [
      "        jO      ",
      "       fa       ",
      "       fiO      ",
      "       fbO      ",
      "       fiO      ",
      "       fcO      ",
      "       fbO      ",
      "        b   ϖϖϖϖ",
      "        bmabcj  ",
      "                ",
      "                ",
      "                ",
      "                ",
      "                ",
      "                ",
      "                "
    ],
    [
      "        a       ",
      "       fh       ",
      "       fm       ",
      "       fh       ",
      "       fj       ",
      "       fh       ",
      "       fc       ",
      "        h       ",
      "        cgjgigj ",
      "                ",
      "                ",
      "                ",
      "                ",
      "                ",
      "                ",
      "                "
    ]
  ]
}