{
  "xsize": 16,
  "zsize": 16,
  "palette": {
    "palette": [
      {
        "char": " ",
        "block": "minecraft:air"
      },
      {
        "char": "c",
        "block": "minecraft:cracked_stone_bricks"
      },
      {
        "char": "f",
        "block": "minecraft:air"
      },
      {
        "char": "h",
        "block": "minecraft:glass_pane[east\u003dfalse,north\u003dtrue,south\u003dtrue,waterlogged\u003dfalse,west\u003dfalse]"
      },
      {
        "char": "a",
        "block": "minecraft:mossy_cobblestone"
      },
      {
        "char": "m",
        "block": "minecraft:stone_bricks[weathering\u003dfalse]"
      },
      {
        "char": "g",
        "block": "minecraft:glass_pane[east\u003dtrue,north\u003dfalse,south\u003dfalse,waterlogged\u003dfalse,west\u003dtrue]"
      },
      {
        "char": "j",
        "block": "minecraft:stone[weathering\u003dfalse]"
      },
      {
        "char": "e",
        "block": "minecraft:air"
      },
      {
        "char": "i",
        "block": "minecraft:cobblestone[weathering\u003dfalse]"
      },
      {
        "char": "b",
        "block": "minecraft:mossy_stone_bricks"
      },
      {
        "char": "Γ",
        "block": "immersive_weathering:mossy_stone_slab[type\u003dtop,waterlogged\u003dfalse]"
      },
      {
        "char": "n",
        "block": "immersive_weathering:mossy_stone"
      },
      {
        "char": "Θ",
        "block": "immersive_weathering:mossy_stone_slab[type\u003dbottom,waterlogged\u003dfalse]"
      },
      {
        "char": "l",
        "block": "minecraft:air"
      },
      {
        "char": "χ",
        "block": "minecraft:oak_stairs[facing\u003dsouth,half\u003dbottom,shape\u003dstraight,waterlogged\u003dfalse]"
      },
      {
        "char": "Ω",
        "block": "minecraft:oak_stairs[facing\u003dnorth,half\u003dbottom,shape\u003dstraight,waterlogged\u003dfalse]"
      },
      {
        "char": ";",
        "block": "minecraft:spruce_stairs[facing\u003dwest,half\u003dtop,shape\u003dstraight,waterlogged\u003dfalse]"
      },
      {
        "char": "C",
        "block": "minecraft:spruce_slab[type\u003dtop,waterlogged\u003dfalse]"
      },
      {
        "char": "ͼ",
        "block": "minecraft:spruce_stairs[facing\u003deast,half\u003dtop,shape\u003dstraight,waterlogged\u003dfalse]"
      },
      {
        "char": "Κ",
        "block": "minecraft:spruce_slab[type\u003dbottom,waterlogged\u003dfalse]"
      }
    ]
  },
  "slices": [
    [
      "        c       ",
      "       fh       ",
      "       fc       ",
      "       fh       ",
      "       fa       ",
      "       fh       ",
      "       fm       ",
      "       fh       ",
      "       fagjgcgjg",
      "        eeeeeeee",
      "                ",
      "                ",
      "                ",
      "                ",
      "                ",
      "                "
    ],
    [
      "        cicabj  ",
      "       faajbibΓ ",
      "       fbacnai Θ",
      "       fbbcacnjn",
      "       fncjcaaja",
      "       facjcacaa",
      "       fbbncbabj",
      "       fbcnabcnj",
      "       fbcacbbba",
      "        eeeeeeee",
      "                ",
      "                ",
      "                ",
      "                ",
      "                ",
      "                "
    ],
    [
      "       lb  χ    ",
      "       fh       ",
      "       fc  Ω    ",
      "       fh ;Cͼ ;Κ",
      "       fc CCC CC",
      "       fh ;Cͼ ;C",
      "       fa  χ   χ",
      "       fh       ",
      "       fmgngjgbg",
      "        eeeeeeee",
      "                ",
      "                ",
      "                ",
      "                ",
      "                ",
      "                "
    ],
    [
      "       lb       ",
      "       fh       ",
      "       fa       ",
      "       fh       ",
      "       fb       ",
      "       fh       ",
      "       fb       ",
      "       fh       ",
      "       fagjgagmg",
      "        eeeeeeee",
      "                ",
      "                ",
      "                ",
      "                ",
      "                ",
      "                "
    ],
    [
      "      llb       ",
      "       fi       ",
      "       fb       ",
      "       fb       ",
      "       fb       ",
      "       fb       ",
      "       fc       ",
      "       fa       ",
      "       faccannic",
      "        eeeeeeee",
      "                ",
      "                ",
      "                ",
      "                ",
      "                ",
      "                "
    ],
    [
      "       lm       ",
      "        h       ",
      "       fn       ",
      "       fh       ",
      "       fi       ",
      "       fh       ",
      "       fn       ",
      "       fh       ",
      "       fmgagbgag",
      "        eeeeeeee",
      "                ",
      "                ",
      "                ",
      "                ",
      "                ",
      "                "
    ]
  ]
}