{
  "xsize": 16,
  "zsize": 16,
  "palette": {
    "palette": [
      {
        "char": " ",
        "block": "minecraft:air"
      },
      {
        "char": "k",
        "block": "minecraft:air"
      },
      {
        "char": "Ι",
        "block": "minecraft:air"
      },
      {
        "char": "c",
        "block": "minecraft:cracked_stone_bricks"
      },
      {
        "char": "g",
        "block": "minecraft:glass_pane[east\u003dtrue,north\u003dfalse,south\u003dfalse,waterlogged\u003dfalse,west\u003dtrue]"
      },
      {
        "char": "a",
        "block": "minecraft:mossy_cobblestone"
      },
      {
        "char": "h",
        "block": "minecraft:glass_pane[east\u003dfalse,north\u003dtrue,south\u003dtrue,waterlogged\u003dfalse,west\u003dfalse]"
      },
      {
        "char": "l",
        "block": "minecraft:air"
      },
      {
        "char": "b",
        "block": "minecraft:mossy_stone_bricks"
      },
      {
        "char": "f",
        "block": "minecraft:air"
      },
      {
        "char": "i",
        "block": "minecraft:cobblestone[weathering\u003dfalse]"
      },
      {
        "char": "m",
        "block": "minecraft:stone_bricks[weathering\u003dfalse]"
      },
      {
        "char": "j",
        "block": "minecraft:stone[weathering\u003dfalse]"
      },
      {
        "char": "n",
        "block": "immersive_weathering:mossy_stone"
      },
      {
        "char": "y",
        "block": "minecraft:stone_slab[type\u003dtop,waterlogged\u003dfalse,weathering\u003dfalse]"
      },
      {
        "char": "Δ",
        "block": "minecraft:glass_pane[east\u003dtrue,north\u003dfalse,south\u003dtrue,waterlogged\u003dfalse,west\u003dtrue]"
      },
      {
        "char": "Ϡ",
        "block": "minecraft:spruce_stairs[facing\u003dnorth,half\u003dbottom,shape\u003dinner_right,waterlogged\u003dfalse]"
      },
      {
        "char": "Ј",
        "block": "minecraft:spruce_stairs[facing\u003deast,half\u003dbottom,shape\u003dstraight,waterlogged\u003dfalse]"
      },
      {
        "char": "Ϛ",
        "block": "minecraft:spruce_stairs[facing\u003dnorth,half\u003dtop,shape\u003dstraight,waterlogged\u003dfalse]"
      },
      {
        "char": "Э",
        "block": "minecraft:spruce_stairs[facing\u003dsouth,half\u003dbottom,shape\u003dinner_left,waterlogged\u003dfalse]"
      },
      {
        "char": "Χ",
        "block": "minecraft:oak_stairs[facing\u003dwest,half\u003dbottom,shape\u003dstraight,waterlogged\u003dfalse]"
      },
      {
        "char": "C",
        "block": "minecraft:spruce_slab[type\u003dtop,waterlogged\u003dfalse]"
      },
      {
        "char": "ϙ",
        "block": "minecraft:spruce_stairs[facing\u003dsouth,half\u003dtop,shape\u003dstraight,waterlogged\u003dfalse]"
      },
      {
        "char": "Ϳ",
        "block": "minecraft:birch_slab[type\u003dtop,waterlogged\u003dfalse]"
      },
      {
        "char": "Ψ",
        "block": "minecraft:heavy_weighted_pressure_plate[power\u003d0]"
      }
    ]
  },
  "slices": [
    [
      "                ",
      "                ",
      "                ",
      "                ",
      "                ",
      "                ",
      "              k ",
      "          kkkkkk",
      "       Ιcgcgagag",
      "        h       ",
      "       lb       ",
      "       fh       ",
      "       fb       ",
      "        h       ",
      "        a       ",
      "        h       "
    ],
    [
      "                ",
      "                ",
      "                ",
      "                ",
      "                ",
      "                ",
      "              k ",
      "          kkkkkk",
      "       laiccacbb",
      "       lmjmanabj",
      "       fmabaijbm",
      "       fimmibbab",
      "       fniibbjcn",
      "        jabajjc ",
      "        mmabc y ",
      "        mmmibc  "
    ],
    [
      "                ",
      "                ",
      "                ",
      "                ",
      "                ",
      "                ",
      "              k ",
      "          kkkkkk",
      "       lagjgjgcΔ",
      "       fh      Ϡ",
      "       fa      Ј",
      "       fh  Ϛ   Э",
      "       fn ΧC    ",
      "        h  ϙ    ",
      "        cl      ",
      "       lll  Ϳ   "
    ],
    [
      "                ",
      "                ",
      "                ",
      "                ",
      "                ",
      "                ",
      "              k ",
      "          kkkkkk",
      "       fagbgcgag",
      "       fh       ",
      "       fc       ",
      "       fh       ",
      "       fml Ψ    ",
      "        hl      ",
      "        cl      ",
      "       l l      "
    ],
    [
      "                ",
      "                ",
      "                ",
      "                ",
      "                ",
      "                ",
      "              k ",
      "          kkkkkk",
      "       fmnacbcca",
      "       fnll     ",
      "       fcl      ",
      "       fbl      ",
      "       fnl      ",
      "        nl      ",
      "        a       ",
      "        i       "
    ],
    [
      "                ",
      "                ",
      "                ",
      "                ",
      "                ",
      "                ",
      "              k ",
      "          kkkkkk",
      "       fbgngagcg",
      "       fhlllll  ",
      "       fnll     ",
      "       fh       ",
      "       fn       ",
      "                ",
      "        b       ",
      "        h       "
    ]
  ]
}