{
  "xsize": 16,
  "zsize": 16,
  "palette": {
    "palette": [
      {
        "char": " ",
        "block": "minecraft:air"
      },
      {
        "char": "f",
        "block": "minecraft:air"
      },
      {
        "char": "k",
        "block": "minecraft:air"
      },
      {
        "char": "Ϫ",
        "block": "minecraft:air"
      },
      {
        "char": "l",
        "block": "minecraft:air"
      },
      {
        "char": "b",
        "block": "minecraft:mossy_stone_bricks"
      },
      {
        "char": "g",
        "block": "minecraft:glass_pane[east\u003dtrue,north\u003dfalse,south\u003dfalse,waterlogged\u003dfalse,west\u003dtrue]"
      },
      {
        "char": "a",
        "block": "minecraft:mossy_cobblestone"
      },
      {
        "char": "d",
        "block": "minecraft:air"
      },
      {
        "char": "h",
        "block": "minecraft:glass_pane[east\u003dfalse,north\u003dtrue,south\u003dtrue,waterlogged\u003dfalse,west\u003dfalse]"
      },
      {
        "char": "j",
        "block": "minecraft:stone[weathering\u003dfalse]"
      },
      {
        "char": "m",
        "block": "minecraft:stone_bricks[weathering\u003dfalse]"
      },
      {
        "char": "i",
        "block": "minecraft:cobblestone[weathering\u003dfalse]"
      },
      {
        "char": "c",
        "block": "minecraft:cracked_stone_bricks"
      },
      {
        "char": "y",
        "block": "minecraft:stone_slab[type\u003dtop,waterlogged\u003dfalse,weathering\u003dfalse]"
      },
      {
        "char": "ц",
        "block": "minecraft:cobblestone_stairs[facing\u003deast,half\u003dtop,shape\u003dstraight,waterlogged\u003dfalse,weathering\u003dfalse]"
      },
      {
        "char": "у",
        "block": "minecraft:stone_stairs[facing\u003deast,half\u003dtop,shape\u003dstraight,waterlogged\u003dfalse,weathering\u003dfalse]"
      },
      {
        "char": "ϧ",
        "block": "minecraft:cobblestone_slab[type\u003dtop,waterlogged\u003dfalse,weathering\u003dfalse]"
      },
      {
        "char": "x",
        "block": "minecraft:light_gray_carpet"
      },
      {
        "char": "Ц",
        "block": "minecraft:air"
      }
    ]
  },
  "slices": [
    [
      "                ",
      "                ",
      "                ",
      "                ",
      "                ",
      "                ",
      "f kϪ            ",
      "l ll            ",
      "bgbgagagad      ",
      "        hd      ",
      "        bd      ",
      "        hd      ",
      "        bdd     ",
      "        hdd     ",
      "        b       ",
      "        h       "
    ],
    [
      "                ",
      "                ",
      "                ",
      "                ",
      "                ",
      "                ",
      "flkl            ",
      " lllll          ",
      "jaamiccicd      ",
      "      yцbd      ",
      "       уcd      ",
      "       ϧad      ",
      "        jdd     ",
      "        bdd     ",
      "        b       ",
      "       ya       "
    ],
    [
      "                ",
      "                ",
      "                ",
      "                ",
      "                ",
      "                ",
      "fl  l           ",
      "lllflll         ",
      "jgjgigcgbd      ",
      "        hd      ",
      "        bd      ",
      "       xhd      ",
      "        bdd     ",
      "        hdd     ",
      "        a       ",
      "        h       "
    ],
    [
      "                ",
      "                ",
      "                ",
      "                ",
      "                ",
      "                ",
      "    Цl          ",
      "ll flll         ",
      "bgbgigagad      ",
      "        hd      ",
      "        cd      ",
      "        hd      ",
      "        bdd     ",
      "        hdd     ",
      "        c       ",
      "        h       "
    ],
    [
      "                ",
      "                ",
      "                ",
      "                ",
      "                ",
      "                ",
      "     kl         ",
      "l    lll        ",
      "ijimbbbamd      ",
      "        cd      ",
      "        bd      ",
      "        ad      ",
      "        cdd     ",
      "        bdd     ",
      "        c       ",
      "        c       "
    ],
    [
      "                ",
      "                ",
      "                ",
      "                ",
      "                ",
      "                ",
      "     kk         ",
      "l    lll        ",
      "bgmgjgmgjd      ",
      "        hd      ",
      "        bd      ",
      "        hd      ",
      "        jdd     ",
      "        hdd     ",
      "        a       ",
      "        h       "
    ]
  ]
}