{
  "xsize": 16,
  "zsize": 16,
  "palette": {
    "palette": [
      {
        "char": " ",
        "block": "minecraft:air"
      },
      {
        "char": "f",
        "block": "minecraft:air"
      },
      {
        "char": "k",
        "block": "minecraft:air"
      },
      {
        "char": "l",
        "block": "minecraft:air"
      },
      {
        "char": "c",
        "block": "minecraft:cracked_stone_bricks"
      },
      {
        "char": "g",
        "block": "minecraft:glass_pane[east\u003dtrue,north\u003dfalse,south\u003dfalse,waterlogged\u003dfalse,west\u003dtrue]"
      },
      {
        "char": "m",
        "block": "minecraft:stone_bricks[weathering\u003dfalse]"
      },
      {
        "char": "a",
        "block": "minecraft:mossy_cobblestone"
      },
      {
        "char": "i",
        "block": "minecraft:cobblestone[weathering\u003dfalse]"
      },
      {
        "char": "b",
        "block": "minecraft:mossy_stone_bricks"
      },
      {
        "char": "ό",
        "block": "minecraft:air"
      },
      {
        "char": "h",
        "block": "minecraft:glass_pane[east\u003dfalse,north\u003dtrue,south\u003dtrue,waterlogged\u003dfalse,west\u003dfalse]"
      },
      {
        "char": "d",
        "block": "minecraft:air"
      },
      {
        "char": "j",
        "block": "minecraft:stone[weathering\u003dfalse]"
      },
      {
        "char": "n",
        "block": "immersive_weathering:mossy_stone"
      },
      {
        "char": "z",
        "block": "minecraft:stone_slab[type\u003dbottom,waterlogged\u003dfalse,weathering\u003dfalse]"
      },
      {
        "char": "р",
        "block": "minecraft:cobblestone_stairs[facing\u003dnorth,half\u003dtop,shape\u003dstraight,waterlogged\u003dfalse,weathering\u003dfalse]"
      },
      {
        "char": "y",
        "block": "minecraft:stone_slab[type\u003dtop,waterlogged\u003dfalse,weathering\u003dfalse]"
      },
      {
        "char": "К",
        "block": "minecraft:stone_stairs[facing\u003dsouth,half\u003dbottom,shape\u003dstraight,waterlogged\u003dfalse,weathering\u003dfalse]"
      },
      {
        "char": "΄",
        "block": "minecraft:mossy_cobblestone_slab[type\u003dbottom,waterlogged\u003dfalse]"
      },
      {
        "char": "Ћ",
        "block": "minecraft:mossy_cobblestone_stairs[facing\u003deast,half\u003dbottom,shape\u003dstraight,waterlogged\u003dfalse]"
      },
      {
        "char": "K",
        "block": "minecraft:cobblestone_slab[type\u003dbottom,waterlogged\u003dfalse,weathering\u003dfalse]"
      },
      {
        "char": "л",
        "block": "immersive_weathering:mossy_stone_stairs[facing\u003deast,half\u003dbottom,shape\u003dstraight,waterlogged\u003dfalse]"
      },
      {
        "char": "п",
        "block": "minecraft:mossy_cobblestone_stairs[facing\u003dwest,half\u003dbottom,shape\u003dstraight,waterlogged\u003dfalse]"
      },
      {
        "char": "Θ",
        "block": "immersive_weathering:mossy_stone_slab[type\u003dbottom,waterlogged\u003dfalse]"
      },
      {
        "char": "A",
        "block": "minecraft:terracotta"
      },
      {
        "char": "μ",
        "block": "minecraft:glass_pane[east\u003dfalse,north\u003dtrue,south\u003dtrue,waterlogged\u003dfalse,west\u003dtrue]"
      },
      {
        "char": "Ϫ",
        "block": "minecraft:air"
      }
    ]
  },
  "slices": [
    [
      "                ",
      "                ",
      "                ",
      "                ",
      "                ",
      "                ",
      "fkkk  l         ",
      "    lllll       ",
      "cgmgagilbό      ",
      "        hd      ",
      "        bd      ",
      "        hd      ",
      "        cdd     ",
      "        hdd     ",
      "        b       ",
      "        h       "
    ],
    [
      "                ",
      "                ",
      "                ",
      "                ",
      "                ",
      "                ",
      "fkkk l ll       ",
      "   lllllll      ",
      "cmjinajcil      ",
      "ibjibbaiaό      ",
      "abiaccaicd      ",
      "ncabacamnd      ",
      "acbnaciabdd     ",
      " z рbacmadd     ",
      "   yjiabn       ",
      "    mcbcn       "
    ],
    [
      "                ",
      "                ",
      "                ",
      "                ",
      "                ",
      "                ",
      "fkkkl           ",
      "l   ll  ll      ",
      "igcgagcgmll     ",
      " К΄ЋK   hl      ",
      "cabbabibj       ",
      "΄лaЋnaaпhd      ",
      "Θ cbjic΄bdd     ",
      "   aacc hdd     ",
      "    bazAa       ",
      "     bKAμ       "
    ],
    [
      "                ",
      "                ",
      "                ",
      "                ",
      "                ",
      "                ",
      "fkkk            ",
      "l lll           ",
      "jgjgagjgjl      ",
      "        hl      ",
      " z      jl      ",
      "  K ΄z΄ hd      ",
      "   zaba add     ",
      "    Θmz hdd     ",
      "        j       ",
      "     ΄  h       "
    ],
    [
      "                ",
      "                ",
      "                ",
      "                ",
      "                ",
      "                ",
      "fϪkk            ",
      "llll            ",
      "jbanaiibjd      ",
      "        cl      ",
      "        il      ",
      "        nd      ",
      "     b  add     ",
      "        ndd     ",
      "        b       ",
      "        j       "
    ],
    [
      "                ",
      "                ",
      "                ",
      "                ",
      "                ",
      "                ",
      "flkk            ",
      " lll            ",
      "jgagbgcgjd      ",
      "        hd      ",
      "        bd      ",
      "        hd      ",
      "        ndd     ",
      "        hdd     ",
      "        j       ",
      "        h       "
    ]
  ]
}