{
  "xsize": 16,
  "zsize": 16,
  "palette": {
    "palette": [
      {
        "char": " ",
        "block": "minecraft:air"
      },
      {
        "char": "f",
        "block": "minecraft:air"
      },
      {
        "char": "a",
        "block": "minecraft:mossy_cobblestone"
      },
      {
        "char": "l",
        "block": "minecraft:air"
      },
      {
        "char": "g",
        "block": "minecraft:glass_pane[east\u003dtrue,north\u003dfalse,south\u003dfalse,waterlogged\u003dfalse,west\u003dtrue]"
      },
      {
        "char": "b",
        "block": "minecraft:mossy_stone_bricks"
      },
      {
        "char": "j",
        "block": "minecraft:stone[weathering\u003dfalse]"
      },
      {
        "char": "c",
        "block": "minecraft:cracked_stone_bricks"
      },
      {
        "char": "e",
        "block": "minecraft:air"
      },
      {
        "char": "m",
        "block": "minecraft:stone_bricks[weathering\u003dfalse]"
      },
      {
        "char": "i",
        "block": "minecraft:cobblestone[weathering\u003dfalse]"
      },
      {
        "char": "y",
        "block": "minecraft:stone_slab[type\u003dtop,waterlogged\u003dfalse,weathering\u003dfalse]"
      },
      {
        "char": "n",
        "block": "immersive_weathering:mossy_stone"
      },
      {
        "char": "Β",
        "block": "minecraft:barrel[facing\u003dup,open\u003dfalse]",
        "loot": "bigbuildingsloot",
        "tag": {
          "z": 583,
          "x": 236,
          "ForgeCaps": {},
          "id": "minecraft:barrel",
          "y": 166,
          "Items": []
        }
      },
      {
        "char": "Υ",
        "block": "minecraft:barrel[facing\u003dnorth,open\u003dfalse]",
        "loot": "bigbuildingsloot",
        "tag": {
          "z": 583,
          "x": 234,
          "ForgeCaps": {},
          "id": "minecraft:barrel",
          "y": 167,
          "Items": []
        }
      },
      {
        "char": "Ͻ",
        "block": "minecraft:barrel[facing\u003deast,open\u003dfalse]",
        "loot": "bigbuildingsloot",
        "tag": {
          "z": 582,
          "x": 235,
          "ForgeCaps": {},
          "id": "minecraft:barrel",
          "y": 167,
          "Items": []
        }
      },
      {
        "char": "N",
        "block": "minecraft:glass_pane[east\u003dtrue,north\u003dtrue,south\u003dtrue,waterlogged\u003dfalse,west\u003dfalse]"
      },
      {
        "char": "Φ",
        "block": "minecraft:glass_pane[east\u003dtrue,north\u003dtrue,south\u003dfalse,waterlogged\u003dfalse,west\u003dtrue]"
      },
      {
        "char": "h",
        "block": "minecraft:glass_pane[east\u003dfalse,north\u003dtrue,south\u003dtrue,waterlogged\u003dfalse,west\u003dfalse]"
      }
    ]
  },
  "slices": [
    [
      "                ",
      "       f        ",
      "       fa       ",
      "       f        ",
      "       f        ",
      "       f        ",
      "       f        ",
      "       f      ll",
      "       fagbgjgcg",
      "        eeeeeeee",
      "                ",
      "                ",
      "                ",
      "                ",
      "                ",
      "                "
    ],
    [
      "         amcb   ",
      "       f bciib  ",
      "       fbcibby  ",
      "       fbbimibbj",
      "       f jjciaac",
      "       f  cccjjb",
      "       f  bcccja",
      "       fmaaacbil",
      "       fnaabnnba",
      "        eeeeeeee",
      "                ",
      "                ",
      "                ",
      "                ",
      "                ",
      "                "
    ],
    [
      "                ",
      "       f        ",
      "       fb       ",
      "       f  Β     ",
      "       fn ΒΒΥ   ",
      "       f  ΒΥΒΒ  ",
      "       fa ΥΒΒϽ  ",
      "       fNΒΥΒΒ   ",
      "       fbΦaΦagag",
      "        eeeeeeee",
      "                ",
      "                ",
      "                ",
      "                ",
      "                ",
      "                "
    ],
    [
      "                ",
      "       f        ",
      "       fj       ",
      "       f        ",
      "       fj       ",
      "       f  Β     ",
      "       fa  Ͻ   l",
      "       fNΥΥΥΥ ll",
      "       fcΦbΦagag",
      "        eeeeeeee",
      "                ",
      "                ",
      "                ",
      "                ",
      "                ",
      "                "
    ],
    [
      "                ",
      "       f        ",
      "       fm       ",
      "       fa       ",
      "       fn       ",
      "       fc       ",
      "       fb    ll ",
      "       fc    lll",
      "       fnccmacac",
      "        eeeeeeee",
      "                ",
      "                ",
      "                ",
      "                ",
      "                ",
      "                "
    ],
    [
      "        i       ",
      "       fh       ",
      "       fb       ",
      "       fh       ",
      "       fj       ",
      "       fh       ",
      "       fn   lll ",
      "       fhllllll ",
      "       fbgbgbgbg",
      "        eeeeeeee",
      "                ",
      "                ",
      "                ",
      "                ",
      "                ",
      "                "
    ]
  ]
}