{
  "xsize": 16,
  "zsize": 16,
  "palette": {
    "palette": [
      {
        "char": " ",
        "block": "minecraft:air"
      },
      {
        "char": "b",
        "block": "minecraft:mossy_stone_bricks"
      },
      {
        "char": "h",
        "block": "minecraft:glass_pane[east\u003dfalse,north\u003dtrue,south\u003dtrue,waterlogged\u003dfalse,west\u003dfalse]"
      },
      {
        "char": "c",
        "block": "minecraft:cracked_stone_bricks"
      },
      {
        "char": "j",
        "block": "minecraft:stone[weathering\u003dfalse]"
      },
      {
        "char": "d",
        "block": "minecraft:air"
      },
      {
        "char": "l",
        "block": "minecraft:air"
      },
      {
        "char": "i",
        "block": "minecraft:cobblestone[weathering\u003dfalse]"
      },
      {
        "char": "g",
        "block": "minecraft:glass_pane[east\u003dtrue,north\u003dfalse,south\u003dfalse,waterlogged\u003dfalse,west\u003dtrue]"
      },
      {
        "char": "m",
        "block": "minecraft:stone_bricks[weathering\u003dfalse]"
      },
      {
        "char": "a",
        "block": "minecraft:mossy_cobblestone"
      },
      {
        "char": "e",
        "block": "minecraft:air"
      },
      {
        "char": "n",
        "block": "immersive_weathering:mossy_stone"
      },
      {
        "char": "y",
        "block": "minecraft:stone_slab[type\u003dtop,waterlogged\u003dfalse,weathering\u003dfalse]"
      },
      {
        "char": "v",
        "block": "minecraft:light_gray_concrete"
      },
      {
        "char": "Ϳ",
        "block": "minecraft:birch_slab[type\u003dtop,waterlogged\u003dfalse]"
      },
      {
        "char": "Ϛ",
        "block": "minecraft:spruce_stairs[facing\u003dnorth,half\u003dtop,shape\u003dstraight,waterlogged\u003dfalse]"
      },
      {
        "char": "C",
        "block": "minecraft:spruce_slab[type\u003dtop,waterlogged\u003dfalse]"
      },
      {
        "char": "ϔ",
        "block": "minecraft:oak_stairs[facing\u003deast,half\u003dbottom,shape\u003dstraight,waterlogged\u003dfalse]"
      },
      {
        "char": "Ѓ",
        "block": "minecraft:spruce_stairs[facing\u003dsouth,half\u003dbottom,shape\u003douter_right,waterlogged\u003dfalse]"
      },
      {
        "char": "ϙ",
        "block": "minecraft:spruce_stairs[facing\u003dsouth,half\u003dtop,shape\u003dstraight,waterlogged\u003dfalse]"
      },
      {
        "char": "Ϯ",
        "block": "minecraft:spruce_stairs[facing\u003dwest,half\u003dbottom,shape\u003dstraight,waterlogged\u003dfalse]"
      },
      {
        "char": "Г",
        "block": "minecraft:spruce_stairs[facing\u003dsouth,half\u003dbottom,shape\u003dinner_right,waterlogged\u003dfalse]"
      },
      {
        "char": "ϛ",
        "block": "minecraft:spruce_stairs[facing\u003dsouth,half\u003dbottom,shape\u003dstraight,waterlogged\u003dfalse]"
      },
      {
        "char": "Ђ",
        "block": "minecraft:spruce_stairs[facing\u003dwest,half\u003dbottom,shape\u003douter_left,waterlogged\u003dfalse]"
      },
      {
        "char": "Φ",
        "block": "minecraft:glass_pane[east\u003dtrue,north\u003dtrue,south\u003dfalse,waterlogged\u003dfalse,west\u003dtrue]"
      },
      {
        "char": "ϳ",
        "block": "minecraft:potted_wither_rose"
      },
      {
        "char": "Ψ",
        "block": "minecraft:heavy_weighted_pressure_plate[power\u003d0]"
      },
      {
        "char": "ϫ",
        "block": "minecraft:flower_pot"
      }
    ]
  },
  "slices": [
    [
      "        b       ",
      "        h       ",
      "        c       ",
      "        h       ",
      "        j       ",
      "        hd      ",
      "     ll id      ",
      "    lll hd      ",
      "cgjgmgagbd      ",
      "ee     ee       ",
      "                ",
      "                ",
      "                ",
      "                ",
      "                ",
      "                "
    ],
    [
      "    iamnn       ",
      "  yycibbb       ",
      "    aambm       ",
      " yijbbbbm       ",
      "iiiabbajc       ",
      "mabbnbiibd      ",
      "jbaccllcad      ",
      "ijaccllind      ",
      "ccnanbbibd      ",
      "ee     ee       ",
      "                ",
      "                ",
      "                ",
      "                ",
      "                ",
      "                "
    ],
    [
      "    vvvva       ",
      "    ͿͿ  h       ",
      "        a       ",
      "     Ϛ  h       ",
      "v    Cϔ i       ",
      "vЃ   ϙ  hd      ",
      "vϮ    llbd      ",
      "vГϛЂ lllhd      ",
      "iΦbgbgcgmd      ",
      "ee     ee       ",
      "                ",
      "                ",
      "                ",
      "                ",
      "                ",
      "                "
    ],
    [
      "     vvvc       ",
      "    ϳ   h       ",
      "        m       ",
      "        h       ",
      "     Ψ  c       ",
      "v    ϫ  hd      ",
      "v      lcd      ",
      "v       hd      ",
      "bgigjgagbd      ",
      "ee     ee       ",
      "                ",
      "                ",
      "                ",
      "                ",
      "                ",
      "                "
    ],
    [
      "        j       ",
      "        i       ",
      "        b       ",
      "        i       ",
      "        b       ",
      "        bd      ",
      "       lad      ",
      "       lcd      ",
      "cnbicbjjbd      ",
      "ee     ee       ",
      "                ",
      "                ",
      "                ",
      "                ",
      "                ",
      "                "
    ],
    [
      "        j       ",
      "       lh       ",
      "      llb       ",
      "      llh       ",
      "       lc       ",
      "      llhd      ",
      "      llad      ",
      "       lhd      ",
      "bgmgcgbgcd      ",
      "ee     ee       ",
      "                ",
      "                ",
      "                ",
      "                ",
      "                ",
      "                "
    ]
  ]
}