{
  "xsize": 16,
  "zsize": 16,
  "palette": {
    "palette": [
      {
        "char": " ",
        "block": "minecraft:air"
      },
      {
        "char": "l",
        "block": "minecraft:air"
      },
      {
        "char": "c",
        "block": "minecraft:cracked_stone_bricks"
      },
      {
        "char": "h",
        "block": "minecraft:glass_pane[east\u003dfalse,north\u003dtrue,south\u003dtrue,waterlogged\u003dfalse,west\u003dfalse]"
      },
      {
        "char": "f",
        "block": "minecraft:air"
      },
      {
        "char": "a",
        "block": "minecraft:mossy_cobblestone"
      },
      {
        "char": "m",
        "block": "minecraft:stone_bricks[weathering\u003dfalse]"
      },
      {
        "char": "n",
        "block": "immersive_weathering:mossy_stone"
      },
      {
        "char": "g",
        "block": "minecraft:glass_pane[east\u003dtrue,north\u003dfalse,south\u003dfalse,waterlogged\u003dfalse,west\u003dtrue]"
      },
      {
        "char": "b",
        "block": "minecraft:mossy_stone_bricks"
      },
      {
        "char": "i",
        "block": "minecraft:cobblestone[weathering\u003dfalse]"
      },
      {
        "char": "e",
        "block": "minecraft:air"
      },
      {
        "char": "j",
        "block": "minecraft:stone[weathering\u003dfalse]"
      },
      {
        "char": "z",
        "block": "minecraft:stone_slab[type\u003dbottom,waterlogged\u003dfalse,weathering\u003dfalse]"
      },
      {
        "char": "x",
        "block": "minecraft:light_gray_carpet"
      },
      {
        "char": "І",
        "block": "minecraft:anvil[facing\u003dwest]"
      },
      {
        "char": "φ",
        "block": "minecraft:tripwire[attached\u003dfalse,disarmed\u003dfalse,east\u003dfalse,north\u003dfalse,powered\u003dfalse,south\u003dfalse,west\u003dfalse]"
      },
      {
        "char": "Υ",
        "block": "minecraft:barrel[facing\u003dnorth,open\u003dfalse]",
        "loot": "bigbuildingsloot",
        "tag": {
          "z": 583,
          "x": 234,
          "ForgeCaps": {},
          "id": "minecraft:barrel",
          "y": 167,
          "Items": []
        }
      },
      {
        "char": "ϯ",
        "block": "minecraft:end_rod[facing\u003dnorth]"
      },
      {
        "char": "Т",
        "block": "minecraft:wither_skeleton_wall_skull[facing\u003dsouth]",
        "tag": {
          "z": 578,
          "x": 233,
          "ForgeCaps": {},
          "id": "minecraft:skull",
          "y": 161
        }
      }
    ]
  },
  "slices": [
    [
      "       lc       ",
      "      llhl  l   ",
      "       fal lllll",
      "       lhllllll ",
      "       fmlll    ",
      "       fh       ",
      "       fc       ",
      "       fh       ",
      "       fngbgcgig",
      "        eeeeeeee",
      "                ",
      "                ",
      "                ",
      "                ",
      "                ",
      "                "
    ],
    [
      "       lbjbcabz ",
      "       fciimmml ",
      "       fbmacball",
      "       facicbbil",
      "       fcciiijbm",
      "       fbaccjicb",
      "       fjbbijccb",
      "       fbibaiiia",
      "       fabbancbn",
      "        eeeeeeee",
      "                ",
      "                ",
      "                ",
      "                ",
      "                ",
      "                "
    ],
    [
      "        axІφІ   ",
      "       fnx    l ",
      "       fb     l ",
      "       fh    lll",
      "       fi   lllx",
      "       f    ll  ",
      "       fcΥlll  x",
      "       fh  ll   ",
      "       fcgagjgcg",
      "        eeeeeeee",
      "                ",
      "                ",
      "                ",
      "                ",
      "                ",
      "                "
    ],
    [
      "        cϯ      ",
      "       fcϯ      ",
      "       fbТ      ",
      "       f        ",
      "       fc    l  ",
      "       f    l   ",
      "       fb   l   ",
      "       f   lll  ",
      "       fbgcgigbg",
      "        eeeeeeee",
      "                ",
      "                ",
      "                ",
      "                ",
      "                ",
      "                "
    ],
    [
      "        b       ",
      "       fa       ",
      "       fm       ",
      "       fa       ",
      "       f        ",
      "       f        ",
      "       f    ll  ",
      "       fn  llll ",
      "       fcnaaaanc",
      "        eeeeeeee",
      "                ",
      "                ",
      "                ",
      "                ",
      "                ",
      "                "
    ],
    [
      "                ",
      "       f        ",
      "       f        ",
      "       f        ",
      "       f        ",
      "       f        ",
      "       f      l ",
      "       f    llll",
      "       fagagcgag",
      "        eeeeeeee",
      "                ",
      "                ",
      "                ",
      "                ",
      "                ",
      "                "
    ]
  ]
}