{
  "xsize": 16,
  "zsize": 16,
  "palette": {
    "palette": [
      {
        "char": " ",
        "block": "minecraft:air"
      },
      {
        "char": "c",
        "block": "minecraft:cracked_stone_bricks"
      },
      {
        "char": "h",
        "block": "minecraft:glass_pane[east\u003dfalse,north\u003dtrue,south\u003dtrue,waterlogged\u003dfalse,west\u003dfalse]"
      },
      {
        "char": "a",
        "block": "minecraft:mossy_cobblestone"
      },
      {
        "char": "d",
        "block": "minecraft:air"
      },
      {
        "char": "n",
        "block": "immersive_weathering:mossy_stone"
      },
      {
        "char": "m",
        "block": "minecraft:stone_bricks[weathering\u003dfalse]"
      },
      {
        "char": "b",
        "block": "minecraft:mossy_stone_bricks"
      },
      {
        "char": "g",
        "block": "minecraft:glass_pane[east\u003dtrue,north\u003dfalse,south\u003dfalse,waterlogged\u003dfalse,west\u003dtrue]"
      },
      {
        "char": "e",
        "block": "minecraft:air"
      },
      {
        "char": "z",
        "block": "minecraft:stone_slab[type\u003dbottom,waterlogged\u003dfalse,weathering\u003dfalse]"
      },
      {
        "char": "i",
        "block": "minecraft:cobblestone[weathering\u003dfalse]"
      },
      {
        "char": "j",
        "block": "minecraft:stone[weathering\u003dfalse]"
      },
      {
        "char": "y",
        "block": "minecraft:stone_slab[type\u003dtop,waterlogged\u003dfalse,weathering\u003dfalse]"
      },
      {
        "char": "ϒ",
        "block": "minecraft:hopper[enabled\u003dtrue,facing\u003ddown]",
        "tag": {
          "z": 583,
          "x": 246,
          "TransferCooldown": 0,
          "ForgeCaps": {},
          "id": "minecraft:hopper",
          "y": 142,
          "Items": []
        }
      },
      {
        "char": "υ",
        "block": "minecraft:activator_rail[powered\u003dfalse,shape\u003deast_west,waterlogged\u003dfalse]"
      },
      {
        "char": "ϓ",
        "block": "minecraft:cobweb"
      }
    ]
  },
  "slices": [
    [
      "        c       ",
      "        h       ",
      "        ad      ",
      "        hd      ",
      "        nd      ",
      "        hd      ",
      "        md      ",
      "        hd      ",
      "bgagagbgad      ",
      "ee  eeeee       ",
      "                ",
      "                ",
      "                ",
      "                ",
      "                ",
      "                "
    ],
    [
      "  zaiiaca       ",
      "   ajcibb       ",
      "    c baid      ",
      " y imbacad      ",
      " c  aaaaad      ",
      " jimjanccd      ",
      "bciacbcjcd      ",
      "bcbaimmmad      ",
      "nabmnanccd      ",
      "ee  eeeee       ",
      "                ",
      "                ",
      "                ",
      "                ",
      "                ",
      "                "
    ],
    [
      "        b       ",
      "        h       ",
      "        m       ",
      "        hd      ",
      "        jd      ",
      "        hd      ",
      "        md      ",
      "ϒϒϒ ϒϒϒ hd      ",
      "agbgcgagad      ",
      "ee  eeeee       ",
      "                ",
      "                ",
      "                ",
      "                ",
      "                ",
      "                "
    ],
    [
      "        i       ",
      "        h       ",
      "        a       ",
      "        hd      ",
      "        ad      ",
      "        hd      ",
      "        nd      ",
      "υυυ υυυ hd      ",
      "ngmgbgjgid      ",
      "ee  eeeee       ",
      "                ",
      "                ",
      "                ",
      "                ",
      "                ",
      "                "
    ],
    [
      "        b       ",
      "        m       ",
      "        a       ",
      "        nd      ",
      "        jd      ",
      "        bd      ",
      "        bd      ",
      "        jd      ",
      "iamicbbbbd      ",
      "ee  eeeee       ",
      "                ",
      "                ",
      "                ",
      "                ",
      "                ",
      "                "
    ],
    [
      "        i       ",
      "        h       ",
      "        m       ",
      "        hd      ",
      "        bd      ",
      "        hd      ",
      "        bd      ",
      "       ϓhd      ",
      "mgmgcgbgcd      ",
      "ee  eeeee       ",
      "                ",
      "                ",
      "                ",
      "                ",
      "                ",
      "                "
    ]
  ]
}