{
  "xsize": 16,
  "zsize": 16,
  "palette": {
    "palette": [
      {
        "char": " ",
        "block": "minecraft:air"
      },
      {
        "char": "f",
        "block": "minecraft:air"
      },
      {
        "char": "k",
        "block": "minecraft:air"
      },
      {
        "char": "a",
        "block": "minecraft:mossy_cobblestone"
      },
      {
        "char": "g",
        "block": "minecraft:glass_pane[east\u003dtrue,north\u003dfalse,south\u003dfalse,waterlogged\u003dfalse,west\u003dtrue]"
      },
      {
        "char": "m",
        "block": "minecraft:stone_bricks[weathering\u003dfalse]"
      },
      {
        "char": "c",
        "block": "minecraft:cracked_stone_bricks"
      },
      {
        "char": "d",
        "block": "minecraft:air"
      },
      {
        "char": "h",
        "block": "minecraft:glass_pane[east\u003dfalse,north\u003dtrue,south\u003dtrue,waterlogged\u003dfalse,west\u003dfalse]"
      },
      {
        "char": "i",
        "block": "minecraft:cobblestone[weathering\u003dfalse]"
      },
      {
        "char": "n",
        "block": "immersive_weathering:mossy_stone"
      },
      {
        "char": "b",
        "block": "minecraft:mossy_stone_bricks"
      },
      {
        "char": "j",
        "block": "minecraft:stone[weathering\u003dfalse]"
      },
      {
        "char": "y",
        "block": "minecraft:stone_slab[type\u003dtop,waterlogged\u003dfalse,weathering\u003dfalse]"
      },
      {
        "char": "ϰ",
        "block": "minecraft:spruce_trapdoor[facing\u003dnorth,half\u003dtop,open\u003dtrue,powered\u003dfalse,waterlogged\u003dfalse]"
      },
      {
        "char": "ϟ",
        "block": "minecraft:spruce_trapdoor[facing\u003dwest,half\u003dtop,open\u003dtrue,powered\u003dfalse,waterlogged\u003dfalse]"
      },
      {
        "char": "ϡ",
        "block": "minecraft:sand"
      },
      {
        "char": "ϱ",
        "block": "minecraft:spruce_trapdoor[facing\u003dsouth,half\u003dtop,open\u003dtrue,powered\u003dfalse,waterlogged\u003dfalse]"
      },
      {
        "char": "с",
        "block": "minecraft:spruce_trapdoor[facing\u003dnorth,half\u003dtop,open\u003dfalse,powered\u003dfalse,waterlogged\u003dfalse]"
      },
      {
        "char": "Ϟ",
        "block": "minecraft:spruce_trapdoor[facing\u003dwest,half\u003dtop,open\u003dfalse,powered\u003dfalse,waterlogged\u003dfalse]"
      },
      {
        "char": "Ϭ",
        "block": "minecraft:kelp[age\u003d0]"
      },
      {
        "char": "Ъ",
        "block": "minecraft:spruce_trapdoor[facing\u003dsouth,half\u003dtop,open\u003dfalse,powered\u003dfalse,waterlogged\u003dfalse]"
      },
      {
        "char": "ϥ",
        "block": "minecraft:spruce_trapdoor[facing\u003dwest,half\u003dbottom,open\u003dfalse,powered\u003dfalse,waterlogged\u003dfalse]"
      }
    ]
  },
  "slices": [
    [
      "                ",
      "                ",
      "                ",
      "                ",
      "                ",
      "                ",
      "fkkk            ",
      "k     kkk       ",
      "agmgmgagcd      ",
      "        hd      ",
      "        id      ",
      "        hd      ",
      "        ndd     ",
      "        hdd     ",
      "        m       ",
      "        h       "
    ],
    [
      "                ",
      "                ",
      "                ",
      "                ",
      "                ",
      "                ",
      "fkkk            ",
      "k      kk       ",
      "aibiccbcbd      ",
      "abcijabcbd      ",
      "bjabbaacbd      ",
      " j bccbnad      ",
      "  maccbccdd     ",
      " ybjcaajbdd     ",
      "     bnai       ",
      "   ibijnj       "
    ],
    [
      "                ",
      "                ",
      "                ",
      "                ",
      "                ",
      "                ",
      "fkkk            ",
      "k       k       ",
      "bgmgigigjd      ",
      "       ϰhd      ",
      "      ϟϡid      ",
      "      ϟϡad      ",
      "      ϟϡbdd     ",
      "       ϱhdd     ",
      "        b       ",
      "        h       "
    ],
    [
      "                ",
      "                ",
      "                ",
      "                ",
      "                ",
      "                ",
      "fkkk            ",
      "k       k       ",
      "bgagjgjgad      ",
      "       сhd      ",
      "      ϞϬad      ",
      "      ϞϬjd      ",
      "      ϞϬbdd     ",
      "       Ъhdd     ",
      "        m       ",
      "        h       "
    ],
    [
      "                ",
      "                ",
      "                ",
      "                ",
      "                ",
      "                ",
      "fkkk            ",
      "k       k       ",
      "cmiiaiaijd      ",
      "        ad      ",
      "       ϥad      ",
      "       ϥ d      ",
      "       ϥadd     ",
      "        mdd     ",
      "        b       ",
      "        b       "
    ],
    [
      "                ",
      "                ",
      "                ",
      "                ",
      "                ",
      "                ",
      "fkkk            ",
      "k       k       ",
      "igbgmgmgcd      ",
      "        hd      ",
      "        bd      ",
      "        hd      ",
      "        cdd     ",
      "        hdd     ",
      "        b       ",
      "        h       "
    ]
  ]
}