{
  "xsize": 16,
  "zsize": 16,
  "palette": {
    "palette": [
      {
        "char": " ",
        "block": "minecraft:air"
      },
      {
        "char": "f",
        "block": "minecraft:air"
      },
      {
        "char": "k",
        "block": "minecraft:air"
      },
      {
        "char": "a",
        "block": "minecraft:mossy_cobblestone"
      },
      {
        "char": "g",
        "block": "minecraft:glass_pane[east\u003dtrue,north\u003dfalse,south\u003dfalse,waterlogged\u003dfalse,west\u003dtrue]"
      },
      {
        "char": "i",
        "block": "minecraft:cobblestone[weathering\u003dfalse]"
      },
      {
        "char": "b",
        "block": "minecraft:mossy_stone_bricks"
      },
      {
        "char": "d",
        "block": "minecraft:air"
      },
      {
        "char": "h",
        "block": "minecraft:glass_pane[east\u003dfalse,north\u003dtrue,south\u003dtrue,waterlogged\u003dfalse,west\u003dfalse]"
      },
      {
        "char": "m",
        "block": "minecraft:stone_bricks[weathering\u003dfalse]"
      },
      {
        "char": "c",
        "block": "minecraft:cracked_stone_bricks"
      },
      {
        "char": "l",
        "block": "minecraft:air"
      },
      {
        "char": "j",
        "block": "minecraft:stone[weathering\u003dfalse]"
      },
      {
        "char": "n",
        "block": "immersive_weathering:mossy_stone"
      },
      {
        "char": "y",
        "block": "minecraft:stone_slab[type\u003dtop,waterlogged\u003dfalse,weathering\u003dfalse]"
      },
      {
        "char": "Δ",
        "block": "minecraft:glass_pane[east\u003dtrue,north\u003dfalse,south\u003dtrue,waterlogged\u003dfalse,west\u003dtrue]"
      },
      {
        "char": "J",
        "block": "minecraft:green_wool"
      },
      {
        "char": "μ",
        "block": "minecraft:glass_pane[east\u003dfalse,north\u003dtrue,south\u003dtrue,waterlogged\u003dfalse,west\u003dtrue]"
      },
      {
        "char": "ϊ",
        "block": "minecraft:spruce_trapdoor[facing\u003dnorth,half\u003dbottom,open\u003dtrue,powered\u003dfalse,waterlogged\u003dfalse]"
      }
    ]
  },
  "slices": [
    [
      "                ",
      "                ",
      "                ",
      "                ",
      "                ",
      "                ",
      "fkkk            ",
      "                ",
      "agigbgigid      ",
      "        hd      ",
      "        md      ",
      "        hd      ",
      "        cdd     ",
      "        hdd     ",
      "   l l  b       ",
      "  lllll h       "
    ],
    [
      "                ",
      "                ",
      "                ",
      "                ",
      "                ",
      "                ",
      "fkkk            ",
      "                ",
      "aiciajacad      ",
      "mbajcbacad      ",
      "mbnabcibad      ",
      "acacjicccd      ",
      "ccjcaajiadd     ",
      "yy cajciadd     ",
      "   ycaacn       ",
      " llliiaac       "
    ],
    [
      "                ",
      "                ",
      "                ",
      "                ",
      "                ",
      "                ",
      "fkkk            ",
      "                ",
      "bgcΔiΔiΔcd      ",
      "  JJJJJJμd      ",
      "  J    Jcd      ",
      "       Jμd      ",
      "       Jidd     ",
      "      JJμdd     ",
      "   l    j       ",
      "  llϊϊϊ h       "
    ],
    [
      "                ",
      "                ",
      "                ",
      "                ",
      "                ",
      "                ",
      "fkkk            ",
      "                ",
      "agmgmgbgmd      ",
      "        hd      ",
      "        bd      ",
      "        hd      ",
      "        add     ",
      "        hdd     ",
      "  ll    b       ",
      " lll    h       "
    ],
    [
      "                ",
      "                ",
      "                ",
      "                ",
      "                ",
      "                ",
      "fkkk            ",
      "                ",
      "ncbijmimnd      ",
      "        ad      ",
      "        bd      ",
      "        nd      ",
      "        jdd     ",
      "        add     ",
      " ll     n       ",
      " ll     b       "
    ],
    [
      "                ",
      "                ",
      "                ",
      "                ",
      "                ",
      "                ",
      "fkkk            ",
      "                ",
      "agcgagcgbd      ",
      "        hd      ",
      "        bd      ",
      "        hd      ",
      "        bdd     ",
      "        hdd     ",
      "  l     c       ",
      " lll    h       "
    ]
  ]
}