{
  "xsize": 16,
  "zsize": 16,
  "palette": {
    "palette": [
      {
        "char": " ",
        "block": "minecraft:air"
      },
      {
        "char": "a",
        "block": "minecraft:mossy_cobblestone"
      },
      {
        "char": "h",
        "block": "minecraft:glass_pane[east\u003dfalse,north\u003dtrue,south\u003dtrue,waterlogged\u003dfalse,west\u003dfalse]"
      },
      {
        "char": "i",
        "block": "minecraft:cobblestone[weathering\u003dfalse]"
      },
      {
        "char": "n",
        "block": "immersive_weathering:mossy_stone"
      },
      {
        "char": "d",
        "block": "minecraft:air"
      },
      {
        "char": "b",
        "block": "minecraft:mossy_stone_bricks"
      },
      {
        "char": "g",
        "block": "minecraft:glass_pane[east\u003dtrue,north\u003dfalse,south\u003dfalse,waterlogged\u003dfalse,west\u003dtrue]"
      },
      {
        "char": "m",
        "block": "minecraft:stone_bricks[weathering\u003dfalse]"
      },
      {
        "char": "e",
        "block": "minecraft:air"
      },
      {
        "char": "j",
        "block": "minecraft:stone[weathering\u003dfalse]"
      },
      {
        "char": "c",
        "block": "minecraft:cracked_stone_bricks"
      },
      {
        "char": "Θ",
        "block": "immersive_weathering:mossy_stone_slab[type\u003dbottom,waterlogged\u003dfalse]"
      },
      {
        "char": "Γ",
        "block": "immersive_weathering:mossy_stone_slab[type\u003dtop,waterlogged\u003dfalse]"
      },
      {
        "char": "v",
        "block": "minecraft:light_gray_concrete"
      },
      {
        "char": "Ϳ",
        "block": "minecraft:birch_slab[type\u003dtop,waterlogged\u003dfalse]"
      },
      {
        "char": "Ϛ",
        "block": "minecraft:spruce_stairs[facing\u003dnorth,half\u003dtop,shape\u003dstraight,waterlogged\u003dfalse]"
      },
      {
        "char": "C",
        "block": "minecraft:spruce_slab[type\u003dtop,waterlogged\u003dfalse]"
      },
      {
        "char": "ϔ",
        "block": "minecraft:oak_stairs[facing\u003deast,half\u003dbottom,shape\u003dstraight,waterlogged\u003dfalse]"
      },
      {
        "char": "Ѓ",
        "block": "minecraft:spruce_stairs[facing\u003dsouth,half\u003dbottom,shape\u003douter_right,waterlogged\u003dfalse]"
      },
      {
        "char": "ϙ",
        "block": "minecraft:spruce_stairs[facing\u003dsouth,half\u003dtop,shape\u003dstraight,waterlogged\u003dfalse]"
      },
      {
        "char": "Ϯ",
        "block": "minecraft:spruce_stairs[facing\u003dwest,half\u003dbottom,shape\u003dstraight,waterlogged\u003dfalse]"
      },
      {
        "char": "Г",
        "block": "minecraft:spruce_stairs[facing\u003dsouth,half\u003dbottom,shape\u003dinner_right,waterlogged\u003dfalse]"
      },
      {
        "char": "ϛ",
        "block": "minecraft:spruce_stairs[facing\u003dsouth,half\u003dbottom,shape\u003dstraight,waterlogged\u003dfalse]"
      },
      {
        "char": "Ђ",
        "block": "minecraft:spruce_stairs[facing\u003dwest,half\u003dbottom,shape\u003douter_left,waterlogged\u003dfalse]"
      },
      {
        "char": "Φ",
        "block": "minecraft:glass_pane[east\u003dtrue,north\u003dtrue,south\u003dfalse,waterlogged\u003dfalse,west\u003dtrue]"
      },
      {
        "char": "ϫ",
        "block": "minecraft:flower_pot"
      },
      {
        "char": "Ψ",
        "block": "minecraft:heavy_weighted_pressure_plate[power\u003d0]"
      }
    ]
  },
  "slices": [
    [
      "        a       ",
      "        h       ",
      "        i       ",
      "        h       ",
      "        nd      ",
      "        hd      ",
      "        bd      ",
      "        hd      ",
      "ngagigmgbd      ",
      "ee     ee       ",
      "                ",
      "                ",
      "                ",
      "                ",
      "                ",
      "                "
    ],
    [
      "   bjcabc       ",
      "   bjcbcj       ",
      "  Θccbjba       ",
      " Γbiabajj       ",
      "jcajinbabd      ",
      "bbijbaicbd      ",
      "aaniabjbad      ",
      "jccaibaaad      ",
      "ncbaciabad      ",
      "ee     ee       ",
      "                ",
      "                ",
      "                ",
      "                ",
      "                ",
      "                "
    ],
    [
      "   vvvvvc       ",
      "    ͿͿ  h       ",
      "        b       ",
      "     Ϛ  h       ",
      "v    Cϔ bd      ",
      "vЃ   ϙ  hd      ",
      "vϮ      md      ",
      "vГϛЂ    hd      ",
      "aΦbgcgagad      ",
      "ee     ee       ",
      "                ",
      "                ",
      "                ",
      "                ",
      "                ",
      "                "
    ],
    [
      "    vvvvb       ",
      "    ϫ   h       ",
      "        b       ",
      "        h       ",
      "     Ψ  b       ",
      "v       hd      ",
      "v       cd      ",
      "v       hd      ",
      "mgmgagbgcd      ",
      "ee     ee       ",
      "                ",
      "                ",
      "                ",
      "                ",
      "                ",
      "                "
    ],
    [
      "        a       ",
      "        b       ",
      "        c       ",
      "        a       ",
      "        n       ",
      "        bd      ",
      "        ad      ",
      "        cd      ",
      "jcbbbjibjd      ",
      "ee     ee       ",
      "                ",
      "                ",
      "                ",
      "                ",
      "                ",
      "                "
    ],
    [
      "        c       ",
      "        h       ",
      "        m       ",
      "        h       ",
      "        i       ",
      "        hd      ",
      "        id      ",
      "        hd      ",
      "jgjgagjgad      ",
      "ee     ee       ",
      "                ",
      "                ",
      "                ",
      "                ",
      "                ",
      "                "
    ]
  ]
}