{
  "xsize": 16,
  "zsize": 16,
  "palette": {
    "palette": [
      {
        "char": " ",
        "block": "minecraft:air"
      },
      {
        "char": "l",
        "block": "minecraft:air"
      },
      {
        "char": "b",
        "block": "minecraft:mossy_stone_bricks"
      },
      {
        "char": "h",
        "block": "minecraft:glass_pane[east\u003dfalse,north\u003dtrue,south\u003dtrue,waterlogged\u003dfalse,west\u003dfalse]"
      },
      {
        "char": "f",
        "block": "minecraft:air"
      },
      {
        "char": "n",
        "block": "immersive_weathering:mossy_stone"
      },
      {
        "char": "a",
        "block": "minecraft:mossy_cobblestone"
      },
      {
        "char": "m",
        "block": "minecraft:stone_bricks[weathering\u003dfalse]"
      },
      {
        "char": "g",
        "block": "minecraft:glass_pane[east\u003dtrue,north\u003dfalse,south\u003dfalse,waterlogged\u003dfalse,west\u003dtrue]"
      },
      {
        "char": "j",
        "block": "minecraft:stone[weathering\u003dfalse]"
      },
      {
        "char": "i",
        "block": "minecraft:cobblestone[weathering\u003dfalse]"
      },
      {
        "char": "c",
        "block": "minecraft:cracked_stone_bricks"
      },
      {
        "char": "e",
        "block": "minecraft:air"
      },
      {
        "char": "y",
        "block": "minecraft:stone_slab[type\u003dtop,waterlogged\u003dfalse,weathering\u003dfalse]"
      },
      {
        "char": "v",
        "block": "minecraft:light_gray_concrete"
      },
      {
        "char": "ϩ",
        "block": "minecraft:spruce_stairs[facing\u003dnorth,half\u003dbottom,shape\u003dstraight,waterlogged\u003dfalse]"
      },
      {
        "char": "Ι",
        "block": "minecraft:air"
      },
      {
        "char": "Ϳ",
        "block": "minecraft:birch_slab[type\u003dtop,waterlogged\u003dfalse]"
      },
      {
        "char": ";",
        "block": "minecraft:spruce_stairs[facing\u003dwest,half\u003dtop,shape\u003dstraight,waterlogged\u003dfalse]"
      },
      {
        "char": "C",
        "block": "minecraft:spruce_slab[type\u003dtop,waterlogged\u003dfalse]"
      },
      {
        "char": "ͼ",
        "block": "minecraft:spruce_stairs[facing\u003deast,half\u003dtop,shape\u003dstraight,waterlogged\u003dfalse]"
      },
      {
        "char": "χ",
        "block": "minecraft:oak_stairs[facing\u003dsouth,half\u003dbottom,shape\u003dstraight,waterlogged\u003dfalse]"
      },
      {
        "char": "Ψ",
        "block": "minecraft:heavy_weighted_pressure_plate[power\u003d0]"
      }
    ]
  },
  "slices": [
    [
      "       lb       ",
      "       lh       ",
      "       fn       ",
      "       fh       ",
      "       fb       ",
      "       fh       ",
      "       fa       ",
      "       fh       ",
      "       fmgjgigcg",
      "        eeeeeeee",
      "                ",
      "                ",
      "                ",
      "                ",
      "                ",
      "                "
    ],
    [
      "       lmnbai   ",
      "       lcammb   ",
      "       fbajai y ",
      "       fnjmbabjb",
      "       faiiacabc",
      "       fmbjcbcbi",
      "       fnacaaanb",
      "       faamcbnjc",
      "       facibaaac",
      "        eeeeeeee",
      "                ",
      "                ",
      "                ",
      "                ",
      "                ",
      "                "
    ],
    [
      "       lilvvv   ",
      "       lhϩ ϩ    ",
      "       Ιb       ",
      "        h       ",
      "       fb      Ϳ",
      "       fh  ;Cͼ  ",
      "       fa   χ   ",
      "       fh       ",
      "       fagbgjgag",
      "        eeeeeeee",
      "                ",
      "                ",
      "                ",
      "                ",
      "                ",
      "                "
    ],
    [
      "        mlvv    ",
      "       lhl      ",
      "       lc       ",
      "        h       ",
      "       fc       ",
      "       fh   Ψ   ",
      "       fa       ",
      "       fh       ",
      "       fagbgbgjg",
      "        eeeeeeee",
      "                ",
      "                ",
      "                ",
      "                ",
      "                ",
      "                "
    ],
    [
      "        il      ",
      "       Ιbl      ",
      "       lnl      ",
      "       lm       ",
      "       fn       ",
      "       fi       ",
      "       fa       ",
      "       fm       ",
      "       fbcjaaabb",
      "        eeeeeeee",
      "                ",
      "                ",
      "                ",
      "                ",
      "                ",
      "                "
    ],
    [
      "        al      ",
      "       lhll     ",
      "       lcll   l ",
      "       lhl l    ",
      "       fi       ",
      "       fh       ",
      "       fm       ",
      "       fh       ",
      "       fjgbgcgag",
      "        eeeeeeee",
      "                ",
      "                ",
      "                ",
      "                ",
      "                ",
      "                "
    ]
  ]
}