{
  "xsize": 16,
  "zsize": 16,
  "palette": {
    "palette": [
      {
        "char": " ",
        "block": "minecraft:air"
      },
      {
        "char": "a",
        "block": "minecraft:mossy_cobblestone"
      },
      {
        "char": "f",
        "block": "minecraft:air"
      },
      {
        "char": "h",
        "block": "minecraft:glass_pane[east\u003dfalse,north\u003dtrue,south\u003dtrue,waterlogged\u003dfalse,west\u003dfalse]"
      },
      {
        "char": "Q",
        "block": "minecraft:oak_fence[east\u003dfalse,north\u003dfalse,south\u003dfalse,waterlogged\u003dfalse,west\u003dfalse]"
      },
      {
        "char": "i",
        "block": "minecraft:cobblestone[weathering\u003dfalse]"
      },
      {
        "char": "c",
        "block": "minecraft:cracked_stone_bricks"
      },
      {
        "char": "m",
        "block": "minecraft:stone_bricks[weathering\u003dfalse]"
      },
      {
        "char": "g",
        "block": "minecraft:glass_pane[east\u003dtrue,north\u003dfalse,south\u003dfalse,waterlogged\u003dfalse,west\u003dtrue]"
      },
      {
        "char": "b",
        "block": "minecraft:mossy_stone_bricks"
      },
      {
        "char": "e",
        "block": "minecraft:air"
      },
      {
        "char": "j",
        "block": "minecraft:stone[weathering\u003dfalse]"
      },
      {
        "char": "y",
        "block": "minecraft:stone_slab[type\u003dtop,waterlogged\u003dfalse,weathering\u003dfalse]"
      },
      {
        "char": "n",
        "block": "immersive_weathering:mossy_stone"
      },
      {
        "char": "A",
        "block": "minecraft:terracotta"
      },
      {
        "char": "σ",
        "block": "minecraft:oak_wall_sign[facing\u003dwest,waterlogged\u003dfalse]",
        "tag": {
          "z": 581,
          "x": 242,
          "is_waxed": "0b",
          "ForgeCaps": {
            "supplementaries:antique_ink": {
              "ink": "0b"
            }
          },
          "id": "minecraft:sign",
          "y": 184,
          "front_text": {
            "color": "black",
            "has_glowing_text": "0b",
            "messages": [
              "{\"text\":\"\"}",
              "{\"text\":\"\"}",
              "{\"text\":\"\"}",
              "{\"text\":\"\"}"
            ]
          },
          "back_text": {
            "color": "black",
            "has_glowing_text": "0b",
            "messages": [
              "{\"text\":\"\"}",
              "{\"text\":\"\"}",
              "{\"text\":\"\"}",
              "{\"text\":\"\"}"
            ]
          }
        }
      },
      {
        "char": "Ζ",
        "block": "minecraft:smooth_stone_slab[type\u003dbottom,waterlogged\u003dfalse]"
      },
      {
        "char": "x",
        "block": "minecraft:light_gray_carpet"
      },
      {
        "char": "ϝ",
        "block": "minecraft:glass_pane[east\u003dfalse,north\u003dtrue,south\u003dfalse,waterlogged\u003dfalse,west\u003dfalse]"
      },
      {
        "char": "λ",
        "block": "minecraft:glass_pane[east\u003dtrue,north\u003dfalse,south\u003dfalse,waterlogged\u003dfalse,west\u003dfalse]"
      }
    ]
  },
  "slices": [
    [
      "        a       ",
      "       fh  Q    ",
      "       fi       ",
      "       fh       ",
      "       fa       ",
      "       fh  Q    ",
      "       fc       ",
      "                ",
      "        mgagbgbg",
      "        eeeeeeee",
      "                ",
      "                ",
      "                ",
      "                ",
      "                ",
      "                "
    ],
    [
      "        jccaayy ",
      "       fnbacb   ",
      "       fcibcby  ",
      "       fnnbaccyy",
      "       fbbabbacc",
      "       faaciaban",
      "       f  biicaj",
      "          njbcjc",
      "         jbmiccc",
      "        eeeeeeee",
      "                ",
      "                ",
      "                ",
      "                ",
      "                ",
      "                "
    ],
    [
      "        m   A   ",
      "       fh σΖA   ",
      "       fa   A   ",
      "       fhx      ",
      "       fn  xAx  ",
      "       f  σΖA σΖ",
      "       f    A   ",
      "             x  ",
      "          cgngbg",
      "        eeeeee  ",
      "                ",
      "                ",
      "                ",
      "                ",
      "                ",
      "                "
    ],
    [
      "        b       ",
      "       fh       ",
      "       fc       ",
      "       fh       ",
      "       fc       ",
      "       f        ",
      "       f        ",
      "                ",
      "          agbgig",
      "        eeeeee  ",
      "                ",
      "                ",
      "                ",
      "                ",
      "                ",
      "                "
    ],
    [
      "        i       ",
      "       fa       ",
      "       fi       ",
      "       fb       ",
      "       f        ",
      "       f        ",
      "       f        ",
      "                ",
      "          biacib",
      "        eeeeee  ",
      "                ",
      "                ",
      "                ",
      "                ",
      "                ",
      "                "
    ],
    [
      "        m       ",
      "       fh       ",
      "       fc       ",
      "       fϝ       ",
      "       f        ",
      "       f        ",
      "       f        ",
      "                ",
      "           λcgcg",
      "        eeeeee  ",
      "                ",
      "                ",
      "                ",
      "                ",
      "                ",
      "                "
    ]
  ]
}