{
  "xsize": 16,
  "zsize": 16,
  "palette": {
    "palette": [
      {
        "char": " ",
        "block": "minecraft:air"
      },
      {
        "char": "f",
        "block": "minecraft:air"
      },
      {
        "char": "k",
        "block": "minecraft:air"
      },
      {
        "char": "a",
        "block": "minecraft:mossy_cobblestone"
      },
      {
        "char": "g",
        "block": "minecraft:glass_pane[east\u003dtrue,north\u003dfalse,south\u003dfalse,waterlogged\u003dfalse,west\u003dtrue]"
      },
      {
        "char": "b",
        "block": "minecraft:mossy_stone_bricks"
      },
      {
        "char": "c",
        "block": "minecraft:cracked_stone_bricks"
      },
      {
        "char": "d",
        "block": "minecraft:air"
      },
      {
        "char": "h",
        "block": "minecraft:glass_pane[east\u003dfalse,north\u003dtrue,south\u003dtrue,waterlogged\u003dfalse,west\u003dfalse]"
      },
      {
        "char": "Q",
        "block": "minecraft:oak_fence[east\u003dfalse,north\u003dfalse,south\u003dfalse,waterlogged\u003dfalse,west\u003dfalse]"
      },
      {
        "char": "m",
        "block": "minecraft:stone_bricks[weathering\u003dfalse]"
      },
      {
        "char": "n",
        "block": "immersive_weathering:mossy_stone"
      },
      {
        "char": "j",
        "block": "minecraft:stone[weathering\u003dfalse]"
      },
      {
        "char": "i",
        "block": "minecraft:cobblestone[weathering\u003dfalse]"
      },
      {
        "char": "z",
        "block": "minecraft:stone_slab[type\u003dbottom,waterlogged\u003dfalse,weathering\u003dfalse]"
      },
      {
        "char": "y",
        "block": "minecraft:stone_slab[type\u003dtop,waterlogged\u003dfalse,weathering\u003dfalse]"
      },
      {
        "char": "H",
        "block": "minecraft:spruce_trapdoor[facing\u003dwest,half\u003dbottom,open\u003dtrue,powered\u003dfalse,waterlogged\u003dfalse]"
      },
      {
        "char": "ͺ",
        "block": "minecraft:chest[facing\u003dsouth,type\u003dright,waterlogged\u003dfalse]",
        "loot": "bigbuildingsloot",
        "tag": {
          "z": 578,
          "x": 245,
          "ForgeCaps": {},
          "id": "minecraft:chest",
          "y": 166,
          "Items": []
        }
      },
      {
        "char": "4",
        "block": "minecraft:chest[facing\u003dsouth,type\u003dleft,waterlogged\u003dfalse]",
        "loot": "bigbuildingsloot",
        "tag": {
          "z": 582,
          "x": 246,
          "ForgeCaps": {},
          "id": "minecraft:chest",
          "y": 167,
          "Items": []
        }
      },
      {
        "char": "F",
        "block": "minecraft:spruce_trapdoor[facing\u003deast,half\u003dbottom,open\u003dtrue,powered\u003dfalse,waterlogged\u003dfalse]"
      },
      {
        "char": "ͻ",
        "block": "minecraft:spruce_trapdoor[facing\u003dsouth,half\u003dbottom,open\u003dfalse,powered\u003dfalse,waterlogged\u003dfalse]"
      }
    ]
  },
  "slices": [
    [
      "                ",
      "                ",
      "                ",
      "                ",
      "                ",
      "                ",
      "fkkk            ",
      "k               ",
      "agagbgagcd      ",
      "        hd      ",
      "        bd      ",
      "        hd      ",
      "        bdd     ",
      "      Q hdd     ",
      "        m       ",
      "      Q h       "
    ],
    [
      "                ",
      "                ",
      "                ",
      "                ",
      "                ",
      "                ",
      "fkkk            ",
      "                ",
      "ccbcmbnjnd      ",
      "niaijbabad      ",
      "bbacjabmbd      ",
      "jncjcbccid      ",
      "cbiicabccdd     ",
      "  zbmcamadd     ",
      "    cciii       ",
      "   yjcbcc       "
    ],
    [
      "                ",
      "                ",
      "                ",
      "                ",
      "                ",
      "                ",
      "fkkk            ",
      "                ",
      "igagcgagmd      ",
      "        hd      ",
      "    Hͺ4Fid      ",
      "        hd      ",
      "    Hͺ4Fbdd     ",
      "        hdd     ",
      "    Hͺ4Fi       ",
      "        h       "
    ],
    [
      "                ",
      "                ",
      "                ",
      "                ",
      "                ",
      "                ",
      "fkkk            ",
      "                ",
      "igagagagad      ",
      "        hd      ",
      "    Hͺ4Fbd      ",
      "        hd      ",
      "    Hͺ4Fndd     ",
      "        hdd     ",
      "    Hͺ4Fb       ",
      "        h       "
    ],
    [
      "                ",
      "                ",
      "                ",
      "                ",
      "                ",
      "                ",
      "fkkk            ",
      "                ",
      "amjammjjid      ",
      "        cd      ",
      "     ͻͻ nd      ",
      "        bd      ",
      "     ͻͻ idd     ",
      "        bdd     ",
      "     ͻͻ n       ",
      "        i       "
    ],
    [
      "                ",
      "                ",
      "                ",
      "                ",
      "                ",
      "                ",
      "fkkk            ",
      "                ",
      "jgbgbgigbd      ",
      "        hd      ",
      "        bd      ",
      "        hd      ",
      "        bdd     ",
      "        hdd     ",
      "        i       ",
      "        h       "
    ]
  ]
}