{
  "xsize": 16,
  "zsize": 16,
  "palette": {
    "palette": [
      {
        "char": " ",
        "block": "minecraft:air"
      },
      {
        "char": "f",
        "block": "minecraft:air"
      },
      {
        "char": "k",
        "block": "minecraft:air"
      },
      {
        "char": "c",
        "block": "minecraft:cracked_stone_bricks"
      },
      {
        "char": "g",
        "block": "minecraft:glass_pane[east\u003dtrue,north\u003dfalse,south\u003dfalse,waterlogged\u003dfalse,west\u003dtrue]"
      },
      {
        "char": "i",
        "block": "minecraft:cobblestone[weathering\u003dfalse]"
      },
      {
        "char": "a",
        "block": "minecraft:mossy_cobblestone"
      },
      {
        "char": "m",
        "block": "minecraft:stone_bricks[weathering\u003dfalse]"
      },
      {
        "char": "d",
        "block": "minecraft:air"
      },
      {
        "char": "h",
        "block": "minecraft:glass_pane[east\u003dfalse,north\u003dtrue,south\u003dtrue,waterlogged\u003dfalse,west\u003dfalse]"
      },
      {
        "char": "j",
        "block": "minecraft:stone[weathering\u003dfalse]"
      },
      {
        "char": "b",
        "block": "minecraft:mossy_stone_bricks"
      },
      {
        "char": "n",
        "block": "immersive_weathering:mossy_stone"
      },
      {
        "char": "z",
        "block": "minecraft:stone_slab[type\u003dbottom,waterlogged\u003dfalse,weathering\u003dfalse]"
      },
      {
        "char": "E",
        "block": "minecraft:redstone_lamp[lit\u003dfalse]"
      },
      {
        "char": "Ζ",
        "block": "minecraft:smooth_stone_slab[type\u003dbottom,waterlogged\u003dfalse]"
      },
      {
        "char": "ϭ",
        "block": "immersive_weathering:exposed_iron_bars[east\u003dfalse,north\u003dfalse,south\u003dtrue,waterlogged\u003dfalse,west\u003dtrue]"
      },
      {
        "char": "Ϣ",
        "block": "immersive_weathering:exposed_iron_bars[east\u003dtrue,north\u003dfalse,south\u003dtrue,waterlogged\u003dfalse,west\u003dfalse]"
      },
      {
        "char": "Ε",
        "block": "minecraft:quartz_pillar[axis\u003dy]"
      },
      {
        "char": "ϋ",
        "block": "immersive_weathering:exposed_iron_bars[east\u003dfalse,north\u003dtrue,south\u003dfalse,waterlogged\u003dfalse,west\u003dfalse]"
      },
      {
        "char": "ω",
        "block": "minecraft:red_wool"
      },
      {
        "char": "Ϧ",
        "block": "minecraft:stone_pressure_plate[powered\u003dfalse]"
      },
      {
        "char": "Q",
        "block": "minecraft:oak_fence[east\u003dfalse,north\u003dfalse,south\u003dfalse,waterlogged\u003dfalse,west\u003dfalse]"
      }
    ]
  },
  "slices": [
    [
      "                ",
      "                ",
      "                ",
      "                ",
      "                ",
      "                ",
      "fkkk            ",
      "k               ",
      "cgcgigagmd      ",
      "        hd      ",
      "        ad      ",
      "        hd      ",
      "        cdd     ",
      "        hdd     ",
      "        j       ",
      "        h       "
    ],
    [
      "                ",
      "                ",
      "                ",
      "                ",
      "                ",
      "                ",
      "fkkk            ",
      "k               ",
      "cjccibncbd      ",
      "jiicbjmcbd      ",
      "mabacjiijd      ",
      "cjcjcijabd      ",
      "cjjcjmibadd     ",
      " c mabijjdd     ",
      "   zcabma       ",
      "    iibii       "
    ],
    [
      "                ",
      "                ",
      "                ",
      "                ",
      "                ",
      "                ",
      "fkkk            ",
      "k               ",
      "agcgbgbgcd      ",
      "        hd      ",
      "   E    bd      ",
      "   E    hd      ",
      "   E    jdd     ",
      "   Ζ    hdd     ",
      "        b       ",
      "        h       "
    ],
    [
      "                ",
      "                ",
      "                ",
      "                ",
      "                ",
      "                ",
      "fkkk            ",
      "k               ",
      "mgcgigagad      ",
      "        hd      ",
      "ϭ ϢΕϭ   bd      ",
      "ϋ ϋ ϋ   hd      ",
      "        ndd     ",
      "      ω hdd     ",
      "        a       ",
      "      ω h       "
    ],
    [
      "                ",
      "                ",
      "                ",
      "                ",
      "                ",
      "                ",
      "fkkk            ",
      "k               ",
      "nmaamacimd      ",
      "        ad      ",
      "   Ϧ    cd      ",
      "        bd      ",
      "        idd     ",
      "      ω add     ",
      "        b       ",
      "      ω a       "
    ],
    [
      "                ",
      "                ",
      "                ",
      "                ",
      "                ",
      "                ",
      "fkkk            ",
      "k               ",
      "agjgigcgjd      ",
      "        hd      ",
      "        id      ",
      "        hd      ",
      "        ndd     ",
      "      Q hdd     ",
      "        a       ",
      "      Q h       "
    ]
  ]
}