{
  "xsize": 16,
  "zsize": 16,
  "palette": {
    "palette": [
      {
        "char": " ",
        "block": "minecraft:air"
      },
      {
        "char": "k",
        "block": "minecraft:air"
      },
      {
        "char": "f",
        "block": "minecraft:air"
      },
      {
        "char": "b",
        "block": "minecraft:mossy_stone_bricks"
      },
      {
        "char": "g",
        "block": "minecraft:glass_pane[east\u003dtrue,north\u003dfalse,south\u003dfalse,waterlogged\u003dfalse,west\u003dtrue]"
      },
      {
        "char": "a",
        "block": "minecraft:mossy_cobblestone"
      },
      {
        "char": "h",
        "block": "minecraft:glass_pane[east\u003dfalse,north\u003dtrue,south\u003dtrue,waterlogged\u003dfalse,west\u003dfalse]"
      },
      {
        "char": "j",
        "block": "minecraft:stone[weathering\u003dfalse]"
      },
      {
        "char": "m",
        "block": "minecraft:stone_bricks[weathering\u003dfalse]"
      },
      {
        "char": "c",
        "block": "minecraft:cracked_stone_bricks"
      },
      {
        "char": "n",
        "block": "immersive_weathering:mossy_stone"
      },
      {
        "char": "i",
        "block": "minecraft:cobblestone[weathering\u003dfalse]"
      },
      {
        "char": "Γ",
        "block": "immersive_weathering:mossy_stone_slab[type\u003dtop,waterlogged\u003dfalse]"
      },
      {
        "char": "Δ",
        "block": "minecraft:glass_pane[east\u003dtrue,north\u003dfalse,south\u003dtrue,waterlogged\u003dfalse,west\u003dtrue]"
      },
      {
        "char": "Я",
        "block": "minecraft:spruce_stairs[facing\u003deast,half\u003dbottom,shape\u003douter_left,waterlogged\u003dfalse]"
      },
      {
        "char": "Ϡ",
        "block": "minecraft:spruce_stairs[facing\u003dnorth,half\u003dbottom,shape\u003dinner_right,waterlogged\u003dfalse]"
      },
      {
        "char": "Ј",
        "block": "minecraft:spruce_stairs[facing\u003deast,half\u003dbottom,shape\u003dstraight,waterlogged\u003dfalse]"
      },
      {
        "char": "Ϛ",
        "block": "minecraft:spruce_stairs[facing\u003dnorth,half\u003dtop,shape\u003dstraight,waterlogged\u003dfalse]"
      },
      {
        "char": "в",
        "block": "minecraft:spruce_stairs[facing\u003dnorth,half\u003dbottom,shape\u003douter_right,waterlogged\u003dfalse]"
      },
      {
        "char": "Χ",
        "block": "minecraft:oak_stairs[facing\u003dwest,half\u003dbottom,shape\u003dstraight,waterlogged\u003dfalse]"
      },
      {
        "char": "C",
        "block": "minecraft:spruce_slab[type\u003dtop,waterlogged\u003dfalse]"
      },
      {
        "char": "ϙ",
        "block": "minecraft:spruce_stairs[facing\u003dsouth,half\u003dtop,shape\u003dstraight,waterlogged\u003dfalse]"
      },
      {
        "char": "Ϳ",
        "block": "minecraft:birch_slab[type\u003dtop,waterlogged\u003dfalse]"
      },
      {
        "char": "Ψ",
        "block": "minecraft:heavy_weighted_pressure_plate[power\u003d0]"
      },
      {
        "char": "ϳ",
        "block": "minecraft:potted_wither_rose"
      }
    ]
  },
  "slices": [
    [
      "                ",
      "                ",
      "                ",
      "                ",
      "                ",
      "                ",
      "              k ",
      "          kkkkk ",
      "       fbgagbgag",
      "       fh       ",
      "       fa       ",
      "        h       ",
      "        j       ",
      "        h       ",
      "        a       ",
      "        h       "
    ],
    [
      "                ",
      "                ",
      "                ",
      "                ",
      "                ",
      "                ",
      "              k ",
      "          kkkkk ",
      "       faaamccaa",
      "       fnjibmaii",
      "       fcnabbbci",
      "        ncbabiic",
      "        ajmjbijm",
      "        bccjcc j",
      "        iccicaΓ ",
      "        majaic  "
    ],
    [
      "                ",
      "                ",
      "                ",
      "                ",
      "                ",
      "                ",
      "              k ",
      "          kkkkk ",
      "       fagbgbgaΔ",
      "       fh     ЯϠ",
      "       fc      Ј",
      "        h  Ϛ   в",
      "        b ΧC    ",
      "        h  ϙ    ",
      "        m       ",
      "        h   Ϳ   "
    ],
    [
      "                ",
      "                ",
      "                ",
      "                ",
      "                ",
      "                ",
      "              k ",
      "          kkkkk ",
      "       fagmgcgag",
      "       fh       ",
      "       fa       ",
      "        h       ",
      "        i  Ψ    ",
      "        h       ",
      "        i       ",
      "        h   ϳ   "
    ],
    [
      "                ",
      "                ",
      "                ",
      "                ",
      "                ",
      "                ",
      "              k ",
      "          kkkkk ",
      "       fbmjccnjj",
      "       fm       ",
      "       fc       ",
      "        i       ",
      "        c       ",
      "        i       ",
      "        i       ",
      "        c       "
    ],
    [
      "                ",
      "                ",
      "                ",
      "                ",
      "                ",
      "                ",
      "              k ",
      "          kkkkk ",
      "       fjgigngcg",
      "       fh       ",
      "       fa       ",
      "        h       ",
      "        b       ",
      "        h       ",
      "        c       ",
      "        h       "
    ]
  ]
}