{
  "xsize": 16,
  "zsize": 16,
  "palette": {
    "palette": [
      {
        "char": " ",
        "block": "minecraft:air"
      },
      {
        "char": "c",
        "block": "minecraft:deepslate[axis\u003dy]"
      },
      {
        "char": "d",
        "block": "minecraft:cobbled_deepslate"
      },
      {
        "char": "e",
        "block": "minecraft:basalt[axis\u003dy]"
      },
      {
        "char": "a",
        "block": "minecraft:cyan_terracotta"
      },
      {
        "char": "b",
        "block": "minecraft:blackstone"
      },
      {
        "char": "g",
        "block": "minecraft:gray_concrete"
      },
      {
        "char": "i",
        "block": "minecraft:light_gray_concrete"
      },
      {
        "char": "ϔ",
        "block": "minecraft:quartz_stairs[facing\u003deast,half\u003dbottom,shape\u003dstraight,waterlogged\u003dfalse]"
      },
      {
        "char": "f",
        "block": "minecraft:glass"
      },
      {
        "char": "x",
        "block": "minecraft:cauldron"
      },
      {
        "char": "H",
        "block": "minecraft:quartz_stairs[facing\u003dsouth,half\u003dbottom,shape\u003dstraight,waterlogged\u003dfalse]"
      },
      {
        "char": "下",
        "block": "doomsday_decoration:crt[facing\u003deast,waterlogged\u003dfalse]"
      },
      {
        "char": "l",
        "block": "minecraft:iron_trapdoor[facing\u003deast,half\u003dbottom,open\u003dfalse,powered\u003dfalse,waterlogged\u003dfalse]"
      },
      {
        "char": "k",
        "block": "minecraft:air"
      },
      {
        "char": "ѷ",
        "block": "doomsday_decoration:crt_3[facing\u003dsouth,waterlogged\u003dfalse]"
      },
      {
        "char": "u",
        "block": "minecraft:iron_trapdoor[facing\u003dsouth,half\u003dbottom,open\u003dfalse,powered\u003dfalse,waterlogged\u003dfalse]"
      },
      {
        "char": "t",
        "block": "minecraft:iron_trapdoor[facing\u003deast,half\u003dtop,open\u003dfalse,powered\u003dfalse,waterlogged\u003dfalse]"
      },
      {
        "char": "w",
        "block": "minecraft:iron_trapdoor[facing\u003dsouth,half\u003dtop,open\u003dfalse,powered\u003dfalse,waterlogged\u003dfalse]"
      }
    ]
  },
  "slices": [
    [
      "cccdeccae       ",
      "aaebccdge       ",
      "ecadbdbac       ",
      "cdebcegc        ",
      "abebacae        ",
      "cbcddegba       ",
      "acdbebgbg       ",
      "accadaba        ",
      "eccedica        ",
      "eeebaag         ",
      "cdeeiea         ",
      "deagag          ",
      "eaaaaa          ",
      "edada           ",
      "daaa            ",
      "aai             "
    ],
    [
      "c ϔ    f        ",
      "c      f        ",
      "ecd    f        ",
      "                ",
      "      f         ",
      "cddddcaba       ",
      "  x             ",
      "     f          ",
      "     f          ",
      "    f           ",
      "ab  f           ",
      "H   d           ",
      "  f  g          ",
      "  f             ",
      "                ",
      "f               "
    ],
    [
      "下      fl       ",
      "       fl       ",
      "       fl       ",
      "      fl        ",
      "      fl        ",
      "dedddagba       ",
      "  k   fl        ",
      "     fl         ",
      "     fl         ",
      "    fl          ",
      "ѷ   fl          ",
      "   fe           ",
      "   u a          ",
      "  fl            ",
      "  l             ",
      " l              "
    ],
    [
      "       ft       ",
      "       ft       ",
      "       ft       ",
      "      ft        ",
      "      ft        ",
      "bbdceaaag       ",
      "  k   ft        ",
      "     ft         ",
      "      t         ",
      "    ft          ",
      "    ft          ",
      "   fa           ",
      "   w a          ",
      "   t            ",
      " ft             ",
      "fw              "
    ],
    [
      "       f        ",
      "       f        ",
      "       f        ",
      "                ",
      "                ",
      "cbbabbgca       ",
      "                ",
      "     f          ",
      "                ",
      "    f           ",
      "    f           ",
      "   fc           ",
      "  f  i          ",
      "  f             ",
      " f              ",
      "f               "
    ],
    [
      "       id       ",
      "       ab       ",
      "       ad       ",
      "      ac        ",
      "      ie        ",
      "abdabaaei       ",
      "      ab        ",
      "     gb         ",
      "     ic         ",
      "    gc          ",
      "    ae          ",
      "   ac           ",
      "  aa a          ",
      "  gc            ",
      " ia             ",
      "ae              "
    ]
  ]
}