{
  "xsize": 16,
  "zsize": 16,
  "palette": {
    "palette": [
      {
        "char": " ",
        "block": "minecraft:air"
      },
      {
        "char": "a",
        "block": "minecraft:cyan_terracotta"
      },
      {
        "char": "b",
        "block": "minecraft:blackstone"
      },
      {
        "char": "c",
        "block": "minecraft:deepslate[axis\u003dy]"
      },
      {
        "char": "d",
        "block": "minecraft:cobbled_deepslate"
      },
      {
        "char": "e",
        "block": "minecraft:basalt[axis\u003dy]"
      },
      {
        "char": "Р",
        "block": "minecraft:stone_brick_stairs[facing\u003dnorth,half\u003dbottom,shape\u003dstraight,waterlogged\u003dfalse,weathering\u003dfalse]"
      },
      {
        "char": "z",
        "block": "minecraft:iron_bars[east\u003dfalse,north\u003dtrue,south\u003dtrue,waterlogged\u003dfalse,west\u003dfalse]"
      },
      {
        "char": "Y",
        "block": "minecraft:iron_bars[east\u003dfalse,north\u003dtrue,south\u003dfalse,waterlogged\u003dfalse,west\u003dfalse]"
      },
      {
        "char": "f",
        "block": "minecraft:glass"
      },
      {
        "char": "O",
        "block": "minecraft:quartz_stairs[facing\u003dwest,half\u003dbottom,shape\u003dstraight,waterlogged\u003dfalse]"
      },
      {
        "char": "x",
        "block": "minecraft:cauldron"
      },
      {
        "char": "П",
        "block": "minecraft:barrel[facing\u003dup,open\u003dfalse]",
        "tag": {
          "z": -275,
          "x": -15,
          "ForgeData": {
            "LockFlag": "1b"
          },
          "id": "minecraft:barrel",
          "y": 2,
          "Items": []
        }
      },
      {
        "char": "У",
        "block": "minecraft:stone_brick_stairs[facing\u003dsouth,half\u003dbottom,shape\u003dstraight,waterlogged\u003dfalse,weathering\u003dfalse]"
      },
      {
        "char": "С",
        "block": "minecraft:stone_brick_stairs[facing\u003dnorth,half\u003dtop,shape\u003dstraight,waterlogged\u003dfalse,weathering\u003dfalse]"
      },
      {
        "char": "Ѫ",
        "block": "doomsday_decoration:crt[facing\u003dwest,waterlogged\u003dfalse]"
      },
      {
        "char": "N",
        "block": "minecraft:white_stained_glass_pane[east\u003dtrue,north\u003dfalse,south\u003dfalse,waterlogged\u003dfalse,west\u003dtrue]"
      },
      {
        "char": "Ѵ",
        "block": "minecraft:white_stained_glass_pane[east\u003dfalse,north\u003dfalse,south\u003dfalse,waterlogged\u003dfalse,west\u003dtrue]"
      },
      {
        "char": "k",
        "block": "minecraft:air"
      },
      {
        "char": "生",
        "block": "minecraft:white_stained_glass_pane[east\u003dfalse,north\u003dfalse,south\u003dfalse,waterlogged\u003dfalse,west\u003dfalse]"
      },
      {
        "char": "у",
        "block": "minecraft:stone_brick_stairs[facing\u003dsouth,half\u003dtop,shape\u003dstraight,waterlogged\u003dfalse,weathering\u003dfalse]"
      },
      {
        "char": "j",
        "block": "minecraft:polished_andesite_slab[type\u003dtop,waterlogged\u003dfalse]"
      }
    ]
  },
  "slices": [
    [
      "abcaaacbddadedac",
      "edadadeabdebddeb",
      "cbcbbbaabeeeceea",
      "bcedcbaedeaacded",
      "bbadaaaadabcceca",
      "dcecbdbebecadcde",
      "dcbabdeadabebedc",
      "bbbcacbeedcedeaa",
      "eaacbeddcabaebba",
      "bdddadcabecdacbe",
      "cedecdaecacbabbc",
      "aabdbbddeddbaaad",
      "dadeeaebbdcaРz c",
      "eedbcebdcaba z c",
      "cdbdedcbcdea Y a",
      "bbbeeaccdbbb   d"
    ],
    [
      "f   Od    e     ",
      "     b          ",
      "                ",
      "  c  c    a     ",
      " Od Oe    bceeee",
      "  c  b     d  x ",
      "           a    ",
      "  b  П          ",
      " Oc Oa          ",
      "  a  e          ",
      "           a    ",
      "  e  d     c a c",
      " Oe Od     b zУd",
      "  c  a     e zСc",
      "cedaaee   cd Y c",
      "  d  c     b   d"
    ],
    [
      "f    Ѫ    b     ",
      "                ",
      "                ",
      "          b     ",
      "  Ѫ  Ѫ    edcNѴ ",
      "           d  k ",
      "           b    ",
      "                ",
      "  Ѫ  Ѫ          ",
      "                ",
      "           d    ",
      "           b d a",
      "  Ѫ  Ѫ     a z c",
      "           a zУa",
      "abadaca   da YСb",
      "     e     c   c"
    ],
    [
      "f         c     ",
      "                ",
      "                ",
      "          a     ",
      "          dae 生 ",
      "           e  k ",
      "           a    ",
      "                ",
      "                ",
      "                ",
      "           d    ",
      "           a c d",
      "           d z e",
      "           d z b",
      "ebdbeab   edуzУc",
      "     e     bcdac"
    ],
    [
      "          b     ",
      "          j     ",
      "          j     ",
      "          d     ",
      "          deeeed",
      "           e    ",
      "           a    ",
      "           j    ",
      "           j    ",
      "           j    ",
      "           b    ",
      "           dacdc",
      "           d z e",
      "           eуz e",
      "cebeaccjjjaeРY e",
      "     a     d   a"
    ],
    [
      "a         a     ",
      "          b     ",
      "          b     ",
      "          e     ",
      "          dccecc",
      "           c    ",
      "           c    ",
      "           c    ",
      "           b    ",
      "           b    ",
      "           b    ",
      "           ddbcd",
      "           cуz b",
      "           bРz e",
      "daaedbbcdeaa Y a",
      "     e     d   d"
    ]
  ]
}