{
  "xsize": 16,
  "zsize": 16,
  "palette": {
    "palette": [
      {
        "char": " ",
        "block": "minecraft:air"
      },
      {
        "char": "a",
        "block": "minecraft:cyan_terracotta"
      },
      {
        "char": "e",
        "block": "minecraft:basalt[axis\u003dy]"
      },
      {
        "char": "d",
        "block": "minecraft:cobbled_deepslate"
      },
      {
        "char": "c",
        "block": "minecraft:deepslate[axis\u003dy]"
      },
      {
        "char": "b",
        "block": "minecraft:blackstone"
      },
      {
        "char": "g",
        "block": "minecraft:gray_concrete"
      },
      {
        "char": "会",
        "block": "minecraft:birch_stairs[facing\u003deast,half\u003dbottom,shape\u003dstraight,waterlogged\u003dfalse]"
      },
      {
        "char": "好",
        "block": "minecraft:birch_stairs[facing\u003dwest,half\u003dbottom,shape\u003dstraight,waterlogged\u003dfalse]"
      },
      {
        "char": "x",
        "block": "minecraft:cauldron"
      },
      {
        "char": "问",
        "block": "minecraft:birch_trapdoor[facing\u003dsouth,half\u003dbottom,open\u003dtrue,powered\u003dfalse,waterlogged\u003dfalse]"
      },
      {
        "char": "k",
        "block": "minecraft:air"
      },
      {
        "char": "P",
        "block": "minecraft:smooth_quartz_slab[type\u003dbottom,waterlogged\u003dfalse]"
      },
      {
        "char": "Ѯ",
        "block": "minecraft:diorite_slab[type\u003dbottom,waterlogged\u003dfalse]"
      },
      {
        "char": "M",
        "block": "minecraft:smooth_quartz_slab[type\u003dtop,waterlogged\u003dfalse]"
      },
      {
        "char": "i",
        "block": "minecraft:light_gray_concrete"
      },
      {
        "char": "ѩ",
        "block": "minecraft:diorite_slab[type\u003dtop,waterlogged\u003dfalse]"
      },
      {
        "char": "ѭ",
        "block": "minecraft:polished_andesite_stairs[facing\u003dwest,half\u003dtop,shape\u003dstraight,waterlogged\u003dfalse]"
      },
      {
        "char": "h",
        "block": "minecraft:andesite_slab[type\u003dtop,waterlogged\u003dfalse]"
      },
      {
        "char": "们",
        "block": "minecraft:polished_andesite_stairs[facing\u003dwest,half\u003dtop,shape\u003dinner_right,waterlogged\u003dfalse]"
      },
      {
        "char": "Т",
        "block": "minecraft:polished_andesite_stairs[facing\u003dnorth,half\u003dtop,shape\u003dstraight,waterlogged\u003dfalse]"
      }
    ]
  },
  "slices": [
    [
      "         aeaedaa",
      "         adcdcbd",
      "         ebabdea",
      "         bebcacb",
      "         bdbccab",
      "        aaaebacc",
      "        agdacaae",
      "         bccedce",
      "         cdcacec",
      "         bcadebc",
      "         eeacceb",
      "         eadaeba",
      "         cbcacde",
      "         bdadabb",
      "         ebabdbe",
      "         cbdbaea"
    ],
    [
      "         b   会好 ",
      "         b   会好 ",
      "         bx  会好 ",
      "         d   问问 ",
      "         d      ",
      "        agx     ",
      "        aa      ",
      "         d      ",
      "         ax     ",
      "         b      ",
      "         e      ",
      "         ca    d",
      "         d      ",
      "         a      ",
      "         ax     ",
      "         d      "
    ],
    [
      "         a      ",
      "         b      ",
      "         dk     ",
      "         d      ",
      "         c      ",
      "        gak     ",
      "        aa      ",
      "         e      ",
      "         bk     ",
      "         e      ",
      "         c      ",
      "         da    e",
      "         a      ",
      "         a      ",
      "         ak     ",
      "         e      "
    ],
    [
      "        Pd      ",
      "        Ѯb      ",
      "        Pdk     ",
      "        Ѯb      ",
      "        Ѯb      ",
      "        gak     ",
      "        ga      ",
      "        Ѯa      ",
      "        Ѯck     ",
      "        Pe      ",
      "        Pc      ",
      "        Pee    c",
      "        Pd      ",
      "        Pb      ",
      "        Pck     ",
      "        Pa      "
    ],
    [
      "        Ma      ",
      "        Mb      ",
      "        Md      ",
      "        Md      ",
      "        Ma      ",
      "        aa      ",
      "        ai      ",
      "        ѩc      ",
      "        Ma      ",
      "        Md      ",
      "        ѩe      ",
      "        ѩce    c",
      "        Me      ",
      "        Ma      ",
      "        Md      ",
      "        ѩb      "
    ],
    [
      "         eѭhhhhh",
      "         aѭhhhhh",
      "         cѭhhhhh",
      "         dѭhhhhh",
      "         eѭhhhhh",
      "        adѭhhhhh",
      "        aaѭhhhhh",
      "         bѭhhhhh",
      "         aѭhhhhh",
      "         dѭhhhhh",
      "         eѭhhhhh",
      "         cabeadd",
      "         e们ТТТТТ",
      "         dѭhhhhh",
      "         gѭhhhhh",
      "         bѭhhhhh"
    ]
  ]
}