{
  "xsize": 16,
  "zsize": 16,
  "palette": {
    "palette": [
      {
        "char": " ",
        "block": "minecraft:air"
      },
      {
        "char": "a",
        "block": "minecraft:cyan_terracotta"
      },
      {
        "char": "d",
        "block": "minecraft:cobbled_deepslate"
      },
      {
        "char": "e",
        "block": "minecraft:basalt[axis\u003dy]"
      },
      {
        "char": "c",
        "block": "minecraft:deepslate[axis\u003dy]"
      },
      {
        "char": "b",
        "block": "minecraft:blackstone"
      },
      {
        "char": "i",
        "block": "minecraft:light_gray_concrete"
      },
      {
        "char": "Р",
        "block": "minecraft:stone_brick_stairs[facing\u003dnorth,half\u003dbottom,shape\u003dstraight,waterlogged\u003dfalse,weathering\u003dfalse]"
      },
      {
        "char": "z",
        "block": "minecraft:iron_bars[east\u003dfalse,north\u003dtrue,south\u003dtrue,waterlogged\u003dfalse,west\u003dfalse]"
      },
      {
        "char": "Y",
        "block": "minecraft:iron_bars[east\u003dfalse,north\u003dtrue,south\u003dfalse,waterlogged\u003dfalse,west\u003dfalse]"
      },
      {
        "char": "f",
        "block": "minecraft:glass"
      },
      {
        "char": "x",
        "block": "minecraft:cauldron"
      },
      {
        "char": "У",
        "block": "minecraft:stone_brick_stairs[facing\u003dsouth,half\u003dbottom,shape\u003dstraight,waterlogged\u003dfalse,weathering\u003dfalse]"
      },
      {
        "char": "С",
        "block": "minecraft:stone_brick_stairs[facing\u003dnorth,half\u003dtop,shape\u003dstraight,waterlogged\u003dfalse,weathering\u003dfalse]"
      },
      {
        "char": "s",
        "block": "minecraft:iron_trapdoor[facing\u003dnorth,half\u003dbottom,open\u003dfalse,powered\u003dfalse,waterlogged\u003dfalse]"
      },
      {
        "char": "m",
        "block": "minecraft:iron_trapdoor[facing\u003dwest,half\u003dbottom,open\u003dfalse,powered\u003dfalse,waterlogged\u003dfalse]"
      },
      {
        "char": "k",
        "block": "minecraft:air"
      },
      {
        "char": "p",
        "block": "minecraft:iron_trapdoor[facing\u003dnorth,half\u003dtop,open\u003dfalse,powered\u003dfalse,waterlogged\u003dfalse]"
      },
      {
        "char": "q",
        "block": "minecraft:iron_trapdoor[facing\u003dwest,half\u003dtop,open\u003dfalse,powered\u003dfalse,waterlogged\u003dfalse]"
      },
      {
        "char": "у",
        "block": "minecraft:stone_brick_stairs[facing\u003dsouth,half\u003dtop,shape\u003dstraight,waterlogged\u003dfalse,weathering\u003dfalse]"
      },
      {
        "char": "I",
        "block": "minecraft:stone_slab[type\u003dtop,waterlogged\u003dfalse,weathering\u003dfalse]"
      },
      {
        "char": "给",
        "block": "minecraft:stone_brick_stairs[facing\u003dsouth,half\u003dtop,shape\u003dstraight,waterlogged\u003dfalse,weathering\u003dtrue]"
      },
      {
        "char": "小",
        "block": "immersive_weathering:cracked_stone_brick_stairs[facing\u003dnorth,half\u003dbottom,shape\u003dstraight,waterlogged\u003dfalse]"
      }
    ]
  },
  "slices": [
    [
      "         adeaecb",
      "       cdeabedbd",
      "      adcaeaceda",
      "     eccabedbddb",
      "    ebaeceeededd",
      "  i dbecaeccbedd",
      "iaaedbdaaecdebec",
      "dabeedcdbeeddcce",
      "bdbaceadacedbeeb",
      "adecacccebbcebbb",
      "cabbedecaceecaeb",
      "ebdccbabaecbecec",
      "bdddabbadeadРz c",
      "babebeadacdd z a",
      "eddbcdeaacbb Y c",
      "cbcaecaedcac   a"
    ],
    [
      "         e      ",
      "         b      ",
      "       ff       ",
      "      f         ",
      "     f          ",
      "  i  f          ",
      "   aa     x     ",
      "ebceccdabcdb   b",
      "  b  x  x       ",
      "  d             ",
      "  c             ",
      "           a b c",
      "           b zУb",
      "  c        d zСa",
      "ebb        b Y c",
      "  b        d   d"
    ],
    [
      "         a      ",
      "       ssb      ",
      "      mf        ",
      "     mf         ",
      "    mf          ",
      "  a mf          ",
      "   ae     k     ",
      "bdeeedbeacae   b",
      "  a  k  k       ",
      "  c             ",
      "  a             ",
      "           e a a",
      "           d z b",
      "  e        c zУe",
      "aad        c YСe",
      "  a        a   b"
    ],
    [
      "         b      ",
      "       ppc      ",
      "      qff       ",
      "     p          ",
      "    qf          ",
      "  a q           ",
      "   ec     k     ",
      "dbdbcebebbba   a",
      "  a  k  k       ",
      "  d             ",
      "  c             ",
      "           b d d",
      "           d z b",
      "  b        e z a",
      "dbb        aуzУc",
      "  c        dcdcc"
    ],
    [
      "         a      ",
      "         e      ",
      "       ff       ",
      "                ",
      "                ",
      "  a  f          ",
      "   cd           ",
      "cccbdaabcadaIIIb",
      "  a             ",
      "  a             ",
      "  c             ",
      "  I        cbcac",
      "  I        a z d",
      "  d        aуz a",
      "bbd        bРY b",
      "  a        d   a"
    ],
    [
      "         d      ",
      "       de       ",
      "      dbb       ",
      "     da         ",
      "    ca          ",
      "  a bd          ",
      "   d            ",
      "eebdecccaeeeddbc",
      "  e             ",
      "  e             ",
      "  e             ",
      "  e        bbaba",
      "  b        a给z e",
      "  a        a小z a",
      "aeb        e Y b",
      "  a        b   c"
    ]
  ]
}