{
  "xsize": 16,
  "zsize": 16,
  "palette": {
    "palette": [
      {
        "char": " ",
        "block": "minecraft:air"
      },
      {
        "char": "b",
        "block": "minecraft:blackstone"
      },
      {
        "char": "c",
        "block": "minecraft:deepslate[axis\u003dy]"
      },
      {
        "char": "a",
        "block": "minecraft:cyan_terracotta"
      },
      {
        "char": "e",
        "block": "minecraft:basalt[axis\u003dy]"
      },
      {
        "char": "d",
        "block": "minecraft:cobbled_deepslate"
      },
      {
        "char": "ϕ",
        "block": "minecraft:quartz_stairs[facing\u003dnorth,half\u003dbottom,shape\u003dstraight,waterlogged\u003dfalse]"
      },
      {
        "char": "O",
        "block": "minecraft:quartz_stairs[facing\u003dwest,half\u003dbottom,shape\u003dstraight,waterlogged\u003dfalse]"
      },
      {
        "char": "ϔ",
        "block": "minecraft:quartz_stairs[facing\u003deast,half\u003dbottom,shape\u003dstraight,waterlogged\u003dfalse]"
      },
      {
        "char": "H",
        "block": "minecraft:quartz_stairs[facing\u003dsouth,half\u003dbottom,shape\u003dstraight,waterlogged\u003dfalse]"
      },
      {
        "char": "x",
        "block": "minecraft:cauldron"
      },
      {
        "char": "k",
        "block": "minecraft:air"
      },
      {
        "char": "该",
        "block": "horror_element_mod:blood_5[facing\u003dsouth,waterlogged\u003dfalse]"
      },
      {
        "char": "者",
        "block": "horror_element_mod:blood_8[facing\u003dwest,waterlogged\u003dfalse]"
      },
      {
        "char": "言",
        "block": "horror_element_mod:spiked_body[facing\u003dsouth,waterlogged\u003dfalse]"
      },
      {
        "char": "进",
        "block": "horror_element_mod:blood_2[facing\u003dsouth,waterlogged\u003dfalse]"
      },
      {
        "char": "你",
        "block": "minecraft:spawner",
        "tag": {
          "SpawnData": {
            "entity": {}
          },
          "MaxNearbyEntities": "6s",
          "MinSpawnDelay": "200s",
          "z": -274,
          "x": -42,
          "MaxSpawnDelay": "800s",
          "RequiredPlayerRange": "16s",
          "SpawnCount": "4s",
          "id": "minecraft:mob_spawner",
          "SpawnPotentials": [],
          "y": 1,
          "SpawnRange": "4s",
          "Delay": "731s"
        }
      },
      {
        "char": "I",
        "block": "minecraft:stone_slab[type\u003dtop,waterlogged\u003dfalse,weathering\u003dfalse]"
      }
    ]
  },
  "slices": [
    [
      "bcaeaeaeabcaeeab",
      "bbddaaedeeacadce",
      "eeaacdedeedaecaa",
      "cbaddaeacbeaabcb",
      "ceeeaccceedbcaad",
      "accabbceccdaecee",
      "aeeaaeabcbbbcace",
      "beacccabbdceacea",
      "ebaabbcabbededdb",
      "dabdaebdcaccdeac",
      "bddaeeacdebbbbbd",
      "babbacdadacbbebb",
      "   daabccbedccce",
      "    edaaeabeaaab",
      "     dccecabeeac",
      "      bcbbbbbaaa"
    ],
    [
      "eeeadebb        ",
      " b              ",
      " d           dad",
      " e          ddcb",
      "cda   ebb aϕecbc",
      " a      b Odϔade",
      "        abcHdeed",
      "       xcdabdaba",
      "        ddaebbcc",
      "      kkdcbbccbe",
      "       ccddcdcdb",
      "      aebaed    ",
      "      caca      ",
      "     cabc a     ",
      "        d   该   ",
      "        c  者言进  "
    ],
    [
      "adecbccd        ",
      " b              ",
      " d              ",
      " d           beb",
      "dcd   aad   ecbd",
      " b      a  cbeae",
      "        e  dbbbb",
      "       kc  daece",
      "        e ecd你ca",
      "        a bbad  ",
      "        c cda   ",
      "       de da    ",
      "       edd      ",
      "     ccba a     ",
      "        d       ",
      "        d       "
    ],
    [
      "eaacbabd        ",
      " d              ",
      " b              ",
      " d              ",
      "ddb   ada     db",
      " c      e    cbe",
      "        c   bcaa",
      "       ke   eaad",
      "        a  dad  ",
      "        d  db   ",
      "        d   d   ",
      "        d dc    ",
      " a      ba      ",
      "     beae a     ",
      "        c       ",
      "        b       "
    ],
    [
      "debedaec        ",
      " a              ",
      " a              ",
      " b              ",
      "acbIIIdbb       ",
      " a      b      c",
      " I      b    bcb",
      " I      c   cc  ",
      " I      b       ",
      " I      c       ",
      " I      b       ",
      " I      e eb    ",
      " c      ec      ",
      "badIIddbc a     ",
      "        b       ",
      "        a       "
    ],
    [
      "acaebdcd        ",
      " e              ",
      " d              ",
      " c              ",
      "ccbaadced       ",
      " c      c       ",
      " d      e       ",
      " d      d       ",
      " b      e       ",
      " d      d       ",
      " d      a       ",
      " b      a       ",
      " b              ",
      "cbacaebb        ",
      " c              ",
      "                "
    ]
  ]
}