{
  "xsize": 16,
  "zsize": 16,
  "palette": {
    "palette": [
      {
        "char": " ",
        "block": "minecraft:air"
      },
      {
        "char": "a",
        "block": "minecraft:cyan_terracotta"
      },
      {
        "char": "d",
        "block": "minecraft:cobbled_deepslate"
      },
      {
        "char": "e",
        "block": "minecraft:basalt[axis\u003dy]"
      },
      {
        "char": "b",
        "block": "minecraft:blackstone"
      },
      {
        "char": "c",
        "block": "minecraft:deepslate[axis\u003dy]"
      },
      {
        "char": "Р",
        "block": "minecraft:stone_brick_stairs[facing\u003dnorth,half\u003dbottom,shape\u003dstraight,waterlogged\u003dfalse,weathering\u003dfalse]"
      },
      {
        "char": "z",
        "block": "minecraft:iron_bars[east\u003dfalse,north\u003dtrue,south\u003dtrue,waterlogged\u003dfalse,west\u003dfalse]"
      },
      {
        "char": "Y",
        "block": "minecraft:iron_bars[east\u003dfalse,north\u003dtrue,south\u003dfalse,waterlogged\u003dfalse,west\u003dfalse]"
      },
      {
        "char": "f",
        "block": "minecraft:glass"
      },
      {
        "char": "O",
        "block": "minecraft:quartz_stairs[facing\u003dwest,half\u003dbottom,shape\u003dstraight,waterlogged\u003dfalse]"
      },
      {
        "char": "x",
        "block": "minecraft:cauldron"
      },
      {
        "char": "П",
        "block": "minecraft:barrel[facing\u003dup,open\u003dfalse]",
        "tag": {
          "z": -275,
          "x": -15,
          "ForgeData": {
            "LockFlag": "1b"
          },
          "id": "minecraft:barrel",
          "y": 2,
          "Items": []
        }
      },
      {
        "char": "У",
        "block": "minecraft:stone_brick_stairs[facing\u003dsouth,half\u003dbottom,shape\u003dstraight,waterlogged\u003dfalse,weathering\u003dfalse]"
      },
      {
        "char": "С",
        "block": "minecraft:stone_brick_stairs[facing\u003dnorth,half\u003dtop,shape\u003dstraight,waterlogged\u003dfalse,weathering\u003dfalse]"
      },
      {
        "char": "Ѥ",
        "block": "refurbished_furniture:computer[facing\u003deast,powered\u003dfalse]",
        "tag": {
          "z": -276,
          "x": -43,
          "id": "refurbished_furniture:computer",
          "y": -39,
          "NodePos": "-11544873218087L",
          "Connections": [
            "L"
          ]
        }
      },
      {
        "char": "Ѳ",
        "block": "minecraft:white_stained_glass_pane[east\u003dtrue,north\u003dfalse,south\u003dfalse,waterlogged\u003dfalse,west\u003dfalse]"
      },
      {
        "char": "N",
        "block": "minecraft:white_stained_glass_pane[east\u003dtrue,north\u003dfalse,south\u003dfalse,waterlogged\u003dfalse,west\u003dtrue]"
      },
      {
        "char": "k",
        "block": "minecraft:air"
      },
      {
        "char": "у",
        "block": "minecraft:stone_brick_stairs[facing\u003dsouth,half\u003dtop,shape\u003dstraight,waterlogged\u003dfalse,weathering\u003dfalse]"
      },
      {
        "char": "j",
        "block": "minecraft:polished_andesite_slab[type\u003dtop,waterlogged\u003dfalse]"
      },
      {
        "char": "g",
        "block": "minecraft:gray_concrete"
      }
    ]
  },
  "slices": [
    [
      "adaedeeaddeabacb",
      "eccebdbdcaeaeebc",
      "cbdaacdaeddcdeac",
      "abaddddcadadecab",
      "acdbcaaebebabbce",
      "bacabdbceadccaba",
      "dcccdbedcdeddbed",
      "adbadcdbaedbecab",
      "beeecbcbacbbaddc",
      "cebdeadedceccaac",
      "abcdbecdabedcbea",
      "ccebdddeacebdbdd",
      "acaecbcadeedРz c",
      "daeeeaaabacc z b",
      "eaaaadeaaeee Y a",
      "bdbcdbadaaca   d"
    ],
    [
      "f   Oe    b     ",
      "     b          ",
      "                ",
      "  d  a    b     ",
      " Oc Oa    cadeeb",
      "  c  a     b  x ",
      "           e    ",
      "  b  d          ",
      " Oa Oc          ",
      "  c  П          ",
      "           d    ",
      "  e  c     c c c",
      " Oe Oc     e zУa",
      "  c  e     d zСb",
      "bebabca   da Y c",
      "  c  e     c   a"
    ],
    [
      "f    Ѥ    b     ",
      "                ",
      "                ",
      "          c     ",
      "  Ѥ  Ѥ    eab ѲN",
      "           b  k ",
      "           a    ",
      "                ",
      "  Ѥ  Ѥ          ",
      "                ",
      "           a    ",
      "           a a b",
      "  Ѥ  Ѥ     c z c",
      "           e zУa",
      "aaededb   ac YСd",
      "     a     e   e"
    ],
    [
      "f         d     ",
      "                ",
      "                ",
      "          c     ",
      "          add ѲN",
      "           b  k ",
      "           b    ",
      "                ",
      "                ",
      "                ",
      "           e    ",
      "           e d e",
      "           e z b",
      "           d z d",
      "ddddbcd   cdуzУa",
      "     d     ccecd"
    ],
    [
      "          c     ",
      "          j     ",
      "          j     ",
      "          e     ",
      "          eaacac",
      "           a    ",
      "           e    ",
      "           j    ",
      "           j    ",
      "           j    ",
      "           d    ",
      "           edbad",
      "           b z b",
      "           eуz b",
      "ceaecccjjjabРY c",
      "     e     b   d"
    ],
    [
      "g         c     ",
      "          d     ",
      "          b     ",
      "          e     ",
      "          cdecbb",
      "           c    ",
      "           e    ",
      "           b    ",
      "           a    ",
      "           e    ",
      "           b    ",
      "           ebeac",
      "           aуz d",
      "           bРz b",
      "ccaabeeeaaec Y d",
      "     b     d   d"
    ]
  ]
}