{
  "xsize": 16,
  "zsize": 16,
  "palette": {
    "palette": [
      {
        "char": " ",
        "block": "minecraft:air"
      },
      {
        "char": "a",
        "block": "minecraft:cyan_terracotta"
      },
      {
        "char": "d",
        "block": "minecraft:cobbled_deepslate"
      },
      {
        "char": "c",
        "block": "minecraft:deepslate[axis\u003dy]"
      },
      {
        "char": "e",
        "block": "minecraft:basalt[axis\u003dy]"
      },
      {
        "char": "b",
        "block": "minecraft:blackstone"
      },
      {
        "char": "Р",
        "block": "minecraft:stone_brick_stairs[facing\u003dnorth,half\u003dbottom,shape\u003dstraight,waterlogged\u003dfalse,weathering\u003dfalse]"
      },
      {
        "char": "z",
        "block": "minecraft:iron_bars[east\u003dfalse,north\u003dtrue,south\u003dtrue,waterlogged\u003dfalse,west\u003dfalse]"
      },
      {
        "char": "Y",
        "block": "minecraft:iron_bars[east\u003dfalse,north\u003dtrue,south\u003dfalse,waterlogged\u003dfalse,west\u003dfalse]"
      },
      {
        "char": "O",
        "block": "minecraft:quartz_stairs[facing\u003dwest,half\u003dbottom,shape\u003dstraight,waterlogged\u003dfalse]"
      },
      {
        "char": "П",
        "block": "minecraft:barrel[facing\u003dup,open\u003dfalse]",
        "tag": {
          "z": -275,
          "x": -15,
          "ForgeData": {
            "LockFlag": "1b"
          },
          "id": "minecraft:barrel",
          "y": 2,
          "Items": []
        }
      },
      {
        "char": "x",
        "block": "minecraft:cauldron"
      },
      {
        "char": "У",
        "block": "minecraft:stone_brick_stairs[facing\u003dsouth,half\u003dbottom,shape\u003dstraight,waterlogged\u003dfalse,weathering\u003dfalse]"
      },
      {
        "char": "С",
        "block": "minecraft:stone_brick_stairs[facing\u003dnorth,half\u003dtop,shape\u003dstraight,waterlogged\u003dfalse,weathering\u003dfalse]"
      },
      {
        "char": "Ѥ",
        "block": "refurbished_furniture:computer[facing\u003deast,powered\u003dfalse]",
        "tag": {
          "z": -276,
          "x": -43,
          "id": "refurbished_furniture:computer",
          "y": -39,
          "NodePos": "-11544873218087L",
          "Connections": [
            "L"
          ]
        }
      },
      {
        "char": "N",
        "block": "minecraft:white_stained_glass_pane[east\u003dtrue,north\u003dfalse,south\u003dfalse,waterlogged\u003dfalse,west\u003dtrue]"
      },
      {
        "char": "k",
        "block": "minecraft:air"
      },
      {
        "char": "Ѵ",
        "block": "minecraft:white_stained_glass_pane[east\u003dfalse,north\u003dfalse,south\u003dfalse,waterlogged\u003dfalse,west\u003dtrue]"
      },
      {
        "char": "Ѳ",
        "block": "minecraft:white_stained_glass_pane[east\u003dtrue,north\u003dfalse,south\u003dfalse,waterlogged\u003dfalse,west\u003dfalse]"
      },
      {
        "char": "道",
        "block": "immersive_weathering:cracked_stone_brick_stairs[facing\u003dsouth,half\u003dtop,shape\u003dstraight,waterlogged\u003dfalse]"
      },
      {
        "char": "j",
        "block": "minecraft:polished_andesite_slab[type\u003dtop,waterlogged\u003dfalse]"
      },
      {
        "char": "小",
        "block": "immersive_weathering:cracked_stone_brick_stairs[facing\u003dnorth,half\u003dbottom,shape\u003dstraight,waterlogged\u003dfalse]"
      }
    ]
  },
  "slices": [
    [
      "a     dddacecdee",
      "ddbcdcacadbcbdac",
      "cccdcaebdecbaaec",
      "bdccddaadcdaebce",
      "acbeaceccbedddec",
      "cabaaaebeabbbdbc",
      "bccaddaaaecebdea",
      "acbeaabbdeebbbdd",
      "bbaddbddeeeabeba",
      "ecbcdbdeededcede",
      "edcceeedbbaedabd",
      "ebcbbaaedadedace",
      "eddbbedcdbccРz a",
      "bedcaacceedd z e",
      "cebccabaccbd Y a",
      "edebcdcbaaab   a"
    ],
    [
      "d         c     ",
      "cdd             ",
      "a               ",
      "  c  d    c     ",
      " Ob Oc    bdceaa",
      "  d  П     b  x ",
      "           e    ",
      "  e  b          ",
      " Oe Od          ",
      "  a  a          ",
      "           a    ",
      "  c  a     e e d",
      " Oc Ob     e zУc",
      "  b  d     e zСd",
      "edaeeec   cc Y e",
      "  a  b     c   e"
    ],
    [
      "          c     ",
      "                ",
      "                ",
      "          c     ",
      "  Ѥ  Ѥ    abcNNN",
      "           b  k ",
      "           c    ",
      "                ",
      "  Ѥ  Ѥ          ",
      "                ",
      "           c    ",
      "           a b b",
      "  Ѥ  Ѥ     e z c",
      "           d zУb",
      "accebeb   ce YСb",
      "     c     b   b"
    ],
    [
      "          d     ",
      "                ",
      "                ",
      "          a     ",
      "          ccbѴ Ѳ",
      "           e  k ",
      "           d    ",
      "                ",
      "                ",
      "                ",
      "           a    ",
      "           c b e",
      "           d z d",
      "           d z c",
      "daecceb   bd道zУa",
      "     c     eeccd"
    ],
    [
      "          e     ",
      "          j     ",
      "          j     ",
      "          a     ",
      "          dadcce",
      "           a    ",
      "           d    ",
      "           j    ",
      "           j    ",
      "           j    ",
      "           a    ",
      "           ccbee",
      "           b z e",
      "           e道z a",
      "badbcadjjjdc小Y c",
      "     e     c   c"
    ],
    [
      "          c     ",
      "          a     ",
      "          d     ",
      "          b     ",
      "          cdaacd",
      "           d    ",
      "           d    ",
      "           a    ",
      "           c    ",
      "           a    ",
      "           b    ",
      "           bbddc",
      "           c道z d",
      "           d小z a",
      "edaaeccddcdc Y b",
      "     d     e   a"
    ]
  ]
}