{
  "xsize": 16,
  "zsize": 16,
  "palette": {
    "palette": [
      {
        "char": " ",
        "block": "minecraft:air"
      },
      {
        "char": "a",
        "block": "minecraft:cyan_terracotta"
      },
      {
        "char": "c",
        "block": "minecraft:deepslate[axis\u003dy]"
      },
      {
        "char": "g",
        "block": "minecraft:gray_concrete"
      },
      {
        "char": "b",
        "block": "minecraft:blackstone"
      },
      {
        "char": "d",
        "block": "minecraft:cobbled_deepslate"
      },
      {
        "char": "e",
        "block": "minecraft:basalt[axis\u003dy]"
      },
      {
        "char": "f",
        "block": "minecraft:glass"
      },
      {
        "char": "ϕ",
        "block": "minecraft:quartz_stairs[facing\u003dnorth,half\u003dbottom,shape\u003dstraight,waterlogged\u003dfalse]"
      },
      {
        "char": "x",
        "block": "minecraft:cauldron"
      },
      {
        "char": "s",
        "block": "minecraft:iron_trapdoor[facing\u003dnorth,half\u003dbottom,open\u003dfalse,powered\u003dfalse,waterlogged\u003dfalse]"
      },
      {
        "char": "i",
        "block": "minecraft:light_gray_concrete"
      },
      {
        "char": "Ҝ",
        "block": "refurbished_furniture:computer[facing\u003dsouth,powered\u003dfalse]",
        "tag": {
          "z": -292,
          "x": -29,
          "id": "refurbished_furniture:computer",
          "y": 63,
          "NodePos": "-7696582590401L",
          "Connections": [
            "L"
          ]
        }
      },
      {
        "char": "k",
        "block": "minecraft:air"
      },
      {
        "char": "p",
        "block": "minecraft:iron_trapdoor[facing\u003dnorth,half\u003dtop,open\u003dfalse,powered\u003dfalse,waterlogged\u003dfalse]"
      },
      {
        "char": "I",
        "block": "minecraft:stone_slab[type\u003dtop,waterlogged\u003dfalse,weathering\u003dfalse]"
      }
    ]
  },
  "slices": [
    [
      "                ",
      "                ",
      "                ",
      "                ",
      "                ",
      "                ",
      " a              ",
      "caccaa  a       ",
      "aaaagabdaa      ",
      "cadaabagaa      ",
      "cdcbdcbdda      ",
      "cbbbccceda      ",
      "eebedaaaaa      ",
      "eaacabedba      ",
      "baaacdbecg      ",
      "aceddcabaag     "
    ],
    [
      "                ",
      "                ",
      "                ",
      "                ",
      "                ",
      "                ",
      " a              ",
      " e      a       ",
      "faff    aa      ",
      " c    ffa       ",
      " e ϕ    b       ",
      " b      e       ",
      "eadba  xd       ",
      " c      b       ",
      " d      d       ",
      "bdd  bcbb g     "
    ],
    [
      "                ",
      "                ",
      "                ",
      "                ",
      "                ",
      "                ",
      " a              ",
      "sdssss  a       ",
      "fiffffssga      ",
      " d    ffa       ",
      " e      c       ",
      " d      d       ",
      " a Ҝ   ka       ",
      " a      d       ",
      " e      d       ",
      "eae  ccbc a     "
    ],
    [
      "                ",
      "                ",
      "                ",
      "                ",
      "                ",
      "                ",
      " g              ",
      "papppp  a       ",
      "faffffppia      ",
      " e    f i       ",
      " d      b       ",
      " c      a       ",
      " e     ke       ",
      " d      c       ",
      " a      e       ",
      "cee  ccec g     "
    ],
    [
      "                ",
      "                ",
      "                ",
      "                ",
      "                ",
      "                ",
      " a              ",
      " b      g       ",
      " afff   aa      ",
      " a    ffg       ",
      " d      b       ",
      " d      b       ",
      " c      d       ",
      " d      a       ",
      " c      b       ",
      "dabIIcaea a     "
    ],
    [
      "                ",
      "                ",
      "                ",
      "                ",
      "                ",
      "                ",
      " a              ",
      "bcdebd  a       ",
      "gaggaaadaa      ",
      " a    gga       ",
      " b      b       ",
      " d      e       ",
      " c      b       ",
      " b      d       ",
      " e      b       ",
      "deedacbdd a     "
    ]
  ]
}