{
  "xsize": 16,
  "zsize": 16,
  "palette": {
    "palette": [
      {
        "char": " ",
        "block": "minecraft:air"
      },
      {
        "char": "b",
        "block": "minecraft:blackstone"
      },
      {
        "char": "e",
        "block": "minecraft:basalt[axis\u003dy]"
      },
      {
        "char": "c",
        "block": "minecraft:deepslate[axis\u003dy]"
      },
      {
        "char": "a",
        "block": "minecraft:cyan_terracotta"
      },
      {
        "char": "d",
        "block": "minecraft:cobbled_deepslate"
      },
      {
        "char": "g",
        "block": "minecraft:gray_concrete"
      },
      {
        "char": "Р",
        "block": "minecraft:stone_brick_stairs[facing\u003dnorth,half\u003dbottom,shape\u003dstraight,waterlogged\u003dfalse,weathering\u003dfalse]"
      },
      {
        "char": "z",
        "block": "minecraft:iron_bars[east\u003dfalse,north\u003dtrue,south\u003dtrue,waterlogged\u003dfalse,west\u003dfalse]"
      },
      {
        "char": "Y",
        "block": "minecraft:iron_bars[east\u003dfalse,north\u003dtrue,south\u003dfalse,waterlogged\u003dfalse,west\u003dfalse]"
      },
      {
        "char": "f",
        "block": "minecraft:glass"
      },
      {
        "char": "x",
        "block": "minecraft:cauldron"
      },
      {
        "char": "У",
        "block": "minecraft:stone_brick_stairs[facing\u003dsouth,half\u003dbottom,shape\u003dstraight,waterlogged\u003dfalse,weathering\u003dfalse]"
      },
      {
        "char": "С",
        "block": "minecraft:stone_brick_stairs[facing\u003dnorth,half\u003dtop,shape\u003dstraight,waterlogged\u003dfalse,weathering\u003dfalse]"
      },
      {
        "char": "如",
        "block": "immersive_weathering:exposed_iron_trapdoor[facing\u003dnorth,half\u003dbottom,open\u003dfalse,powered\u003dfalse,waterlogged\u003dfalse]"
      },
      {
        "char": "s",
        "block": "minecraft:iron_trapdoor[facing\u003dnorth,half\u003dbottom,open\u003dfalse,powered\u003dfalse,waterlogged\u003dfalse]"
      },
      {
        "char": "了",
        "block": "immersive_weathering:exposed_iron_trapdoor[facing\u003dwest,half\u003dbottom,open\u003dfalse,powered\u003dfalse,waterlogged\u003dfalse]"
      },
      {
        "char": "m",
        "block": "minecraft:iron_trapdoor[facing\u003dwest,half\u003dbottom,open\u003dfalse,powered\u003dfalse,waterlogged\u003dfalse]"
      },
      {
        "char": "k",
        "block": "minecraft:air"
      },
      {
        "char": "p",
        "block": "minecraft:iron_trapdoor[facing\u003dnorth,half\u003dtop,open\u003dfalse,powered\u003dfalse,waterlogged\u003dfalse]"
      },
      {
        "char": "q",
        "block": "minecraft:iron_trapdoor[facing\u003dwest,half\u003dtop,open\u003dfalse,powered\u003dfalse,waterlogged\u003dfalse]"
      },
      {
        "char": "у",
        "block": "minecraft:stone_brick_stairs[facing\u003dsouth,half\u003dtop,shape\u003dstraight,waterlogged\u003dfalse,weathering\u003dfalse]"
      },
      {
        "char": "I",
        "block": "minecraft:stone_slab[type\u003dtop,waterlogged\u003dfalse,weathering\u003dfalse]"
      }
    ]
  },
  "slices": [
    [
      "         bbecada",
      "       aabdbabda",
      "      caebaeacaa",
      "     cbcedbdeaee",
      "    addecbeaebae",
      "  a dcdedecaebcc",
      "aggeebbedbdedebd",
      "acedeebcacacbbaa",
      "bcbbcbadbebdaede",
      "edaeaaedecbbcecb",
      "acdaecbaceebcace",
      "bceceadbbacaacdb",
      "dbaccebcaabeРz a",
      "debeddacecbc z d",
      "addcddcedadb Y b",
      "ebdeccdbaddc   e"
    ],
    [
      "         e      ",
      "         d      ",
      "       ff       ",
      "                ",
      "     f          ",
      "  a  f          ",
      "   bb     x     ",
      "eeebaacbedbd   d",
      "  b  x  x       ",
      "  a             ",
      "  e             ",
      "           d a a",
      "           a zУc",
      "  b        a zСe",
      "cbe        c Y e",
      "  a        b   d"
    ],
    [
      "         a      ",
      "       如sd      ",
      "      了ff       ",
      "     m          ",
      "    mf          ",
      "  a mf          ",
      "   dc     k     ",
      "dbabadcbeccb   d",
      "  e  k  k       ",
      "  c             ",
      "  a             ",
      "           d d c",
      "           a z e",
      "  c        c zУb",
      "bbb        a YСd",
      "  e        a   e"
    ],
    [
      "         b      ",
      "       ppe      ",
      "      qff       ",
      "     p          ",
      "    qf          ",
      "  a qf          ",
      "   ae     k     ",
      "addaacbbabed   a",
      "  e  k  k       ",
      "  c             ",
      "  d             ",
      "           c a c",
      "           b z d",
      "  b        a z b",
      "bce        cуzУc",
      "  c        daeda"
    ],
    [
      "         c      ",
      "         e      ",
      "       ff       ",
      "      f         ",
      "     f          ",
      "  a  f          ",
      "   ad           ",
      "bcccaeddcbebIIIa",
      "  d             ",
      "  a             ",
      "  a             ",
      "  I        cbace",
      "  I        a z e",
      "  a        eуz b",
      "dbc        cРY b",
      "  d        e   e"
    ],
    [
      "         b      ",
      "       aa       ",
      "      eba       ",
      "     eb         ",
      "    bc          ",
      "  a be          ",
      "   b            ",
      "cdcccccabeaceeac",
      "  c             ",
      "  b             ",
      "  c             ",
      "  a        ddbae",
      "  d        bуz e",
      "  d        aРz c",
      "caa        c Y d",
      "  d        c   b"
    ]
  ]
}