{
  "xsize": 16,
  "zsize": 16,
  "palette": {
    "palette": [
      {
        "char": " ",
        "block": "minecraft:air"
      },
      {
        "char": "a",
        "block": "minecraft:cyan_terracotta"
      },
      {
        "char": "e",
        "block": "minecraft:basalt[axis\u003dy]"
      },
      {
        "char": "c",
        "block": "minecraft:deepslate[axis\u003dy]"
      },
      {
        "char": "b",
        "block": "minecraft:blackstone"
      },
      {
        "char": "d",
        "block": "minecraft:cobbled_deepslate"
      },
      {
        "char": "Р",
        "block": "minecraft:stone_brick_stairs[facing\u003dnorth,half\u003dbottom,shape\u003dstraight,waterlogged\u003dfalse,weathering\u003dfalse]"
      },
      {
        "char": "z",
        "block": "minecraft:iron_bars[east\u003dfalse,north\u003dtrue,south\u003dtrue,waterlogged\u003dfalse,west\u003dfalse]"
      },
      {
        "char": "Y",
        "block": "minecraft:iron_bars[east\u003dfalse,north\u003dtrue,south\u003dfalse,waterlogged\u003dfalse,west\u003dfalse]"
      },
      {
        "char": "f",
        "block": "minecraft:glass"
      },
      {
        "char": "O",
        "block": "minecraft:quartz_stairs[facing\u003dwest,half\u003dbottom,shape\u003dstraight,waterlogged\u003dfalse]"
      },
      {
        "char": "П",
        "block": "minecraft:barrel[facing\u003dup,open\u003dfalse]",
        "tag": {
          "z": -275,
          "x": -15,
          "ForgeData": {
            "LockFlag": "1b"
          },
          "id": "minecraft:barrel",
          "y": 2,
          "Items": []
        }
      },
      {
        "char": "x",
        "block": "minecraft:cauldron"
      },
      {
        "char": "У",
        "block": "minecraft:stone_brick_stairs[facing\u003dsouth,half\u003dbottom,shape\u003dstraight,waterlogged\u003dfalse,weathering\u003dfalse]"
      },
      {
        "char": "С",
        "block": "minecraft:stone_brick_stairs[facing\u003dnorth,half\u003dtop,shape\u003dstraight,waterlogged\u003dfalse,weathering\u003dfalse]"
      },
      {
        "char": "Ѥ",
        "block": "refurbished_furniture:computer[facing\u003deast,powered\u003dfalse]",
        "tag": {
          "z": -276,
          "x": -43,
          "id": "refurbished_furniture:computer",
          "y": -39,
          "NodePos": "-11544873218087L",
          "Connections": [
            "L"
          ]
        }
      },
      {
        "char": "N",
        "block": "minecraft:white_stained_glass_pane[east\u003dtrue,north\u003dfalse,south\u003dfalse,waterlogged\u003dfalse,west\u003dtrue]"
      },
      {
        "char": "k",
        "block": "minecraft:air"
      },
      {
        "char": "у",
        "block": "minecraft:stone_brick_stairs[facing\u003dsouth,half\u003dtop,shape\u003dstraight,waterlogged\u003dfalse,weathering\u003dfalse]"
      },
      {
        "char": "j",
        "block": "minecraft:polished_andesite_slab[type\u003dtop,waterlogged\u003dfalse]"
      }
    ]
  },
  "slices": [
    [
      "aecbebacdbdbdbbd",
      "aebacebbcdbdabdd",
      "dabcbacdcdccebad",
      "aebeeedbebbceada",
      "bcdaccdeeaaababc",
      "abcdcbeedbabeebc",
      "cdeaeccabceedacd",
      "bdddaaceeacdcebc",
      "ccdaaeaeeddddadb",
      "dbcadbcbceccddbb",
      "aaecceabeadebbbb",
      "dcccaccbebdcabca",
      "bcecaeccbbadРz a",
      "addcecacadbb z c",
      "ceedcedbbcbc Y a",
      "eedabdddceda   c"
    ],
    [
      "f   Oc    e     ",
      "     П          ",
      "                ",
      "  c  c    a     ",
      " Oa Oc    bacbee",
      "  e  e     b  x ",
      "           c    ",
      "  c  d          ",
      " Oa Od          ",
      "  b  a          ",
      "           c    ",
      "  a  П     b c c",
      " Oa Oa     c zУe",
      "  e  e     a zСa",
      "ddacbeb   bd Y a",
      "  a  d     d   d"
    ],
    [
      "f    Ѥ    b     ",
      "                ",
      "                ",
      "          e     ",
      "  Ѥ  Ѥ    cadNNN",
      "           a  k ",
      "           e    ",
      "                ",
      "  Ѥ  Ѥ          ",
      "                ",
      "           e    ",
      "           e c a",
      "  Ѥ  Ѥ     e z b",
      "           b zУc",
      "acccccd   ee YСc",
      "     b     b   c"
    ],
    [
      "f         e     ",
      "                ",
      "                ",
      "          b     ",
      "          dceNNN",
      "           a  k ",
      "           e    ",
      "                ",
      "                ",
      "                ",
      "           e    ",
      "           e d d",
      "           d z c",
      "           c z e",
      "ddecbbb   aaуzУd",
      "     c     aedbc"
    ],
    [
      "f         b     ",
      "          j     ",
      "          j     ",
      "          d     ",
      "          dacccd",
      "           c    ",
      "           d    ",
      "           j    ",
      "           j    ",
      "           j    ",
      "           b    ",
      "           dbbcb",
      "           c z d",
      "           dуz d",
      "aabbdbcjjjeeРY b",
      "     c     b   d"
    ],
    [
      "a         d     ",
      "          b     ",
      "          c     ",
      "          a     ",
      "          aabeda",
      "           d    ",
      "           c    ",
      "           b    ",
      "           d    ",
      "           b    ",
      "           b    ",
      "           deedb",
      "           dуz c",
      "           eРz d",
      "ebdbbcabcacc Y a",
      "     c     c   c"
    ]
  ]
}