{
  "xsize": 16,
  "zsize": 16,
  "palette": {
    "palette": [
      {
        "char": " ",
        "block": "minecraft:air"
      },
      {
        "char": "b",
        "block": "minecraft:blackstone"
      },
      {
        "char": "e",
        "block": "minecraft:basalt[axis\u003dy]"
      },
      {
        "char": "d",
        "block": "minecraft:cobbled_deepslate"
      },
      {
        "char": "a",
        "block": "minecraft:cyan_terracotta"
      },
      {
        "char": "c",
        "block": "minecraft:deepslate[axis\u003dy]"
      },
      {
        "char": "i",
        "block": "minecraft:light_gray_concrete"
      },
      {
        "char": "ϕ",
        "block": "minecraft:quartz_stairs[facing\u003dnorth,half\u003dbottom,shape\u003dstraight,waterlogged\u003dfalse]"
      },
      {
        "char": "O",
        "block": "minecraft:quartz_stairs[facing\u003dwest,half\u003dbottom,shape\u003dstraight,waterlogged\u003dfalse]"
      },
      {
        "char": "ϓ",
        "block": "refurbished_furniture:spruce_table[east\u003dfalse,north\u003dfalse,south\u003dfalse,west\u003dfalse]"
      },
      {
        "char": "ϔ",
        "block": "minecraft:quartz_stairs[facing\u003deast,half\u003dbottom,shape\u003dstraight,waterlogged\u003dfalse]"
      },
      {
        "char": "f",
        "block": "minecraft:glass"
      },
      {
        "char": "x",
        "block": "minecraft:cauldron"
      },
      {
        "char": "m",
        "block": "minecraft:iron_trapdoor[facing\u003dwest,half\u003dbottom,open\u003dfalse,powered\u003dfalse,waterlogged\u003dfalse]"
      },
      {
        "char": "k",
        "block": "minecraft:air"
      },
      {
        "char": "u",
        "block": "minecraft:iron_trapdoor[facing\u003dsouth,half\u003dbottom,open\u003dfalse,powered\u003dfalse,waterlogged\u003dfalse]"
      },
      {
        "char": "q",
        "block": "minecraft:iron_trapdoor[facing\u003dwest,half\u003dtop,open\u003dfalse,powered\u003dfalse,waterlogged\u003dfalse]"
      },
      {
        "char": "w",
        "block": "minecraft:iron_trapdoor[facing\u003dsouth,half\u003dtop,open\u003dfalse,powered\u003dfalse,waterlogged\u003dfalse]"
      },
      {
        "char": "I",
        "block": "minecraft:stone_slab[type\u003dtop,waterlogged\u003dfalse,weathering\u003dfalse]"
      },
      {
        "char": "ϗ",
        "block": "minecraft:stone_brick_wall[east\u003dnone,north\u003dnone,south\u003dnone,up\u003dtrue,waterlogged\u003dfalse,weathering\u003dfalse,west\u003dnone]"
      }
    ]
  },
  "slices": [
    [
      "bebddbabedcccbeb",
      "dcbbaebbbeeacbab",
      "aeeeeeeebddaadcd",
      "eecdcbcdbdaeddee",
      "ccbeebabdccbacda",
      "aeeecbcbeaeacdbc",
      "aaidaabacbbccedb",
      "  a bcdabceaabcc",
      "    ccaebaeabaac",
      "     cddebcbacae",
      "      aedbeade  ",
      "       ddceee   ",
      "         cab    ",
      "                ",
      "                ",
      "                "
    ],
    [
      "           caace",
      "                ",
      "  c             ",
      "  c             ",
      "  c   ϕ   bed   ",
      "ecb  Oϓϔ  a     ",
      "   dee    a     ",
      "  a  f    cx    ",
      "          b     ",
      "      f   d     ",
      "         ba     ",
      "         cb     ",
      "         e e    ",
      "                ",
      "                ",
      "                "
    ],
    [
      "           cccee",
      "                ",
      "  c             ",
      "  c             ",
      "  e       ccc   ",
      "eac       b     ",
      "   cad    b     ",
      "  a mf    ck    ",
      "    mf    c     ",
      "     m    b     ",
      "      mffed     ",
      "       uuad     ",
      "         e d    ",
      "                ",
      "                ",
      "                "
    ],
    [
      "           cdecb",
      "                ",
      "  b             ",
      "  c             ",
      "  a       dec   ",
      "bba       b     ",
      "   dac    c     ",
      "  i qf    dk    ",
      "    qf    a     ",
      "     wf   c     ",
      "      qf cc     ",
      "       wwc  a   ",
      "                ",
      "                ",
      "                ",
      "                "
    ],
    [
      "  I        aecad",
      "  I             ",
      "  d             ",
      "  a             ",
      "  e       cadIII",
      "eda       d     ",
      "   eeb    d     ",
      "  a  f    e     ",
      "     f    c     ",
      "      f   e     ",
      "       ffa      ",
      "         c  b   ",
      "                ",
      "                ",
      "                ",
      "                "
    ],
    [
      "  e        debaa",
      "  b             ",
      "  b             ",
      "  d             ",
      "  a       cebdce",
      "abc       a     ",
      "   dea    a     ",
      "  a eb    e     ",
      "    aa    d     ",
      "     ba   b     ",
      "      eaee      ",
      "       ea   ϗ   ",
      "                ",
      "                ",
      "                ",
      "                "
    ]
  ]
}