{
  "xsize": 16,
  "zsize": 16,
  "palette": {
    "palette": [
      {
        "char": " ",
        "block": "minecraft:air"
      },
      {
        "char": "a",
        "block": "minecraft:cyan_terracotta"
      },
      {
        "char": "d",
        "block": "minecraft:cobbled_deepslate"
      },
      {
        "char": "e",
        "block": "minecraft:basalt[axis\u003dy]"
      },
      {
        "char": "c",
        "block": "minecraft:deepslate[axis\u003dy]"
      },
      {
        "char": "b",
        "block": "minecraft:blackstone"
      },
      {
        "char": "g",
        "block": "minecraft:gray_concrete"
      },
      {
        "char": "i",
        "block": "minecraft:light_gray_concrete"
      },
      {
        "char": "ϔ",
        "block": "minecraft:quartz_stairs[facing\u003deast,half\u003dbottom,shape\u003dstraight,waterlogged\u003dfalse]"
      },
      {
        "char": "f",
        "block": "minecraft:glass"
      },
      {
        "char": "x",
        "block": "minecraft:cauldron"
      },
      {
        "char": "H",
        "block": "minecraft:quartz_stairs[facing\u003dsouth,half\u003dbottom,shape\u003dstraight,waterlogged\u003dfalse]"
      },
      {
        "char": "Ӻ",
        "block": "refurbished_furniture:computer[facing\u003dwest,powered\u003dfalse]",
        "tag": {
          "z": -276,
          "x": -15,
          "id": "refurbished_furniture:computer",
          "y": 27,
          "NodePos": "-3848291827685L",
          "Connections": [
            "L"
          ]
        }
      },
      {
        "char": "l",
        "block": "minecraft:iron_trapdoor[facing\u003deast,half\u003dbottom,open\u003dfalse,powered\u003dfalse,waterlogged\u003dfalse]"
      },
      {
        "char": "k",
        "block": "minecraft:air"
      },
      {
        "char": "ϐ",
        "block": "refurbished_furniture:computer[facing\u003dnorth,powered\u003dfalse]",
        "tag": {
          "z": -259,
          "x": -34,
          "id": "refurbished_furniture:computer",
          "y": -21,
          "NodePos": "-9070971985941L",
          "Connections": [
            "L"
          ]
        }
      },
      {
        "char": "u",
        "block": "minecraft:iron_trapdoor[facing\u003dsouth,half\u003dbottom,open\u003dfalse,powered\u003dfalse,waterlogged\u003dfalse]"
      },
      {
        "char": "Ӟ",
        "block": "immersive_weathering:exposed_iron_trapdoor[facing\u003deast,half\u003dbottom,open\u003dfalse,powered\u003dfalse,waterlogged\u003dfalse]"
      },
      {
        "char": "t",
        "block": "minecraft:iron_trapdoor[facing\u003deast,half\u003dtop,open\u003dfalse,powered\u003dfalse,waterlogged\u003dfalse]"
      },
      {
        "char": "w",
        "block": "minecraft:iron_trapdoor[facing\u003dsouth,half\u003dtop,open\u003dfalse,powered\u003dfalse,waterlogged\u003dfalse]"
      },
      {
        "char": "在",
        "block": "immersive_weathering:exposed_iron_trapdoor[facing\u003deast,half\u003dtop,open\u003dfalse,powered\u003dfalse,waterlogged\u003dfalse]"
      }
    ]
  },
  "slices": [
    [
      "addeecbgd       ",
      "ebacdbcge       ",
      "baacaeeia       ",
      "ccdbcbac        ",
      "deceedgb        ",
      "dcbadaaeg       ",
      "eebaaciaa       ",
      "dacbeabi        ",
      "cceedaei        ",
      "cdcbaag         ",
      "eacbaea         ",
      "cbeaea          ",
      "aciegg          ",
      "bagca           ",
      "eida            ",
      "adg             "
    ],
    [
      "b ϔ    f        ",
      "c      f        ",
      "aeb    f        ",
      "      f         ",
      "      f         ",
      "cdabdbaba       ",
      "  x   f         ",
      "     f          ",
      "     f          ",
      "    f           ",
      "cb  f           ",
      "H   e           ",
      "  f  g          ",
      "  f             ",
      " f              ",
      "f               "
    ],
    [
      "Ӻ      fl       ",
      "       fl       ",
      "       fl       ",
      "      fl        ",
      "      fl        ",
      "dacedeaaa       ",
      "  k   fl        ",
      "     fl         ",
      "     fl         ",
      "    fl          ",
      "ϐ   fl          ",
      "   fb           ",
      "  fu g          ",
      "  fl            ",
      "  l             ",
      "fӞ              "
    ],
    [
      "       ft       ",
      "       ft       ",
      "       ft       ",
      "       t        ",
      "      ft        ",
      "dddaebgba       ",
      "  k   ft        ",
      "      t         ",
      "     ft         ",
      "    ft          ",
      "     t          ",
      "   fa           ",
      "  fw i          ",
      "   t            ",
      " f在             ",
      "fw              "
    ],
    [
      "       f        ",
      "       f        ",
      "       f        ",
      "      f         ",
      "                ",
      "bbbdbcgai       ",
      "      f         ",
      "     f          ",
      "                ",
      "    f           ",
      "    f           ",
      "   fe           ",
      "  f  a          ",
      "                ",
      "                ",
      "f               "
    ],
    [
      "       ga       ",
      "       ab       ",
      "       ad       ",
      "      gb        ",
      "      aa        ",
      "dadeddaba       ",
      "      aa        ",
      "     ad         ",
      "     aa         ",
      "    gc          ",
      "    ac          ",
      "   gb           ",
      "  ab a          ",
      "  ad            ",
      " ae             ",
      "ae              "
    ]
  ]
}