{
  "xsize": 16,
  "zsize": 16,
  "palette": {
    "palette": [
      {
        "char": " ",
        "block": "minecraft:air"
      },
      {
        "char": "d",
        "block": "minecraft:cobbled_deepslate"
      },
      {
        "char": "c",
        "block": "minecraft:deepslate[axis\u003dy]"
      },
      {
        "char": "b",
        "block": "minecraft:blackstone"
      },
      {
        "char": "a",
        "block": "minecraft:cyan_terracotta"
      },
      {
        "char": "e",
        "block": "minecraft:basalt[axis\u003dy]"
      },
      {
        "char": "Z",
        "block": "minecraft:stone_brick_wall[east\u003dtall,north\u003dtall,south\u003dnone,up\u003dtrue,waterlogged\u003dfalse,weathering\u003dfalse,west\u003dtall]"
      },
      {
        "char": "G",
        "block": "minecraft:iron_bars[east\u003dfalse,north\u003dfalse,south\u003dtrue,waterlogged\u003dfalse,west\u003dfalse]"
      },
      {
        "char": "H",
        "block": "minecraft:quartz_stairs[facing\u003dsouth,half\u003dbottom,shape\u003dstraight,waterlogged\u003dfalse]"
      },
      {
        "char": "ϕ",
        "block": "minecraft:quartz_stairs[facing\u003dnorth,half\u003dbottom,shape\u003dstraight,waterlogged\u003dfalse]"
      },
      {
        "char": "O",
        "block": "minecraft:quartz_stairs[facing\u003dwest,half\u003dbottom,shape\u003dstraight,waterlogged\u003dfalse]"
      },
      {
        "char": "ϓ",
        "block": "refurbished_furniture:spruce_table[east\u003dfalse,north\u003dfalse,south\u003dfalse,west\u003dfalse]"
      },
      {
        "char": "x",
        "block": "minecraft:cauldron"
      },
      {
        "char": "v",
        "block": "minecraft:quartz_pillar[axis\u003dx]"
      },
      {
        "char": "n",
        "block": "minecraft:smooth_quartz"
      },
      {
        "char": "Ѳ",
        "block": "minecraft:white_stained_glass_pane[east\u003dtrue,north\u003dfalse,south\u003dfalse,waterlogged\u003dfalse,west\u003dfalse]"
      },
      {
        "char": "N",
        "block": "minecraft:white_stained_glass_pane[east\u003dtrue,north\u003dfalse,south\u003dfalse,waterlogged\u003dfalse,west\u003dtrue]"
      },
      {
        "char": "k",
        "block": "minecraft:air"
      },
      {
        "char": "o",
        "block": "minecraft:chiseled_quartz_block"
      },
      {
        "char": "j",
        "block": "minecraft:polished_andesite_slab[type\u003dtop,waterlogged\u003dfalse]"
      }
    ]
  },
  "slices": [
    [
      "dcbdddaeabddbeaa",
      "ebceeadedbbddddd",
      "accaceecaaaecbbc",
      "abbdeabecccabbcc",
      "eeacaeaaebaccaee",
      "cbeecbeddbdebdbd",
      "caeedababdabbeca",
      "abaeaebbabbcedea",
      "dbcccacdbceeebad",
      "eacecbebedcbcabd",
      "deeebcabbaabcbaa",
      "acdcbcaeceddddbb",
      "ZZZaZZZddbddccde",
      "   e   becbdbbbe",
      "   a   bcebacdad",
      " G b G cbaeceaab"
    ],
    [
      " c      e  H    ",
      " b             ϕ",
      " c            Oϓ",
      " d      c      H",
      "cedceaebe       ",
      " c  x  e        ",
      "       c        ",
      "             eeb",
      "             c  ",
      "             d  ",
      "       d     a  ",
      "   a   d        ",
      "vvnavvvd        ",
      "   d   c     c  ",
      "   a   de   cbea",
      " G a G d     d  "
    ],
    [
      " d      a       ",
      " e              ",
      " a              ",
      " a      e       ",
      "dcb ѲNaab       ",
      " b  k  a        ",
      "       e        ",
      "             bba",
      "             c  ",
      "             c  ",
      "       d     a  ",
      "   e   c        ",
      "vvvevooa        ",
      "   b   a     a  ",
      "   a   da   dbee",
      " G b G c     d  "
    ],
    [
      " c      d       ",
      " a              ",
      " c              ",
      " e      c       ",
      "ade ѲNebc       ",
      " a  k  a        ",
      "       e        ",
      "             ebb",
      "             b  ",
      "             e  ",
      "       e     a  ",
      "   e   d        ",
      "vvvbvvvc        ",
      "   d   d     d  ",
      "   e   cc   ddcd",
      " G d G b     b  "
    ],
    [
      " b      e       ",
      " a      j       ",
      " e      j       ",
      " e      a       ",
      "ccacadcad       ",
      " e     b        ",
      "       c        ",
      "       j     bce",
      "       j     a  ",
      "       j     b  ",
      "       e     b  ",
      "jjjejjjc     j  ",
      "vvvcvova     j  ",
      "   e   d     c  ",
      "   e   cajjjcbdc",
      " G c G b     c  "
    ],
    [
      " b      a       ",
      " e      d       ",
      " d      e       ",
      " a      b       ",
      "dcbcbaaad       ",
      " b     d        ",
      "       b        ",
      "       d     cee",
      "       b     e  ",
      "       c     b  ",
      "       b     a  ",
      "eadabadb     c  ",
      "   a   b     d  ",
      "   a   b     e  ",
      "   d   dbbbacbec",
      " G e G a     b  "
    ]
  ]
}