{
  "xsize": 16,
  "zsize": 16,
  "palette": {
    "palette": [
      {
        "char": " ",
        "block": "minecraft:air"
      },
      {
        "char": "e",
        "block": "minecraft:basalt[axis\u003dy]"
      },
      {
        "char": "d",
        "block": "minecraft:cobbled_deepslate"
      },
      {
        "char": "c",
        "block": "minecraft:deepslate[axis\u003dy]"
      },
      {
        "char": "b",
        "block": "minecraft:blackstone"
      },
      {
        "char": "a",
        "block": "minecraft:cyan_terracotta"
      },
      {
        "char": "Ӿ",
        "block": "minecraft:cobblestone_wall[east\u003dtall,north\u003dtall,south\u003dnone,up\u003dtrue,waterlogged\u003dfalse,weathering\u003dfalse,west\u003dtall]"
      },
      {
        "char": "Z",
        "block": "minecraft:stone_brick_wall[east\u003dtall,north\u003dtall,south\u003dnone,up\u003dtrue,waterlogged\u003dfalse,weathering\u003dfalse,west\u003dtall]"
      },
      {
        "char": "G",
        "block": "minecraft:iron_bars[east\u003dfalse,north\u003dfalse,south\u003dtrue,waterlogged\u003dfalse,west\u003dfalse]"
      },
      {
        "char": "H",
        "block": "minecraft:quartz_stairs[facing\u003dsouth,half\u003dbottom,shape\u003dstraight,waterlogged\u003dfalse]"
      },
      {
        "char": "ϕ",
        "block": "minecraft:quartz_stairs[facing\u003dnorth,half\u003dbottom,shape\u003dstraight,waterlogged\u003dfalse]"
      },
      {
        "char": "O",
        "block": "minecraft:quartz_stairs[facing\u003dwest,half\u003dbottom,shape\u003dstraight,waterlogged\u003dfalse]"
      },
      {
        "char": "ϓ",
        "block": "refurbished_furniture:spruce_table[east\u003dfalse,north\u003dfalse,south\u003dfalse,west\u003dfalse]"
      },
      {
        "char": "x",
        "block": "minecraft:cauldron"
      },
      {
        "char": "v",
        "block": "minecraft:quartz_pillar[axis\u003dx]"
      },
      {
        "char": "N",
        "block": "minecraft:white_stained_glass_pane[east\u003dtrue,north\u003dfalse,south\u003dfalse,waterlogged\u003dfalse,west\u003dtrue]"
      },
      {
        "char": "Ѵ",
        "block": "minecraft:white_stained_glass_pane[east\u003dfalse,north\u003dfalse,south\u003dfalse,waterlogged\u003dfalse,west\u003dtrue]"
      },
      {
        "char": "k",
        "block": "minecraft:air"
      },
      {
        "char": "J",
        "block": "minecraft:diorite"
      },
      {
        "char": "j",
        "block": "minecraft:polished_andesite_slab[type\u003dtop,waterlogged\u003dfalse]"
      },
      {
        "char": "o",
        "block": "minecraft:chiseled_quartz_block"
      }
    ]
  },
  "slices": [
    [
      "eedccbedacddbdcd",
      "badddbaececeaebd",
      "dccdacdbedbbadcb",
      "bdebbcebcaacbbcd",
      "aabddedadccbbaac",
      "cdbaacbacebeabbd",
      "ebccceaebbeededc",
      "aacceecccccaacec",
      "ccbaabcecadecbce",
      "eaebaaddbeaabbbe",
      "cedaaabeceadecca",
      "ddccdecaaceddeba",
      "ӾZZaZӾZccdaacead",
      "   c   ecedcbebc",
      "   a   dabbceadd",
      " G a G eedddeaec"
    ],
    [
      " b      c  H    ",
      " c             ϕ",
      " b            Oϓ",
      " d      a      H",
      "ebacbadeb       ",
      " c  x  d        ",
      "       b        ",
      "             ebc",
      "             d  ",
      "             b  ",
      "       a     c  ",
      "   e   d        ",
      "vvvbvvvd        ",
      "   e   c     e  ",
      "   c   be   bebb",
      " G d G d     e  "
    ],
    [
      " e      b       ",
      " b              ",
      " e              ",
      " a      e       ",
      "dccNѴ aeb       ",
      " e  k  b        ",
      "       b        ",
      "             dcb",
      "             a  ",
      "             b  ",
      "       d     d  ",
      "   e   c        ",
      "vvvcvvvc        ",
      "   a   a     c  ",
      "   c   be   bbce",
      " G d G d     e  "
    ],
    [
      " a      c       ",
      " b              ",
      " a              ",
      " e      d       ",
      "deeNѴ edb       ",
      " c  k  a        ",
      "       c        ",
      "             cca",
      "             e  ",
      "             e  ",
      "       c     c  ",
      "   a   d        ",
      "vvJavJve        ",
      "   d   b     e  ",
      "   d   dc   daec",
      " G c G c     e  "
    ],
    [
      " c      e       ",
      " c      j       ",
      " d      j       ",
      " e      a       ",
      "eddaeeceb       ",
      " e     c        ",
      "       c        ",
      "       j     cec",
      "       j     b  ",
      "       j     e  ",
      "       d     c  ",
      "jjjejjjb     j  ",
      "vvvevovd     j  ",
      "   a   e     e  ",
      "   a   acjjjeadd",
      " G c G b     b  "
    ],
    [
      " b      b       ",
      " e      e       ",
      " c      b       ",
      " e      b       ",
      "eadcaaabd       ",
      " d     d        ",
      "       c        ",
      "       a     cbb",
      "       d     d  ",
      "       d     d  ",
      "       b     e  ",
      "adbcceeb     b  ",
      "   a   c     a  ",
      "   d   d     c  ",
      "   c   ddaeebbdc",
      " G a G c     d  "
    ]
  ]
}