{
  "xsize": 16,
  "zsize": 16,
  "palette": {
    "palette": [
      {
        "char": " ",
        "block": "minecraft:air"
      },
      {
        "char": "d",
        "block": "minecraft:cobbled_deepslate"
      },
      {
        "char": "a",
        "block": "minecraft:cyan_terracotta"
      },
      {
        "char": "c",
        "block": "minecraft:deepslate[axis\u003dy]"
      },
      {
        "char": "b",
        "block": "minecraft:blackstone"
      },
      {
        "char": "e",
        "block": "minecraft:basalt[axis\u003dy]"
      },
      {
        "char": "Z",
        "block": "minecraft:stone_brick_wall[east\u003dtall,north\u003dtall,south\u003dnone,up\u003dtrue,waterlogged\u003dfalse,weathering\u003dfalse,west\u003dtall]"
      },
      {
        "char": "Ӿ",
        "block": "minecraft:cobblestone_wall[east\u003dtall,north\u003dtall,south\u003dnone,up\u003dtrue,waterlogged\u003dfalse,weathering\u003dfalse,west\u003dtall]"
      },
      {
        "char": "G",
        "block": "minecraft:iron_bars[east\u003dfalse,north\u003dfalse,south\u003dtrue,waterlogged\u003dfalse,west\u003dfalse]"
      },
      {
        "char": "H",
        "block": "minecraft:quartz_stairs[facing\u003dsouth,half\u003dbottom,shape\u003dstraight,waterlogged\u003dfalse]"
      },
      {
        "char": "O",
        "block": "minecraft:quartz_stairs[facing\u003dwest,half\u003dbottom,shape\u003dstraight,waterlogged\u003dfalse]"
      },
      {
        "char": "ϓ",
        "block": "refurbished_furniture:spruce_table[east\u003dfalse,north\u003dfalse,south\u003dfalse,west\u003dfalse]"
      },
      {
        "char": "x",
        "block": "minecraft:cauldron"
      },
      {
        "char": "C",
        "block": "minecraft:quartz_pillar[axis\u003dy]"
      },
      {
        "char": "v",
        "block": "minecraft:quartz_pillar[axis\u003dx]"
      },
      {
        "char": "o",
        "block": "minecraft:chiseled_quartz_block"
      },
      {
        "char": "Ѳ",
        "block": "minecraft:white_stained_glass_pane[east\u003dtrue,north\u003dfalse,south\u003dfalse,waterlogged\u003dfalse,west\u003dfalse]"
      },
      {
        "char": "N",
        "block": "minecraft:white_stained_glass_pane[east\u003dtrue,north\u003dfalse,south\u003dfalse,waterlogged\u003dfalse,west\u003dtrue]"
      },
      {
        "char": "k",
        "block": "minecraft:air"
      },
      {
        "char": "n",
        "block": "minecraft:smooth_quartz"
      },
      {
        "char": "K",
        "block": "minecraft:quartz_block"
      },
      {
        "char": "j",
        "block": "minecraft:polished_andesite_slab[type\u003dtop,waterlogged\u003dfalse]"
      },
      {
        "char": "r",
        "block": "minecraft:polished_diorite"
      }
    ]
  },
  "slices": [
    [
      "ddacaabedbcdbc  ",
      "eadcaabdadeceaae",
      "baccbcccddcaebac",
      "edbbabedbdabdada",
      "ebaaaeaaedbbddda",
      "eeedaceabdbeeabd",
      "ededaacdbceecabe",
      "dbcadeebadaacedc",
      "acdaaadedaeeadae",
      "ecdcdeebaeeeaddd",
      "baebcdeecebcddba",
      "cebbababddbdeaec",
      "ZZZbӾZӾdbedecccb",
      "   c   baaadbdbc",
      "   b   acbdecdad",
      " G e G dccebdeed"
    ],
    [
      " d      d  H    ",
      " c              ",
      " d            Oϓ",
      " e      d      H",
      "dacbeebde       ",
      " b  x  b        ",
      "       a        ",
      "             cae",
      "             e  ",
      "             b  ",
      "       a     b  ",
      "   c   e        ",
      "Cvoevvva        ",
      "   b   d     a  ",
      "   c   cc   aabb",
      " G a G a     d  "
    ],
    [
      " d      b       ",
      " b              ",
      " d              ",
      " e      a       ",
      "ebe ѲNabe       ",
      " b  k  c        ",
      "       d        ",
      "             aab",
      "             b  ",
      "             e  ",
      "       c     d  ",
      "   e   b        ",
      "vvndKnvc        ",
      "   c   e     d  ",
      "   a   cc   dcac",
      " G c G d     e  "
    ],
    [
      " d      a       ",
      " d              ",
      " e              ",
      " a      e       ",
      "eabNNNbae       ",
      " b  k  d        ",
      "       d        ",
      "             eab",
      "             a  ",
      "             b  ",
      "       a     c  ",
      "   c   d        ",
      "nvvdvvvd        ",
      "   b   e     e  ",
      "   c   de   abde",
      " G a G c     a  "
    ],
    [
      " b      c       ",
      " b      j       ",
      " b      j       ",
      " d      c       ",
      "adceacdcd       ",
      " a     d        ",
      "       e        ",
      "       j     aab",
      "       j     d  ",
      "       j     a  ",
      "       b     d  ",
      "jjjbjjje     j  ",
      "vordvvvc     j  ",
      "   a   a     e  ",
      "   e   bajjjcdcd",
      " G e G b     c  "
    ],
    [
      " c      b       ",
      " d      b       ",
      " a      c       ",
      " a      e       ",
      "aeeaeddcc       ",
      " b     e        ",
      "       c        ",
      "       e     dbc",
      "       e     b  ",
      "       d     b  ",
      "       c     b  ",
      "ccebabde     e  ",
      "   b   c     c  ",
      "   e   e     e  ",
      "   a   ecedcdaea",
      " G b G d     c  "
    ]
  ]
}