{
  "xsize": 16,
  "zsize": 16,
  "palette": {
    "palette": [
      {
        "char": " ",
        "block": "minecraft:air"
      },
      {
        "char": "a",
        "block": "minecraft:cyan_terracotta"
      },
      {
        "char": "c",
        "block": "minecraft:deepslate[axis\u003dy]"
      },
      {
        "char": "b",
        "block": "minecraft:blackstone"
      },
      {
        "char": "e",
        "block": "minecraft:basalt[axis\u003dy]"
      },
      {
        "char": "d",
        "block": "minecraft:cobbled_deepslate"
      },
      {
        "char": "Р",
        "block": "minecraft:stone_brick_stairs[facing\u003dnorth,half\u003dbottom,shape\u003dstraight,waterlogged\u003dfalse,weathering\u003dfalse]"
      },
      {
        "char": "z",
        "block": "minecraft:iron_bars[east\u003dfalse,north\u003dtrue,south\u003dtrue,waterlogged\u003dfalse,west\u003dfalse]"
      },
      {
        "char": "Y",
        "block": "minecraft:iron_bars[east\u003dfalse,north\u003dtrue,south\u003dfalse,waterlogged\u003dfalse,west\u003dfalse]"
      },
      {
        "char": "f",
        "block": "minecraft:glass"
      },
      {
        "char": "O",
        "block": "minecraft:quartz_stairs[facing\u003dwest,half\u003dbottom,shape\u003dstraight,waterlogged\u003dfalse]"
      },
      {
        "char": "П",
        "block": "minecraft:barrel[facing\u003dup,open\u003dfalse]",
        "tag": {
          "z": -275,
          "x": -15,
          "ForgeData": {
            "LockFlag": "1b"
          },
          "id": "minecraft:barrel",
          "y": 2,
          "Items": []
        }
      },
      {
        "char": "x",
        "block": "minecraft:cauldron"
      },
      {
        "char": "У",
        "block": "minecraft:stone_brick_stairs[facing\u003dsouth,half\u003dbottom,shape\u003dstraight,waterlogged\u003dfalse,weathering\u003dfalse]"
      },
      {
        "char": "机",
        "block": "immersive_weathering:cracked_stone_brick_stairs[facing\u003dnorth,half\u003dtop,shape\u003dstraight,waterlogged\u003dfalse]"
      },
      {
        "char": "Ѥ",
        "block": "refurbished_furniture:computer[facing\u003deast,powered\u003dfalse]",
        "tag": {
          "z": -276,
          "x": -43,
          "id": "refurbished_furniture:computer",
          "y": -39,
          "NodePos": "-11544873218087L",
          "Connections": [
            "L"
          ]
        }
      },
      {
        "char": "Ѳ",
        "block": "minecraft:white_stained_glass_pane[east\u003dtrue,north\u003dfalse,south\u003dfalse,waterlogged\u003dfalse,west\u003dfalse]"
      },
      {
        "char": "N",
        "block": "minecraft:white_stained_glass_pane[east\u003dtrue,north\u003dfalse,south\u003dfalse,waterlogged\u003dfalse,west\u003dtrue]"
      },
      {
        "char": "k",
        "block": "minecraft:air"
      },
      {
        "char": "没",
        "block": "immersive_weathering:cracked_stone_brick_stairs[facing\u003dsouth,half\u003dbottom,shape\u003dstraight,waterlogged\u003dfalse]"
      },
      {
        "char": "С",
        "block": "minecraft:stone_brick_stairs[facing\u003dnorth,half\u003dtop,shape\u003dstraight,waterlogged\u003dfalse,weathering\u003dfalse]"
      },
      {
        "char": "у",
        "block": "minecraft:stone_brick_stairs[facing\u003dsouth,half\u003dtop,shape\u003dstraight,waterlogged\u003dfalse,weathering\u003dfalse]"
      },
      {
        "char": "j",
        "block": "minecraft:polished_andesite_slab[type\u003dtop,waterlogged\u003dfalse]"
      }
    ]
  },
  "slices": [
    [
      "acaacacacabbaebb",
      "acaeebcbebcdaaea",
      "abcbcebbddedddbb",
      "edeeaccdcabdcacc",
      "badbeaacacdddeee",
      "bdacbedddecbbacb",
      "beeccdbaceadbcca",
      "eaabebbabccbdacc",
      "cabaedcedeccdaeb",
      "bcddeabdaedabedd",
      "cbaedebdddcdceac",
      "eabaeebeeeaededb",
      "bdcacccdcabcРz e",
      "cbcdbcddaebc z d",
      "eebbcacacaeb Y a",
      "cecdbaeccbda   a"
    ],
    [
      "f   Ob    c     ",
      "     b          ",
      "                ",
      "  b  b    d     ",
      " Ob Ob    ceeacc",
      "  П  b     d  x ",
      "           a    ",
      "  b  b          ",
      " Ob Ob          ",
      "  b  b          ",
      "           a    ",
      "  b  b     c a b",
      " Ob Ob     b zУa",
      "  b  b     b z机d",
      "adcbaab   de Y b",
      "  a  d     e   c"
    ],
    [
      "f    Ѥ    b     ",
      "                ",
      "                ",
      "          b     ",
      "  Ѥ  Ѥ    edb ѲN",
      "           a  k ",
      "           c    ",
      "                ",
      "  Ѥ  Ѥ          ",
      "                ",
      "           a    ",
      "           b a b",
      "  Ѥ  Ѥ     c z a",
      "           d z没e",
      "eabddaa   ee YСe",
      "     b     d   b"
    ],
    [
      "f         b     ",
      "                ",
      "                ",
      "          a     ",
      "          ddb ѲN",
      "           c  k ",
      "           e    ",
      "                ",
      "                ",
      "                ",
      "           c    ",
      "           e a c",
      "           c z d",
      "           a z e",
      "abbcbad   ccуzУc",
      "     b     eaeac"
    ],
    [
      "f         a     ",
      "          j     ",
      "          j     ",
      "          e     ",
      "          adebcb",
      "           c    ",
      "           b    ",
      "           j    ",
      "           j    ",
      "           j    ",
      "           a    ",
      "           decda",
      "           b z c",
      "           cуz c",
      "baabdbejjjabРY e",
      "     c     e   b"
    ],
    [
      "a         c     ",
      "          b     ",
      "          d     ",
      "          d     ",
      "          dbadde",
      "           c    ",
      "           e    ",
      "           b    ",
      "           c    ",
      "           c    ",
      "           d    ",
      "           aadbb",
      "           aуz a",
      "           aРz c",
      "dedbdebbccba Y b",
      "     c     c   b"
    ]
  ]
}