{
  "xsize": 16,
  "zsize": 16,
  "palette": {
    "palette": [
      {
        "char": " ",
        "block": "minecraft:air"
      },
      {
        "char": "Ѧ",
        "block": "minecraft:quartz_bricks"
      },
      {
        "char": "e",
        "block": "minecraft:basalt[axis\u003dy]"
      },
      {
        "char": "b",
        "block": "minecraft:blackstone"
      },
      {
        "char": "a",
        "block": "minecraft:cyan_terracotta"
      },
      {
        "char": "o",
        "block": "minecraft:chiseled_quartz_block"
      },
      {
        "char": "d",
        "block": "minecraft:cobbled_deepslate"
      },
      {
        "char": "c",
        "block": "minecraft:deepslate[axis\u003dy]"
      },
      {
        "char": "那",
        "block": "minecraft:white_terracotta"
      },
      {
        "char": "g",
        "block": "minecraft:gray_concrete"
      },
      {
        "char": "n",
        "block": "minecraft:smooth_quartz"
      },
      {
        "char": "Z",
        "block": "minecraft:stone_brick_wall[east\u003dtall,north\u003dtall,south\u003dnone,up\u003dtrue,waterlogged\u003dfalse,weathering\u003dfalse,west\u003dtall]"
      },
      {
        "char": "Ӿ",
        "block": "minecraft:cobblestone_wall[east\u003dtall,north\u003dtall,south\u003dnone,up\u003dtrue,waterlogged\u003dfalse,weathering\u003dfalse,west\u003dtall]"
      },
      {
        "char": "G",
        "block": "minecraft:iron_bars[east\u003dfalse,north\u003dfalse,south\u003dtrue,waterlogged\u003dfalse,west\u003dfalse]"
      },
      {
        "char": "P",
        "block": "minecraft:smooth_quartz_slab[type\u003dbottom,waterlogged\u003dfalse]"
      },
      {
        "char": "x",
        "block": "minecraft:cauldron"
      },
      {
        "char": "Ӣ",
        "block": "refurbished_furniture:spruce_chair[facing\u003dwest,tucked\u003dfalse]"
      },
      {
        "char": "ϓ",
        "block": "refurbished_furniture:spruce_table[east\u003dfalse,north\u003dfalse,south\u003dfalse,west\u003dfalse]"
      },
      {
        "char": "Ѻ",
        "block": "refurbished_furniture:spruce_chair[facing\u003dsouth,tucked\u003dfalse]"
      },
      {
        "char": "Ѯ",
        "block": "minecraft:diorite_slab[type\u003dbottom,waterlogged\u003dfalse]"
      },
      {
        "char": "ӝ",
        "block": "refurbished_furniture:spruce_chair[facing\u003dnorth,tucked\u003dfalse]"
      },
      {
        "char": "ӛ",
        "block": "refurbished_furniture:spruce_chair[facing\u003deast,tucked\u003dfalse]"
      },
      {
        "char": "v",
        "block": "minecraft:quartz_pillar[axis\u003dx]"
      },
      {
        "char": "k",
        "block": "minecraft:air"
      },
      {
        "char": "i",
        "block": "minecraft:light_gray_concrete"
      },
      {
        "char": "r",
        "block": "minecraft:polished_diorite"
      },
      {
        "char": "j",
        "block": "minecraft:polished_andesite_slab[type\u003dtop,waterlogged\u003dfalse]"
      },
      {
        "char": "C",
        "block": "minecraft:quartz_pillar[axis\u003dy]"
      },
      {
        "char": "h",
        "block": "minecraft:andesite_slab[type\u003dtop,waterlogged\u003dfalse]"
      },
      {
        "char": "T",
        "block": "minecraft:redstone_lamp[lit\u003dfalse]"
      }
    ]
  },
  "slices": [
    [
      "          Ѧebbab",
      "          obbedb",
      "          Ѧecbca",
      "          那ddeac",
      "          Ѧbcedb",
      "         ggacecd",
      "oѦ那ѦonѦѦѦaadbbbe",
      "ebabbdedadebecdd",
      "acebeacdbcebeaad",
      "eaccadaaedcedbdb",
      "beaaceecadaabdec",
      "dcddbcdeecbdcccd",
      "ZZZaZZӾeeeacaaec",
      "   e   ecdbcdaed",
      "   a   aaccbbaec",
      " G a G babdbacab"
    ],
    [
      "          Px  Ӣϓ",
      "          P    Ѻ",
      "          P     ",
      "          Px    ",
      "          P     ",
      "         aa     ",
      "PPPPѮPPPPga     ",
      "                ",
      "              ӝ ",
      "             Ӣϓӛ",
      "              Ѻ ",
      "   e   b        ",
      "vvvevvnax       ",
      "   b   c      ӝ ",
      "   a   b     Ӣϓӛ",
      " G d G bx     Ѻ "
    ],
    [
      "           k    ",
      "                ",
      "                ",
      "           k    ",
      "                ",
      "         ag     ",
      "         ii     ",
      "                ",
      "                ",
      "                ",
      "                ",
      "   b   e        ",
      "vrvcvvvck       ",
      "   b   a        ",
      "   a   d        ",
      " G b G bk       "
    ],
    [
      "           k    ",
      "                ",
      "                ",
      "           k    ",
      "                ",
      "         aa     ",
      "         aa     ",
      "                ",
      "                ",
      "                ",
      "                ",
      "   c   b        ",
      "vvravvvak       ",
      "   a   d        ",
      "   c   e        ",
      " G b G dk       "
    ],
    [
      "                ",
      "                ",
      "                ",
      "                ",
      "                ",
      "         ia     ",
      "         gi     ",
      "                ",
      "                ",
      "                ",
      "                ",
      "jjjbjjja        ",
      "vvCbvvve        ",
      "   c   d        ",
      "   e   c        ",
      " G c G b        "
    ],
    [
      "hhhhhhhhhhhhhhhh",
      "hhhhhhhhhhhhhhhh",
      "hhhhhhhhhhhhhhhh",
      "hThhhhhhhhhhhhhh",
      "hhhhhhhhhhhhhhhh",
      "hhhhhhhhhaihhhhh",
      "hhhhhhhhhaghhhhh",
      "hhhhhhhhhhhhhhhh",
      "hhhhhhhhhhhhhhhh",
      "hhhhhhhhhhhhhhhh",
      "hhhhhhhhhhhhhhhh",
      "cdebcacchhhhhhhh",
      "adddceadhhhhhhhh",
      "   a   bhhhhhhhh",
      "   b   ahhhhhhhh",
      " G c G chhhhhhhh"
    ]
  ]
}