{
  "xsize": 16,
  "zsize": 16,
  "palette": {
    "palette": [
      {
        "char": " ",
        "block": "minecraft:air"
      },
      {
        "char": "a",
        "block": "minecraft:cyan_terracotta"
      },
      {
        "char": "b",
        "block": "minecraft:blackstone"
      },
      {
        "char": "c",
        "block": "minecraft:deepslate[axis\u003dy]"
      },
      {
        "char": "d",
        "block": "minecraft:cobbled_deepslate"
      },
      {
        "char": "e",
        "block": "minecraft:basalt[axis\u003dy]"
      },
      {
        "char": "g",
        "block": "minecraft:gray_concrete"
      },
      {
        "char": "i",
        "block": "minecraft:light_gray_concrete"
      },
      {
        "char": "ϔ",
        "block": "minecraft:quartz_stairs[facing\u003deast,half\u003dbottom,shape\u003dstraight,waterlogged\u003dfalse]"
      },
      {
        "char": "f",
        "block": "minecraft:glass"
      },
      {
        "char": "x",
        "block": "minecraft:cauldron"
      },
      {
        "char": "H",
        "block": "minecraft:quartz_stairs[facing\u003dsouth,half\u003dbottom,shape\u003dstraight,waterlogged\u003dfalse]"
      },
      {
        "char": "下",
        "block": "doomsday_decoration:crt[facing\u003deast,waterlogged\u003dfalse]"
      },
      {
        "char": "l",
        "block": "minecraft:iron_trapdoor[facing\u003deast,half\u003dbottom,open\u003dfalse,powered\u003dfalse,waterlogged\u003dfalse]"
      },
      {
        "char": "k",
        "block": "minecraft:air"
      },
      {
        "char": "ο",
        "block": "doomsday_decoration:crt[facing\u003dsouth,waterlogged\u003dfalse]"
      },
      {
        "char": "ѧ",
        "block": "doomsday_decoration:host[facing\u003dsouth,waterlogged\u003dfalse]"
      },
      {
        "char": "u",
        "block": "minecraft:iron_trapdoor[facing\u003dsouth,half\u003dbottom,open\u003dfalse,powered\u003dfalse,waterlogged\u003dfalse]"
      },
      {
        "char": "Ӟ",
        "block": "immersive_weathering:exposed_iron_trapdoor[facing\u003deast,half\u003dbottom,open\u003dfalse,powered\u003dfalse,waterlogged\u003dfalse]"
      },
      {
        "char": "t",
        "block": "minecraft:iron_trapdoor[facing\u003deast,half\u003dtop,open\u003dfalse,powered\u003dfalse,waterlogged\u003dfalse]"
      },
      {
        "char": "w",
        "block": "minecraft:iron_trapdoor[facing\u003dsouth,half\u003dtop,open\u003dfalse,powered\u003dfalse,waterlogged\u003dfalse]"
      },
      {
        "char": "在",
        "block": "immersive_weathering:exposed_iron_trapdoor[facing\u003deast,half\u003dtop,open\u003dfalse,powered\u003dfalse,waterlogged\u003dfalse]"
      }
    ]
  },
  "slices": [
    [
      "abcddecga       ",
      "bceadeaae       ",
      "bbddbabac       ",
      "abbddaab        ",
      "cddeabaa        ",
      "acadbaaea       ",
      "ebaaadabi       ",
      "acaceaeg        ",
      "dabbaidg        ",
      "ddacaei         ",
      "dbadaca         ",
      "ccdaca          ",
      "ebibaa          ",
      "bcacg           ",
      "baba            ",
      "adi             "
    ],
    [
      "e ϔ    f        ",
      "c      f        ",
      "dcd    f        ",
      "      f         ",
      "      f         ",
      "adabcagea       ",
      "  x             ",
      "     f          ",
      "     f          ",
      "                ",
      "db  f           ",
      "H  fa           ",
      "  f  a          ",
      "  f             ",
      " f              ",
      "f               "
    ],
    [
      "下      fl       ",
      "        l       ",
      "        l       ",
      "      fl        ",
      "      fl        ",
      "eeaaecaeg       ",
      "  k    l        ",
      "      l         ",
      "     fl         ",
      "    fl          ",
      "οѧ   l          ",
      "    c           ",
      "  fu a          ",
      "   Ӟ            ",
      " fӞ             ",
      "fl              "
    ],
    [
      "        t       ",
      "        t       ",
      "       ft       ",
      "      ft        ",
      "      ft        ",
      "eedcbdacg       ",
      "  k   ft        ",
      "     ft         ",
      "     ft         ",
      "    ft          ",
      "    ft          ",
      "   fa           ",
      "  fw a          ",
      "  f在            ",
      "  在             ",
      "fw              "
    ],
    [
      "       f        ",
      "       f        ",
      "       f        ",
      "      f         ",
      "      f         ",
      "bdeeacica       ",
      "      f         ",
      "                ",
      "     f          ",
      "    f           ",
      "    f           ",
      "    b           ",
      "     g          ",
      "                ",
      " f              ",
      "f               "
    ],
    [
      "       ad       ",
      "       ae       ",
      "       aa       ",
      "      id        ",
      "      ae        ",
      "bbcaadgda       ",
      "      aa        ",
      "     ac         ",
      "     id         ",
      "    gd          ",
      "    ae          ",
      "   gc           ",
      "  ab g          ",
      "  ae            ",
      " ae             ",
      "ib              "
    ]
  ]
}