{
  "xsize": 16,
  "zsize": 16,
  "palette": {
    "palette": [
      {
        "char": " ",
        "block": "minecraft:air"
      },
      {
        "char": "a",
        "block": "minecraft:cyan_terracotta"
      },
      {
        "char": "d",
        "block": "minecraft:cobbled_deepslate"
      },
      {
        "char": "e",
        "block": "minecraft:basalt[axis\u003dy]"
      },
      {
        "char": "c",
        "block": "minecraft:deepslate[axis\u003dy]"
      },
      {
        "char": "b",
        "block": "minecraft:blackstone"
      },
      {
        "char": "i",
        "block": "minecraft:light_gray_concrete"
      },
      {
        "char": "g",
        "block": "minecraft:gray_concrete"
      },
      {
        "char": "x",
        "block": "minecraft:cauldron"
      },
      {
        "char": "k",
        "block": "minecraft:air"
      },
      {
        "char": "Ѯ",
        "block": "minecraft:diorite_slab[type\u003dbottom,waterlogged\u003dfalse]"
      },
      {
        "char": "P",
        "block": "minecraft:smooth_quartz_slab[type\u003dbottom,waterlogged\u003dfalse]"
      },
      {
        "char": "ѩ",
        "block": "minecraft:diorite_slab[type\u003dtop,waterlogged\u003dfalse]"
      },
      {
        "char": "M",
        "block": "minecraft:smooth_quartz_slab[type\u003dtop,waterlogged\u003dfalse]"
      },
      {
        "char": "ѭ",
        "block": "minecraft:polished_andesite_stairs[facing\u003dwest,half\u003dtop,shape\u003dstraight,waterlogged\u003dfalse]"
      },
      {
        "char": "h",
        "block": "minecraft:andesite_slab[type\u003dtop,waterlogged\u003dfalse]"
      },
      {
        "char": "何",
        "block": "minecraft:polished_andesite_stairs[facing\u003dsouth,half\u003dtop,shape\u003dinner_right,waterlogged\u003dfalse]"
      },
      {
        "char": "相",
        "block": "minecraft:polished_andesite_stairs[facing\u003dwest,half\u003dtop,shape\u003douter_left,waterlogged\u003dfalse]"
      },
      {
        "char": "W",
        "block": "minecraft:polished_andesite_stairs[facing\u003dsouth,half\u003dtop,shape\u003dstraight,waterlogged\u003dfalse]"
      }
    ]
  },
  "slices": [
    [
      "         adedcda",
      "         adbeddd",
      "         bccebed",
      "        igbaedea",
      "        aaabdaec",
      "         bebdacc",
      "         adagebb",
      "           aa   ",
      "                ",
      "                ",
      "                ",
      "                ",
      "                ",
      "                ",
      "                ",
      "                "
    ],
    [
      "         ex     ",
      "         c      ",
      "         c      ",
      "        iax     ",
      "        ga      ",
      "         b      ",
      "         beaaeee",
      "           ga   ",
      "                ",
      "                ",
      "                ",
      "                ",
      "                ",
      "                ",
      "                ",
      "                "
    ],
    [
      "         bk     ",
      "         e      ",
      "         b      ",
      "        aak     ",
      "        ag      ",
      "         e      ",
      "         bbagcad",
      "           aa   ",
      "                ",
      "                ",
      "                ",
      "                ",
      "                ",
      "                ",
      "                ",
      "                "
    ],
    [
      "        Ѯak     ",
      "        Ѯe      ",
      "        Pe      ",
      "        ggk     ",
      "        ia      ",
      "        Ѯb      ",
      "        Pddaicac",
      "        PѮPaaPPP",
      "                ",
      "                ",
      "                ",
      "                ",
      "                ",
      "                ",
      "                ",
      "                "
    ],
    [
      "        ѩa      ",
      "        Mc      ",
      "        Me      ",
      "        ag      ",
      "        aa      ",
      "        Md      ",
      "        Mebiiebb",
      "        MѩMiaѩMM",
      "                ",
      "                ",
      "                ",
      "                ",
      "                ",
      "                ",
      "                ",
      "                "
    ],
    [
      "         aѭhhhhh",
      "         aѭhhhhh",
      "         cѭhhhhh",
      "        gbѭhhhhh",
      "        ae何相hhhh",
      "         ed何WWWW",
      "         ceeeeaa",
      "           ga   ",
      "                ",
      "                ",
      "                ",
      "                ",
      "                ",
      "                ",
      "                ",
      "                "
    ]
  ]
}