{
  "xsize": 16,
  "zsize": 16,
  "palette": {
    "palette": [
      {
        "char": " ",
        "block": "minecraft:air"
      },
      {
        "char": "a",
        "block": "minecraft:cyan_terracotta"
      },
      {
        "char": "d",
        "block": "minecraft:cobbled_deepslate"
      },
      {
        "char": "c",
        "block": "minecraft:deepslate[axis\u003dy]"
      },
      {
        "char": "b",
        "block": "minecraft:blackstone"
      },
      {
        "char": "e",
        "block": "minecraft:basalt[axis\u003dy]"
      },
      {
        "char": "g",
        "block": "minecraft:gray_concrete"
      },
      {
        "char": "i",
        "block": "minecraft:light_gray_concrete"
      },
      {
        "char": "ϕ",
        "block": "minecraft:quartz_stairs[facing\u003dnorth,half\u003dbottom,shape\u003dstraight,waterlogged\u003dfalse]"
      },
      {
        "char": "O",
        "block": "minecraft:quartz_stairs[facing\u003dwest,half\u003dbottom,shape\u003dstraight,waterlogged\u003dfalse]"
      },
      {
        "char": "ϓ",
        "block": "refurbished_furniture:spruce_table[east\u003dfalse,north\u003dfalse,south\u003dfalse,west\u003dfalse]"
      },
      {
        "char": "ϔ",
        "block": "minecraft:quartz_stairs[facing\u003deast,half\u003dbottom,shape\u003dstraight,waterlogged\u003dfalse]"
      },
      {
        "char": "H",
        "block": "minecraft:quartz_stairs[facing\u003dsouth,half\u003dbottom,shape\u003dstraight,waterlogged\u003dfalse]"
      },
      {
        "char": "x",
        "block": "minecraft:cauldron"
      },
      {
        "char": "o",
        "block": "minecraft:chiseled_quartz_block"
      },
      {
        "char": "C",
        "block": "minecraft:quartz_pillar[axis\u003dy]"
      },
      {
        "char": "k",
        "block": "minecraft:air"
      },
      {
        "char": "l",
        "block": "minecraft:iron_trapdoor[facing\u003deast,half\u003dbottom,open\u003dfalse,powered\u003dfalse,waterlogged\u003dfalse]"
      },
      {
        "char": "Ӟ",
        "block": "immersive_weathering:exposed_iron_trapdoor[facing\u003deast,half\u003dbottom,open\u003dfalse,powered\u003dfalse,waterlogged\u003dfalse]"
      },
      {
        "char": "I",
        "block": "minecraft:stone_slab[type\u003dtop,waterlogged\u003dfalse,weathering\u003dfalse]"
      }
    ]
  },
  "slices": [
    [
      "addcbbeddacabdee",
      "bbedcbeccccedaab",
      "becedbecceddedcb",
      "deebbbdeeebbddac",
      "adddedbabbdcbcce",
      "ecadaacabaaebbca",
      "bbbaacdaeccdbdba",
      "eaecbecdbcbceeec",
      "cdabebdcacedbcde",
      "acbdeaeddacaeaac",
      "dbdeeddebbbaeabe",
      "ecdeeacadddbdccb",
      "gbbceacecdaddc  ",
      "iebaeabdabcea   ",
      "aaabaaac        ",
      " aaaeed         "
    ],
    [
      "           ebcda",
      "                ",
      "  c             ",
      "  e             ",
      "  a   ϕ   ecd   ",
      "aeb  Oϓϔ  d     ",
      "   d  H   c     ",
      "  a a     ax    ",
      "    e     e     ",
      "     a    b     ",
      "      c   ax    ",
      "       cd a     ",
      "         cb     ",
      "        i eed   ",
      "o               ",
      " C              "
    ],
    [
      "           ceeee",
      "                ",
      "  d             ",
      "  a             ",
      "  b       dce   ",
      "cda       d     ",
      "   a      a     ",
      "  a c     ck    ",
      "    d     d     ",
      "     a    b     ",
      "      a   ak    ",
      "       eb b     ",
      "         ea     ",
      "        a ceb   ",
      "l               ",
      " Ӟ              "
    ],
    [
      "           acbba",
      "                ",
      "  e             ",
      "  a             ",
      "  c       dbc   ",
      "bad       a     ",
      "   d      a     ",
      "  a d     ck    ",
      "    a     b     ",
      "     a    a     ",
      "      b   ak    ",
      "       ae d     ",
      "         ea     ",
      "        g aceb  ",
      "                ",
      "                "
    ],
    [
      "  I        badba",
      "  I             ",
      "  c             ",
      "  b             ",
      "  a       cdbIII",
      "dcc       b     ",
      "   c      b     ",
      "  a c     c     ",
      "    a     e     ",
      "     e    e     ",
      "      d   e     ",
      "       ad a     ",
      "         ac     ",
      "        a    dII",
      "                ",
      "                "
    ],
    [
      "  a        caabb",
      "  d             ",
      "  a             ",
      "  b             ",
      "  a       dadaad",
      "aea       d     ",
      "   d      c     ",
      "  a b     c     ",
      "    a     b     ",
      "     c    b     ",
      "      c   a     ",
      "       dc d     ",
      "         ca     ",
      "        g     bb",
      "                ",
      "                "
    ]
  ]
}