{
  "xsize": 16,
  "zsize": 16,
  "palette": {
    "palette": [
      {
        "char": " ",
        "block": "minecraft:air"
      },
      {
        "char": "a",
        "block": "minecraft:cyan_terracotta"
      },
      {
        "char": "b",
        "block": "minecraft:blackstone"
      },
      {
        "char": "e",
        "block": "minecraft:basalt[axis\u003dy]"
      },
      {
        "char": "c",
        "block": "minecraft:deepslate[axis\u003dy]"
      },
      {
        "char": "d",
        "block": "minecraft:cobbled_deepslate"
      },
      {
        "char": "g",
        "block": "minecraft:gray_concrete"
      },
      {
        "char": "Р",
        "block": "minecraft:stone_brick_stairs[facing\u003dnorth,half\u003dbottom,shape\u003dstraight,waterlogged\u003dfalse,weathering\u003dfalse]"
      },
      {
        "char": "z",
        "block": "minecraft:iron_bars[east\u003dfalse,north\u003dtrue,south\u003dtrue,waterlogged\u003dfalse,west\u003dfalse]"
      },
      {
        "char": "Y",
        "block": "minecraft:iron_bars[east\u003dfalse,north\u003dtrue,south\u003dfalse,waterlogged\u003dfalse,west\u003dfalse]"
      },
      {
        "char": "f",
        "block": "minecraft:glass"
      },
      {
        "char": "x",
        "block": "minecraft:cauldron"
      },
      {
        "char": "У",
        "block": "minecraft:stone_brick_stairs[facing\u003dsouth,half\u003dbottom,shape\u003dstraight,waterlogged\u003dfalse,weathering\u003dfalse]"
      },
      {
        "char": "С",
        "block": "minecraft:stone_brick_stairs[facing\u003dnorth,half\u003dtop,shape\u003dstraight,waterlogged\u003dfalse,weathering\u003dfalse]"
      },
      {
        "char": "如",
        "block": "immersive_weathering:exposed_iron_trapdoor[facing\u003dnorth,half\u003dbottom,open\u003dfalse,powered\u003dfalse,waterlogged\u003dfalse]"
      },
      {
        "char": "s",
        "block": "minecraft:iron_trapdoor[facing\u003dnorth,half\u003dbottom,open\u003dfalse,powered\u003dfalse,waterlogged\u003dfalse]"
      },
      {
        "char": "m",
        "block": "minecraft:iron_trapdoor[facing\u003dwest,half\u003dbottom,open\u003dfalse,powered\u003dfalse,waterlogged\u003dfalse]"
      },
      {
        "char": "k",
        "block": "minecraft:air"
      },
      {
        "char": "p",
        "block": "minecraft:iron_trapdoor[facing\u003dnorth,half\u003dtop,open\u003dfalse,powered\u003dfalse,waterlogged\u003dfalse]"
      },
      {
        "char": "q",
        "block": "minecraft:iron_trapdoor[facing\u003dwest,half\u003dtop,open\u003dfalse,powered\u003dfalse,waterlogged\u003dfalse]"
      },
      {
        "char": "у",
        "block": "minecraft:stone_brick_stairs[facing\u003dsouth,half\u003dtop,shape\u003dstraight,waterlogged\u003dfalse,weathering\u003dfalse]"
      },
      {
        "char": "I",
        "block": "minecraft:stone_slab[type\u003dtop,waterlogged\u003dfalse,weathering\u003dfalse]"
      }
    ]
  },
  "slices": [
    [
      "         abbaeac",
      "       bdeadebae",
      "      dbddaaebae",
      "     bebdebcddec",
      "    cccbcbdbccba",
      "  a aabacdacdbbc",
      "aagbebddbcaceacb",
      "adceaeaabcbbadad",
      "eccaddaedeeeadbd",
      "abadbccecdbeacdd",
      "ccdecedededbbeea",
      "dcddacaccbaecbae",
      "cebdeddbddbbРz a",
      "badbacabbcce z d",
      "cabeedeaeeac Y c",
      "ddbebabdebce   a"
    ],
    [
      "         b      ",
      "         b      ",
      "       ff       ",
      "      f         ",
      "     f          ",
      "  a             ",
      "   aa     x     ",
      "bcbaaaaeaedb   c",
      "  e  x  x       ",
      "  c             ",
      "  d             ",
      "           a a b",
      "           c zУa",
      "  a        b zСa",
      "ddc        d Y e",
      "  a        d   d"
    ],
    [
      "         c      ",
      "       如sb      ",
      "      m         ",
      "     mf         ",
      "    m           ",
      "  g mf          ",
      "   be     k     ",
      "deeebcaeddad   e",
      "  e  k  k       ",
      "  a             ",
      "  d             ",
      "           a b a",
      "           a z d",
      "  b        d zУb",
      "ddd        a YСc",
      "  c        a   d"
    ],
    [
      "         e      ",
      "       ppc      ",
      "      qff       ",
      "     p          ",
      "    qf          ",
      "  a qf          ",
      "   db     k     ",
      "caadbcddbcbb   a",
      "  b  k  k       ",
      "  a             ",
      "  e             ",
      "           b d a",
      "           c z d",
      "  b        b z c",
      "dbc        bуzУe",
      "  b        bbece"
    ],
    [
      "         e      ",
      "         d      ",
      "       ff       ",
      "                ",
      "     f          ",
      "  a  f          ",
      "   ad           ",
      "bebceacbacadIIIc",
      "  d             ",
      "  e             ",
      "  d             ",
      "  I        adedd",
      "  I        b z d",
      "  b        eуz b",
      "dcd        cРY d",
      "  c        a   b"
    ],
    [
      "         a      ",
      "       da       ",
      "      eac       ",
      "     da         ",
      "    bd          ",
      "  a ca          ",
      "   e            ",
      "bccaaebcbeabadbd",
      "  e             ",
      "  a             ",
      "  d             ",
      "  e        edccb",
      "  e        eуz a",
      "  c        cРz e",
      "bed        a Y a",
      "  e        a   e"
    ]
  ]
}