{
  "xsize": 16,
  "zsize": 16,
  "palette": {
    "palette": [
      {
        "char": " ",
        "block": "minecraft:air"
      },
      {
        "char": "C",
        "block": "minecraft:mossy_cobblestone"
      },
      {
        "char": "E",
        "block": "minecraft:stone_bricks[weathering\u003dfalse]"
      },
      {
        "char": "j",
        "block": "minecraft:air"
      },
      {
        "char": "o",
        "block": "minecraft:quartz_block"
      },
      {
        "char": "请",
        "block": "minecraft:air"
      },
      {
        "char": "l",
        "block": "minecraft:air"
      },
      {
        "char": "e",
        "block": "minecraft:smooth_quartz"
      },
      {
        "char": "f",
        "block": "minecraft:polished_diorite"
      },
      {
        "char": "性",
        "block": "minecraft:air"
      },
      {
        "char": "H",
        "block": "minecraft:cobblestone[weathering\u003dfalse]"
      },
      {
        "char": "y",
        "block": "minecraft:quartz_pillar[axis\u003dy]"
      },
      {
        "char": "p",
        "block": "minecraft:diorite"
      },
      {
        "char": "m",
        "block": "minecraft:air"
      },
      {
        "char": "D",
        "block": "minecraft:cracked_stone_bricks"
      },
      {
        "char": "i",
        "block": "minecraft:air"
      },
      {
        "char": "z",
        "block": "minecraft:mossy_stone_bricks"
      },
      {
        "char": "A",
        "block": "immersive_weathering:exposed_iron_bars[east\u003dtrue,north\u003dfalse,south\u003dfalse,waterlogged\u003dfalse,west\u003dtrue]"
      },
      {
        "char": "t",
        "block": "minecraft:stone_slab[type\u003dbottom,waterlogged\u003dfalse,weathering\u003dfalse]"
      },
      {
        "char": "天",
        "block": "minecraft:stone_slab[type\u003ddouble,waterlogged\u003dfalse,weathering\u003dfalse]"
      },
      {
        "char": "他",
        "block": "immersive_weathering:mossy_stone_slab[type\u003dbottom,waterlogged\u003dfalse]"
      },
      {
        "char": "v",
        "block": "minecraft:air"
      }
    ]
  },
  "slices": [
    [
      "         CEj    ",
      "         o请     ",
      "        lej     ",
      "        lfj     ",
      "        lej     ",
      "         oj     ",
      "        lej     ",
      "         o性     ",
      "         CH     ",
      "        lf请     ",
      "         yj     ",
      "         e      ",
      "         p      ",
      "    mmm  o性     ",
      "fDfypeefeDC     ",
      "iz请  i iizz请i ii"
    ],
    [
      "         HCj    ",
      "         e请     ",
      "         ej     ",
      "         fj     ",
      "        lfj     ",
      "         ej     ",
      "        lpj     ",
      "         f性     ",
      "         CE     ",
      "        lo请     ",
      "         o      ",
      "         e      ",
      "         f      ",
      "    mm   e性     ",
      "oDeffpppyEC     ",
      "iE请  i iiHC请i ii"
    ],
    [
      "         zE     ",
      "         y请     ",
      "         fj     ",
      "         ej     ",
      "         ej     ",
      "         fj     ",
      "        lyj     ",
      "         p性     ",
      "         CC     ",
      "         e请     ",
      "         e      ",
      "         e      ",
      "         f      ",
      "         oj     ",
      "yCefoeyoozD     ",
      "iCj  i iiDD请i ii"
    ],
    [
      "         zzAAAAA",
      "         p请     ",
      "         ej     ",
      "         y      ",
      "         oj     ",
      "         pj     ",
      "         yj     ",
      "         y      ",
      "         DDAAAAA",
      "         y      ",
      "         y      ",
      "         e      ",
      "         e      ",
      "         p      ",
      "pzoeeeefoHHAAAAA",
      "iCj  i iiHz请i ii"
    ],
    [
      "         Cz     ",
      "         e请     ",
      "         pj     ",
      "         f      ",
      "         ej     ",
      "         fj     ",
      "         oj     ",
      "         o      ",
      "         Dz     ",
      "         e      ",
      "         o      ",
      "         p      ",
      "         y      ",
      "         e      ",
      "fDeeeeeoeEC     ",
      "iC   i iiECii ii"
    ],
    [
      "t天t他tttttEC  v v",
      " t       oi     ",
      " t v v   fj     ",
      " t       e      ",
      "vt vvv   ej     ",
      " t   vv  e      ",
      " t       e      ",
      " t   v   y      ",
      "ttttt他他t天Dz     ",
      " t       f      ",
      " t       e      ",
      "v他       f      ",
      " 他       p      ",
      " 天       y      ",
      "fzfofeyfoHE     ",
      " E     iiCHii ii"
    ]
  ]
}