{
  "xsize": 16,
  "zsize": 16,
  "palette": {
    "palette": [
      {
        "char": " ",
        "block": "minecraft:air"
      },
      {
        "char": "m",
        "block": "minecraft:air"
      },
      {
        "char": "f",
        "block": "minecraft:polished_diorite"
      },
      {
        "char": "性",
        "block": "minecraft:air"
      },
      {
        "char": "p",
        "block": "minecraft:diorite"
      },
      {
        "char": "g",
        "block": "minecraft:blue_concrete"
      },
      {
        "char": "E",
        "block": "minecraft:stone_bricks[weathering\u003dfalse]"
      },
      {
        "char": "z",
        "block": "minecraft:mossy_stone_bricks"
      },
      {
        "char": "D",
        "block": "minecraft:cracked_stone_bricks"
      },
      {
        "char": "y",
        "block": "minecraft:quartz_pillar[axis\u003dy]"
      },
      {
        "char": "e",
        "block": "minecraft:smooth_quartz"
      },
      {
        "char": "H",
        "block": "minecraft:cobblestone[weathering\u003dfalse]"
      },
      {
        "char": "i",
        "block": "minecraft:air"
      },
      {
        "char": "呵",
        "block": "minecraft:air"
      },
      {
        "char": "思",
        "block": "minecraft:air"
      },
      {
        "char": "l",
        "block": "minecraft:air"
      },
      {
        "char": "j",
        "block": "minecraft:air"
      },
      {
        "char": "队",
        "block": "minecraft:air"
      },
      {
        "char": "必",
        "block": "minecraft:air"
      },
      {
        "char": "那",
        "block": "minecraft:air"
      },
      {
        "char": "o",
        "block": "minecraft:quartz_block"
      },
      {
        "char": "黑",
        "block": "minecraft:air"
      },
      {
        "char": "数",
        "block": "minecraft:air"
      },
      {
        "char": "C",
        "block": "minecraft:mossy_cobblestone"
      },
      {
        "char": "受",
        "block": "minecraft:air"
      },
      {
        "char": "ҭ",
        "block": "minecraft:air"
      },
      {
        "char": "天",
        "block": "minecraft:stone_slab[type\u003ddouble,waterlogged\u003dfalse,weathering\u003dfalse]"
      },
      {
        "char": "t",
        "block": "minecraft:stone_slab[type\u003dbottom,waterlogged\u003dfalse,weathering\u003dfalse]"
      },
      {
        "char": "v",
        "block": "minecraft:air"
      },
      {
        "char": "他",
        "block": "immersive_weathering:mossy_stone_slab[type\u003dbottom,waterlogged\u003dfalse]"
      }
    ]
  },
  "slices": [
    [
      "                ",
      " mmmm m  mm  mm ",
      "mf  fmf性  f ffpm",
      "gggggggggggggggg",
      "gggggggggggggggg",
      "gggggggggggggggg",
      "gggggggggggggggg",
      "gEgggggggzgggggg",
      "fDfyfppepHeepfff",
      "iiiiii ii ii iii",
      "                ",
      "                ",
      "    呵           ",
      "     思 l        ",
      "     j队         ",
      "    必那          "
    ],
    [
      "                ",
      "  mmm m  mm   m ",
      "meoff f黑p f mmfm",
      "gggggggggggggggg",
      "gggggggggggggggg",
      "gggggggggggggggg",
      "gggggggggggggggg",
      "gzgggggggEgggggg",
      "fDoffefyeHppeeyy",
      "iiii   ii ii iii",
      "                ",
      "                ",
      "    呵           ",
      "     思 l        ",
      "     j队         ",
      "    必那          "
    ],
    [
      "                ",
      "   mm m  m    m ",
      "mf数 e fomeo mmem",
      "gggggggggggggggg",
      "gggggggggggggggg",
      "gggggggggggggggg",
      "gggggggggggggggg",
      "gCgggggggCgggggg",
      "fCyyeeoypCeyoyee",
      "iiii   ii ii   i",
      "                ",
      "                ",
      "    呵           ",
      "     思 l        ",
      "     j队         ",
      "    必那          "
    ],
    [
      "                ",
      "   m            ",
      "m那of  ommme mmfm",
      "gggggggggggggggg",
      "gggggggggggggggg",
      "gggggggggggggggg",
      "gggggggggggggggg",
      "gDgggggggDgggggg",
      "pDeyfyeeoHpfoyff",
      "i ii   ii ii   受",
      "                ",
      "                ",
      "    呵           ",
      "     思 l        ",
      "     j队         ",
      "    必那          "
    ],
    [
      "                ",
      "                ",
      "  mm  m mm  m mm",
      "gggggggggggggggg",
      "gggggggggggggggg",
      "gggggggggggggggg",
      "gggggggggggggggg",
      "gHgggggggDgggggg",
      "yCpfeepofCffeffo",
      "  ii           ҭ",
      "                ",
      "                ",
      "    呵           ",
      "     思 l        ",
      "     j队         ",
      "    必那          "
    ],
    [
      "                ",
      "                ",
      "  mm  数 mm    mm",
      "gggggggggggggggg",
      "gggggggggggggggg",
      "gggggggggggggggg",
      "gggggggggggggggg",
      "gEgggggggDgggggg",
      "fzeoyfypeDeoffof",
      " 天       天    ҭ ",
      " t       t      ",
      " t    v  t   v  ",
      " t  呵vvvv他  vv  ",
      " t  v思vlv他      ",
      " t  vj队v tv    v",
      "v他  必那v  t     v"
    ]
  ]
}