{
  "xsize": 16,
  "zsize": 16,
  "palette": {
    "palette": [
      {
        "char": " ",
        "block": "minecraft:air"
      },
      {
        "char": "e",
        "block": "minecraft:smooth_quartz"
      },
      {
        "char": "f",
        "block": "minecraft:polished_diorite"
      },
      {
        "char": "o",
        "block": "minecraft:quartz_block"
      },
      {
        "char": "E",
        "block": "minecraft:stone_bricks[weathering\u003dfalse]"
      },
      {
        "char": "i",
        "block": "minecraft:air"
      },
      {
        "char": "请",
        "block": "minecraft:air"
      },
      {
        "char": "O",
        "block": "minecraft:dark_oak_fence[east\u003dfalse,north\u003dfalse,south\u003dfalse,waterlogged\u003dfalse,west\u003dfalse]"
      },
      {
        "char": "m",
        "block": "minecraft:air"
      },
      {
        "char": "l",
        "block": "minecraft:air"
      },
      {
        "char": "g",
        "block": "minecraft:blue_concrete"
      },
      {
        "char": "j",
        "block": "minecraft:air"
      },
      {
        "char": "y",
        "block": "minecraft:quartz_pillar[axis\u003dy]"
      },
      {
        "char": "p",
        "block": "minecraft:diorite"
      },
      {
        "char": "D",
        "block": "minecraft:cracked_stone_bricks"
      },
      {
        "char": "z",
        "block": "minecraft:mossy_stone_bricks"
      },
      {
        "char": "C",
        "block": "minecraft:mossy_cobblestone"
      },
      {
        "char": "天",
        "block": "minecraft:stone_slab[type\u003ddouble,waterlogged\u003dfalse,weathering\u003dfalse]"
      },
      {
        "char": "t",
        "block": "minecraft:stone_slab[type\u003dbottom,waterlogged\u003dfalse,weathering\u003dfalse]"
      },
      {
        "char": "拉",
        "block": "minecraft:air"
      },
      {
        "char": "受",
        "block": "minecraft:air"
      },
      {
        "char": "怪",
        "block": "immersive_weathering:mossy_stone_slab[type\u003ddouble,waterlogged\u003dfalse]"
      },
      {
        "char": "他",
        "block": "immersive_weathering:mossy_stone_slab[type\u003dbottom,waterlogged\u003dfalse]"
      },
      {
        "char": "v",
        "block": "minecraft:air"
      }
    ]
  },
  "slices": [
    [
      "eeefoeeefE      ",
      "ii 请ii  i       ",
      "                ",
      "     O         O",
      "                ",
      "                ",
      "                ",
      "     O         O",
      "                ",
      "                ",
      "                ",
      "                ",
      "                ",
      "                ",
      " m    m         ",
      "lgj  lgj    mm m"
    ],
    [
      "fooyyeofyE      ",
      "ii 请ii  i       ",
      "                ",
      "     O         O",
      "                ",
      "                ",
      "                ",
      "     O         O",
      "                ",
      "                ",
      "                ",
      "                ",
      "                ",
      "                ",
      " m    m         ",
      "lgj  lgj        "
    ],
    [
      "eefefepyyD      ",
      "ii 请ii  i       ",
      "                ",
      "     O         O",
      "                ",
      "                ",
      "                ",
      "     O         O",
      "                ",
      "                ",
      "                ",
      "                ",
      "                ",
      "                ",
      " m    m         ",
      " gj  lg         "
    ],
    [
      "oeeoppppez      ",
      "ii 请ii  i       ",
      "                ",
      "     O         O",
      "                ",
      "                ",
      "                ",
      "     O         O",
      "                ",
      "                ",
      "                ",
      "                ",
      "                ",
      "                ",
      "                ",
      "                "
    ],
    [
      "oyeofooyyE      ",
      "   请ii  i       ",
      "                ",
      "     O         O",
      "                ",
      "                ",
      "                ",
      "     O         O",
      "                ",
      "                ",
      "                ",
      "                ",
      "                ",
      "                ",
      "                ",
      "                "
    ],
    [
      "fyeofeoppC天ttttt",
      "  天拉受    怪      ",
      "  t      他    v ",
      " vt  Ov  他    vO",
      " vt  v  v他 v  v ",
      "  t      t      ",
      "  t      t  v   ",
      "  t  O   t     O",
      "tt天tttttt天tttttt",
      "  t      t      ",
      "  t  v   t      ",
      "  他v v v t vvv  ",
      "v 他v    vtv   v ",
      "  t  v v t   v  ",
      "  t  v   t      ",
      "  t      t      "
    ]
  ]
}