{
  "xsize": 16,
  "zsize": 16,
  "palette": {
    "palette": [
      {
        "char": " ",
        "block": "minecraft:air"
      },
      {
        "char": "m",
        "block": "minecraft:air"
      },
      {
        "char": "D",
        "block": "minecraft:cracked_stone_bricks"
      },
      {
        "char": "消",
        "block": "horror_element_mod:chained_entity[facing\u003dnorth]"
      },
      {
        "char": "B",
        "block": "minecraft:smooth_quartz_slab[type\u003dtop,waterlogged\u003dfalse]"
      },
      {
        "char": "C",
        "block": "minecraft:mossy_cobblestone"
      },
      {
        "char": "l",
        "block": "minecraft:air"
      },
      {
        "char": "f",
        "block": "minecraft:polished_diorite"
      },
      {
        "char": "黑",
        "block": "minecraft:air"
      },
      {
        "char": "抓",
        "block": "minecraft:air"
      },
      {
        "char": "e",
        "block": "minecraft:smooth_quartz"
      },
      {
        "char": "u",
        "block": "minecraft:smooth_quartz_slab[type\u003dbottom,waterlogged\u003dfalse]"
      },
      {
        "char": "g",
        "block": "minecraft:blue_concrete"
      },
      {
        "char": "y",
        "block": "minecraft:quartz_pillar[axis\u003dy]"
      },
      {
        "char": "自",
        "block": "minecraft:smooth_quartz_slab[type\u003ddouble,waterlogged\u003dfalse]"
      },
      {
        "char": "没",
        "block": "minecraft:redstone_lamp[lit\u003dfalse]"
      },
      {
        "char": "数",
        "block": "minecraft:air"
      },
      {
        "char": "p",
        "block": "minecraft:diorite"
      },
      {
        "char": "O",
        "block": "minecraft:dark_oak_fence[east\u003dfalse,north\u003dfalse,south\u003dfalse,waterlogged\u003dfalse,west\u003dfalse]"
      }
    ]
  },
  "slices": [
    [
      "   m            ",
      "                ",
      "            D   ",
      "                ",
      "                ",
      "                ",
      "                ",
      "                ",
      "              mm",
      "                ",
      "                ",
      "       消        ",
      "                ",
      "                ",
      "                ",
      "m      mmmm     "
    ],
    [
      "   m            ",
      "BBBBBBBBBBBBBB  ",
      "BBBBBBBBBBBBCB  ",
      "             B  ",
      "             B  ",
      "             B  ",
      "             B  ",
      "             B  ",
      "             Bmm",
      "             B  ",
      "             B  ",
      "             B  ",
      "             B  ",
      "             B  ",
      "             B  ",
      "m      mmmm  B  "
    ],
    [
      "   m            ",
      "  lf黑抓e    Bu   ",
      "gggyggegggg自u   ",
      "           Bu   ",
      "           Bu   ",
      " 没没没  没没没  Bu   ",
      "           Bu   ",
      "           Bu   ",
      "           Bummm",
      "           Bu   ",
      "           Bu   ",
      " 没没没  没没没  Bu   ",
      "           Bu   ",
      "           Bu   ",
      "           Bu   ",
      "       mmm数Bu   "
    ],
    [
      "                ",
      "B   ff   Bu     ",
      "自gggfpggg自u     ",
      "B        Bu     ",
      "B        Bu     ",
      "BO O  O OBu     ",
      "B        Bu     ",
      "B        Bu     ",
      "B        Bum mmm",
      "B        Bu     ",
      "B        Bu     ",
      "BO O  O OBu     ",
      "B        Bu     ",
      "B        Bu     ",
      "B        Bu     ",
      "B      m数Bu     "
    ],
    [
      "                ",
      " uB    Bu       ",
      " u自gggg自u       ",
      " uB    Bu       ",
      " uB    Bu       ",
      " uBO  OBu       ",
      " uB    Bu       ",
      " uB    Bu       ",
      "muB    Bum m mmm",
      " uB    Bu       ",
      " uB    Bu       ",
      " uBO  OBu       ",
      " uB    Bu       ",
      " uB    Bu       ",
      " uB    Bu       ",
      " uB    Bu       "
    ],
    [
      "                ",
      "   uBBu         ",
      "   u自自u         ",
      "   uBBu         ",
      "   uBBu         ",
      "   uBBu         ",
      "   uBBu         ",
      "   uBBu         ",
      "mmmuBBu mm m mmm",
      "   uBBu         ",
      "   uBBu         ",
      "   uBBu         ",
      "   uBBu         ",
      "   uBBu         ",
      "   uBBu         ",
      "   uBBu         "
    ]
  ]
}