{
  "xsize": 16,
  "zsize": 16,
  "palette": {
    "palette": [
      {
        "char": " ",
        "block": "minecraft:air"
      },
      {
        "char": "m",
        "block": "minecraft:air"
      },
      {
        "char": "数",
        "block": "minecraft:air"
      },
      {
        "char": "z",
        "block": "minecraft:mossy_stone_bricks"
      },
      {
        "char": "C",
        "block": "minecraft:mossy_cobblestone"
      },
      {
        "char": "D",
        "block": "minecraft:cracked_stone_bricks"
      },
      {
        "char": "H",
        "block": "minecraft:cobblestone[weathering\u003dfalse]"
      },
      {
        "char": "f",
        "block": "minecraft:polished_diorite"
      },
      {
        "char": "受",
        "block": "minecraft:air"
      },
      {
        "char": "e",
        "block": "minecraft:smooth_quartz"
      },
      {
        "char": "v",
        "block": "minecraft:air"
      },
      {
        "char": "h",
        "block": "minecraft:white_stained_glass"
      },
      {
        "char": "j",
        "block": "minecraft:air"
      },
      {
        "char": "速",
        "block": "minecraft:dark_oak_fence[east\u003dfalse,north\u003dfalse,south\u003dfalse,waterlogged\u003dfalse,west\u003dtrue]"
      },
      {
        "char": "孩",
        "block": "minecraft:dark_oak_fence[east\u003dtrue,north\u003dfalse,south\u003dfalse,waterlogged\u003dfalse,west\u003dfalse]"
      },
      {
        "char": "把",
        "block": "minecraft:air"
      },
      {
        "char": "l",
        "block": "minecraft:air"
      },
      {
        "char": "o",
        "block": "minecraft:quartz_block"
      },
      {
        "char": "p",
        "block": "minecraft:diorite"
      },
      {
        "char": "i",
        "block": "minecraft:air"
      },
      {
        "char": "u",
        "block": "minecraft:smooth_quartz_slab[type\u003dbottom,waterlogged\u003dfalse]"
      },
      {
        "char": "自",
        "block": "minecraft:smooth_quartz_slab[type\u003ddouble,waterlogged\u003dfalse]"
      },
      {
        "char": "g",
        "block": "minecraft:blue_concrete"
      },
      {
        "char": "风",
        "block": "immersive_weathering:weathered_iron_bars[east\u003dtrue,north\u003dfalse,south\u003dfalse,waterlogged\u003dfalse,west\u003dtrue]"
      },
      {
        "char": "B",
        "block": "minecraft:smooth_quartz_slab[type\u003dtop,waterlogged\u003dfalse]"
      },
      {
        "char": "E",
        "block": "minecraft:stone_bricks[weathering\u003dfalse]"
      }
    ]
  },
  "slices": [
    [
      "  mmmmm数m 数数 m  ",
      "zzzCDDDDzDDzCHDD",
      "f 受受e e受vve     ",
      "h   h h   hj    ",
      "h   h h   hj    ",
      "h速 孩h h速 孩h     ",
      "h   h h   hj    ",
      "h  把h h   h     ",
      "h   h h   hj    ",
      "h速 孩h h速 孩h     ",
      "h   hlh   hj    ",
      "ffefo opffoj    ",
      "i ii    ii      ",
      "                ",
      "                ",
      "                "
    ],
    [
      "uuuuuuuuuuu自u   ",
      "ggggggggggg自uD风风",
      " eee   eef      ",
      "lf e   f e      ",
      "lf f   o o      ",
      "lf fj  o pj     ",
      "lfvfj  f o      ",
      " e f  le ej     ",
      "lf ej lo e      ",
      "le e   e e      ",
      "le pj  e p      ",
      "leefj lpoo      ",
      "   i     i      ",
      "                ",
      "                ",
      "                "
    ],
    [
      "数mmuBumm数Bu     ",
      "ggggggggg自u  E风风",
      "  p     o       ",
      "  h     hj      ",
      " lhj   lh       ",
      "  hj    hj      ",
      "  hj   lh       ",
      " lhj   lhj      ",
      " lhj    hj      ",
      " lhj    hj      ",
      "  hj    hj      ",
      "  o     f       ",
      "                ",
      "                ",
      "                ",
      "                "
    ],
    [
      "uB数m   Bu       ",
      "u自ggggg自u    E  ",
      "                ",
      "                ",
      "                ",
      "                ",
      "                ",
      "                ",
      "                ",
      "                ",
      "                ",
      "                ",
      "                ",
      "                ",
      "                ",
      "                "
    ],
    [
      "  uB Bu         ",
      "  u自g自u         ",
      "                ",
      "                ",
      "                ",
      "                ",
      "                ",
      "                ",
      "                ",
      "                ",
      "                ",
      "                ",
      "                ",
      "                ",
      "                ",
      "                "
    ],
    [
      "    u           ",
      "    u           ",
      "                ",
      "                ",
      "                ",
      "                ",
      "                ",
      "                ",
      "                ",
      "                ",
      "                ",
      "                ",
      "                ",
      "                ",
      "                ",
      "                "
    ]
  ]
}