{
  "xsize": 16,
  "zsize": 16,
  "palette": {
    "palette": [
      {
        "char": " ",
        "block": "minecraft:air"
      },
      {
        "char": "o",
        "block": "minecraft:quartz_block"
      },
      {
        "char": "e",
        "block": "minecraft:smooth_quartz"
      },
      {
        "char": "f",
        "block": "minecraft:polished_diorite"
      },
      {
        "char": "m",
        "block": "minecraft:air"
      },
      {
        "char": "p",
        "block": "minecraft:diorite"
      },
      {
        "char": "E",
        "block": "minecraft:stone_bricks[weathering\u003dfalse]"
      },
      {
        "char": "y",
        "block": "minecraft:quartz_pillar[axis\u003dy]"
      },
      {
        "char": "Ұ",
        "block": "minecraft:air"
      },
      {
        "char": "C",
        "block": "minecraft:mossy_cobblestone"
      },
      {
        "char": "i",
        "block": "minecraft:air"
      },
      {
        "char": "j",
        "block": "minecraft:air"
      },
      {
        "char": "l",
        "block": "minecraft:air"
      },
      {
        "char": "那",
        "block": "minecraft:air"
      },
      {
        "char": "D",
        "block": "minecraft:cracked_stone_bricks"
      },
      {
        "char": "z",
        "block": "minecraft:mossy_stone_bricks"
      },
      {
        "char": "H",
        "block": "minecraft:cobblestone[weathering\u003dfalse]"
      },
      {
        "char": "A",
        "block": "immersive_weathering:exposed_iron_bars[east\u003dtrue,north\u003dfalse,south\u003dfalse,waterlogged\u003dfalse,west\u003dtrue]"
      },
      {
        "char": "t",
        "block": "minecraft:stone_slab[type\u003dbottom,waterlogged\u003dfalse,weathering\u003dfalse]"
      },
      {
        "char": "天",
        "block": "minecraft:stone_slab[type\u003ddouble,waterlogged\u003dfalse,weathering\u003dfalse]"
      },
      {
        "char": "他",
        "block": "immersive_weathering:mossy_stone_slab[type\u003dbottom,waterlogged\u003dfalse]"
      },
      {
        "char": "v",
        "block": "minecraft:air"
      },
      {
        "char": "怪",
        "block": "immersive_weathering:mossy_stone_slab[type\u003ddouble,waterlogged\u003dfalse]"
      }
    ]
  },
  "slices": [
    [
      " o              ",
      " e              ",
      " o              ",
      " f              ",
      " f              ",
      " f              ",
      " f              ",
      "mem    m m      ",
      "pEyeoeeeyy      ",
      "ҰCi  ii  fj     ",
      " i      lp      ",
      "        ly      ",
      "         y      ",
      "        那o m mmm",
      "DCEzEECCHEefpfee",
      "ii   i   ziiiiii"
    ],
    [
      " o              ",
      " p              ",
      " o              ",
      " e              ",
      " f              ",
      " e              ",
      " e              ",
      "me     m m      ",
      "fCfoeyepoe      ",
      "ҰEi  ii  fj     ",
      " i      lf      ",
      "        ly      ",
      "         e      ",
      "        le m mm ",
      "AAAAAAAAzzefffef",
      "         Diiiiii"
    ],
    [
      "                ",
      "                ",
      "                ",
      "                ",
      "                ",
      "                ",
      "                ",
      "m      m        ",
      "ezfyfoyepp      ",
      "ҰCi   i  o      ",
      " i      ly      ",
      "        lo      ",
      "         e      ",
      "         p m mm ",
      "AAAAAAAAHDypeffp",
      "         ziiiiii"
    ],
    [
      "                ",
      "                ",
      "                ",
      "                ",
      "                ",
      "                ",
      "                ",
      "       m        ",
      "fEoeefffef      ",
      "ҰEi      f      ",
      " i      lp      ",
      "        lf      ",
      "         o      ",
      "         f m mm ",
      "        Ezfefpof",
      "         Hiiiiii"
    ],
    [
      "                ",
      "                ",
      "                ",
      "                ",
      "                ",
      "                ",
      "                ",
      "                ",
      "oDyoyfffpo      ",
      "lzi      f      ",
      " i       e      ",
      "         y      ",
      "         y      ",
      "         f m  m ",
      "        EEpeeoef",
      "         Eiiii i"
    ],
    [
      "t天ttttttt天tttt他t",
      " t       t    vv",
      " t v v   t  v   ",
      " t v  v vt    v ",
      " tvv     t   v  ",
      " t       t      ",
      " t    v  t  v v ",
      " 天      v怪      ",
      "yDfyoffyfe天ttttt",
      "lCi      e      ",
      " i       e v v v",
      "         e   v  ",
      "         o      ",
      "         o   v  ",
      "        DDpoeppy",
      "         E i   i"
    ]
  ]
}