{
  "xsize": 16,
  "zsize": 16,
  "palette": {
    "palette": [
      {
        "char": " ",
        "block": "minecraft:air"
      },
      {
        "char": "m",
        "block": "minecraft:air"
      },
      {
        "char": "p",
        "block": "minecraft:diorite"
      },
      {
        "char": "e",
        "block": "minecraft:smooth_quartz"
      },
      {
        "char": "死",
        "block": "minecraft:air"
      },
      {
        "char": "黑",
        "block": "minecraft:air"
      },
      {
        "char": "H",
        "block": "minecraft:cobblestone[weathering\u003dfalse]"
      },
      {
        "char": "z",
        "block": "minecraft:mossy_stone_bricks"
      },
      {
        "char": "g",
        "block": "minecraft:blue_concrete"
      },
      {
        "char": "C",
        "block": "minecraft:mossy_cobblestone"
      },
      {
        "char": "o",
        "block": "minecraft:quartz_block"
      },
      {
        "char": "f",
        "block": "minecraft:polished_diorite"
      },
      {
        "char": "y",
        "block": "minecraft:quartz_pillar[axis\u003dy]"
      },
      {
        "char": "Ұ",
        "block": "minecraft:air"
      },
      {
        "char": "ҭ",
        "block": "minecraft:air"
      },
      {
        "char": "思",
        "block": "minecraft:air"
      },
      {
        "char": "i",
        "block": "minecraft:air"
      },
      {
        "char": "O",
        "block": "minecraft:dark_oak_fence[east\u003dfalse,north\u003dfalse,south\u003dfalse,waterlogged\u003dfalse,west\u003dfalse]"
      },
      {
        "char": "那",
        "block": "minecraft:air"
      },
      {
        "char": "E",
        "block": "minecraft:stone_bricks[weathering\u003dfalse]"
      },
      {
        "char": "D",
        "block": "minecraft:cracked_stone_bricks"
      },
      {
        "char": "请",
        "block": "minecraft:air"
      },
      {
        "char": "油",
        "block": "minecraft:air"
      },
      {
        "char": "j",
        "block": "minecraft:air"
      },
      {
        "char": "数",
        "block": "minecraft:air"
      },
      {
        "char": "天",
        "block": "minecraft:stone_slab[type\u003ddouble,waterlogged\u003dfalse,weathering\u003dfalse]"
      },
      {
        "char": "他",
        "block": "immersive_weathering:mossy_stone_slab[type\u003dbottom,waterlogged\u003dfalse]"
      },
      {
        "char": "t",
        "block": "minecraft:stone_slab[type\u003dbottom,waterlogged\u003dfalse,weathering\u003dfalse]"
      },
      {
        "char": "v",
        "block": "minecraft:air"
      }
    ]
  },
  "slices": [
    [
      "                ",
      " mm m m mmm m mm",
      "mp  e死 e   p黑死Hz",
      "ggggggggggggggCz",
      "gggggggggggggggo",
      "gggggggggggggggp",
      "gggggggggggggggo",
      "gCgggggggHgggggp",
      "fHfeeppfyzeeypof",
      "Ұ   ҭҭ思ҭ      ii",
      " i ii   ii  i   ",
      "                ",
      "                ",
      "                ",
      "          O     ",
      "                "
    ],
    [
      "                ",
      " mm m m mmm m mm",
      "mfepp死emo p那f死zC",
      "ggggggggggggggEC",
      "gggggggggggggggf",
      "gggggggggggggggf",
      "gggggggggggggggf",
      "gzgggggggCgggggf",
      "yCoeooeyfDpeyffo",
      "Ұ  ҭ请iiiҭҭ    ii",
      " i i    ii  i   ",
      "                ",
      "                ",
      "                ",
      "          O     ",
      "                "
    ],
    [
      "                ",
      " m    m  m  m mm",
      "mo  fmpm om那f那Ez",
      "ggggggggggggggEC",
      "gggggggggggggggy",
      "ggggggggggggggge",
      "gggggggggggggggo",
      "gzgggggggzgggggf",
      "oEfpfyepeHfyyypo",
      "Ұ ҭ iiiii ҭҭ  ii",
      " i          i   ",
      "                ",
      "                ",
      "                ",
      "          O     ",
      "                "
    ],
    [
      "                ",
      "      m     m   ",
      "mmopmmem m mf那zz",
      "ggggggggggggggEC",
      "gggggggggggggggp",
      "gggggggggggggggo",
      "gggggggggggggggo",
      "gHgggggggEggggge",
      "ozeefpyefzoefeyp",
      "油ҭj iiii   油ҭ ii",
      " i          i   ",
      "                ",
      "                ",
      "                ",
      "          O     ",
      "                "
    ],
    [
      "                ",
      "                ",
      "mm  mmmm m mm那zz",
      "ggggggggggggggDD",
      "gggggggggggggggo",
      "gggggggggggggggf",
      "gggggggggggggggf",
      "gEgggggggEgggggy",
      "ozoofoooyCeefyee",
      "ҭ   ii     ҭ    ",
      "                ",
      "                ",
      "                ",
      "                ",
      "          O     ",
      "                "
    ],
    [
      "                ",
      "                ",
      "mm  数      mm那Ez",
      "ggggggggggggggzE",
      "gggggggggggggggf",
      "gggggggggggggggf",
      "gggggggggggggggy",
      "gCgggggggEgggggp",
      "pEepfepfyzfeofee",
      " 天       他ҭ     ",
      " t  vv   t  vv  ",
      " t v v v t     v",
      " t v  v  t      ",
      " 他v  v   t v  vv",
      " t v v   tO v   ",
      " t       t      "
    ]
  ]
}