{
  "xsize": 16,
  "zsize": 16,
  "palette": {
    "palette": [
      {
        "char": " ",
        "block": "minecraft:air"
      },
      {
        "char": "F",
        "block": "minecraft:stone_brick_slab[type\u003dtop,waterlogged\u003dfalse,weathering\u003dfalse]"
      },
      {
        "char": "u",
        "block": "minecraft:smooth_quartz_slab[type\u003dbottom,waterlogged\u003dfalse]"
      },
      {
        "char": "E",
        "block": "minecraft:stone_bricks[weathering\u003dfalse]"
      },
      {
        "char": "C",
        "block": "minecraft:mossy_cobblestone"
      },
      {
        "char": "D",
        "block": "minecraft:cracked_stone_bricks"
      },
      {
        "char": "z",
        "block": "minecraft:mossy_stone_bricks"
      },
      {
        "char": "H",
        "block": "minecraft:cobblestone[weathering\u003dfalse]"
      },
      {
        "char": "e",
        "block": "minecraft:smooth_quartz"
      },
      {
        "char": "o",
        "block": "minecraft:quartz_block"
      },
      {
        "char": "h",
        "block": "minecraft:white_stained_glass"
      },
      {
        "char": "f",
        "block": "minecraft:polished_diorite"
      },
      {
        "char": "p",
        "block": "minecraft:diorite"
      },
      {
        "char": "呵",
        "block": "minecraft:air"
      },
      {
        "char": "思",
        "block": "minecraft:air"
      },
      {
        "char": "l",
        "block": "minecraft:air"
      },
      {
        "char": "j",
        "block": "minecraft:air"
      },
      {
        "char": "队",
        "block": "minecraft:air"
      },
      {
        "char": "必",
        "block": "minecraft:air"
      },
      {
        "char": "那",
        "block": "minecraft:air"
      },
      {
        "char": "x",
        "block": "minecraft:smooth_stone"
      },
      {
        "char": "头",
        "block": "minecraft:rail[shape\u003dsouth_east,waterlogged\u003dfalse]"
      },
      {
        "char": "考",
        "block": "minecraft:rail[shape\u003dsouth_west,waterlogged\u003dfalse]"
      },
      {
        "char": "城",
        "block": "minecraft:rail[shape\u003dnorth_south,waterlogged\u003dfalse]"
      },
      {
        "char": "难",
        "block": "minecraft:rail[shape\u003dnorth_east,waterlogged\u003dfalse]"
      },
      {
        "char": "喜",
        "block": "minecraft:rail[shape\u003dnorth_west,waterlogged\u003dfalse]"
      }
    ]
  },
  "slices": [
    [
      "                ",
      "FFFFFFFFFFFFFFFF",
      "uuuuuuuuuuuuuuuu",
      "uuuuuuuuuuuuuuuu",
      "uuuuuuuuuuuuuuuu",
      "uuuuuuuuuuuuuuuu",
      "uuuuuuuuuuuuuuuu",
      "uEuuuuuuuEuuuuuu",
      "ECDEDEDDDCzCHEDE",
      "eohhhhhhhfefeofo",
      "ffhhhhhhhepfeefe",
      "eehhhhhhhffoepep",
      "oehh呵hhhhoefeffp",
      "fehhh思hlheffppeo",
      "pfhhhj队hhpffffpp",
      "oehh必那hhhfefoffe"
    ],
    [
      "                ",
      "                ",
      "                ",
      "                ",
      "                ",
      "                ",
      "                ",
      "                ",
      "                ",
      "                ",
      "                ",
      "                ",
      "             xx ",
      "             xx ",
      "             xx ",
      "                "
    ],
    [
      "                ",
      "                ",
      "                ",
      "                ",
      "                ",
      "                ",
      "                ",
      "                ",
      "                ",
      "                ",
      "                ",
      "                ",
      "             头考 ",
      "             城城 ",
      "             难喜 ",
      "                "
    ],
    [
      "                ",
      "                ",
      "                ",
      "                ",
      "                ",
      "                ",
      "                ",
      "                ",
      "                ",
      "                ",
      "                ",
      "                ",
      "                ",
      "                ",
      "                ",
      "                "
    ],
    [
      "                ",
      "                ",
      "                ",
      "                ",
      "                ",
      "                ",
      "                ",
      "                ",
      "                ",
      "                ",
      "                ",
      "                ",
      "                ",
      "                ",
      "                ",
      "                "
    ],
    [
      "                ",
      "                ",
      "                ",
      "                ",
      "                ",
      "                ",
      "                ",
      "                ",
      "                ",
      "                ",
      "                ",
      "                ",
      "                ",
      "                ",
      "                ",
      "                "
    ]
  ]
}