{
  "xsize": 16,
  "zsize": 16,
  "palette": {
    "palette": [
      {
        "char": " ",
        "block": "minecraft:air"
      },
      {
        "char": "e",
        "block": "minecraft:smooth_quartz"
      },
      {
        "char": "p",
        "block": "minecraft:diorite"
      },
      {
        "char": "y",
        "block": "minecraft:quartz_pillar[axis\u003dy]"
      },
      {
        "char": "o",
        "block": "minecraft:quartz_block"
      },
      {
        "char": "f",
        "block": "minecraft:polished_diorite"
      },
      {
        "char": "i",
        "block": "minecraft:air"
      },
      {
        "char": "m",
        "block": "minecraft:air"
      },
      {
        "char": "l",
        "block": "minecraft:air"
      },
      {
        "char": "g",
        "block": "minecraft:blue_concrete"
      },
      {
        "char": "j",
        "block": "minecraft:air"
      },
      {
        "char": "受",
        "block": "minecraft:air"
      },
      {
        "char": "天",
        "block": "minecraft:stone_slab[type\u003ddouble,waterlogged\u003dfalse,weathering\u003dfalse]"
      },
      {
        "char": "t",
        "block": "minecraft:stone_slab[type\u003dbottom,waterlogged\u003dfalse,weathering\u003dfalse]"
      },
      {
        "char": "v",
        "block": "minecraft:air"
      },
      {
        "char": "他",
        "block": "immersive_weathering:mossy_stone_slab[type\u003dbottom,waterlogged\u003dfalse]"
      }
    ]
  },
  "slices": [
    [
      "epypeoeoppfoeefy",
      "ii iiii ii iiiii",
      "                ",
      "                ",
      "                ",
      "                ",
      "                ",
      "                ",
      "                ",
      "                ",
      "                ",
      "                ",
      "                ",
      "                ",
      "     m    m     ",
      "    lgj  lgj    "
    ],
    [
      "oeeeepfeyepofpef",
      "ii iiii ii iii  ",
      "                ",
      "                ",
      "                ",
      "                ",
      "                ",
      "                ",
      "                ",
      "                ",
      "                ",
      "                ",
      "                ",
      "                ",
      "     m    m     ",
      "    lgj  lgj    "
    ],
    [
      "feopeppfepfefepe",
      "i   iii  i iii  ",
      "                ",
      "                ",
      "                ",
      "                ",
      "                ",
      "                ",
      "                ",
      "                ",
      "                ",
      "                ",
      "                ",
      "                ",
      "     m    m     ",
      "    lg    gj    "
    ],
    [
      "oypeooffpeeeyofo",
      "i   ii   i iii  ",
      "                ",
      "                ",
      "                ",
      "                ",
      "                ",
      "                ",
      "                ",
      "                ",
      "                ",
      "                ",
      "                ",
      "                ",
      "                ",
      "                "
    ],
    [
      "efeeooefofepeefe",
      "i    i      i   ",
      "                ",
      "                ",
      "                ",
      "                ",
      "                ",
      "                ",
      "                ",
      "                ",
      "                ",
      "                ",
      "                ",
      "                ",
      "                ",
      "                "
    ],
    [
      "epfyffefffoyyyeo",
      "受  天       天    ",
      "   t v     t  v ",
      "   t   v   t  vv",
      "   t v  v  t   v",
      "v  t  v v  t v v",
      "   t  v    t    ",
      "  vt       t    ",
      "tt他天ttt他ttt天tttt",
      "v  t   v   t    ",
      "   t    v  t  v ",
      " v t  v    t  vv",
      "   t v vv vt    ",
      "v  t       他v   ",
      "v  t     v t   v",
      "   t       t    "
    ]
  ]
}