{
  "xsize": 16,
  "zsize": 16,
  "palette": {
    "palette": [
      {
        "char": " ",
        "block": "minecraft:air"
      },
      {
        "char": "m",
        "block": "minecraft:air"
      },
      {
        "char": "g",
        "block": "minecraft:blue_concrete"
      },
      {
        "char": "j",
        "block": "minecraft:air"
      },
      {
        "char": "C",
        "block": "minecraft:mossy_cobblestone"
      },
      {
        "char": "z",
        "block": "minecraft:mossy_stone_bricks"
      },
      {
        "char": "H",
        "block": "minecraft:cobblestone[weathering\u003dfalse]"
      },
      {
        "char": "e",
        "block": "minecraft:smooth_quartz"
      },
      {
        "char": "y",
        "block": "minecraft:quartz_pillar[axis\u003dy]"
      },
      {
        "char": "f",
        "block": "minecraft:polished_diorite"
      },
      {
        "char": "p",
        "block": "minecraft:diorite"
      },
      {
        "char": "D",
        "block": "minecraft:cracked_stone_bricks"
      },
      {
        "char": "i",
        "block": "minecraft:air"
      },
      {
        "char": "Ұ",
        "block": "minecraft:air"
      },
      {
        "char": "请",
        "block": "minecraft:air"
      },
      {
        "char": "l",
        "block": "minecraft:air"
      },
      {
        "char": "O",
        "block": "minecraft:dark_oak_fence[east\u003dfalse,north\u003dfalse,south\u003dfalse,waterlogged\u003dfalse,west\u003dfalse]"
      },
      {
        "char": "E",
        "block": "minecraft:stone_bricks[weathering\u003dfalse]"
      },
      {
        "char": "o",
        "block": "minecraft:quartz_block"
      },
      {
        "char": "数",
        "block": "minecraft:air"
      },
      {
        "char": "F",
        "block": "minecraft:stone_brick_slab[type\u003dtop,waterlogged\u003dfalse,weathering\u003dfalse]"
      },
      {
        "char": "t",
        "block": "minecraft:stone_slab[type\u003dbottom,waterlogged\u003dfalse,weathering\u003dfalse]"
      },
      {
        "char": "受",
        "block": "minecraft:air"
      },
      {
        "char": "v",
        "block": "minecraft:air"
      },
      {
        "char": "身",
        "block": "minecraft:stone_brick_slab[type\u003dbottom,waterlogged\u003dfalse,weathering\u003dfalse]"
      },
      {
        "char": "马",
        "block": "minecraft:stone_brick_slab[type\u003ddouble,waterlogged\u003dfalse,weathering\u003dfalse]"
      }
    ]
  },
  "slices": [
    [
      "                ",
      "                ",
      "                ",
      "                ",
      "  m m    m      ",
      "gggggggggg      ",
      "         ggj    ",
      " C       zH     ",
      "eHyfypfffDHj    ",
      "  iiii iҰf请     ",
      "        lfj     ",
      "        lfj     ",
      "        l j     ",
      "        lfj     ",
      "O       lfm     ",
      "         fCj  mm"
    ],
    [
      "                ",
      "                ",
      "                ",
      "                ",
      "                ",
      "                ",
      "gggggggggg      ",
      " E       EC     ",
      "fEfeefyeyCzj    ",
      "  iiii  lf请     ",
      "        l j     ",
      "         ej     ",
      "        lfj     ",
      "        lpj     ",
      "O       lem     ",
      "         ezj  mm"
    ],
    [
      "                ",
      "                ",
      "                ",
      "                ",
      "                ",
      "                ",
      "                ",
      "gggggggggCE     ",
      "yEypffyoeCEj    ",
      "  iiii  lf请     ",
      "        lfj     ",
      "         f      ",
      "        loj     ",
      "        lej     ",
      "O       lpm     ",
      "         ezj  mm"
    ],
    [
      "                ",
      "                ",
      "                ",
      "                ",
      "                ",
      "                ",
      "                ",
      " H       EC     ",
      "yzfepeopeEHj    ",
      "  ii i  lf请     ",
      "        lpj     ",
      "         o      ",
      "        lfj     ",
      "        lej     ",
      "O        ym     ",
      "         yzj  mm"
    ],
    [
      "                ",
      "                ",
      "                ",
      "                ",
      "                ",
      "                ",
      "                ",
      " E       DD     ",
      "fDeeffefpHEj    ",
      "  ii i   o请     ",
      "         pj     ",
      "         e      ",
      "        lfj     ",
      "         f      ",
      "O        p数     ",
      "         oC    F"
    ],
    [
      "                ",
      "                ",
      "                ",
      "                ",
      "                ",
      "                ",
      "                ",
      " C       CC     ",
      "pEoeffoeeECj    ",
      " t受v v   f请     ",
      " t       f      ",
      " t       y      ",
      " t v    vfj     ",
      " tv      fF    身",
      "Ot       e马FFFF身",
      " t    v  e马马马马马 "
    ]
  ]
}